Workbook

Sheet Draft
A2: Pick | B2: Your Pick | C2: Round 1 | D2: Round 2 | E2: Round 3 | F2: Round 4 | G2: Round 5 | H2: Round 6 | I2: Round 7 | J2: Round 8 | K2: Round 9 | L2: Round 10 | M2: Round 11 | N2: Round 12
A3: 1 | B3: FALSE | C3: Nikola Jokic | D3: Tyrese Haliburton | E3: Donovan Mitchell | F3: John Collins | G3: Jamal Murray | H3: Marcus Smart | I3: Tyrese Maxey | J3: Gordon Hayward | K3: RJ Barrett | L3: Luguentz Dort | M3: Onyeka Okongwu
A4: 2 | B4: FALSE | C4: Giannis Antetokounmpo | D4: LeBron James | E4: Jrue Holiday | F4: Khris Middleton | G4: Jakob Poeltl | H4: OG Anunoby | I4: Jabari Smith Jr | J4: Anfernee Simons | K4: Herbert Jones | O4: L4 y M4 que onda?
A5: 3 | B5: FALSE | C5: Joel Embiid | D5: Paul George | E5: Dejounte Murray | F5: Deandre Ayton | G5: Jalen Green | H5: Gary Trent Jr. | I5: Mikal Bridges | J5: Jerami Grant | K5: Cameron Johnson | L5: Robert Williams | M5: JaVale McGee
A6: 4 | B6: FALSE | C6: Luka Doncic | D6: Anthony Davis | E6: Bradley Beal | F6: De'Aaron Fox | G6: Jonas Valanciunas | H6: Jalen Brunson | I6: Michael Porter Jr. | J6: Jalen Smith | K6: Brook Lopez | L6: Spencer Dinwiddie | M6: Steven Adams
A7: 5 | B7: FALSE | C7: James Harden | D7: Kyrie Irving | E7: Zion Williamson | F7: Jarrett Allen | G7: Christian Wood | H7: Wendell Carter Jr. | I7: Keldon Johnson | J7: Mitchell Robinson | K7: Nicolas Claxton | L7: Josh Hart | M7: Isaiah Stewart
A8: 6 | B8: TRUE | C8: Kevin Durant | D8: Bam Adebayo | E8: Jimmy Butler | F8: Myles Turner | G8: Desmond Bane | H8: Jordan Poole | I8: Jusuf Nurkic | J8: Al Horford | K8: Keegan Murray | L8: Kelly Olynyk | M8: Bobby Portis
A9: 7 | B9: FALSE | C9: Stephen Curry | D9: Fred VanVleet | E9: Chris Paul | F9: Nikola Vucevic | G9: Draymond Green | H9: D'Angelo Russell | I9: Klay Thompson | J9: Saddiq Bey | K9: Jarred Vanderbilt | L9: Monte Morris | M9: Ivica Zubac
A10: 8 | B10: FALSE | C10: Jayson Tatum | D10: Devin Booker | E10: Darius Garland | F10: DeMar DeRozan | G10: Jaylen Brown | H10: CJ McCollum | I10: Kyle Lowry | J10: Andrew Wiggins | K10: Kyle Kuzma | L10: Malcolm Brogdon | M10: Bojan Bogdanovic
A11: 9 | B11: FALSE | C11: LaMelo Ball | D11: Ja Morant | E11: Kristaps Porzingis | F11: Shai Gilgeous-Alexander | G11: Terry Rozier | H11: Brandon Ingram | I11: Lauri Markkanen | J11: Tobias Harris | K11: Tre Jones | L11: Jaren Jackson Jr. | M11: Isaiah Hartenstein
A12: 10 | B12: FALSE | C12: Trae Young | D12: Rudy Gobert | E12: Cade Cunningham | F12: Zach LaVine | G12: Julius Randle | H12: Devin Vassell | I12: Buddy Hield | J12: PJ Washington | K12: Mike Conley | L12: Brandon Clarke | M12: Cole Anthony
A13: 11 | B13: FALSE | C13: Karl-Anthony Towns | D13: Domantas Sabonis | E13: Pascal Siakam | F13: Scottie Barnes | G13: Ben Simmons | H13: Kevin Porter Jr. | I13: Franz Wagner | J13: Tyler Herro | K13: Clint Capela | L13: Bones Hyland | M13: Harrison Barnes | N13: Markelle Fultz
A14: 12 | B14: FALSE | C14: Damian Lillard | D14: Kawhi Leonard | E14: Anthony Edwards | F14: Evan Mobley | G14: Alperen Sengun | H14: Josh Giddey | I14: Paolo Banchero | J14: Collin Sexton | K14: Jalen Suggs | L14: Isaiah Jackson | M14: Chris Duarte | N14: Alex Caruso
B16: Pick # | C16: =IF(B3=TRUE,"1",IF(B4=TRUE,"2", IF(B5=True, "3",IF(B6=True, "4",IF(B7=True, "5",IF(B8=True, "6",IF(B9=True, "7",IF(B10=True, "8",IF(B11=True, "9",IF(B12=True, "10",IF(B13=True, "11",IF(B14=True, "12")))))))))))) -> 6 | D16: =IF(B3=TRUE,"24",IF(B4=TRUE,"23", IF(B5=True, "22",IF(B6=True, "21",IF(B7=True, "20",IF(B8=True, "19",IF(B9=True, "18",IF(B10=True, "17",IF(B11=True, "16",IF(B12=True, "15",IF(B13=True, "14",IF(B14=True, "13")))))))))))) -> 19 | E16: =IF(B3=TRUE,"25",IF(B4=TRUE,"26", IF(B5=True, "27",IF(B6=True, "28",IF(B7=True, "29",IF(B8=True, "30",IF(B9=True, "31",IF(B10=True, "32",IF(B11=True, "33",IF(B12=True, "34",IF(B13=True, "35",IF(B14=True, "36")))))))))))) -> 30 | F16: =IF(B3=TRUE,"48",IF(B4=TRUE,"47", IF(B5=True, "46",IF(B6=True, "45",IF(B7=True, "44",IF(B8=True, "43",IF(B9=True, "42",IF(B10=True, "41",IF(B11=True, "40",IF(B12=True, "39",IF(B13=True, "38",IF(B14=True, "37")))))))))))) -> 43 | G16: =IF(B3=TRUE,"49",IF(B4=TRUE,"50", IF(B5=True, "51",IF(B6=True, "52",IF(B7=True, "53",IF(B8=True, "54",IF(B9=True, "55",IF(B10=True, "56",IF(B11=True, "57",IF(B12=True, "58",IF(B13=True, "59",IF(B14=True, "60")))))))))))) -> 54 | H16: =IF(B3=TRUE,"72",IF(B4=TRUE,"71", IF(B5=True, "70",IF(B6=True, "69",IF(B7=True, "68",IF(B8=True, "67",IF(B9=True, "66",IF(B10=True, "65",IF(B11=True, "64",IF(B12=True, "63",IF(B13=True, "62",IF(B14=True, "61")))))))))))) -> 67 | I16: =IF(B3=TRUE,"73",IF(B4=TRUE,"74", IF(B5=True, "75",IF(B6=True, "76",IF(B7=True, "77",IF(B8=True, "78",IF(B9=True, "79",IF(B10=True, "80",IF(B11=True, "81",IF(B12=True, "82",IF(B13=True, "83",IF(B14=True, "84")))))))))))) -> 78 | J16: =IF(B3=TRUE,"96",IF(B4=TRUE,"95", IF(B5=True, "94",IF(B6=True, "93",IF(B7=True, "92",IF(B8=True, "91",IF(B9=True, "90",IF(B10=True, "89",IF(B11=True, "88",IF(B12=True, "87",IF(B13=True, "86",IF(B14=True, "85")))))))))))) -> 91 | K16: =IF(B3=TRUE,"97",IF(B4=TRUE,"98", IF(B5=True, "99",IF(B6=True, "100",IF(B7=True, "101",IF(B8=True, "102",IF(B9=True, "103",IF(B10=True, "104",IF(B11=True, "105",IF(B12=True, "106",IF(B13=True, "107",IF(B14=True, "108")))))))))))) -> 102 | L16: =IF(B3=TRUE,"120",IF(B4=TRUE,"119", IF(B5=True, "118",IF(B6=True, "117",IF(B7=True, "116",IF(B8=True, "115",IF(B9=True, "114",IF(B10=True, "113",IF(B11=True, "112",IF(B12=True, "111",IF(B13=True, "110",IF(B14=True, "109")))))))))))) -> 115 | M16: =IF(B3=TRUE,"121",IF(B4=TRUE,"122", IF(B5=True, "123",IF(B6=True, "124",IF(B7=True, "125",IF(B8=True, "126",IF(B9=True, "127",IF(B10=True, "128",IF(B11=True, "129",IF(B12=True, "130",IF(B13=True, "131",IF(B14=True, "132")))))))))))) -> 126 | N16: =IF(B3=TRUE,"144",IF(B4=TRUE,"143", IF(B5=True, "142",IF(B6=True, "141",IF(B7=True, "140",IF(B8=True, "139",IF(B9=True, "138",IF(B10=True, "137",IF(B11=True, "136",IF(B12=True, "135",IF(B13=True, "134",IF(B14=True, "133")))))))))))) -> 139
B17: 3RR | C17: =C16 -> 6 | D17: =D16 -> 19 | E17: =E16+IF($B$3,11, IF($B$4,9,IF($B$5,7,IF($B$6,5,IF($B$7,3,IF($B$8,1,IF($B$9,-1,IF($B$10,-3,IF($B$11,-5,IF($B$12,-7, IF($B$13,-9, IF($B$14,-11)))))))))))) -> 31 | F17: =F16-IF($B$3,11, IF($B$4,9,IF($B$5,7,IF($B$6,5,IF($B$7,3,IF($B$8,1,IF($B$9,-1,IF($B$10,-3,IF($B$11,-5,IF($B$12,-7, IF($B$13,-9, IF($B$14,-11)))))))))))) -> 42 | G17: =G16+IF($B$3,11, IF($B$4,9,IF($B$5,7,IF($B$6,5,IF($B$7,3,IF($B$8,1,IF($B$9,-1,IF($B$10,-3,IF($B$11,-5,IF($B$12,-7, IF($B$13,-9, IF($B$14,-11)))))))))))) -> 55 | H17: =H16-IF($B$3,11, IF($B$4,9,IF($B$5,7,IF($B$6,5,IF($B$7,3,IF($B$8,1,IF($B$9,-1,IF($B$10,-3,IF($B$11,-5,IF($B$12,-7, IF($B$13,-9, IF($B$14,-11)))))))))))) -> 66 | I17: =I16+IF($B$3,11, IF($B$4,9,IF($B$5,7,IF($B$6,5,IF($B$7,3,IF($B$8,1,IF($B$9,-1,IF($B$10,-3,IF($B$11,-5,IF($B$12,-7, IF($B$13,-9, IF($B$14,-11)))))))))))) -> 79 | J17: =J16-IF($B$3,11, IF($B$4,9,IF($B$5,7,IF($B$6,5,IF($B$7,3,IF($B$8,1,IF($B$9,-1,IF($B$10,-3,IF($B$11,-5,IF($B$12,-7, IF($B$13,-9, IF($B$14,-11)))))))))))) -> 90 | K17: =K16+IF($B$3,11, IF($B$4,9,IF($B$5,7,IF($B$6,5,IF($B$7,3,IF($B$8,1,IF($B$9,-1,IF($B$10,-3,IF($B$11,-5,IF($B$12,-7, IF($B$13,-9, IF($B$14,-11)))))))))))) -> 103 | L17: =L16-IF($B$3,11, IF($B$4,9,IF($B$5,7,IF($B$6,5,IF($B$7,3,IF($B$8,1,IF($B$9,-1,IF($B$10,-3,IF($B$11,-5,IF($B$12,-7, IF($B$13,-9, IF($B$14,-11)))))))))))) -> 114 | M17: =M16+IF($B$3,11, IF($B$4,9,IF($B$5,7,IF($B$6,5,IF($B$7,3,IF($B$8,1,IF($B$9,-1,IF($B$10,-3,IF($B$11,-5,IF($B$12,-7, IF($B$13,-9, IF($B$14,-11)))))))))))) -> 127 | N17: =N16-IF($B$3,11, IF($B$4,9,IF($B$5,7,IF($B$6,5,IF($B$7,3,IF($B$8,1,IF($B$9,-1,IF($B$10,-3,IF($B$11,-5,IF($B$12,-7, IF($B$13,-9, IF($B$14,-11)))))))))))) -> 138
C19: MAKE A COPY
C20: File -> Make a copy

Sheet Projections
G2: Sort by | H2: Remove Drafted | J2: -1 Cat | K2: -2 Cat | L2: PTS | M2: 3P | N2: REB | O2: AST | P2: STL | Q2: BLK | R2: FG% | S2: FT% | T2: TO | U2: PG | V2: SG | W2: SF | X2: PF | Y2: C
G3: PuntV | H3: TRUE | J3: FALSE | K3: FALSE | L3: 1.5 | M3: 1 | N3: 1 | O3: 1.25 | P3: 1.25 | Q3: 0 | R3: 0 | S3: 0.5 | T3: 0 | U3: PG | V3: SG | W3: SF | X3: PF | Y3: C
A5: TM | B5: W19 | C5: W20 | D5: W21 | E5: Total | F5: Rank | G5: LgRank | H5: Player | I5: GP | J5: Pos | K5: LeagV | L5: PuntV | M5: Punt+ | N5: PTS | O5: 3P | P5: REB | Q5: AST | R5: STL | S5: BLK | T5: FG% | U5: FT% | V5: TO | W5: z p/g | X5: z 3/g | Y5: z r/g | Z5: z a/g | AA5: z s/g | AB5: z b/g | AC5: z fg% | AD5: z ft% | AE5: z to/g
A6: =IF(VLOOKUP(H6,'Paste #BBall'!$C$2:$Q$201,3,)="BRO","BKN",IF(VLOOKUP(H6,'Paste #BBall'!$C$2:$Q$201,3,)="OKL","OKC",VLOOKUP(H6,'Paste #BBall'!$C$2:$Q$201,3,))) -> CHI | B6: =VLOOKUP(A6,'Paste #BBall'!$A$204:$D$233,4,) -> 4 | C6: =VLOOKUP(A6,'Paste #BBall'!$A$204:$C$233,3,) -> 2 | D6: =VLOOKUP(A6,'Paste #BBall'!$A$204:$B$233,2,) -> 3 | E6: =SUM(B6:D6) -> 9 | F6: 1 | G6: =IFERROR(__xludf.DUMMYFUNCTION("Filter('NO USAR3'!B5:Z395,IF('NO USAR3'!AA5:AA395="""",FALSE,TRUE),NOT(COUNTIF('NO USAR3'!A5:A148,'NO USAR3'!C5:C395)))"),76.0) -> 76 | H6: =IFERROR(__xludf.DUMMYFUNCTION("""COMPUTED_VALUE"""),"Lonzo Ball") -> Lonzo Ball | I6: =IFERROR(__xludf.DUMMYFUNCTION("""COMPUTED_VALUE"""),66.0) -> 66 | J6: =IFERROR(__xludf.DUMMYFUNCTION("""COMPUTED_VALUE"""),"PG") -> PG | K6: =IFERROR(__xludf.DUMMYFUNCTION("""COMPUTED_VALUE"""),-0.8495294929194547) -> -0.84952949 | L6: =IFERROR(__xludf.DUMMYFUNCTION("""COMPUTED_VALUE"""),-0.038425265583858725) -> -0.038425266 | M6: =IFERROR(__xludf.DUMMYFUNCTION("""COMPUTED_VALUE"""),0.811104227335596) -> 0.81110423 | N6: =IFERROR(__xludf.DUMMYFUNCTION("""COMPUTED_VALUE"""),10.3) -> 10.3 | O6: =IFERROR(__xludf.DUMMYFUNCTION("""COMPUTED_VALUE"""),2.3) -> 2.3 | P6: =IFERROR(__xludf.DUMMYFUNCTION("""COMPUTED_VALUE"""),4.4) -> 4.4 | Q6: =IFERROR(__xludf.DUMMYFUNCTION("""COMPUTED_VALUE"""),4.6) -> 4.6 | R6: =IFERROR(__xludf.DUMMYFUNCTION("""COMPUTED_VALUE"""),1.3) -> 1.3 | S6: =IFERROR(__xludf.DUMMYFUNCTION("""COMPUTED_VALUE"""),0.6) -> 0.6 | T6: =IFERROR(__xludf.DUMMYFUNCTION("""COMPUTED_VALUE"""),40.86021505376344) -> 40.860215 | U6: =IFERROR(__xludf.DUMMYFUNCTION("""COMPUTED_VALUE"""),80.0) -> 80 | V6: =IFERROR(__xludf.DUMMYFUNCTION("""COMPUTED_VALUE"""),2.1) -> 2.1 | W6: =IFERROR(__xludf.DUMMYFUNCTION("""COMPUTED_VALUE"""),-1.771598474828728) -> -1.7715985 | X6: =IFERROR(__xludf.DUMMYFUNCTION("""COMPUTED_VALUE"""),0.6865466714679571) -> 0.68654667 | Y6: =IFERROR(__xludf.DUMMYFUNCTION("""COMPUTED_VALUE"""),-0.683555322539028) -> -0.68355532 | Z6: =IFERROR(__xludf.DUMMYFUNCTION("""COMPUTED_VALUE"""),0.5124748429845672) -> 0.51247484 | AA6: =IFERROR(__xludf.DUMMYFUNCTION("""COMPUTED_VALUE"""),1.209937837528042) -> 1.2099378 | AB6: =IFERROR(__xludf.DUMMYFUNCTION("""COMPUTED_VALUE"""),0.0) -> 0 | AC6: =IFERROR(__xludf.DUMMYFUNCTION("""COMPUTED_VALUE"""),0.0) -> 0 | AD6: =IFERROR(__xludf.DUMMYFUNCTION("""COMPUTED_VALUE"""),0.007769179803330916) -> 0.0077691798 | AE6: =IFERROR(__xludf.DUMMYFUNCTION("""COMPUTED_VALUE"""),0.0) -> 0
A7: =IF(VLOOKUP(H7,'Paste #BBall'!$C$2:$Q$201,3,)="BRO","BKN",IF(VLOOKUP(H7,'Paste #BBall'!$C$2:$Q$201,3,)="OKL","OKC",VLOOKUP(H7,'Paste #BBall'!$C$2:$Q$201,3,))) -> ATL | B7: =VLOOKUP(A7,'Paste #BBall'!$A$204:$D$233,4,) -> 3 | C7: =VLOOKUP(A7,'Paste #BBall'!$A$204:$C$233,3,) -> 4 | D7: =VLOOKUP(A7,'Paste #BBall'!$A$204:$B$233,2,) -> 3 | E7: =SUM(B7:D7) -> 10 | F7: 2 | G7: =IFERROR(__xludf.DUMMYFUNCTION("""COMPUTED_VALUE"""),100.0) -> 100 | H7: =IFERROR(__xludf.DUMMYFUNCTION("""COMPUTED_VALUE"""),"Bogdan Bogdanovic") -> Bogdan Bogdanovic | I7: =IFERROR(__xludf.DUMMYFUNCTION("""COMPUTED_VALUE"""),64.0) -> 64 | J7: =IFERROR(__xludf.DUMMYFUNCTION("""COMPUTED_VALUE"""),"SG/SF") -> SG/SF | K7: =IFERROR(__xludf.DUMMYFUNCTION("""COMPUTED_VALUE"""),-1.8930544712636013) -> -1.8930545 | L7: =IFERROR(__xludf.DUMMYFUNCTION("""COMPUTED_VALUE"""),-0.43986477131310475) -> -0.43986477 | M7: =IFERROR(__xludf.DUMMYFUNCTION("""COMPUTED_VALUE"""),1.4531896999504965) -> 1.4531897 | N7: =IFERROR(__xludf.DUMMYFUNCTION("""COMPUTED_VALUE"""),14.7) -> 14.7 | O7: =IFERROR(__xludf.DUMMYFUNCTION("""COMPUTED_VALUE"""),2.6) -> 2.6 | P7: =IFERROR(__xludf.DUMMYFUNCTION("""COMPUTED_VALUE"""),3.9) -> 3.9 | Q7: =IFERROR(__xludf.DUMMYFUNCTION("""COMPUTED_VALUE"""),2.9) -> 2.9 | R7: =IFERROR(__xludf.DUMMYFUNCTION("""COMPUTED_VALUE"""),1.1) -> 1.1 | S7: =IFERROR(__xludf.DUMMYFUNCTION("""COMPUTED_VALUE"""),0.2) -> 0.2 | T7: =IFERROR(__xludf.DUMMYFUNCTION("""COMPUTED_VALUE"""),43.442622950819676) -> 43.442623 | U7: =IFERROR(__xludf.DUMMYFUNCTION("""COMPUTED_VALUE"""),83.33333333333333) -> 83.333333 | V7: =IFERROR(__xludf.DUMMYFUNCTION("""COMPUTED_VALUE"""),1.1) -> 1.1 | W7: =IFERROR(__xludf.DUMMYFUNCTION("""COMPUTED_VALUE"""),-0.5999451306365412) -> -0.59994513 | X7: =IFERROR(__xludf.DUMMYFUNCTION("""COMPUTED_VALUE"""),0.9865333402325488) -> 0.98653334 | Y7: =IFERROR(__xludf.DUMMYFUNCTION("""COMPUTED_VALUE"""),-0.8876630240586981) -> -0.88766302 | Z7: =IFERROR(__xludf.DUMMYFUNCTION("""COMPUTED_VALUE"""),-0.4577036153711197) -> -0.45770362 | AA7: =IFERROR(__xludf.DUMMYFUNCTION("""COMPUTED_VALUE"""),0.39233811965195126) -> 0.39233812 | AB7: =IFERROR(__xludf.DUMMYFUNCTION("""COMPUTED_VALUE"""),0.0) -> 0 | AC7: =IFERROR(__xludf.DUMMYFUNCTION("""COMPUTED_VALUE"""),0.0) -> 0 | AD7: =IFERROR(__xludf.DUMMYFUNCTION("""COMPUTED_VALUE"""),0.1265755388687542) -> 0.12657554 | AE7: =IFERROR(__xludf.DUMMYFUNCTION("""COMPUTED_VALUE"""),0.0) -> 0
A8: =IF(VLOOKUP(H8,'Paste #BBall'!$C$2:$Q$201,3,)="BRO","BKN",IF(VLOOKUP(H8,'Paste #BBall'!$C$2:$Q$201,3,)="OKL","OKC",VLOOKUP(H8,'Paste #BBall'!$C$2:$Q$201,3,))) -> MEM | B8: =VLOOKUP(A8,'Paste #BBall'!$A$204:$D$233,4,) -> 4 | C8: =VLOOKUP(A8,'Paste #BBall'!$A$204:$C$233,3,) -> 3 | D8: =VLOOKUP(A8,'Paste #BBall'!$A$204:$B$233,2,) -> 4 | E8: =SUM(B8:D8) -> 11 | F8: 3 | G8: =IFERROR(__xludf.DUMMYFUNCTION("""COMPUTED_VALUE"""),124.0) -> 124 | H8: =IFERROR(__xludf.DUMMYFUNCTION("""COMPUTED_VALUE"""),"Dillon Brooks") -> Dillon Brooks | I8: =IFERROR(__xludf.DUMMYFUNCTION("""COMPUTED_VALUE"""),72.0) -> 72 | J8: =IFERROR(__xludf.DUMMYFUNCTION("""COMPUTED_VALUE"""),"SG/SF") -> SG/SF | K8: =IFERROR(__xludf.DUMMYFUNCTION("""COMPUTED_VALUE"""),-2.6767779097681297) -> -2.6767779 | L8: =IFERROR(__xludf.DUMMYFUNCTION("""COMPUTED_VALUE"""),-0.8015330545038539) -> -0.80153305 | M8: =IFERROR(__xludf.DUMMYFUNCTION("""COMPUTED_VALUE"""),1.8752448552642758) -> 1.8752449 | N8: =IFERROR(__xludf.DUMMYFUNCTION("""COMPUTED_VALUE"""),19.6) -> 19.6 | O8: =IFERROR(__xludf.DUMMYFUNCTION("""COMPUTED_VALUE"""),1.5) -> 1.5 | P8: =IFERROR(__xludf.DUMMYFUNCTION("""COMPUTED_VALUE"""),3.5) -> 3.5 | Q8: =IFERROR(__xludf.DUMMYFUNCTION("""COMPUTED_VALUE"""),2.4) -> 2.4 | R8: =IFERROR(__xludf.DUMMYFUNCTION("""COMPUTED_VALUE"""),1.0) -> 1 | S8: =IFERROR(__xludf.DUMMYFUNCTION("""COMPUTED_VALUE"""),0.3) -> 0.3 | T8: =IFERROR(__xludf.DUMMYFUNCTION("""COMPUTED_VALUE"""),42.13483146067416) -> 42.134831 | U8: =IFERROR(__xludf.DUMMYFUNCTION("""COMPUTED_VALUE"""),86.11111111111111) -> 86.111111 | V8: =IFERROR(__xludf.DUMMYFUNCTION("""COMPUTED_VALUE"""),1.8) -> 1.8 | W8: =IFERROR(__xludf.DUMMYFUNCTION("""COMPUTED_VALUE"""),0.7048506390320313) -> 0.70485064 | X8: =IFERROR(__xludf.DUMMYFUNCTION("""COMPUTED_VALUE"""),-0.1134177785709532) -> -0.11341778 | Y8: =IFERROR(__xludf.DUMMYFUNCTION("""COMPUTED_VALUE"""),-1.0509491852744342) -> -1.0509492 | Z8: =IFERROR(__xludf.DUMMYFUNCTION("""COMPUTED_VALUE"""),-0.743050220769851) -> -0.74305022 | AA8: =IFERROR(__xludf.DUMMYFUNCTION("""COMPUTED_VALUE"""),-0.01646173928609459) -> -0.016461739 | AB8: =IFERROR(__xludf.DUMMYFUNCTION("""COMPUTED_VALUE"""),0.0) -> 0 | AC8: =IFERROR(__xludf.DUMMYFUNCTION("""COMPUTED_VALUE"""),0.0) -> 0 | AD8: =IFERROR(__xludf.DUMMYFUNCTION("""COMPUTED_VALUE"""),0.4174952303654477) -> 0.41749523 | AE8: =IFERROR(__xludf.DUMMYFUNCTION("""COMPUTED_VALUE"""),0.0) -> 0
A9: =IF(VLOOKUP(H9,'Paste #BBall'!$C$2:$Q$201,3,)="BRO","BKN",IF(VLOOKUP(H9,'Paste #BBall'!$C$2:$Q$201,3,)="OKL","OKC",VLOOKUP(H9,'Paste #BBall'!$C$2:$Q$201,3,))) -> PHI | B9: =VLOOKUP(A9,'Paste #BBall'!$A$204:$D$233,4,) -> 3 | C9: =VLOOKUP(A9,'Paste #BBall'!$A$204:$C$233,3,) -> 4 | D9: =VLOOKUP(A9,'Paste #BBall'!$A$204:$B$233,2,) -> 3 | E9: =SUM(B9:D9) -> 10 | F9: 4 | G9: =IFERROR(__xludf.DUMMYFUNCTION("""COMPUTED_VALUE"""),96.0) -> 96 | H9: =IFERROR(__xludf.DUMMYFUNCTION("""COMPUTED_VALUE"""),"De'Anthony Melton") -> De'Anthony Melton | I9: =IFERROR(__xludf.DUMMYFUNCTION("""COMPUTED_VALUE"""),72.0) -> 72 | J9: =IFERROR(__xludf.DUMMYFUNCTION("""COMPUTED_VALUE"""),"PG/SG") -> PG/SG | K9: =IFERROR(__xludf.DUMMYFUNCTION("""COMPUTED_VALUE"""),-1.817659418801747) -> -1.8176594 | L9: =IFERROR(__xludf.DUMMYFUNCTION("""COMPUTED_VALUE"""),-1.0159198979675303) -> -1.0159199 | M9: =IFERROR(__xludf.DUMMYFUNCTION("""COMPUTED_VALUE"""),0.8017395208342166) -> 0.80173952 | N9: =IFERROR(__xludf.DUMMYFUNCTION("""COMPUTED_VALUE"""),12.1) -> 12.1 | O9: =IFERROR(__xludf.DUMMYFUNCTION("""COMPUTED_VALUE"""),2.0) -> 2 | P9: =IFERROR(__xludf.DUMMYFUNCTION("""COMPUTED_VALUE"""),4.1) -> 4.1 | Q9: =IFERROR(__xludf.DUMMYFUNCTION("""COMPUTED_VALUE"""),2.7) -> 2.7 | R9: =IFERROR(__xludf.DUMMYFUNCTION("""COMPUTED_VALUE"""),1.3) -> 1.3 | S9: =IFERROR(__xludf.DUMMYFUNCTION("""COMPUTED_VALUE"""),0.6) -> 0.6 | T9: =IFERROR(__xludf.DUMMYFUNCTION("""COMPUTED_VALUE"""),41.12149532710281) -> 41.121495 | U9: =IFERROR(__xludf.DUMMYFUNCTION("""COMPUTED_VALUE"""),81.25) -> 81.25 | V9: =IFERROR(__xludf.DUMMYFUNCTION("""COMPUTED_VALUE"""),1.7) -> 1.7 | W9: =IFERROR(__xludf.DUMMYFUNCTION("""COMPUTED_VALUE"""),-1.2922857431137424) -> -1.2922857 | X9: =IFERROR(__xludf.DUMMYFUNCTION("""COMPUTED_VALUE"""),0.3865600027033658) -> 0.38656 | Y9: =IFERROR(__xludf.DUMMYFUNCTION("""COMPUTED_VALUE"""),-0.8060199434508303) -> -0.80601994 | Z9: =IFERROR(__xludf.DUMMYFUNCTION("""COMPUTED_VALUE"""),-0.5718422575306121) -> -0.57184226 | AA9: =IFERROR(__xludf.DUMMYFUNCTION("""COMPUTED_VALUE"""),1.209937837528042) -> 1.2099378 | AB9: =IFERROR(__xludf.DUMMYFUNCTION("""COMPUTED_VALUE"""),0.0) -> 0 | AC9: =IFERROR(__xludf.DUMMYFUNCTION("""COMPUTED_VALUE"""),0.0) -> 0 | AD9: =IFERROR(__xludf.DUMMYFUNCTION("""COMPUTED_VALUE"""),0.05773020589624655) -> 0.057730206 | AE9: =IFERROR(__xludf.DUMMYFUNCTION("""COMPUTED_VALUE"""),0.0) -> 0
A10: =IF(VLOOKUP(H10,'Paste #BBall'!$C$2:$Q$201,3,)="BRO","BKN",IF(VLOOKUP(H10,'Paste #BBall'!$C$2:$Q$201,3,)="OKL","OKC",VLOOKUP(H10,'Paste #BBall'!$C$2:$Q$201,3,))) -> CHA | B10: =VLOOKUP(A10,'Paste #BBall'!$A$204:$D$233,4,) -> 3 | C10: =VLOOKUP(A10,'Paste #BBall'!$A$204:$C$233,3,) -> 4 | D10: =VLOOKUP(A10,'Paste #BBall'!$A$204:$B$233,2,) -> 2 | E10: =SUM(B10:D10) -> 9 | F10: 5 | G10: =IFERROR(__xludf.DUMMYFUNCTION("""COMPUTED_VALUE"""),137.0) -> 137 | H10: =IFERROR(__xludf.DUMMYFUNCTION("""COMPUTED_VALUE"""),"Kelly Oubre Jr.") -> Kelly Oubre Jr. | I10: =IFERROR(__xludf.DUMMYFUNCTION("""COMPUTED_VALUE"""),70.0) -> 70 | J10: =IFERROR(__xludf.DUMMYFUNCTION("""COMPUTED_VALUE"""),"SG/PF") -> SG/PF | K10: =IFERROR(__xludf.DUMMYFUNCTION("""COMPUTED_VALUE"""),-3.164588205533593) -> -3.1645882 | L10: =IFERROR(__xludf.DUMMYFUNCTION("""COMPUTED_VALUE"""),-1.4644166934643184) -> -1.4644167 | M10: =IFERROR(__xludf.DUMMYFUNCTION("""COMPUTED_VALUE"""),1.7001715120692746) -> 1.7001715 | N10: =IFERROR(__xludf.DUMMYFUNCTION("""COMPUTED_VALUE"""),16.2) -> 16.2 | O10: =IFERROR(__xludf.DUMMYFUNCTION("""COMPUTED_VALUE"""),2.7) -> 2.7 | P10: =IFERROR(__xludf.DUMMYFUNCTION("""COMPUTED_VALUE"""),4.2) -> 4.2 | Q10: =IFERROR(__xludf.DUMMYFUNCTION("""COMPUTED_VALUE"""),1.2) -> 1.2 | R10: =IFERROR(__xludf.DUMMYFUNCTION("""COMPUTED_VALUE"""),1.1) -> 1.1 | S10: =IFERROR(__xludf.DUMMYFUNCTION("""COMPUTED_VALUE"""),0.4) -> 0.4 | T10: =IFERROR(__xludf.DUMMYFUNCTION("""COMPUTED_VALUE"""),43.609022556390975) -> 43.609023 | U10: =IFERROR(__xludf.DUMMYFUNCTION("""COMPUTED_VALUE"""),66.66666666666666) -> 66.666667 | V10: =IFERROR(__xludf.DUMMYFUNCTION("""COMPUTED_VALUE"""),1.0) -> 1 | W10: =IFERROR(__xludf.DUMMYFUNCTION("""COMPUTED_VALUE"""),-0.20051785420738652) -> -0.20051785 | X10: =IFERROR(__xludf.DUMMYFUNCTION("""COMPUTED_VALUE"""),1.0865288964874127) -> 1.0865289 | Y10: =IFERROR(__xludf.DUMMYFUNCTION("""COMPUTED_VALUE"""),-0.765198403146896) -> -0.7651984 | Z10: =IFERROR(__xludf.DUMMYFUNCTION("""COMPUTED_VALUE"""),-1.427882073726807) -> -1.4278821 | AA10: =IFERROR(__xludf.DUMMYFUNCTION("""COMPUTED_VALUE"""),0.39233811965195126) -> 0.39233812 | AB10: =IFERROR(__xludf.DUMMYFUNCTION("""COMPUTED_VALUE"""),0.0) -> 0 | AC10: =IFERROR(__xludf.DUMMYFUNCTION("""COMPUTED_VALUE"""),0.0) -> 0 | AD10: =IFERROR(__xludf.DUMMYFUNCTION("""COMPUTED_VALUE"""),-0.5496853785225927) -> -0.54968538 | AE10: =IFERROR(__xludf.DUMMYFUNCTION("""COMPUTED_VALUE"""),0.0) -> 0
A11: =IF(VLOOKUP(H11,'Paste #BBall'!$C$2:$Q$201,3,)="BRO","BKN",IF(VLOOKUP(H11,'Paste #BBall'!$C$2:$Q$201,3,)="OKL","OKC",VLOOKUP(H11,'Paste #BBall'!$C$2:$Q$201,3,))) -> IND | B11: =VLOOKUP(A11,'Paste #BBall'!$A$204:$D$233,4,) -> 3 | C11: =VLOOKUP(A11,'Paste #BBall'!$A$204:$C$233,3,) -> 3 | D11: =VLOOKUP(A11,'Paste #BBall'!$A$204:$B$233,2,) -> 3 | E11: =SUM(B11:D11) -> 9 | F11: 6 | G11: =IFERROR(__xludf.DUMMYFUNCTION("""COMPUTED_VALUE"""),133.0) -> 133 | H11: =IFERROR(__xludf.DUMMYFUNCTION("""COMPUTED_VALUE"""),"Chris Duarte") -> Chris Duarte | I11: =IFERROR(__xludf.DUMMYFUNCTION("""COMPUTED_VALUE"""),67.0) -> 67 | J11: =IFERROR(__xludf.DUMMYFUNCTION("""COMPUTED_VALUE"""),"SG") -> SG | K11: =IFERROR(__xludf.DUMMYFUNCTION("""COMPUTED_VALUE"""),-3.059400187946779) -> -3.0594002 | L11: =IFERROR(__xludf.DUMMYFUNCTION("""COMPUTED_VALUE"""),-1.750132341625896) -> -1.7501323 | M11: =IFERROR(__xludf.DUMMYFUNCTION("""COMPUTED_VALUE"""),1.309267846320883) -> 1.3092678 | N11: =IFERROR(__xludf.DUMMYFUNCTION("""COMPUTED_VALUE"""),13.9) -> 13.9 | O11: =IFERROR(__xludf.DUMMYFUNCTION("""COMPUTED_VALUE"""),1.8) -> 1.8 | P11: =IFERROR(__xludf.DUMMYFUNCTION("""COMPUTED_VALUE"""),4.3) -> 4.3 | Q11: =IFERROR(__xludf.DUMMYFUNCTION("""COMPUTED_VALUE"""),2.2) -> 2.2 | R11: =IFERROR(__xludf.DUMMYFUNCTION("""COMPUTED_VALUE"""),1.1) -> 1.1 | S11: =IFERROR(__xludf.DUMMYFUNCTION("""COMPUTED_VALUE"""),0.2) -> 0.2 | T11: =IFERROR(__xludf.DUMMYFUNCTION("""COMPUTED_VALUE"""),43.69747899159664) -> 43.697479 | U11: =IFERROR(__xludf.DUMMYFUNCTION("""COMPUTED_VALUE"""),80.95238095238095) -> 80.952381 | V11: =IFERROR(__xludf.DUMMYFUNCTION("""COMPUTED_VALUE"""),1.7) -> 1.7 | W11: =IFERROR(__xludf.DUMMYFUNCTION("""COMPUTED_VALUE"""),-0.8129730113987568) -> -0.81297301 | X11: =IFERROR(__xludf.DUMMYFUNCTION("""COMPUTED_VALUE"""),0.18656889019363826) -> 0.18656889 | Y11: =IFERROR(__xludf.DUMMYFUNCTION("""COMPUTED_VALUE"""),-0.7243768628429622) -> -0.72437686 | Z11: =IFERROR(__xludf.DUMMYFUNCTION("""COMPUTED_VALUE"""),-0.8571888629293436) -> -0.85718886 | AA11: =IFERROR(__xludf.DUMMYFUNCTION("""COMPUTED_VALUE"""),0.39233811965195126) -> 0.39233812 | AB11: =IFERROR(__xludf.DUMMYFUNCTION("""COMPUTED_VALUE"""),0.0) -> 0 | AC11: =IFERROR(__xludf.DUMMYFUNCTION("""COMPUTED_VALUE"""),0.0) -> 0 | AD11: =IFERROR(__xludf.DUMMYFUNCTION("""COMPUTED_VALUE"""),0.0654993856995771) -> 0.065499386 | AE11: =IFERROR(__xludf.DUMMYFUNCTION("""COMPUTED_VALUE"""),0.0) -> 0
A12: =IF(VLOOKUP(H12,'Paste #BBall'!$C$2:$Q$201,3,)="BRO","BKN",IF(VLOOKUP(H12,'Paste #BBall'!$C$2:$Q$201,3,)="OKL","OKC",VLOOKUP(H12,'Paste #BBall'!$C$2:$Q$201,3,))) -> DAL | B12: =VLOOKUP(A12,'Paste #BBall'!$A$204:$D$233,4,) -> 3 | C12: =VLOOKUP(A12,'Paste #BBall'!$A$204:$C$233,3,) -> 3 | D12: =VLOOKUP(A12,'Paste #BBall'!$A$204:$B$233,2,) -> 3 | E12: =SUM(B12:D12) -> 9 | F12: 7 | G12: =IFERROR(__xludf.DUMMYFUNCTION("""COMPUTED_VALUE"""),102.0) -> 102 | H12: =IFERROR(__xludf.DUMMYFUNCTION("""COMPUTED_VALUE"""),"Dorian Finney-Smith") -> Dorian Finney-Smith | I12: =IFERROR(__xludf.DUMMYFUNCTION("""COMPUTED_VALUE"""),76.0) -> 76 | J12: =IFERROR(__xludf.DUMMYFUNCTION("""COMPUTED_VALUE"""),"SF/PF") -> SF/PF | K12: =IFERROR(__xludf.DUMMYFUNCTION("""COMPUTED_VALUE"""),-1.903552351572669) -> -1.9035524 | L12: =IFERROR(__xludf.DUMMYFUNCTION("""COMPUTED_VALUE"""),-1.9139741615331212) -> -1.9139742 | M12: =IFERROR(__xludf.DUMMYFUNCTION("""COMPUTED_VALUE"""),-0.010421809960452055) -> -0.01042181 | N12: =IFERROR(__xludf.DUMMYFUNCTION("""COMPUTED_VALUE"""),12.0) -> 12 | O12: =IFERROR(__xludf.DUMMYFUNCTION("""COMPUTED_VALUE"""),2.2) -> 2.2 | P12: =IFERROR(__xludf.DUMMYFUNCTION("""COMPUTED_VALUE"""),4.7) -> 4.7 | Q12: =IFERROR(__xludf.DUMMYFUNCTION("""COMPUTED_VALUE"""),1.9) -> 1.9 | R12: =IFERROR(__xludf.DUMMYFUNCTION("""COMPUTED_VALUE"""),1.1) -> 1.1 | S12: =IFERROR(__xludf.DUMMYFUNCTION("""COMPUTED_VALUE"""),0.5) -> 0.5 | T12: =IFERROR(__xludf.DUMMYFUNCTION("""COMPUTED_VALUE"""),47.368421052631575) -> 47.368421 | U12: =IFERROR(__xludf.DUMMYFUNCTION("""COMPUTED_VALUE"""),80.0) -> 80 | V12: =IFERROR(__xludf.DUMMYFUNCTION("""COMPUTED_VALUE"""),1.0) -> 1 | W12: =IFERROR(__xludf.DUMMYFUNCTION("""COMPUTED_VALUE"""),-1.3189142282090194) -> -1.3189142 | X12: =IFERROR(__xludf.DUMMYFUNCTION("""COMPUTED_VALUE"""),0.5865511152130937) -> 0.58655112 | Y12: =IFERROR(__xludf.DUMMYFUNCTION("""COMPUTED_VALUE"""),-0.5610907016272261) -> -0.5610907 | Z12: =IFERROR(__xludf.DUMMYFUNCTION("""COMPUTED_VALUE"""),-1.0283968261685825) -> -1.0283968 | AA12: =IFERROR(__xludf.DUMMYFUNCTION("""COMPUTED_VALUE"""),0.39233811965195126) -> 0.39233812 | AB12: =IFERROR(__xludf.DUMMYFUNCTION("""COMPUTED_VALUE"""),0.0) -> 0 | AC12: =IFERROR(__xludf.DUMMYFUNCTION("""COMPUTED_VALUE"""),0.0) -> 0 | AD12: =IFERROR(__xludf.DUMMYFUNCTION("""COMPUTED_VALUE"""),0.015538359606661832) -> 0.01553836 | AE12: =IFERROR(__xludf.DUMMYFUNCTION("""COMPUTED_VALUE"""),0.0) -> 0
A13: =IF(VLOOKUP(H13,'Paste #BBall'!$C$2:$Q$201,3,)="BRO","BKN",IF(VLOOKUP(H13,'Paste #BBall'!$C$2:$Q$201,3,)="OKL","OKC",VLOOKUP(H13,'Paste #BBall'!$C$2:$Q$201,3,))) -> DEN | B13: =VLOOKUP(A13,'Paste #BBall'!$A$204:$D$233,4,) -> 2 | C13: =VLOOKUP(A13,'Paste #BBall'!$A$204:$C$233,3,) -> 4 | D13: =VLOOKUP(A13,'Paste #BBall'!$A$204:$B$233,2,) -> 4 | E13: =SUM(B13:D13) -> 10 | F13: 8 | G13: =IFERROR(__xludf.DUMMYFUNCTION("""COMPUTED_VALUE"""),120.0) -> 120 | H13: =IFERROR(__xludf.DUMMYFUNCTION("""COMPUTED_VALUE"""),"Kentavious Caldwell-Pope") -> Kentavious Caldwell-Pope | I13: =IFERROR(__xludf.DUMMYFUNCTION("""COMPUTED_VALUE"""),72.0) -> 72 | J13: =IFERROR(__xludf.DUMMYFUNCTION("""COMPUTED_VALUE"""),"SG/SF") -> SG/SF | K13: =IFERROR(__xludf.DUMMYFUNCTION("""COMPUTED_VALUE"""),-2.4757149587040717) -> -2.475715 | L13: =IFERROR(__xludf.DUMMYFUNCTION("""COMPUTED_VALUE"""),-2.0287316425159547) -> -2.0287316 | M13: =IFERROR(__xludf.DUMMYFUNCTION("""COMPUTED_VALUE"""),0.44698331618811693) -> 0.44698332 | N13: =IFERROR(__xludf.DUMMYFUNCTION("""COMPUTED_VALUE"""),12.9) -> 12.9 | O13: =IFERROR(__xludf.DUMMYFUNCTION("""COMPUTED_VALUE"""),2.0) -> 2 | P13: =IFERROR(__xludf.DUMMYFUNCTION("""COMPUTED_VALUE"""),3.3) -> 3.3 | Q13: =IFERROR(__xludf.DUMMYFUNCTION("""COMPUTED_VALUE"""),1.8) -> 1.8 | R13: =IFERROR(__xludf.DUMMYFUNCTION("""COMPUTED_VALUE"""),1.1) -> 1.1 | S13: =IFERROR(__xludf.DUMMYFUNCTION("""COMPUTED_VALUE"""),0.3) -> 0.3 | T13: =IFERROR(__xludf.DUMMYFUNCTION("""COMPUTED_VALUE"""),43.8095238095238) -> 43.809524 | U13: =IFERROR(__xludf.DUMMYFUNCTION("""COMPUTED_VALUE"""),94.73684210526316) -> 94.736842 | V13: =IFERROR(__xludf.DUMMYFUNCTION("""COMPUTED_VALUE"""),1.3) -> 1.3 | W13: =IFERROR(__xludf.DUMMYFUNCTION("""COMPUTED_VALUE"""),-1.0792578623515265) -> -1.0792579 | X13: =IFERROR(__xludf.DUMMYFUNCTION("""COMPUTED_VALUE"""),0.3865600027033658) -> 0.38656 | Y13: =IFERROR(__xludf.DUMMYFUNCTION("""COMPUTED_VALUE"""),-1.1325922658823022) -> -1.1325923 | Z13: =IFERROR(__xludf.DUMMYFUNCTION("""COMPUTED_VALUE"""),-1.085466147248329) -> -1.0854661 | AA13: =IFERROR(__xludf.DUMMYFUNCTION("""COMPUTED_VALUE"""),0.39233811965195126) -> 0.39233812 | AB13: =IFERROR(__xludf.DUMMYFUNCTION("""COMPUTED_VALUE"""),0.0) -> 0 | AC13: =IFERROR(__xludf.DUMMYFUNCTION("""COMPUTED_VALUE"""),0.0) -> 0 | AD13: =IFERROR(__xludf.DUMMYFUNCTION("""COMPUTED_VALUE"""),0.48968651061088586) -> 0.48968651 | AE13: =IFERROR(__xludf.DUMMYFUNCTION("""COMPUTED_VALUE"""),0.0) -> 0
A14: =IF(VLOOKUP(H14,'Paste #BBall'!$C$2:$Q$201,3,)="BRO","BKN",IF(VLOOKUP(H14,'Paste #BBall'!$C$2:$Q$201,3,)="OKL","OKC",VLOOKUP(H14,'Paste #BBall'!$C$2:$Q$201,3,))) -> MIA | B14: =VLOOKUP(A14,'Paste #BBall'!$A$204:$D$233,4,) -> 3 | C14: =VLOOKUP(A14,'Paste #BBall'!$A$204:$C$233,3,) -> 4 | D14: =VLOOKUP(A14,'Paste #BBall'!$A$204:$B$233,2,) -> 4 | E14: =SUM(B14:D14) -> 11 | F14: 9 | G14: =IFERROR(__xludf.DUMMYFUNCTION("""COMPUTED_VALUE"""),154.0) -> 154 | H14: =IFERROR(__xludf.DUMMYFUNCTION("""COMPUTED_VALUE"""),"Victor Oladipo") -> Victor Oladipo | I14: =IFERROR(__xludf.DUMMYFUNCTION("""COMPUTED_VALUE"""),60.0) -> 60 | J14: =IFERROR(__xludf.DUMMYFUNCTION("""COMPUTED_VALUE"""),"SG") -> SG | K14: =IFERROR(__xludf.DUMMYFUNCTION("""COMPUTED_VALUE"""),-3.6845677265262684) -> -3.6845677 | L14: =IFERROR(__xludf.DUMMYFUNCTION("""COMPUTED_VALUE"""),-2.0827878439502587) -> -2.0827878 | M14: =IFERROR(__xludf.DUMMYFUNCTION("""COMPUTED_VALUE"""),1.6017798825760097) -> 1.6017799 | N14: =IFERROR(__xludf.DUMMYFUNCTION("""COMPUTED_VALUE"""),15.1) -> 15.1 | O14: =IFERROR(__xludf.DUMMYFUNCTION("""COMPUTED_VALUE"""),2.3) -> 2.3 | P14: =IFERROR(__xludf.DUMMYFUNCTION("""COMPUTED_VALUE"""),3.5) -> 3.5 | Q14: =IFERROR(__xludf.DUMMYFUNCTION("""COMPUTED_VALUE"""),4.0) -> 4 | R14: =IFERROR(__xludf.DUMMYFUNCTION("""COMPUTED_VALUE"""),0.7) -> 0.7 | S14: =IFERROR(__xludf.DUMMYFUNCTION("""COMPUTED_VALUE"""),0.1) -> 0.1 | T14: =IFERROR(__xludf.DUMMYFUNCTION("""COMPUTED_VALUE"""),44.53781512605042) -> 44.537815 | U14: =IFERROR(__xludf.DUMMYFUNCTION("""COMPUTED_VALUE"""),75.86206896551725) -> 75.862069 | V14: =IFERROR(__xludf.DUMMYFUNCTION("""COMPUTED_VALUE"""),2.4) -> 2.4 | W14: =IFERROR(__xludf.DUMMYFUNCTION("""COMPUTED_VALUE"""),-0.4934311902554332) -> -0.49343119 | X14: =IFERROR(__xludf.DUMMYFUNCTION("""COMPUTED_VALUE"""),0.6865466714679571) -> 0.68654667 | Y14: =IFERROR(__xludf.DUMMYFUNCTION("""COMPUTED_VALUE"""),-1.0509491852744342) -> -1.0509492 | Z14: =IFERROR(__xludf.DUMMYFUNCTION("""COMPUTED_VALUE"""),0.17005891650608962) -> 0.17005892 | AA14: =IFERROR(__xludf.DUMMYFUNCTION("""COMPUTED_VALUE"""),-1.2428613161002313) -> -1.2428613 | AB14: =IFERROR(__xludf.DUMMYFUNCTION("""COMPUTED_VALUE"""),0.0) -> 0 | AC14: =IFERROR(__xludf.DUMMYFUNCTION("""COMPUTED_VALUE"""),0.0) -> 0 | AD14: =IFERROR(__xludf.DUMMYFUNCTION("""COMPUTED_VALUE"""),-0.15215174029420697) -> -0.15215174 | AE14: =IFERROR(__xludf.DUMMYFUNCTION("""COMPUTED_VALUE"""),0.0) -> 0
A15: =IF(VLOOKUP(H15,'Paste #BBall'!$C$2:$Q$201,3,)="BRO","BKN",IF(VLOOKUP(H15,'Paste #BBall'!$C$2:$Q$201,3,)="OKL","OKC",VLOOKUP(H15,'Paste #BBall'!$C$2:$Q$201,3,))) -> DAL | B15: =VLOOKUP(A15,'Paste #BBall'!$A$204:$D$233,4,) -> 3 | C15: =VLOOKUP(A15,'Paste #BBall'!$A$204:$C$233,3,) -> 3 | D15: =VLOOKUP(A15,'Paste #BBall'!$A$204:$B$233,2,) -> 3 | E15: =SUM(B15:D15) -> 9 | F15: 10 | G15: =IFERROR(__xludf.DUMMYFUNCTION("""COMPUTED_VALUE"""),168.0) -> 168 | H15: =IFERROR(__xludf.DUMMYFUNCTION("""COMPUTED_VALUE"""),"Tim Hardaway Jr.") -> Tim Hardaway Jr. | I15: =IFERROR(__xludf.DUMMYFUNCTION("""COMPUTED_VALUE"""),68.0) -> 68 | J15: =IFERROR(__xludf.DUMMYFUNCTION("""COMPUTED_VALUE"""),"SG/SF") -> SG/SF | K15: =IFERROR(__xludf.DUMMYFUNCTION("""COMPUTED_VALUE"""),-4.011723958858206) -> -4.011724 | L15: =IFERROR(__xludf.DUMMYFUNCTION("""COMPUTED_VALUE"""),-2.084143781963946) -> -2.0841438 | M15: =IFERROR(__xludf.DUMMYFUNCTION("""COMPUTED_VALUE"""),1.92758017689426) -> 1.9275802 | N15: =IFERROR(__xludf.DUMMYFUNCTION("""COMPUTED_VALUE"""),15.1) -> 15.1 | O15: =IFERROR(__xludf.DUMMYFUNCTION("""COMPUTED_VALUE"""),2.4) -> 2.4 | P15: =IFERROR(__xludf.DUMMYFUNCTION("""COMPUTED_VALUE"""),3.7) -> 3.7 | Q15: =IFERROR(__xludf.DUMMYFUNCTION("""COMPUTED_VALUE"""),2.2) -> 2.2 | R15: =IFERROR(__xludf.DUMMYFUNCTION("""COMPUTED_VALUE"""),0.9) -> 0.9 | S15: =IFERROR(__xludf.DUMMYFUNCTION("""COMPUTED_VALUE"""),0.1) -> 0.1 | T15: =IFERROR(__xludf.DUMMYFUNCTION("""COMPUTED_VALUE"""),42.1875) -> 42.1875 | U15: =IFERROR(__xludf.DUMMYFUNCTION("""COMPUTED_VALUE"""),76.0) -> 76 | V15: =IFERROR(__xludf.DUMMYFUNCTION("""COMPUTED_VALUE"""),0.8) -> 0.8 | W15: =IFERROR(__xludf.DUMMYFUNCTION("""COMPUTED_VALUE"""),-0.4934311902554332) -> -0.49343119 | X15: =IFERROR(__xludf.DUMMYFUNCTION("""COMPUTED_VALUE"""),0.786542227722821) -> 0.78654223 | Y15: =IFERROR(__xludf.DUMMYFUNCTION("""COMPUTED_VALUE"""),-0.9693061046665661) -> -0.9693061 | Z15: =IFERROR(__xludf.DUMMYFUNCTION("""COMPUTED_VALUE"""),-0.8571888629293436) -> -0.85718886 | AA15: =IFERROR(__xludf.DUMMYFUNCTION("""COMPUTED_VALUE"""),-0.42526159822414) -> -0.4252616 | AB15: =IFERROR(__xludf.DUMMYFUNCTION("""COMPUTED_VALUE"""),0.0) -> 0 | AC15: =IFERROR(__xludf.DUMMYFUNCTION("""COMPUTED_VALUE"""),0.0) -> 0 | AD15: =IFERROR(__xludf.DUMMYFUNCTION("""COMPUTED_VALUE"""),-0.12549825361128425) -> -0.12549825 | AE15: =IFERROR(__xludf.DUMMYFUNCTION("""COMPUTED_VALUE"""),0.0) -> 0
A16: =IF(VLOOKUP(H16,'Paste #BBall'!$C$2:$Q$201,3,)="BRO","BKN",IF(VLOOKUP(H16,'Paste #BBall'!$C$2:$Q$201,3,)="OKL","OKC",VLOOKUP(H16,'Paste #BBall'!$C$2:$Q$201,3,))) -> CHA | B16: =VLOOKUP(A16,'Paste #BBall'!$A$204:$D$233,4,) -> 3 | C16: =VLOOKUP(A16,'Paste #BBall'!$A$204:$C$233,3,) -> 4 | D16: =VLOOKUP(A16,'Paste #BBall'!$A$204:$B$233,2,) -> 2 | E16: =SUM(B16:D16) -> 9 | F16: 11 | G16: =IFERROR(__xludf.DUMMYFUNCTION("""COMPUTED_VALUE"""),108.0) -> 108 | H16: =IFERROR(__xludf.DUMMYFUNCTION("""COMPUTED_VALUE"""),"Cody Martin") -> Cody Martin | I16: =IFERROR(__xludf.DUMMYFUNCTION("""COMPUTED_VALUE"""),72.0) -> 72 | J16: =IFERROR(__xludf.DUMMYFUNCTION("""COMPUTED_VALUE"""),"SF") -> SF | K16: =IFERROR(__xludf.DUMMYFUNCTION("""COMPUTED_VALUE"""),-2.022992408641519) -> -2.0229924 | L16: =IFERROR(__xludf.DUMMYFUNCTION("""COMPUTED_VALUE"""),-2.1252246978309444) -> -2.1252247 | M16: =IFERROR(__xludf.DUMMYFUNCTION("""COMPUTED_VALUE"""),-0.10223228918942517) -> -0.10223229 | N16: =IFERROR(__xludf.DUMMYFUNCTION("""COMPUTED_VALUE"""),10.3) -> 10.3 | O16: =IFERROR(__xludf.DUMMYFUNCTION("""COMPUTED_VALUE"""),1.1) -> 1.1 | P16: =IFERROR(__xludf.DUMMYFUNCTION("""COMPUTED_VALUE"""),4.8) -> 4.8 | Q16: =IFERROR(__xludf.DUMMYFUNCTION("""COMPUTED_VALUE"""),2.9) -> 2.9 | R16: =IFERROR(__xludf.DUMMYFUNCTION("""COMPUTED_VALUE"""),1.3) -> 1.3 | S16: =IFERROR(__xludf.DUMMYFUNCTION("""COMPUTED_VALUE"""),0.6) -> 0.6 | T16: =IFERROR(__xludf.DUMMYFUNCTION("""COMPUTED_VALUE"""),48.192771084337345) -> 48.192771 | U16: =IFERROR(__xludf.DUMMYFUNCTION("""COMPUTED_VALUE"""),76.47058823529413) -> 76.470588 | V16: =IFERROR(__xludf.DUMMYFUNCTION("""COMPUTED_VALUE"""),1.1) -> 1.1 | W16: =IFERROR(__xludf.DUMMYFUNCTION("""COMPUTED_VALUE"""),-1.771598474828728) -> -1.7715985 | X16: =IFERROR(__xludf.DUMMYFUNCTION("""COMPUTED_VALUE"""),-0.5134000035904084) -> -0.5134 | Y16: =IFERROR(__xludf.DUMMYFUNCTION("""COMPUTED_VALUE"""),-0.5202691613232922) -> -0.52026916 | Z16: =IFERROR(__xludf.DUMMYFUNCTION("""COMPUTED_VALUE"""),-0.4577036153711197) -> -0.45770362 | AA16: =IFERROR(__xludf.DUMMYFUNCTION("""COMPUTED_VALUE"""),1.209937837528042) -> 1.2099378 | AB16: =IFERROR(__xludf.DUMMYFUNCTION("""COMPUTED_VALUE"""),0.0) -> 0 | AC16: =IFERROR(__xludf.DUMMYFUNCTION("""COMPUTED_VALUE"""),0.0) -> 0 | AD16: =IFERROR(__xludf.DUMMYFUNCTION("""COMPUTED_VALUE"""),-0.07219128024543806) -> -0.07219128 | AE16: =IFERROR(__xludf.DUMMYFUNCTION("""COMPUTED_VALUE"""),0.0) -> 0
A17: =IF(VLOOKUP(H17,'Paste #BBall'!$C$2:$Q$201,3,)="BRO","BKN",IF(VLOOKUP(H17,'Paste #BBall'!$C$2:$Q$201,3,)="OKL","OKC",VLOOKUP(H17,'Paste #BBall'!$C$2:$Q$201,3,))) -> LAC | B17: =VLOOKUP(A17,'Paste #BBall'!$A$204:$D$233,4,) -> 4 | C17: =VLOOKUP(A17,'Paste #BBall'!$A$204:$C$233,3,) -> 2 | D17: =VLOOKUP(A17,'Paste #BBall'!$A$204:$B$233,2,) -> 3 | E17: =SUM(B17:D17) -> 9 | F17: 12 | G17: =IFERROR(__xludf.DUMMYFUNCTION("""COMPUTED_VALUE"""),143.0) -> 143 | H17: =IFERROR(__xludf.DUMMYFUNCTION("""COMPUTED_VALUE"""),"Reggie Jackson") -> Reggie Jackson | I17: =IFERROR(__xludf.DUMMYFUNCTION("""COMPUTED_VALUE"""),70.0) -> 70 | J17: =IFERROR(__xludf.DUMMYFUNCTION("""COMPUTED_VALUE"""),"PG") -> PG | K17: =IFERROR(__xludf.DUMMYFUNCTION("""COMPUTED_VALUE"""),-3.297195379736017) -> -3.2971954 | L17: =IFERROR(__xludf.DUMMYFUNCTION("""COMPUTED_VALUE"""),-2.217482100520478) -> -2.2174821 | M17: =IFERROR(__xludf.DUMMYFUNCTION("""COMPUTED_VALUE"""),1.079713279215539) -> 1.0797133 | N17: =IFERROR(__xludf.DUMMYFUNCTION("""COMPUTED_VALUE"""),15.4) -> 15.4 | O17: =IFERROR(__xludf.DUMMYFUNCTION("""COMPUTED_VALUE"""),2.0) -> 2 | P17: =IFERROR(__xludf.DUMMYFUNCTION("""COMPUTED_VALUE"""),3.3) -> 3.3 | Q17: =IFERROR(__xludf.DUMMYFUNCTION("""COMPUTED_VALUE"""),4.4) -> 4.4 | R17: =IFERROR(__xludf.DUMMYFUNCTION("""COMPUTED_VALUE"""),0.6) -> 0.6 | S17: =IFERROR(__xludf.DUMMYFUNCTION("""COMPUTED_VALUE"""),0.2) -> 0.2 | T17: =IFERROR(__xludf.DUMMYFUNCTION("""COMPUTED_VALUE"""),44.6969696969697) -> 44.69697 | U17: =IFERROR(__xludf.DUMMYFUNCTION("""COMPUTED_VALUE"""),85.0) -> 85 | V17: =IFERROR(__xludf.DUMMYFUNCTION("""COMPUTED_VALUE"""),2.1) -> 2.1 | W17: =IFERROR(__xludf.DUMMYFUNCTION("""COMPUTED_VALUE"""),-0.41354573496960206) -> -0.41354574 | X17: =IFERROR(__xludf.DUMMYFUNCTION("""COMPUTED_VALUE"""),0.3865600027033658) -> 0.38656 | Y17: =IFERROR(__xludf.DUMMYFUNCTION("""COMPUTED_VALUE"""),-1.1325922658823022) -> -1.1325923 | Z17: =IFERROR(__xludf.DUMMYFUNCTION("""COMPUTED_VALUE"""),0.39833620082507504) -> 0.3983362 | AA17: =IFERROR(__xludf.DUMMYFUNCTION("""COMPUTED_VALUE"""),-1.6516611750382768) -> -1.6516612 | AB17: =IFERROR(__xludf.DUMMYFUNCTION("""COMPUTED_VALUE"""),0.0) -> 0 | AC17: =IFERROR(__xludf.DUMMYFUNCTION("""COMPUTED_VALUE"""),0.0) -> 0 | AD17: =IFERROR(__xludf.DUMMYFUNCTION("""COMPUTED_VALUE"""),0.1954208718412621) -> 0.19542087 | AE17: =IFERROR(__xludf.DUMMYFUNCTION("""COMPUTED_VALUE"""),0.0) -> 0
A18: =IF(VLOOKUP(H18,'Paste #BBall'!$C$2:$Q$201,3,)="BRO","BKN",IF(VLOOKUP(H18,'Paste #BBall'!$C$2:$Q$201,3,)="OKL","OKC",VLOOKUP(H18,'Paste #BBall'!$C$2:$Q$201,3,))) -> PHX | B18: =VLOOKUP(A18,'Paste #BBall'!$A$204:$D$233,4,) -> 3 | C18: =VLOOKUP(A18,'Paste #BBall'!$A$204:$C$233,3,) -> 2 | D18: =VLOOKUP(A18,'Paste #BBall'!$A$204:$B$233,2,) -> 4 | E18: =SUM(B18:D18) -> 9 | F18: 13 | G18: =IFERROR(__xludf.DUMMYFUNCTION("""COMPUTED_VALUE"""),136.0) -> 136 | H18: =IFERROR(__xludf.DUMMYFUNCTION("""COMPUTED_VALUE"""),"Jae Crowder") -> Jae Crowder | I18: =IFERROR(__xludf.DUMMYFUNCTION("""COMPUTED_VALUE"""),70.0) -> 70 | J18: =IFERROR(__xludf.DUMMYFUNCTION("""COMPUTED_VALUE"""),"SF/PF") -> SF/PF | K18: =IFERROR(__xludf.DUMMYFUNCTION("""COMPUTED_VALUE"""),-3.157014127365177) -> -3.1570141 | L18: =IFERROR(__xludf.DUMMYFUNCTION("""COMPUTED_VALUE"""),-2.425792125670338) -> -2.4257921 | M18: =IFERROR(__xludf.DUMMYFUNCTION("""COMPUTED_VALUE"""),0.7312220016948388) -> 0.731222 | N18: =IFERROR(__xludf.DUMMYFUNCTION("""COMPUTED_VALUE"""),8.8) -> 8.8 | O18: =IFERROR(__xludf.DUMMYFUNCTION("""COMPUTED_VALUE"""),1.8) -> 1.8 | P18: =IFERROR(__xludf.DUMMYFUNCTION("""COMPUTED_VALUE"""),4.8) -> 4.8 | Q18: =IFERROR(__xludf.DUMMYFUNCTION("""COMPUTED_VALUE"""),1.8) -> 1.8 | R18: =IFERROR(__xludf.DUMMYFUNCTION("""COMPUTED_VALUE"""),1.3) -> 1.3 | S18: =IFERROR(__xludf.DUMMYFUNCTION("""COMPUTED_VALUE"""),0.4) -> 0.4 | T18: =IFERROR(__xludf.DUMMYFUNCTION("""COMPUTED_VALUE"""),40.0) -> 40 | U18: =IFERROR(__xludf.DUMMYFUNCTION("""COMPUTED_VALUE"""),76.92307692307692) -> 76.923077 | V18: =IFERROR(__xludf.DUMMYFUNCTION("""COMPUTED_VALUE"""),0.7) -> 0.7 | W18: =IFERROR(__xludf.DUMMYFUNCTION("""COMPUTED_VALUE"""),-2.1710257512578823) -> -2.1710258 | X18: =IFERROR(__xludf.DUMMYFUNCTION("""COMPUTED_VALUE"""),0.18656889019363826) -> 0.18656889 | Y18: =IFERROR(__xludf.DUMMYFUNCTION("""COMPUTED_VALUE"""),-0.5202691613232922) -> -0.52026916 | Z18: =IFERROR(__xludf.DUMMYFUNCTION("""COMPUTED_VALUE"""),-1.085466147248329) -> -1.0854661 | AA18: =IFERROR(__xludf.DUMMYFUNCTION("""COMPUTED_VALUE"""),1.209937837528042) -> 1.2099378 | AB18: =IFERROR(__xludf.DUMMYFUNCTION("""COMPUTED_VALUE"""),0.0) -> 0 | AC18: =IFERROR(__xludf.DUMMYFUNCTION("""COMPUTED_VALUE"""),0.0) -> 0 | AD18: =IFERROR(__xludf.DUMMYFUNCTION("""COMPUTED_VALUE"""),-0.045537793562515326) -> -0.045537794 | AE18: =IFERROR(__xludf.DUMMYFUNCTION("""COMPUTED_VALUE"""),0.0) -> 0
A19: =IF(VLOOKUP(H19,'Paste #BBall'!$C$2:$Q$201,3,)="BRO","BKN",IF(VLOOKUP(H19,'Paste #BBall'!$C$2:$Q$201,3,)="OKL","OKC",VLOOKUP(H19,'Paste #BBall'!$C$2:$Q$201,3,))) -> LAC | B19: =VLOOKUP(A19,'Paste #BBall'!$A$204:$D$233,4,) -> 4 | C19: =VLOOKUP(A19,'Paste #BBall'!$A$204:$C$233,3,) -> 2 | D19: =VLOOKUP(A19,'Paste #BBall'!$A$204:$B$233,2,) -> 3 | E19: =SUM(B19:D19) -> 9 | F19: 14 | G19: =IFERROR(__xludf.DUMMYFUNCTION("""COMPUTED_VALUE"""),82.0) -> 82 | H19: =IFERROR(__xludf.DUMMYFUNCTION("""COMPUTED_VALUE"""),"Robert Covington") -> Robert Covington | I19: =IFERROR(__xludf.DUMMYFUNCTION("""COMPUTED_VALUE"""),70.0) -> 70 | J19: =IFERROR(__xludf.DUMMYFUNCTION("""COMPUTED_VALUE"""),"SF/PF") -> SF/PF | K19: =IFERROR(__xludf.DUMMYFUNCTION("""COMPUTED_VALUE"""),-1.311893170231) -> -1.3118932 | L19: =IFERROR(__xludf.DUMMYFUNCTION("""COMPUTED_VALUE"""),-2.5649042466479512) -> -2.5649042 | M19: =IFERROR(__xludf.DUMMYFUNCTION("""COMPUTED_VALUE"""),-1.2530110764169513) -> -1.2530111 | N19: =IFERROR(__xludf.DUMMYFUNCTION("""COMPUTED_VALUE"""),8.2) -> 8.2 | O19: =IFERROR(__xludf.DUMMYFUNCTION("""COMPUTED_VALUE"""),1.8) -> 1.8 | P19: =IFERROR(__xludf.DUMMYFUNCTION("""COMPUTED_VALUE"""),5.4) -> 5.4 | Q19: =IFERROR(__xludf.DUMMYFUNCTION("""COMPUTED_VALUE"""),1.3) -> 1.3 | R19: =IFERROR(__xludf.DUMMYFUNCTION("""COMPUTED_VALUE"""),1.3) -> 1.3 | S19: =IFERROR(__xludf.DUMMYFUNCTION("""COMPUTED_VALUE"""),1.2) -> 1.2 | T19: =IFERROR(__xludf.DUMMYFUNCTION("""COMPUTED_VALUE"""),41.17647058823529) -> 41.176471 | U19: =IFERROR(__xludf.DUMMYFUNCTION("""COMPUTED_VALUE"""),80.0) -> 80 | V19: =IFERROR(__xludf.DUMMYFUNCTION("""COMPUTED_VALUE"""),1.1) -> 1.1 | W19: =IFERROR(__xludf.DUMMYFUNCTION("""COMPUTED_VALUE"""),-2.330796661829545) -> -2.3307967 | X19: =IFERROR(__xludf.DUMMYFUNCTION("""COMPUTED_VALUE"""),0.18656889019363826) -> 0.18656889 | Y19: =IFERROR(__xludf.DUMMYFUNCTION("""COMPUTED_VALUE"""),-0.27533991949968795) -> -0.27533992 | Z19: =IFERROR(__xludf.DUMMYFUNCTION("""COMPUTED_VALUE"""),-1.3708127526470602) -> -1.3708128 | AA19: =IFERROR(__xludf.DUMMYFUNCTION("""COMPUTED_VALUE"""),1.209937837528042) -> 1.2099378 | AB19: =IFERROR(__xludf.DUMMYFUNCTION("""COMPUTED_VALUE"""),0.0) -> 0 | AC19: =IFERROR(__xludf.DUMMYFUNCTION("""COMPUTED_VALUE"""),0.0) -> 0 | AD19: =IFERROR(__xludf.DUMMYFUNCTION("""COMPUTED_VALUE"""),0.015538359606661832) -> 0.01553836 | AE19: =IFERROR(__xludf.DUMMYFUNCTION("""COMPUTED_VALUE"""),0.0) -> 0
A20: =IF(VLOOKUP(H20,'Paste #BBall'!$C$2:$Q$201,3,)="BRO","BKN",IF(VLOOKUP(H20,'Paste #BBall'!$C$2:$Q$201,3,)="OKL","OKC",VLOOKUP(H20,'Paste #BBall'!$C$2:$Q$201,3,))) -> UTA | B20: =VLOOKUP(A20,'Paste #BBall'!$A$204:$D$233,4,) -> 3 | C20: =VLOOKUP(A20,'Paste #BBall'!$A$204:$C$233,3,) -> 3 | D20: =VLOOKUP(A20,'Paste #BBall'!$A$204:$B$233,2,) -> 2 | E20: =SUM(B20:D20) -> 8 | F20: 15 | G20: =IFERROR(__xludf.DUMMYFUNCTION("""COMPUTED_VALUE"""),175.0) -> 175 | H20: =IFERROR(__xludf.DUMMYFUNCTION("""COMPUTED_VALUE"""),"Jordan Clarkson") -> Jordan Clarkson | I20: =IFERROR(__xludf.DUMMYFUNCTION("""COMPUTED_VALUE"""),64.0) -> 64 | J20: =IFERROR(__xludf.DUMMYFUNCTION("""COMPUTED_VALUE"""),"SG") -> SG | K20: =IFERROR(__xludf.DUMMYFUNCTION("""COMPUTED_VALUE"""),-4.137784141412638) -> -4.1377841 | L20: =IFERROR(__xludf.DUMMYFUNCTION("""COMPUTED_VALUE"""),-2.575608423381195) -> -2.5756084 | M20: =IFERROR(__xludf.DUMMYFUNCTION("""COMPUTED_VALUE"""),1.562175718031443) -> 1.5621757 | N20: =IFERROR(__xludf.DUMMYFUNCTION("""COMPUTED_VALUE"""),15.0) -> 15 | O20: =IFERROR(__xludf.DUMMYFUNCTION("""COMPUTED_VALUE"""),2.3) -> 2.3 | P20: =IFERROR(__xludf.DUMMYFUNCTION("""COMPUTED_VALUE"""),3.2) -> 3.2 | Q20: =IFERROR(__xludf.DUMMYFUNCTION("""COMPUTED_VALUE"""),2.3) -> 2.3 | R20: =IFERROR(__xludf.DUMMYFUNCTION("""COMPUTED_VALUE"""),0.8) -> 0.8 | S20: =IFERROR(__xludf.DUMMYFUNCTION("""COMPUTED_VALUE"""),0.2) -> 0.2 | T20: =IFERROR(__xludf.DUMMYFUNCTION("""COMPUTED_VALUE"""),41.66666666666667) -> 41.666667 | U20: =IFERROR(__xludf.DUMMYFUNCTION("""COMPUTED_VALUE"""),80.95238095238095) -> 80.952381 | V20: =IFERROR(__xludf.DUMMYFUNCTION("""COMPUTED_VALUE"""),1.5) -> 1.5 | W20: =IFERROR(__xludf.DUMMYFUNCTION("""COMPUTED_VALUE"""),-0.5200596753507101) -> -0.52005968 | X20: =IFERROR(__xludf.DUMMYFUNCTION("""COMPUTED_VALUE"""),0.6865466714679571) -> 0.68654667 | Y20: =IFERROR(__xludf.DUMMYFUNCTION("""COMPUTED_VALUE"""),-1.173413806186236) -> -1.1734138 | Z20: =IFERROR(__xludf.DUMMYFUNCTION("""COMPUTED_VALUE"""),-0.8001195418495975) -> -0.80011954 | AA20: =IFERROR(__xludf.DUMMYFUNCTION("""COMPUTED_VALUE"""),-0.8340614571621854) -> -0.83406146 | AB20: =IFERROR(__xludf.DUMMYFUNCTION("""COMPUTED_VALUE"""),0.0) -> 0 | AC20: =IFERROR(__xludf.DUMMYFUNCTION("""COMPUTED_VALUE"""),0.0) -> 0 | AD20: =IFERROR(__xludf.DUMMYFUNCTION("""COMPUTED_VALUE"""),0.0654993856995771) -> 0.065499386 | AE20: =IFERROR(__xludf.DUMMYFUNCTION("""COMPUTED_VALUE"""),0.0) -> 0
A21: =IF(VLOOKUP(H21,'Paste #BBall'!$C$2:$Q$201,3,)="BRO","BKN",IF(VLOOKUP(H21,'Paste #BBall'!$C$2:$Q$201,3,)="OKL","OKC",VLOOKUP(H21,'Paste #BBall'!$C$2:$Q$201,3,))) -> LAL | B21: =VLOOKUP(A21,'Paste #BBall'!$A$204:$D$233,4,) -> 4 | C21: =VLOOKUP(A21,'Paste #BBall'!$A$204:$C$233,3,) -> 3 | D21: =VLOOKUP(A21,'Paste #BBall'!$A$204:$B$233,2,) -> 4 | E21: =SUM(B21:D21) -> 11 | F21: 16 | G21: =IFERROR(__xludf.DUMMYFUNCTION("""COMPUTED_VALUE"""),128.0) -> 128 | H21: =IFERROR(__xludf.DUMMYFUNCTION("""COMPUTED_VALUE"""),"Kendrick Nunn") -> Kendrick Nunn | I21: =IFERROR(__xludf.DUMMYFUNCTION("""COMPUTED_VALUE"""),70.0) -> 70 | J21: =IFERROR(__xludf.DUMMYFUNCTION("""COMPUTED_VALUE"""),"SG") -> SG | K21: =IFERROR(__xludf.DUMMYFUNCTION("""COMPUTED_VALUE"""),-2.8448698230497627) -> -2.8448698 | L21: =IFERROR(__xludf.DUMMYFUNCTION("""COMPUTED_VALUE"""),-2.6497891012798527) -> -2.6497891 | M21: =IFERROR(__xludf.DUMMYFUNCTION("""COMPUTED_VALUE"""),0.19508072176990998) -> 0.19508072 | N21: =IFERROR(__xludf.DUMMYFUNCTION("""COMPUTED_VALUE"""),13.6) -> 13.6 | O21: =IFERROR(__xludf.DUMMYFUNCTION("""COMPUTED_VALUE"""),2.1) -> 2.1 | P21: =IFERROR(__xludf.DUMMYFUNCTION("""COMPUTED_VALUE"""),3.0) -> 3 | Q21: =IFERROR(__xludf.DUMMYFUNCTION("""COMPUTED_VALUE"""),2.4) -> 2.4 | R21: =IFERROR(__xludf.DUMMYFUNCTION("""COMPUTED_VALUE"""),0.9) -> 0.9 | S21: =IFERROR(__xludf.DUMMYFUNCTION("""COMPUTED_VALUE"""),0.3) -> 0.3 | T21: =IFERROR(__xludf.DUMMYFUNCTION("""COMPUTED_VALUE"""),48.18181818181818) -> 48.181818 | U21: =IFERROR(__xludf.DUMMYFUNCTION("""COMPUTED_VALUE"""),90.0) -> 90 | V21: =IFERROR(__xludf.DUMMYFUNCTION("""COMPUTED_VALUE"""),1.3) -> 1.3 | W21: =IFERROR(__xludf.DUMMYFUNCTION("""COMPUTED_VALUE"""),-0.8928584666845878) -> -0.89285847 | X21: =IFERROR(__xludf.DUMMYFUNCTION("""COMPUTED_VALUE"""),0.4865555589582297) -> 0.48655556 | Y21: =IFERROR(__xludf.DUMMYFUNCTION("""COMPUTED_VALUE"""),-1.255056886794104) -> -1.2550569 | Z21: =IFERROR(__xludf.DUMMYFUNCTION("""COMPUTED_VALUE"""),-0.743050220769851) -> -0.74305022 | AA21: =IFERROR(__xludf.DUMMYFUNCTION("""COMPUTED_VALUE"""),-0.42526159822414) -> -0.4252616 | AB21: =IFERROR(__xludf.DUMMYFUNCTION("""COMPUTED_VALUE"""),0.0) -> 0 | AC21: =IFERROR(__xludf.DUMMYFUNCTION("""COMPUTED_VALUE"""),0.0) -> 0 | AD21: =IFERROR(__xludf.DUMMYFUNCTION("""COMPUTED_VALUE"""),0.17988251223460047) -> 0.17988251 | AE21: =IFERROR(__xludf.DUMMYFUNCTION("""COMPUTED_VALUE"""),0.0) -> 0
A22: =IF(VLOOKUP(H22,'Paste #BBall'!$C$2:$Q$201,3,)="BRO","BKN",IF(VLOOKUP(H22,'Paste #BBall'!$C$2:$Q$201,3,)="OKL","OKC",VLOOKUP(H22,'Paste #BBall'!$C$2:$Q$201,3,))) -> LAC | B22: =VLOOKUP(A22,'Paste #BBall'!$A$204:$D$233,4,) -> 4 | C22: =VLOOKUP(A22,'Paste #BBall'!$A$204:$C$233,3,) -> 2 | D22: =VLOOKUP(A22,'Paste #BBall'!$A$204:$B$233,2,) -> 3 | E22: =SUM(B22:D22) -> 9 | F22: 17 | G22: =IFERROR(__xludf.DUMMYFUNCTION("""COMPUTED_VALUE"""),127.0) -> 127 | H22: =IFERROR(__xludf.DUMMYFUNCTION("""COMPUTED_VALUE"""),"Norman Powell") -> Norman Powell | I22: =IFERROR(__xludf.DUMMYFUNCTION("""COMPUTED_VALUE"""),76.0) -> 76 | J22: =IFERROR(__xludf.DUMMYFUNCTION("""COMPUTED_VALUE"""),"SG/SF") -> SG/SF | K22: =IFERROR(__xludf.DUMMYFUNCTION("""COMPUTED_VALUE"""),-2.8278501582441953) -> -2.8278502 | L22: =IFERROR(__xludf.DUMMYFUNCTION("""COMPUTED_VALUE"""),-2.681245816852229) -> -2.6812458 | M22: =IFERROR(__xludf.DUMMYFUNCTION("""COMPUTED_VALUE"""),0.1466043413919662) -> 0.14660434 | N22: =IFERROR(__xludf.DUMMYFUNCTION("""COMPUTED_VALUE"""),16.2) -> 16.2 | O22: =IFERROR(__xludf.DUMMYFUNCTION("""COMPUTED_VALUE"""),2.1) -> 2.1 | P22: =IFERROR(__xludf.DUMMYFUNCTION("""COMPUTED_VALUE"""),2.7) -> 2.7 | Q22: =IFERROR(__xludf.DUMMYFUNCTION("""COMPUTED_VALUE"""),1.8) -> 1.8 | R22: =IFERROR(__xludf.DUMMYFUNCTION("""COMPUTED_VALUE"""),0.8) -> 0.8 | S22: =IFERROR(__xludf.DUMMYFUNCTION("""COMPUTED_VALUE"""),0.4) -> 0.4 | T22: =IFERROR(__xludf.DUMMYFUNCTION("""COMPUTED_VALUE"""),46.49122807017543) -> 46.491228 | U22: =IFERROR(__xludf.DUMMYFUNCTION("""COMPUTED_VALUE"""),83.72093023255815) -> 83.72093 | V22: =IFERROR(__xludf.DUMMYFUNCTION("""COMPUTED_VALUE"""),1.3) -> 1.3 | W22: =IFERROR(__xludf.DUMMYFUNCTION("""COMPUTED_VALUE"""),-0.20051785420738652) -> -0.20051785 | X22: =IFERROR(__xludf.DUMMYFUNCTION("""COMPUTED_VALUE"""),0.4865555589582297) -> 0.48655556 | Y22: =IFERROR(__xludf.DUMMYFUNCTION("""COMPUTED_VALUE"""),-1.377521507705906) -> -1.3775215 | Z22: =IFERROR(__xludf.DUMMYFUNCTION("""COMPUTED_VALUE"""),-1.085466147248329) -> -1.0854661 | AA22: =IFERROR(__xludf.DUMMYFUNCTION("""COMPUTED_VALUE"""),-0.8340614571621854) -> -0.83406146 | AB22: =IFERROR(__xludf.DUMMYFUNCTION("""COMPUTED_VALUE"""),0.0) -> 0 | AC22: =IFERROR(__xludf.DUMMYFUNCTION("""COMPUTED_VALUE"""),0.0) -> 0 | AD22: =IFERROR(__xludf.DUMMYFUNCTION("""COMPUTED_VALUE"""),0.32976559051334775) -> 0.32976559 | AE22: =IFERROR(__xludf.DUMMYFUNCTION("""COMPUTED_VALUE"""),0.0) -> 0
A23: =IF(VLOOKUP(H23,'Paste #BBall'!$C$2:$Q$201,3,)="BRO","BKN",IF(VLOOKUP(H23,'Paste #BBall'!$C$2:$Q$201,3,)="OKL","OKC",VLOOKUP(H23,'Paste #BBall'!$C$2:$Q$201,3,))) -> NYK | B23: =VLOOKUP(A23,'Paste #BBall'!$A$204:$D$233,4,) -> 3 | C23: =VLOOKUP(A23,'Paste #BBall'!$A$204:$C$233,3,) -> 4 | D23: =VLOOKUP(A23,'Paste #BBall'!$A$204:$B$233,2,) -> 2 | E23: =SUM(B23:D23) -> 9 | F23: 18 | G23: =IFERROR(__xludf.DUMMYFUNCTION("""COMPUTED_VALUE"""),173.0) -> 173 | H23: =IFERROR(__xludf.DUMMYFUNCTION("""COMPUTED_VALUE"""),"Immanuel Quickley") -> Immanuel Quickley | I23: =IFERROR(__xludf.DUMMYFUNCTION("""COMPUTED_VALUE"""),76.0) -> 76 | J23: =IFERROR(__xludf.DUMMYFUNCTION("""COMPUTED_VALUE"""),"PG") -> PG | K23: =IFERROR(__xludf.DUMMYFUNCTION("""COMPUTED_VALUE"""),-4.079061846098121) -> -4.0790618 | L23: =IFERROR(__xludf.DUMMYFUNCTION("""COMPUTED_VALUE"""),-2.949756739025076) -> -2.9497567 | M23: =IFERROR(__xludf.DUMMYFUNCTION("""COMPUTED_VALUE"""),1.1293051070730447) -> 1.1293051 | N23: =IFERROR(__xludf.DUMMYFUNCTION("""COMPUTED_VALUE"""),12.3) -> 12.3 | O23: =IFERROR(__xludf.DUMMYFUNCTION("""COMPUTED_VALUE"""),1.9) -> 1.9 | P23: =IFERROR(__xludf.DUMMYFUNCTION("""COMPUTED_VALUE"""),3.3) -> 3.3 | Q23: =IFERROR(__xludf.DUMMYFUNCTION("""COMPUTED_VALUE"""),3.6) -> 3.6 | R23: =IFERROR(__xludf.DUMMYFUNCTION("""COMPUTED_VALUE"""),0.7) -> 0.7 | S23: =IFERROR(__xludf.DUMMYFUNCTION("""COMPUTED_VALUE"""),0.0) -> 0 | T23: =IFERROR(__xludf.DUMMYFUNCTION("""COMPUTED_VALUE"""),41.66666666666667) -> 41.666667 | U23: =IFERROR(__xludf.DUMMYFUNCTION("""COMPUTED_VALUE"""),88.88888888888889) -> 88.888889 | V23: =IFERROR(__xludf.DUMMYFUNCTION("""COMPUTED_VALUE"""),1.3) -> 1.3 | W23: =IFERROR(__xludf.DUMMYFUNCTION("""COMPUTED_VALUE"""),-1.2390287729231884) -> -1.2390288 | X23: =IFERROR(__xludf.DUMMYFUNCTION("""COMPUTED_VALUE"""),0.28656444644850193) -> 0.28656445 | Y23: =IFERROR(__xludf.DUMMYFUNCTION("""COMPUTED_VALUE"""),-1.1325922658823022) -> -1.1325923 | Z23: =IFERROR(__xludf.DUMMYFUNCTION("""COMPUTED_VALUE"""),-0.058218367812895515) -> -0.058218368 | AA23: =IFERROR(__xludf.DUMMYFUNCTION("""COMPUTED_VALUE"""),-1.2428613161002313) -> -1.2428613 | AB23: =IFERROR(__xludf.DUMMYFUNCTION("""COMPUTED_VALUE"""),0.0) -> 0 | AC23: =IFERROR(__xludf.DUMMYFUNCTION("""COMPUTED_VALUE"""),0.0) -> 0 | AD23: =IFERROR(__xludf.DUMMYFUNCTION("""COMPUTED_VALUE"""),0.43637953724503936) -> 0.43637954 | AE23: =IFERROR(__xludf.DUMMYFUNCTION("""COMPUTED_VALUE"""),0.0) -> 0
A24: =IF(VLOOKUP(H24,'Paste #BBall'!$C$2:$Q$201,3,)="BRO","BKN",IF(VLOOKUP(H24,'Paste #BBall'!$C$2:$Q$201,3,)="OKL","OKC",VLOOKUP(H24,'Paste #BBall'!$C$2:$Q$201,3,))) -> ORL | B24: =VLOOKUP(A24,'Paste #BBall'!$A$204:$D$233,4,) -> 4 | C24: =VLOOKUP(A24,'Paste #BBall'!$A$204:$C$233,3,) -> 3 | D24: =VLOOKUP(A24,'Paste #BBall'!$A$204:$B$233,2,) -> 4 | E24: =SUM(B24:D24) -> 11 | F24: 19 | G24: =IFERROR(__xludf.DUMMYFUNCTION("""COMPUTED_VALUE"""),139.0) -> 139 | H24: =IFERROR(__xludf.DUMMYFUNCTION("""COMPUTED_VALUE"""),"Chuma Okeke") -> Chuma Okeke | I24: =IFERROR(__xludf.DUMMYFUNCTION("""COMPUTED_VALUE"""),67.0) -> 67 | J24: =IFERROR(__xludf.DUMMYFUNCTION("""COMPUTED_VALUE"""),"PF") -> PF | K24: =IFERROR(__xludf.DUMMYFUNCTION("""COMPUTED_VALUE"""),-3.1729721277845986) -> -3.1729721 | L24: =IFERROR(__xludf.DUMMYFUNCTION("""COMPUTED_VALUE"""),-3.034567840121997) -> -3.0345678 | M24: =IFERROR(__xludf.DUMMYFUNCTION("""COMPUTED_VALUE"""),0.1384042876626017) -> 0.13840429 | N24: =IFERROR(__xludf.DUMMYFUNCTION("""COMPUTED_VALUE"""),7.9) -> 7.9 | O24: =IFERROR(__xludf.DUMMYFUNCTION("""COMPUTED_VALUE"""),1.6) -> 1.6 | P24: =IFERROR(__xludf.DUMMYFUNCTION("""COMPUTED_VALUE"""),4.6) -> 4.6 | Q24: =IFERROR(__xludf.DUMMYFUNCTION("""COMPUTED_VALUE"""),1.6) -> 1.6 | R24: =IFERROR(__xludf.DUMMYFUNCTION("""COMPUTED_VALUE"""),1.3) -> 1.3 | S24: =IFERROR(__xludf.DUMMYFUNCTION("""COMPUTED_VALUE"""),0.6) -> 0.6 | T24: =IFERROR(__xludf.DUMMYFUNCTION("""COMPUTED_VALUE"""),40.0) -> 40 | U24: =IFERROR(__xludf.DUMMYFUNCTION("""COMPUTED_VALUE"""),77.77777777777777) -> 77.777778 | V24: =IFERROR(__xludf.DUMMYFUNCTION("""COMPUTED_VALUE"""),0.7) -> 0.7 | W24: =IFERROR(__xludf.DUMMYFUNCTION("""COMPUTED_VALUE"""),-2.4106821171153756) -> -2.4106821 | X24: =IFERROR(__xludf.DUMMYFUNCTION("""COMPUTED_VALUE"""),-0.013422222316089305) -> -0.013422222 | Y24: =IFERROR(__xludf.DUMMYFUNCTION("""COMPUTED_VALUE"""),-0.6019122419311602) -> -0.60191224 | Z24: =IFERROR(__xludf.DUMMYFUNCTION("""COMPUTED_VALUE"""),-1.1996047894078214) -> -1.1996048 | AA24: =IFERROR(__xludf.DUMMYFUNCTION("""COMPUTED_VALUE"""),1.209937837528042) -> 1.2099378 | AB24: =IFERROR(__xludf.DUMMYFUNCTION("""COMPUTED_VALUE"""),0.0) -> 0 | AC24: =IFERROR(__xludf.DUMMYFUNCTION("""COMPUTED_VALUE"""),0.0) -> 0 | AD24: =IFERROR(__xludf.DUMMYFUNCTION("""COMPUTED_VALUE"""),-0.0188843068795923) -> -0.018884307 | AE24: =IFERROR(__xludf.DUMMYFUNCTION("""COMPUTED_VALUE"""),0.0) -> 0
A25: =IF(VLOOKUP(H25,'Paste #BBall'!$C$2:$Q$201,3,)="BRO","BKN",IF(VLOOKUP(H25,'Paste #BBall'!$C$2:$Q$201,3,)="OKL","OKC",VLOOKUP(H25,'Paste #BBall'!$C$2:$Q$201,3,))) -> WAS | B25: =VLOOKUP(A25,'Paste #BBall'!$A$204:$D$233,4,) -> 3 | C25: =VLOOKUP(A25,'Paste #BBall'!$A$204:$C$233,3,) -> 4 | D25: =VLOOKUP(A25,'Paste #BBall'!$A$204:$B$233,2,) -> 3 | E25: =SUM(B25:D25) -> 10 | F25: 20 | G25: =IFERROR(__xludf.DUMMYFUNCTION("""COMPUTED_VALUE"""),165.0) -> 165 | H25: =IFERROR(__xludf.DUMMYFUNCTION("""COMPUTED_VALUE"""),"Will Barton") -> Will Barton | I25: =IFERROR(__xludf.DUMMYFUNCTION("""COMPUTED_VALUE"""),60.0) -> 60 | J25: =IFERROR(__xludf.DUMMYFUNCTION("""COMPUTED_VALUE"""),"PG/SG") -> PG/SG | K25: =IFERROR(__xludf.DUMMYFUNCTION("""COMPUTED_VALUE"""),-3.884669330997389) -> -3.8846693 | L25: =IFERROR(__xludf.DUMMYFUNCTION("""COMPUTED_VALUE"""),-3.0971380863975897) -> -3.0971381 | M25: =IFERROR(__xludf.DUMMYFUNCTION("""COMPUTED_VALUE"""),0.7875312445997995) -> 0.78753124 | N25: =IFERROR(__xludf.DUMMYFUNCTION("""COMPUTED_VALUE"""),12.5) -> 12.5 | O25: =IFERROR(__xludf.DUMMYFUNCTION("""COMPUTED_VALUE"""),1.9) -> 1.9 | P25: =IFERROR(__xludf.DUMMYFUNCTION("""COMPUTED_VALUE"""),4.1) -> 4.1 | Q25: =IFERROR(__xludf.DUMMYFUNCTION("""COMPUTED_VALUE"""),3.4) -> 3.4 | R25: =IFERROR(__xludf.DUMMYFUNCTION("""COMPUTED_VALUE"""),0.7) -> 0.7 | S25: =IFERROR(__xludf.DUMMYFUNCTION("""COMPUTED_VALUE"""),0.3) -> 0.3 | T25: =IFERROR(__xludf.DUMMYFUNCTION("""COMPUTED_VALUE"""),43.51851851851852) -> 43.518519 | U25: =IFERROR(__xludf.DUMMYFUNCTION("""COMPUTED_VALUE"""),80.0) -> 80 | V25: =IFERROR(__xludf.DUMMYFUNCTION("""COMPUTED_VALUE"""),1.6) -> 1.6 | W25: =IFERROR(__xludf.DUMMYFUNCTION("""COMPUTED_VALUE"""),-1.1857718027326345) -> -1.1857718 | X25: =IFERROR(__xludf.DUMMYFUNCTION("""COMPUTED_VALUE"""),0.28656444644850193) -> 0.28656445 | Y25: =IFERROR(__xludf.DUMMYFUNCTION("""COMPUTED_VALUE"""),-0.8060199434508303) -> -0.80601994 | Z25: =IFERROR(__xludf.DUMMYFUNCTION("""COMPUTED_VALUE"""),-0.17235700997238818) -> -0.17235701 | AA25: =IFERROR(__xludf.DUMMYFUNCTION("""COMPUTED_VALUE"""),-1.2428613161002313) -> -1.2428613 | AB25: =IFERROR(__xludf.DUMMYFUNCTION("""COMPUTED_VALUE"""),0.0) -> 0 | AC25: =IFERROR(__xludf.DUMMYFUNCTION("""COMPUTED_VALUE"""),0.0) -> 0 | AD25: =IFERROR(__xludf.DUMMYFUNCTION("""COMPUTED_VALUE"""),0.023307539409992476) -> 0.023307539 | AE25: =IFERROR(__xludf.DUMMYFUNCTION("""COMPUTED_VALUE"""),0.0) -> 0
A26: =IF(VLOOKUP(H26,'Paste #BBall'!$C$2:$Q$201,3,)="BRO","BKN",IF(VLOOKUP(H26,'Paste #BBall'!$C$2:$Q$201,3,)="OKL","OKC",VLOOKUP(H26,'Paste #BBall'!$C$2:$Q$201,3,))) -> IND | B26: =VLOOKUP(A26,'Paste #BBall'!$A$204:$D$233,4,) -> 3 | C26: =VLOOKUP(A26,'Paste #BBall'!$A$204:$C$233,3,) -> 3 | D26: =VLOOKUP(A26,'Paste #BBall'!$A$204:$B$233,2,) -> 3 | E26: =SUM(B26:D26) -> 9 | F26: 21 | G26: =IFERROR(__xludf.DUMMYFUNCTION("""COMPUTED_VALUE"""),170.0) -> 170 | H26: =IFERROR(__xludf.DUMMYFUNCTION("""COMPUTED_VALUE"""),"Bennedict Mathurin") -> Bennedict Mathurin | I26: =IFERROR(__xludf.DUMMYFUNCTION("""COMPUTED_VALUE"""),77.0) -> 77 | J26: =IFERROR(__xludf.DUMMYFUNCTION("""COMPUTED_VALUE"""),"SF") -> SF | K26: =IFERROR(__xludf.DUMMYFUNCTION("""COMPUTED_VALUE"""),-4.023659401206252) -> -4.0236594 | L26: =IFERROR(__xludf.DUMMYFUNCTION("""COMPUTED_VALUE"""),-3.132123762245191) -> -3.1321238 | M26: =IFERROR(__xludf.DUMMYFUNCTION("""COMPUTED_VALUE"""),0.8915356389610607) -> 0.89153564 | N26: =IFERROR(__xludf.DUMMYFUNCTION("""COMPUTED_VALUE"""),15.2) -> 15.2 | O26: =IFERROR(__xludf.DUMMYFUNCTION("""COMPUTED_VALUE"""),1.9) -> 1.9 | P26: =IFERROR(__xludf.DUMMYFUNCTION("""COMPUTED_VALUE"""),3.6) -> 3.6 | Q26: =IFERROR(__xludf.DUMMYFUNCTION("""COMPUTED_VALUE"""),1.8) -> 1.8 | R26: =IFERROR(__xludf.DUMMYFUNCTION("""COMPUTED_VALUE"""),0.8) -> 0.8 | S26: =IFERROR(__xludf.DUMMYFUNCTION("""COMPUTED_VALUE"""),0.3) -> 0.3 | T26: =IFERROR(__xludf.DUMMYFUNCTION("""COMPUTED_VALUE"""),44.8) -> 44.8 | U26: =IFERROR(__xludf.DUMMYFUNCTION("""COMPUTED_VALUE"""),78.57142857142858) -> 78.571429 | V26: =IFERROR(__xludf.DUMMYFUNCTION("""COMPUTED_VALUE"""),1.6) -> 1.6 | W26: =IFERROR(__xludf.DUMMYFUNCTION("""COMPUTED_VALUE"""),-0.4668027051601563) -> -0.46680271 | X26: =IFERROR(__xludf.DUMMYFUNCTION("""COMPUTED_VALUE"""),0.28656444644850193) -> 0.28656445 | Y26: =IFERROR(__xludf.DUMMYFUNCTION("""COMPUTED_VALUE"""),-1.0101276449705001) -> -1.0101276 | Z26: =IFERROR(__xludf.DUMMYFUNCTION("""COMPUTED_VALUE"""),-1.085466147248329) -> -1.0854661 | AA26: =IFERROR(__xludf.DUMMYFUNCTION("""COMPUTED_VALUE"""),-0.8340614571621854) -> -0.83406146 | AB26: =IFERROR(__xludf.DUMMYFUNCTION("""COMPUTED_VALUE"""),0.0) -> 0 | AC26: =IFERROR(__xludf.DUMMYFUNCTION("""COMPUTED_VALUE"""),0.0) -> 0 | AD26: =IFERROR(__xludf.DUMMYFUNCTION("""COMPUTED_VALUE"""),-0.022230254152522107) -> -0.022230254 | AE26: =IFERROR(__xludf.DUMMYFUNCTION("""COMPUTED_VALUE"""),0.0) -> 0
