Workbook

Sheet Draft
A2: Pick | B2: Your Pick | C2: Round 1 | D2: Round 2 | E2: Round 3 | F2: Round 4 | G2: Round 5 | H2: Round 6 | I2: Round 7 | J2: Round 8 | K2: Round 9 | L2: Round 10 | M2: Round 11 | N2: Round 12 | O2: Round 13 | P2: Round 14
A3: 1 | B3: FALSE
A4: 2 | B4: FALSE
A5: 3 | B5: FALSE
A6: 4 | B6: FALSE
A7: 5 | B7: FALSE
A8: 6 | B8: FALSE | D8: Domantas Sabonis | F8: Jordan Poole | H8: OG Anunoby | J8: Markelle Fultz
A9: 7 | B9: TRUE | C9: Jayson Tatum | E9: Karl-Anthony Towns | G9: Josh Giddey | I9: Anfernee Simons
A10: 8 | B10: FALSE
A11: 9 | B11: FALSE
A12: 10 | B12: FALSE
A13: 11 | B13: FALSE
A14: 12 | B14: FALSE
B15: Pick Fill Direction | C15: ↓ | D15: ↓ | E15: =IF($H$19, "↑","↓") -> ↑ | F15: =IF($H$19,"↓", "↑") -> ↓ | G15: =IF($H$19, "↑","↓") -> ↑ | H15: =IF($H$19,"↓", "↑") -> ↓ | I15: =IF($H$19, "↑","↓") -> ↑ | J15: =IF($H$19,"↓", "↑") -> ↓ | K15: =IF($H$19, "↑","↓") -> ↑ | L15: =IF($H$19,"↓", "↑") -> ↓ | M15: =IF($H$19, "↑","↓") -> ↑ | N15: =IF($H$19,"↓", "↑") -> ↓ | O15: =IF($H$19, "↑","↓") -> ↑ | P15: =IF($H$19,"↓", "↑") -> ↓
B16: Pick # | C16: =IF(B3=TRUE,"1",IF(B4=TRUE,"2", IF(B5=True, "3",IF(B6=True, "4",IF(B7=True, "5",IF(B8=True, "6",IF(B9=True, "7",IF(B10=True, "8",IF(B11=True, "9",IF(B12=True, "10",IF(B13=True, "11",IF(B14=True, "12")))))))))))) -> 7 | D16: =IF(B3=TRUE,"24",IF(B4=TRUE,"23", IF(B5=True, "22",IF(B6=True, "21",IF(B7=True, "20",IF(B8=True, "19",IF(B9=True, "18",IF(B10=True, "17",IF(B11=True, "16",IF(B12=True, "15",IF(B13=True, "14",IF(B14=True, "13")))))))))))) -> 18 | E16: =IF(B3=TRUE,"25",IF(B4=TRUE,"26", IF(B5=True, "27",IF(B6=True, "28",IF(B7=True, "29",IF(B8=True, "30",IF(B9=True, "31",IF(B10=True, "32",IF(B11=True, "33",IF(B12=True, "34",IF(B13=True, "35",IF(B14=True, "36")))))))))))) -> 31 | F16: =IF(B3=TRUE,"48",IF(B4=TRUE,"47", IF(B5=True, "46",IF(B6=True, "45",IF(B7=True, "44",IF(B8=True, "43",IF(B9=True, "42",IF(B10=True, "41",IF(B11=True, "40",IF(B12=True, "39",IF(B13=True, "38",IF(B14=True, "37")))))))))))) -> 42 | G16: =IF(B3=TRUE,"49",IF(B4=TRUE,"50", IF(B5=True, "51",IF(B6=True, "52",IF(B7=True, "53",IF(B8=True, "54",IF(B9=True, "55",IF(B10=True, "56",IF(B11=True, "57",IF(B12=True, "58",IF(B13=True, "59",IF(B14=True, "60")))))))))))) -> 55 | H16: =IF(B3=TRUE,"72",IF(B4=TRUE,"71", IF(B5=True, "70",IF(B6=True, "69",IF(B7=True, "68",IF(B8=True, "67",IF(B9=True, "66",IF(B10=True, "65",IF(B11=True, "64",IF(B12=True, "63",IF(B13=True, "62",IF(B14=True, "61")))))))))))) -> 66 | I16: =IF(B3=TRUE,"73",IF(B4=TRUE,"74", IF(B5=True, "75",IF(B6=True, "76",IF(B7=True, "77",IF(B8=True, "78",IF(B9=True, "79",IF(B10=True, "80",IF(B11=True, "81",IF(B12=True, "82",IF(B13=True, "83",IF(B14=True, "84")))))))))))) -> 79 | J16: =IF(B3=TRUE,"96",IF(B4=TRUE,"95", IF(B5=True, "94",IF(B6=True, "93",IF(B7=True, "92",IF(B8=True, "91",IF(B9=True, "90",IF(B10=True, "89",IF(B11=True, "88",IF(B12=True, "87",IF(B13=True, "86",IF(B14=True, "85")))))))))))) -> 90 | K16: =IF(B3=TRUE,"97",IF(B4=TRUE,"98", IF(B5=True, "99",IF(B6=True, "100",IF(B7=True, "101",IF(B8=True, "102",IF(B9=True, "103",IF(B10=True, "104",IF(B11=True, "105",IF(B12=True, "106",IF(B13=True, "107",IF(B14=True, "108")))))))))))) -> 103 | L16: =IF(B3=TRUE,"120",IF(B4=TRUE,"119", IF(B5=True, "118",IF(B6=True, "117",IF(B7=True, "116",IF(B8=True, "115",IF(B9=True, "114",IF(B10=True, "113",IF(B11=True, "112",IF(B12=True, "111",IF(B13=True, "110",IF(B14=True, "109")))))))))))) -> 114 | M16: =IF(B3=TRUE,"121",IF(B4=TRUE,"122", IF(B5=True, "123",IF(B6=True, "124",IF(B7=True, "125",IF(B8=True, "126",IF(B9=True, "127",IF(B10=True, "128",IF(B11=True, "129",IF(B12=True, "130",IF(B13=True, "131",IF(B14=True, "132")))))))))))) -> 127 | N16: =IF(B3=TRUE,"144",IF(B4=TRUE,"143", IF(B5=True, "142",IF(B6=True, "141",IF(B7=True, "140",IF(B8=True, "139",IF(B9=True, "138",IF(B10=True, "137",IF(B11=True, "136",IF(B12=True, "135",IF(B13=True, "134",IF(B14=True, "133")))))))))))) -> 138 | O16: =IF(B3=TRUE,"145",IF(B4=TRUE,"146", IF(B5=True, "147",IF(B6=True, "148",IF(B7=True, "149",IF(B8=True, "150",IF(B9=True, "151",IF(B10=True, "152",IF(B11=True, "153",IF(B12=True, "154",IF(B13=True, "155",IF(B14=True, "156")))))))))))) -> 151 | P16: =IF(B3=TRUE,"168",IF(B4=TRUE,"167", IF(B5=True, "166",IF(B6=True, "165",IF(B7=True, "164",IF(B8=True, "163",IF(B9=True, "162",IF(B10=True, "161",IF(B11=True, "160",IF(B12=True, "159",IF(B13=True, "158",IF(B14=True, "157")))))))))))) -> 162
B17: 3RR | C17: =C16 -> 7 | D17: =D16 -> 18 | E17: =E16+IF($B$3,11, IF($B$4,9,IF($B$5,7,IF($B$6,5,IF($B$7,3,IF($B$8,1,IF($B$9,-1,IF($B$10,-3,IF($B$11,-5,IF($B$12,-7, IF($B$13,-9, IF($B$14,-11)))))))))))) -> 30 | F17: =F16-IF($B$3,11, IF($B$4,9,IF($B$5,7,IF($B$6,5,IF($B$7,3,IF($B$8,1,IF($B$9,-1,IF($B$10,-3,IF($B$11,-5,IF($B$12,-7, IF($B$13,-9, IF($B$14,-11)))))))))))) -> 43 | G17: =G16+IF($B$3,11, IF($B$4,9,IF($B$5,7,IF($B$6,5,IF($B$7,3,IF($B$8,1,IF($B$9,-1,IF($B$10,-3,IF($B$11,-5,IF($B$12,-7, IF($B$13,-9, IF($B$14,-11)))))))))))) -> 54 | H17: =H16-IF($B$3,11, IF($B$4,9,IF($B$5,7,IF($B$6,5,IF($B$7,3,IF($B$8,1,IF($B$9,-1,IF($B$10,-3,IF($B$11,-5,IF($B$12,-7, IF($B$13,-9, IF($B$14,-11)))))))))))) -> 67 | I17: =I16+IF($B$3,11, IF($B$4,9,IF($B$5,7,IF($B$6,5,IF($B$7,3,IF($B$8,1,IF($B$9,-1,IF($B$10,-3,IF($B$11,-5,IF($B$12,-7, IF($B$13,-9, IF($B$14,-11)))))))))))) -> 78 | J17: =J16-IF($B$3,11, IF($B$4,9,IF($B$5,7,IF($B$6,5,IF($B$7,3,IF($B$8,1,IF($B$9,-1,IF($B$10,-3,IF($B$11,-5,IF($B$12,-7, IF($B$13,-9, IF($B$14,-11)))))))))))) -> 91 | K17: =K16+IF($B$3,11, IF($B$4,9,IF($B$5,7,IF($B$6,5,IF($B$7,3,IF($B$8,1,IF($B$9,-1,IF($B$10,-3,IF($B$11,-5,IF($B$12,-7, IF($B$13,-9, IF($B$14,-11)))))))))))) -> 102 | L17: =L16-IF($B$3,11, IF($B$4,9,IF($B$5,7,IF($B$6,5,IF($B$7,3,IF($B$8,1,IF($B$9,-1,IF($B$10,-3,IF($B$11,-5,IF($B$12,-7, IF($B$13,-9, IF($B$14,-11)))))))))))) -> 115 | M17: =M16+IF($B$3,11, IF($B$4,9,IF($B$5,7,IF($B$6,5,IF($B$7,3,IF($B$8,1,IF($B$9,-1,IF($B$10,-3,IF($B$11,-5,IF($B$12,-7, IF($B$13,-9, IF($B$14,-11)))))))))))) -> 126 | N17: =N16-IF($B$3,11, IF($B$4,9,IF($B$5,7,IF($B$6,5,IF($B$7,3,IF($B$8,1,IF($B$9,-1,IF($B$10,-3,IF($B$11,-5,IF($B$12,-7, IF($B$13,-9, IF($B$14,-11)))))))))))) -> 139 | O17: =O16+IF($B$3,11, IF($B$4,9,IF($B$5,7,IF($B$6,5,IF($B$7,3,IF($B$8,1,IF($B$9,-1,IF($B$10,-3,IF($B$11,-5,IF($B$12,-7, IF($B$13,-9, IF($B$14,-11)))))))))))) -> 150 | P17: =P16-IF($B$3,11, IF($B$4,9,IF($B$5,7,IF($B$6,5,IF($B$7,3,IF($B$8,1,IF($B$9,-1,IF($B$10,-3,IF($B$11,-5,IF($B$12,-7, IF($B$13,-9, IF($B$14,-11)))))))))))) -> 163
C19: MAKE A COPY | G19: 3RR | H19: TRUE
C20: File -> Make a copy

Sheet Projections
G2: Sort by | H2: Remove Drafted | J2: -1 Cat | K2: -2 Cat | L2: PTS | M2: 3P | N2: REB | O2: AST | P2: STL | Q2: BLK | R2: FG% | S2: FT% | T2: TO | U2: PG | V2: SG | W2: SF | X2: PF | Y2: C
G3: PuntV | H3: FALSE | J3: TRUE | K3: FALSE | L3: 1 | M3: 0.9 | N3: 1 | O3: 1.1 | P3: 0.7 | Q3: 0.7 | R3: 0.9 | S3: 0.8 | T3: 0.25 | U3: PG | V3: SG | W3: SF | X3: PF | Y3: C
A5: TM | B5: W19 | C5: W20 | D5: W21 | E5: Total | F5: Rank | G5: LgRank | H5: Player | I5: GP | J5: Pos | K5: LeagV | L5: PuntV | M5: Punt+ | N5: PTS | O5: 3P | P5: REB | Q5: AST | R5: STL | S5: BLK | T5: FG% | U5: FT% | V5: TO | W5: z p/g | X5: z 3/g | Y5: z r/g | Z5: z a/g | AA5: z s/g | AB5: z b/g | AC5: z fg% | AD5: z ft% | AE5: z to/g
A6: =IF(VLOOKUP(H6,'Paste #BBall'!$B$2:$N1001,3,)="BRO","BKN",IF(VLOOKUP(H6,'Paste #BBall'!$B$2:$N1001,3,)="OKL","OKC",VLOOKUP(H6,'Paste #BBall'!$B$2:$N1001,3,))) -> DEN | B6: =VLOOKUP($A6,Schedule!$C$2:$G$31,2,0) -> 3 | C6: =VLOOKUP($A6,Schedule!$C$2:$G$31,3,0) -> 4 | D6: =VLOOKUP($A6,Schedule!$C$2:$G$31,4,0) -> 3 | E6: =SUM(B6:D6) -> 10 | F6: 1 | G6: =IFERROR(__xludf.DUMMYFUNCTION("Filter('NO USAR3'!B5:Z405,IF('NO USAR3'!AA5:AA405="""",FALSE,TRUE),NOT(COUNTIF('NO USAR3'!A5:A200,'NO USAR3'!C5:C405)))"),1.0) -> 1 | H6: =IFERROR(__xludf.DUMMYFUNCTION("""COMPUTED_VALUE"""),"Nikola Jokic") -> Nikola Jokic | I6: =IFERROR(__xludf.DUMMYFUNCTION("""COMPUTED_VALUE"""),72.0) -> 72 | J6: =IFERROR(__xludf.DUMMYFUNCTION("""COMPUTED_VALUE"""),"C") -> C | K6: =IFERROR(__xludf.DUMMYFUNCTION("""COMPUTED_VALUE"""),9.54924845456491) -> 9.5492485 | L6: =IFERROR(__xludf.DUMMYFUNCTION("""COMPUTED_VALUE"""),9.214627913768442) -> 9.2146279 | M6: =IFERROR(__xludf.DUMMYFUNCTION("""COMPUTED_VALUE"""),-0.3346205407964682) -> -0.33462054 | N6: =IFERROR(__xludf.DUMMYFUNCTION("""COMPUTED_VALUE"""),24.5) -> 24.5 | O6: =IFERROR(__xludf.DUMMYFUNCTION("""COMPUTED_VALUE"""),1.0) -> 1 | P6: =IFERROR(__xludf.DUMMYFUNCTION("""COMPUTED_VALUE"""),11.7) -> 11.7 | Q6: =IFERROR(__xludf.DUMMYFUNCTION("""COMPUTED_VALUE"""),9.7) -> 9.7 | R6: =IFERROR(__xludf.DUMMYFUNCTION("""COMPUTED_VALUE"""),1.4) -> 1.4 | S6: =IFERROR(__xludf.DUMMYFUNCTION("""COMPUTED_VALUE"""),0.7) -> 0.7 | T6: =IFERROR(__xludf.DUMMYFUNCTION("""COMPUTED_VALUE"""),62.16216216216215) -> 62.162162 | U6: =IFERROR(__xludf.DUMMYFUNCTION("""COMPUTED_VALUE"""),81.9672131147541) -> 81.967213 | V6: =IFERROR(__xludf.DUMMYFUNCTION("""COMPUTED_VALUE"""),3.7) -> 3.7 | W6: =IFERROR(__xludf.DUMMYFUNCTION("""COMPUTED_VALUE"""),1.2206927237691836) -> 1.2206927 | X6: =IFERROR(__xludf.DUMMYFUNCTION("""COMPUTED_VALUE"""),-0.5590090246596284) -> -0.55900902 | Y6: =IFERROR(__xludf.DUMMYFUNCTION("""COMPUTED_VALUE"""),2.3436120958610913) -> 2.3436121 | Z6: =IFERROR(__xludf.DUMMYFUNCTION("""COMPUTED_VALUE"""),2.986704087554234) -> 2.9867041 | AA6: =IFERROR(__xludf.DUMMYFUNCTION("""COMPUTED_VALUE"""),0.883828931240691) -> 0.88382893 | AB6: =IFERROR(__xludf.DUMMYFUNCTION("""COMPUTED_VALUE"""),-0.0017508778622903794) -> -0.0017508779 | AC6: =IFERROR(__xludf.DUMMYFUNCTION("""COMPUTED_VALUE"""),1.857320056544927) -> 1.8573201 | AD6: =IFERROR(__xludf.DUMMYFUNCTION("""COMPUTED_VALUE"""),0.4536630262097989) -> 0.45366303 | AE6: =IFERROR(__xludf.DUMMYFUNCTION("""COMPUTED_VALUE"""),-0.5294421295491943) -> -0.52944213
A7: =IF(VLOOKUP(H7,'Paste #BBall'!$B$2:$N1001,3,)="BRO","BKN",IF(VLOOKUP(H7,'Paste #BBall'!$B$2:$N1001,3,)="OKL","OKC",VLOOKUP(H7,'Paste #BBall'!$B$2:$N1001,3,))) -> PHI | B7: =VLOOKUP($A7,Schedule!$C$2:$G$31,2,0) -> 4 | C7: =VLOOKUP($A7,Schedule!$C$2:$G$31,3,0) -> 3 | D7: =VLOOKUP($A7,Schedule!$C$2:$G$31,4,0) -> 4 | E7: =SUM(B7:D7) -> 11 | F7: 2 | G7: =IFERROR(__xludf.DUMMYFUNCTION("""COMPUTED_VALUE"""),2.0) -> 2 | H7: =IFERROR(__xludf.DUMMYFUNCTION("""COMPUTED_VALUE"""),"Joel Embiid") -> Joel Embiid | I7: =IFERROR(__xludf.DUMMYFUNCTION("""COMPUTED_VALUE"""),67.0) -> 67 | J7: =IFERROR(__xludf.DUMMYFUNCTION("""COMPUTED_VALUE"""),"C") -> C | K7: =IFERROR(__xludf.DUMMYFUNCTION("""COMPUTED_VALUE"""),8.589996039505778) -> 8.589996 | L7: =IFERROR(__xludf.DUMMYFUNCTION("""COMPUTED_VALUE"""),7.635406106501781) -> 7.6354061 | M7: =IFERROR(__xludf.DUMMYFUNCTION("""COMPUTED_VALUE"""),-0.9545899330039962) -> -0.95458993 | N7: =IFERROR(__xludf.DUMMYFUNCTION("""COMPUTED_VALUE"""),32.6) -> 32.6 | O7: =IFERROR(__xludf.DUMMYFUNCTION("""COMPUTED_VALUE"""),1.2) -> 1.2 | P7: =IFERROR(__xludf.DUMMYFUNCTION("""COMPUTED_VALUE"""),10.2) -> 10.2 | Q7: =IFERROR(__xludf.DUMMYFUNCTION("""COMPUTED_VALUE"""),4.2) -> 4.2 | R7: =IFERROR(__xludf.DUMMYFUNCTION("""COMPUTED_VALUE"""),1.1) -> 1.1 | S7: =IFERROR(__xludf.DUMMYFUNCTION("""COMPUTED_VALUE"""),1.6) -> 1.6 | T7: =IFERROR(__xludf.DUMMYFUNCTION("""COMPUTED_VALUE"""),54.0) -> 54 | U7: =IFERROR(__xludf.DUMMYFUNCTION("""COMPUTED_VALUE"""),83.19327731092437) -> 83.193277 | V7: =IFERROR(__xludf.DUMMYFUNCTION("""COMPUTED_VALUE"""),3.3) -> 3.3 | W7: =IFERROR(__xludf.DUMMYFUNCTION("""COMPUTED_VALUE"""),2.5857563771327903) -> 2.5857564 | X7: =IFERROR(__xludf.DUMMYFUNCTION("""COMPUTED_VALUE"""),-0.38558326726780967) -> -0.38558327 | Y7: =IFERROR(__xludf.DUMMYFUNCTION("""COMPUTED_VALUE"""),1.7163815480214986) -> 1.7163815 | Z7: =IFERROR(__xludf.DUMMYFUNCTION("""COMPUTED_VALUE"""),0.18156875942098802) -> 0.18156876 | AA7: =IFERROR(__xludf.DUMMYFUNCTION("""COMPUTED_VALUE"""),0.22967922884215308) -> 0.22967923 | AB7: =IFERROR(__xludf.DUMMYFUNCTION("""COMPUTED_VALUE"""),1.1800916791835507) -> 1.1800917 | AC7: =IFERROR(__xludf.DUMMYFUNCTION("""COMPUTED_VALUE"""),0.8793122989733448) -> 0.8793123 | AD7: =IFERROR(__xludf.DUMMYFUNCTION("""COMPUTED_VALUE"""),1.2481994821952669) -> 1.2481995 | AE7: =IFERROR(__xludf.DUMMYFUNCTION("""COMPUTED_VALUE"""),-0.40525711089027455) -> -0.40525711
A8: =IF(VLOOKUP(H8,'Paste #BBall'!$B$2:$N1001,3,)="BRO","BKN",IF(VLOOKUP(H8,'Paste #BBall'!$B$2:$N1001,3,)="OKL","OKC",VLOOKUP(H8,'Paste #BBall'!$B$2:$N1001,3,))) -> DAL | B8: =VLOOKUP($A8,Schedule!$C$2:$G$31,2,0) -> 3 | C8: =VLOOKUP($A8,Schedule!$C$2:$G$31,3,0) -> 4 | D8: =VLOOKUP($A8,Schedule!$C$2:$G$31,4,0) -> 2 | E8: =SUM(B8:D8) -> 9 | F8: 3 | G8: =IFERROR(__xludf.DUMMYFUNCTION("""COMPUTED_VALUE"""),3.0) -> 3 | H8: =IFERROR(__xludf.DUMMYFUNCTION("""COMPUTED_VALUE"""),"Luka Doncic") -> Luka Doncic | I8: =IFERROR(__xludf.DUMMYFUNCTION("""COMPUTED_VALUE"""),66.0) -> 66 | J8: =IFERROR(__xludf.DUMMYFUNCTION("""COMPUTED_VALUE"""),"PG") -> PG | K8: =IFERROR(__xludf.DUMMYFUNCTION("""COMPUTED_VALUE"""),6.6677410644050665) -> 6.6677411 | L8: =IFERROR(__xludf.DUMMYFUNCTION("""COMPUTED_VALUE"""),6.872562954664767) -> 6.872563 | M8: =IFERROR(__xludf.DUMMYFUNCTION("""COMPUTED_VALUE"""),0.20482189025970055) -> 0.20482189 | N8: =IFERROR(__xludf.DUMMYFUNCTION("""COMPUTED_VALUE"""),32.7) -> 32.7 | O8: =IFERROR(__xludf.DUMMYFUNCTION("""COMPUTED_VALUE"""),3.0) -> 3 | P8: =IFERROR(__xludf.DUMMYFUNCTION("""COMPUTED_VALUE"""),8.8) -> 8.8 | Q8: =IFERROR(__xludf.DUMMYFUNCTION("""COMPUTED_VALUE"""),8.1) -> 8.1 | R8: =IFERROR(__xludf.DUMMYFUNCTION("""COMPUTED_VALUE"""),1.3) -> 1.3 | S8: =IFERROR(__xludf.DUMMYFUNCTION("""COMPUTED_VALUE"""),0.5) -> 0.5 | T8: =IFERROR(__xludf.DUMMYFUNCTION("""COMPUTED_VALUE"""),49.10714285714286) -> 49.107143 | U8: =IFERROR(__xludf.DUMMYFUNCTION("""COMPUTED_VALUE"""),76.47058823529413) -> 76.470588 | V8: =IFERROR(__xludf.DUMMYFUNCTION("""COMPUTED_VALUE"""),3.6) -> 3.6 | W8: =IFERROR(__xludf.DUMMYFUNCTION("""COMPUTED_VALUE"""),2.602609014828637) -> 2.602609 | X8: =IFERROR(__xludf.DUMMYFUNCTION("""COMPUTED_VALUE"""),1.1752485492585598) -> 1.1752485 | Y8: =IFERROR(__xludf.DUMMYFUNCTION("""COMPUTED_VALUE"""),1.1309663700378794) -> 1.1309664 | Z8: =IFERROR(__xludf.DUMMYFUNCTION("""COMPUTED_VALUE"""),2.170664719370017) -> 2.1706647 | AA8: =IFERROR(__xludf.DUMMYFUNCTION("""COMPUTED_VALUE"""),0.6657790304411786) -> 0.66577903 | AB8: =IFERROR(__xludf.DUMMYFUNCTION("""COMPUTED_VALUE"""),-0.2643825572058105) -> -0.26438256 | AC8: =IFERROR(__xludf.DUMMYFUNCTION("""COMPUTED_VALUE"""),-0.10992629718122864) -> -0.1099263 | AD8: =IFERROR(__xludf.DUMMYFUNCTION("""COMPUTED_VALUE"""),-0.6370246463324157) -> -0.63702465 | AE8: =IFERROR(__xludf.DUMMYFUNCTION("""COMPUTED_VALUE"""),-0.49839587488446435) -> -0.49839587
A9: =IF(VLOOKUP(H9,'Paste #BBall'!$B$2:$N1001,3,)="BRO","BKN",IF(VLOOKUP(H9,'Paste #BBall'!$B$2:$N1001,3,)="OKL","OKC",VLOOKUP(H9,'Paste #BBall'!$B$2:$N1001,3,))) -> IND | B9: =VLOOKUP($A9,Schedule!$C$2:$G$31,2,0) -> 3 | C9: =VLOOKUP($A9,Schedule!$C$2:$G$31,3,0) -> 3 | D9: =VLOOKUP($A9,Schedule!$C$2:$G$31,4,0) -> 4 | E9: =SUM(B9:D9) -> 10 | F9: 4 | G9: =IFERROR(__xludf.DUMMYFUNCTION("""COMPUTED_VALUE"""),5.0) -> 5 | H9: =IFERROR(__xludf.DUMMYFUNCTION("""COMPUTED_VALUE"""),"Tyrese Haliburton") -> Tyrese Haliburton | I9: =IFERROR(__xludf.DUMMYFUNCTION("""COMPUTED_VALUE"""),73.0) -> 73 | J9: =IFERROR(__xludf.DUMMYFUNCTION("""COMPUTED_VALUE"""),"PG,SG") -> PG,SG | K9: =IFERROR(__xludf.DUMMYFUNCTION("""COMPUTED_VALUE"""),6.550969880100022) -> 6.5509699 | L9: =IFERROR(__xludf.DUMMYFUNCTION("""COMPUTED_VALUE"""),6.817439699232969) -> 6.8174397 | M9: =IFERROR(__xludf.DUMMYFUNCTION("""COMPUTED_VALUE"""),0.2664698191329471) -> 0.26646982 | N9: =IFERROR(__xludf.DUMMYFUNCTION("""COMPUTED_VALUE"""),23.3) -> 23.3 | O9: =IFERROR(__xludf.DUMMYFUNCTION("""COMPUTED_VALUE"""),2.8) -> 2.8 | P9: =IFERROR(__xludf.DUMMYFUNCTION("""COMPUTED_VALUE"""),4.0) -> 4 | Q9: =IFERROR(__xludf.DUMMYFUNCTION("""COMPUTED_VALUE"""),10.5) -> 10.5 | R9: =IFERROR(__xludf.DUMMYFUNCTION("""COMPUTED_VALUE"""),1.7) -> 1.7 | S9: =IFERROR(__xludf.DUMMYFUNCTION("""COMPUTED_VALUE"""),0.4) -> 0.4 | T9: =IFERROR(__xludf.DUMMYFUNCTION("""COMPUTED_VALUE"""),48.913043478260875) -> 48.913043 | U9: =IFERROR(__xludf.DUMMYFUNCTION("""COMPUTED_VALUE"""),86.66666666666667) -> 86.666667 | V9: =IFERROR(__xludf.DUMMYFUNCTION("""COMPUTED_VALUE"""),2.6) -> 2.6 | W9: =IFERROR(__xludf.DUMMYFUNCTION("""COMPUTED_VALUE"""),1.0184610714190199) -> 1.0184611 | X9: =IFERROR(__xludf.DUMMYFUNCTION("""COMPUTED_VALUE"""),1.001822791866741) -> 1.0018228 | Y9: =IFERROR(__xludf.DUMMYFUNCTION("""COMPUTED_VALUE"""),-0.8761713830488173) -> -0.87617138 | Z9: =IFERROR(__xludf.DUMMYFUNCTION("""COMPUTED_VALUE"""),3.3947237716463428) -> 3.3947238 | AA9: =IFERROR(__xludf.DUMMYFUNCTION("""COMPUTED_VALUE"""),1.5379786336392296) -> 1.5379786 | AB9: =IFERROR(__xludf.DUMMYFUNCTION("""COMPUTED_VALUE"""),-0.39569839687757064) -> -0.3956984 | AC9: =IFERROR(__xludf.DUMMYFUNCTION("""COMPUTED_VALUE"""),-0.12597035229978393) -> -0.12597035 | AD9: =IFERROR(__xludf.DUMMYFUNCTION("""COMPUTED_VALUE"""),0.5740555080761552) -> 0.57405551 | AE9: =IFERROR(__xludf.DUMMYFUNCTION("""COMPUTED_VALUE"""),-0.18793332823716524) -> -0.18793333
A10: =IF(VLOOKUP(H10,'Paste #BBall'!$B$2:$N1001,3,)="BRO","BKN",IF(VLOOKUP(H10,'Paste #BBall'!$B$2:$N1001,3,)="OKL","OKC",VLOOKUP(H10,'Paste #BBall'!$B$2:$N1001,3,))) -> CHA | B10: =VLOOKUP($A10,Schedule!$C$2:$G$31,2,0) -> 3 | C10: =VLOOKUP($A10,Schedule!$C$2:$G$31,3,0) -> 4 | D10: =VLOOKUP($A10,Schedule!$C$2:$G$31,4,0) -> 2 | E10: =SUM(B10:D10) -> 9 | F10: 5 | G10: =IFERROR(__xludf.DUMMYFUNCTION("""COMPUTED_VALUE"""),7.0) -> 7 | H10: =IFERROR(__xludf.DUMMYFUNCTION("""COMPUTED_VALUE"""),"LaMelo Ball") -> LaMelo Ball | I10: =IFERROR(__xludf.DUMMYFUNCTION("""COMPUTED_VALUE"""),69.0) -> 69 | J10: =IFERROR(__xludf.DUMMYFUNCTION("""COMPUTED_VALUE"""),"PG,SG") -> PG,SG | K10: =IFERROR(__xludf.DUMMYFUNCTION("""COMPUTED_VALUE"""),6.185474007494449) -> 6.185474 | L10: =IFERROR(__xludf.DUMMYFUNCTION("""COMPUTED_VALUE"""),6.634110243347756) -> 6.6341102 | M10: =IFERROR(__xludf.DUMMYFUNCTION("""COMPUTED_VALUE"""),0.44863623585330714) -> 0.44863624 | N10: =IFERROR(__xludf.DUMMYFUNCTION("""COMPUTED_VALUE"""),23.4) -> 23.4 | O10: =IFERROR(__xludf.DUMMYFUNCTION("""COMPUTED_VALUE"""),3.7) -> 3.7 | P10: =IFERROR(__xludf.DUMMYFUNCTION("""COMPUTED_VALUE"""),7.0) -> 7 | Q10: =IFERROR(__xludf.DUMMYFUNCTION("""COMPUTED_VALUE"""),8.6) -> 8.6 | R10: =IFERROR(__xludf.DUMMYFUNCTION("""COMPUTED_VALUE"""),1.6) -> 1.6 | S10: =IFERROR(__xludf.DUMMYFUNCTION("""COMPUTED_VALUE"""),0.4) -> 0.4 | T10: =IFERROR(__xludf.DUMMYFUNCTION("""COMPUTED_VALUE"""),42.78350515463919) -> 42.783505 | U10: =IFERROR(__xludf.DUMMYFUNCTION("""COMPUTED_VALUE"""),85.71428571428571) -> 85.714286 | V10: =IFERROR(__xludf.DUMMYFUNCTION("""COMPUTED_VALUE"""),3.6) -> 3.6 | W10: =IFERROR(__xludf.DUMMYFUNCTION("""COMPUTED_VALUE"""),1.0353137091148663) -> 1.0353137 | X10: =IFERROR(__xludf.DUMMYFUNCTION("""COMPUTED_VALUE"""),1.7822387001299258) -> 1.7822387 | Y10: =IFERROR(__xludf.DUMMYFUNCTION("""COMPUTED_VALUE"""),0.3782897126303679) -> 0.37828971 | Z10: =IFERROR(__xludf.DUMMYFUNCTION("""COMPUTED_VALUE"""),2.4256770219275845) -> 2.425677 | AA10: =IFERROR(__xludf.DUMMYFUNCTION("""COMPUTED_VALUE"""),1.319928732839717) -> 1.3199287 | AB10: =IFERROR(__xludf.DUMMYFUNCTION("""COMPUTED_VALUE"""),-0.39569839687757064) -> -0.3956984 | AC10: =IFERROR(__xludf.DUMMYFUNCTION("""COMPUTED_VALUE"""),-1.3205973735909926) -> -1.3205974 | AD10: =IFERROR(__xludf.DUMMYFUNCTION("""COMPUTED_VALUE"""),0.5867566384673297) -> 0.58675664 | AE10: =IFERROR(__xludf.DUMMYFUNCTION("""COMPUTED_VALUE"""),-0.49839587488446435) -> -0.49839587
A11: =IF(VLOOKUP(H11,'Paste #BBall'!$B$2:$N1001,3,)="BRO","BKN",IF(VLOOKUP(H11,'Paste #BBall'!$B$2:$N1001,3,)="OKL","OKC",VLOOKUP(H11,'Paste #BBall'!$B$2:$N1001,3,))) -> BOS | B11: =VLOOKUP($A11,Schedule!$C$2:$G$31,2,0) -> 3 | C11: =VLOOKUP($A11,Schedule!$C$2:$G$31,3,0) -> 4 | D11: =VLOOKUP($A11,Schedule!$C$2:$G$31,4,0) -> 4 | E11: =SUM(B11:D11) -> 11 | F11: 6 | G11: =IFERROR(__xludf.DUMMYFUNCTION("""COMPUTED_VALUE"""),6.0) -> 6 | H11: =IFERROR(__xludf.DUMMYFUNCTION("""COMPUTED_VALUE"""),"Jayson Tatum") -> Jayson Tatum | I11: =IFERROR(__xludf.DUMMYFUNCTION("""COMPUTED_VALUE"""),75.0) -> 75 | J11: =IFERROR(__xludf.DUMMYFUNCTION("""COMPUTED_VALUE"""),"SF,PF") -> SF,PF | K11: =IFERROR(__xludf.DUMMYFUNCTION("""COMPUTED_VALUE"""),6.237419142116777) -> 6.2374191 | L11: =IFERROR(__xludf.DUMMYFUNCTION("""COMPUTED_VALUE"""),6.073044076011835) -> 6.0730441 | M11: =IFERROR(__xludf.DUMMYFUNCTION("""COMPUTED_VALUE"""),-0.16437506610494168) -> -0.16437507 | N11: =IFERROR(__xludf.DUMMYFUNCTION("""COMPUTED_VALUE"""),29.5) -> 29.5 | O11: =IFERROR(__xludf.DUMMYFUNCTION("""COMPUTED_VALUE"""),3.3) -> 3.3 | P11: =IFERROR(__xludf.DUMMYFUNCTION("""COMPUTED_VALUE"""),8.2) -> 8.2 | Q11: =IFERROR(__xludf.DUMMYFUNCTION("""COMPUTED_VALUE"""),4.8) -> 4.8 | R11: =IFERROR(__xludf.DUMMYFUNCTION("""COMPUTED_VALUE"""),1.1) -> 1.1 | S11: =IFERROR(__xludf.DUMMYFUNCTION("""COMPUTED_VALUE"""),0.7) -> 0.7 | T11: =IFERROR(__xludf.DUMMYFUNCTION("""COMPUTED_VALUE"""),46.666666666666664) -> 46.666667 | U11: =IFERROR(__xludf.DUMMYFUNCTION("""COMPUTED_VALUE"""),85.71428571428571) -> 85.714286 | V11: =IFERROR(__xludf.DUMMYFUNCTION("""COMPUTED_VALUE"""),3.0) -> 3 | W11: =IFERROR(__xludf.DUMMYFUNCTION("""COMPUTED_VALUE"""),2.0633246085615333) -> 2.0633246 | X11: =IFERROR(__xludf.DUMMYFUNCTION("""COMPUTED_VALUE"""),1.435387185346288) -> 1.4353872 | Y11: =IFERROR(__xludf.DUMMYFUNCTION("""COMPUTED_VALUE"""),0.8800741509020418) -> 0.88007415 | Z11: =IFERROR(__xludf.DUMMYFUNCTION("""COMPUTED_VALUE"""),0.4875835224900693) -> 0.48758352 | AA11: =IFERROR(__xludf.DUMMYFUNCTION("""COMPUTED_VALUE"""),0.22967922884215308) -> 0.22967923 | AB11: =IFERROR(__xludf.DUMMYFUNCTION("""COMPUTED_VALUE"""),-0.0017508778622903794) -> -0.0017508779 | AC11: =IFERROR(__xludf.DUMMYFUNCTION("""COMPUTED_VALUE"""),-0.6149742310855772) -> -0.61497423 | AD11: =IFERROR(__xludf.DUMMYFUNCTION("""COMPUTED_VALUE"""),1.2908646046281254) -> 1.2908646 | AE11: =IFERROR(__xludf.DUMMYFUNCTION("""COMPUTED_VALUE"""),-0.31211834689608486) -> -0.31211835
A12: =IF(VLOOKUP(H12,'Paste #BBall'!$B$2:$N1001,3,)="BRO","BKN",IF(VLOOKUP(H12,'Paste #BBall'!$B$2:$N1001,3,)="OKL","OKC",VLOOKUP(H12,'Paste #BBall'!$B$2:$N1001,3,))) -> OKC | B12: =VLOOKUP($A12,Schedule!$C$2:$G$31,2,0) -> 4 | C12: =VLOOKUP($A12,Schedule!$C$2:$G$31,3,0) -> 3 | D12: =VLOOKUP($A12,Schedule!$C$2:$G$31,4,0) -> 3 | E12: =SUM(B12:D12) -> 10 | F12: 7 | G12: =IFERROR(__xludf.DUMMYFUNCTION("""COMPUTED_VALUE"""),4.0) -> 4 | H12: =IFERROR(__xludf.DUMMYFUNCTION("""COMPUTED_VALUE"""),"Shai Gilgeous-Alexander") -> Shai Gilgeous-Alexander | I12: =IFERROR(__xludf.DUMMYFUNCTION("""COMPUTED_VALUE"""),67.0) -> 67 | J12: =IFERROR(__xludf.DUMMYFUNCTION("""COMPUTED_VALUE"""),"PG,SG") -> PG,SG | K12: =IFERROR(__xludf.DUMMYFUNCTION("""COMPUTED_VALUE"""),6.586598644459562) -> 6.5865986 | L12: =IFERROR(__xludf.DUMMYFUNCTION("""COMPUTED_VALUE"""),5.834728981810113) -> 5.834729 | M12: =IFERROR(__xludf.DUMMYFUNCTION("""COMPUTED_VALUE"""),-0.7518696626494483) -> -0.75186966 | N12: =IFERROR(__xludf.DUMMYFUNCTION("""COMPUTED_VALUE"""),29.6) -> 29.6 | O12: =IFERROR(__xludf.DUMMYFUNCTION("""COMPUTED_VALUE"""),1.0) -> 1 | P12: =IFERROR(__xludf.DUMMYFUNCTION("""COMPUTED_VALUE"""),5.0) -> 5 | Q12: =IFERROR(__xludf.DUMMYFUNCTION("""COMPUTED_VALUE"""),5.6) -> 5.6 | R12: =IFERROR(__xludf.DUMMYFUNCTION("""COMPUTED_VALUE"""),1.5) -> 1.5 | S12: =IFERROR(__xludf.DUMMYFUNCTION("""COMPUTED_VALUE"""),0.9) -> 0.9 | T12: =IFERROR(__xludf.DUMMYFUNCTION("""COMPUTED_VALUE"""),48.5) -> 48.5 | U12: =IFERROR(__xludf.DUMMYFUNCTION("""COMPUTED_VALUE"""),88.46153846153845) -> 88.461538 | V12: =IFERROR(__xludf.DUMMYFUNCTION("""COMPUTED_VALUE"""),2.9) -> 2.9 | W12: =IFERROR(__xludf.DUMMYFUNCTION("""COMPUTED_VALUE"""),2.08017724625738) -> 2.0801772 | X12: =IFERROR(__xludf.DUMMYFUNCTION("""COMPUTED_VALUE"""),-0.5590090246596284) -> -0.55900902 | Y12: =IFERROR(__xludf.DUMMYFUNCTION("""COMPUTED_VALUE"""),-0.45801768448908886) -> -0.45801768 | Z12: =IFERROR(__xludf.DUMMYFUNCTION("""COMPUTED_VALUE"""),0.8956032065821777) -> 0.89560321 | AA12: =IFERROR(__xludf.DUMMYFUNCTION("""COMPUTED_VALUE"""),1.101878832040204) -> 1.1018788 | AB12: =IFERROR(__xludf.DUMMYFUNCTION("""COMPUTED_VALUE"""),0.2608808014812299) -> 0.2608808 | AC12: =IFERROR(__xludf.DUMMYFUNCTION("""COMPUTED_VALUE"""),-0.21943923317493375) -> -0.21943923 | AD12: =IFERROR(__xludf.DUMMYFUNCTION("""COMPUTED_VALUE"""),2.4547179053444985) -> 2.4547179 | AE12: =IFERROR(__xludf.DUMMYFUNCTION("""COMPUTED_VALUE"""),-0.28107209223135493) -> -0.28107209
A13: =IF(VLOOKUP(H13,'Paste #BBall'!$B$2:$N1001,3,)="BRO","BKN",IF(VLOOKUP(H13,'Paste #BBall'!$B$2:$N1001,3,)="OKL","OKC",VLOOKUP(H13,'Paste #BBall'!$B$2:$N1001,3,))) -> MIL | B13: =VLOOKUP($A13,Schedule!$C$2:$G$31,2,0) -> 4 | C13: =VLOOKUP($A13,Schedule!$C$2:$G$31,3,0) -> 3 | D13: =VLOOKUP($A13,Schedule!$C$2:$G$31,4,0) -> 3 | E13: =SUM(B13:D13) -> 10 | F13: 8 | G13: =IFERROR(__xludf.DUMMYFUNCTION("""COMPUTED_VALUE"""),29.0) -> 29 | H13: =IFERROR(__xludf.DUMMYFUNCTION("""COMPUTED_VALUE"""),"Giannis Antetokounmpo") -> Giannis Antetokounmpo | I13: =IFERROR(__xludf.DUMMYFUNCTION("""COMPUTED_VALUE"""),65.0) -> 65 | J13: =IFERROR(__xludf.DUMMYFUNCTION("""COMPUTED_VALUE"""),"PF,C") -> PF,C | K13: =IFERROR(__xludf.DUMMYFUNCTION("""COMPUTED_VALUE"""),2.440947221287024) -> 2.4409472 | L13: =IFERROR(__xludf.DUMMYFUNCTION("""COMPUTED_VALUE"""),5.804536560306708) -> 5.8045366 | M13: =IFERROR(__xludf.DUMMYFUNCTION("""COMPUTED_VALUE"""),3.3635893390196845) -> 3.3635893 | N13: =IFERROR(__xludf.DUMMYFUNCTION("""COMPUTED_VALUE"""),28.3) -> 28.3 | O13: =IFERROR(__xludf.DUMMYFUNCTION("""COMPUTED_VALUE"""),0.9) -> 0.9 | P13: =IFERROR(__xludf.DUMMYFUNCTION("""COMPUTED_VALUE"""),11.6) -> 11.6 | Q13: =IFERROR(__xludf.DUMMYFUNCTION("""COMPUTED_VALUE"""),5.7) -> 5.7 | R13: =IFERROR(__xludf.DUMMYFUNCTION("""COMPUTED_VALUE"""),1.1) -> 1.1 | S13: =IFERROR(__xludf.DUMMYFUNCTION("""COMPUTED_VALUE"""),1.0) -> 1 | T13: =IFERROR(__xludf.DUMMYFUNCTION("""COMPUTED_VALUE"""),56.7251461988304) -> 56.725146 | U13: =IFERROR(__xludf.DUMMYFUNCTION("""COMPUTED_VALUE"""),67.79661016949152) -> 67.79661 | V13: =IFERROR(__xludf.DUMMYFUNCTION("""COMPUTED_VALUE"""),3.6) -> 3.6 | W13: =IFERROR(__xludf.DUMMYFUNCTION("""COMPUTED_VALUE"""),1.8610929562113694) -> 1.861093 | X13: =IFERROR(__xludf.DUMMYFUNCTION("""COMPUTED_VALUE"""),-0.6457219033555379) -> -0.6457219 | Y13: =IFERROR(__xludf.DUMMYFUNCTION("""COMPUTED_VALUE"""),2.3017967260051186) -> 2.3017967 | Z13: =IFERROR(__xludf.DUMMYFUNCTION("""COMPUTED_VALUE"""),0.9466056670936915) -> 0.94660567 | AA13: =IFERROR(__xludf.DUMMYFUNCTION("""COMPUTED_VALUE"""),0.22967922884215308) -> 0.22967923 | AB13: =IFERROR(__xludf.DUMMYFUNCTION("""COMPUTED_VALUE"""),0.39219664115299) -> 0.39219664 | AC13: =IFERROR(__xludf.DUMMYFUNCTION("""COMPUTED_VALUE"""),1.2172831192413873) -> 1.2172831 | AD13: =IFERROR(__xludf.DUMMYFUNCTION("""COMPUTED_VALUE"""),-3.2847641480178242) -> -3.2847641 | AE13: =IFERROR(__xludf.DUMMYFUNCTION("""COMPUTED_VALUE"""),-0.49839587488446435) -> -0.49839587
A14: =IF(VLOOKUP(H14,'Paste #BBall'!$B$2:$N1001,3,)="BRO","BKN",IF(VLOOKUP(H14,'Paste #BBall'!$B$2:$N1001,3,)="OKL","OKC",VLOOKUP(H14,'Paste #BBall'!$B$2:$N1001,3,))) -> MIL | B14: =VLOOKUP($A14,Schedule!$C$2:$G$31,2,0) -> 4 | C14: =VLOOKUP($A14,Schedule!$C$2:$G$31,3,0) -> 3 | D14: =VLOOKUP($A14,Schedule!$C$2:$G$31,4,0) -> 3 | E14: =SUM(B14:D14) -> 10 | F14: 9 | G14: =IFERROR(__xludf.DUMMYFUNCTION("""COMPUTED_VALUE"""),9.0) -> 9 | H14: =IFERROR(__xludf.DUMMYFUNCTION("""COMPUTED_VALUE"""),"Damian Lillard") -> Damian Lillard | I14: =IFERROR(__xludf.DUMMYFUNCTION("""COMPUTED_VALUE"""),67.0) -> 67 | J14: =IFERROR(__xludf.DUMMYFUNCTION("""COMPUTED_VALUE"""),"PG") -> PG | K14: =IFERROR(__xludf.DUMMYFUNCTION("""COMPUTED_VALUE"""),5.471375355219976) -> 5.4713754 | L14: =IFERROR(__xludf.DUMMYFUNCTION("""COMPUTED_VALUE"""),5.737778982304781) -> 5.737779 | M14: =IFERROR(__xludf.DUMMYFUNCTION("""COMPUTED_VALUE"""),0.2664036270848049) -> 0.26640363 | N14: =IFERROR(__xludf.DUMMYFUNCTION("""COMPUTED_VALUE"""),27.2) -> 27.2 | O14: =IFERROR(__xludf.DUMMYFUNCTION("""COMPUTED_VALUE"""),3.8) -> 3.8 | P14: =IFERROR(__xludf.DUMMYFUNCTION("""COMPUTED_VALUE"""),4.0) -> 4 | Q14: =IFERROR(__xludf.DUMMYFUNCTION("""COMPUTED_VALUE"""),6.9) -> 6.9 | R14: =IFERROR(__xludf.DUMMYFUNCTION("""COMPUTED_VALUE"""),0.9) -> 0.9 | S14: =IFERROR(__xludf.DUMMYFUNCTION("""COMPUTED_VALUE"""),0.3) -> 0.3 | T14: =IFERROR(__xludf.DUMMYFUNCTION("""COMPUTED_VALUE"""),46.067415730337075) -> 46.067416 | U14: =IFERROR(__xludf.DUMMYFUNCTION("""COMPUTED_VALUE"""),91.02564102564102) -> 91.025641 | V14: =IFERROR(__xludf.DUMMYFUNCTION("""COMPUTED_VALUE"""),3.1) -> 3.1 | W14: =IFERROR(__xludf.DUMMYFUNCTION("""COMPUTED_VALUE"""),1.6757139415570521) -> 1.6757139 | X14: =IFERROR(__xludf.DUMMYFUNCTION("""COMPUTED_VALUE"""),1.868951578825835) -> 1.8689516 | Y14: =IFERROR(__xludf.DUMMYFUNCTION("""COMPUTED_VALUE"""),-0.8761713830488173) -> -0.87617138 | Z14: =IFERROR(__xludf.DUMMYFUNCTION("""COMPUTED_VALUE"""),1.5586351932318547) -> 1.5586352 | AA14: =IFERROR(__xludf.DUMMYFUNCTION("""COMPUTED_VALUE"""),-0.2064205727568726) -> -0.20642057 | AB14: =IFERROR(__xludf.DUMMYFUNCTION("""COMPUTED_VALUE"""),-0.5270142365493308) -> -0.52701424 | AC14: =IFERROR(__xludf.DUMMYFUNCTION("""COMPUTED_VALUE"""),-0.6278094751804226) -> -0.62780948 | AD14: =IFERROR(__xludf.DUMMYFUNCTION("""COMPUTED_VALUE"""),2.3388871547374808) -> 2.3388872 | AE14: =IFERROR(__xludf.DUMMYFUNCTION("""COMPUTED_VALUE"""),-0.3431646015608148) -> -0.3431646
A15: =IF(VLOOKUP(H15,'Paste #BBall'!$B$2:$N1001,3,)="BRO","BKN",IF(VLOOKUP(H15,'Paste #BBall'!$B$2:$N1001,3,)="OKL","OKC",VLOOKUP(H15,'Paste #BBall'!$B$2:$N1001,3,))) -> GS | B15: =VLOOKUP($A15,Schedule!$C$2:$G$31,2,0) -> 3 | C15: =VLOOKUP($A15,Schedule!$C$2:$G$31,3,0) -> 3 | D15: =VLOOKUP($A15,Schedule!$C$2:$G$31,4,0) -> 4 | E15: =SUM(B15:D15) -> 10 | F15: 10 | G15: =IFERROR(__xludf.DUMMYFUNCTION("""COMPUTED_VALUE"""),8.0) -> 8 | H15: =IFERROR(__xludf.DUMMYFUNCTION("""COMPUTED_VALUE"""),"Stephen Curry") -> Stephen Curry | I15: =IFERROR(__xludf.DUMMYFUNCTION("""COMPUTED_VALUE"""),65.0) -> 65 | J15: =IFERROR(__xludf.DUMMYFUNCTION("""COMPUTED_VALUE"""),"PG") -> PG | K15: =IFERROR(__xludf.DUMMYFUNCTION("""COMPUTED_VALUE"""),5.8071797150291085) -> 5.8071797 | L15: =IFERROR(__xludf.DUMMYFUNCTION("""COMPUTED_VALUE"""),5.6849205284665425) -> 5.6849205 | M15: =IFERROR(__xludf.DUMMYFUNCTION("""COMPUTED_VALUE"""),-0.12225918656256596) -> -0.12225919 | N15: =IFERROR(__xludf.DUMMYFUNCTION("""COMPUTED_VALUE"""),28.0) -> 28 | O15: =IFERROR(__xludf.DUMMYFUNCTION("""COMPUTED_VALUE"""),4.7) -> 4.7 | P15: =IFERROR(__xludf.DUMMYFUNCTION("""COMPUTED_VALUE"""),5.6) -> 5.6 | Q15: =IFERROR(__xludf.DUMMYFUNCTION("""COMPUTED_VALUE"""),5.6) -> 5.6 | R15: =IFERROR(__xludf.DUMMYFUNCTION("""COMPUTED_VALUE"""),0.9) -> 0.9 | S15: =IFERROR(__xludf.DUMMYFUNCTION("""COMPUTED_VALUE"""),0.3) -> 0.3 | T15: =IFERROR(__xludf.DUMMYFUNCTION("""COMPUTED_VALUE"""),47.474747474747474) -> 47.474747 | U15: =IFERROR(__xludf.DUMMYFUNCTION("""COMPUTED_VALUE"""),91.83673469387755) -> 91.836735 | V15: =IFERROR(__xludf.DUMMYFUNCTION("""COMPUTED_VALUE"""),3.3) -> 3.3 | W15: =IFERROR(__xludf.DUMMYFUNCTION("""COMPUTED_VALUE"""),1.8105350431238283) -> 1.810535 | X15: =IFERROR(__xludf.DUMMYFUNCTION("""COMPUTED_VALUE"""),2.64936748708902) -> 2.6493675 | Y15: =IFERROR(__xludf.DUMMYFUNCTION("""COMPUTED_VALUE"""),-0.207125465353252) -> -0.20712547 | Z15: =IFERROR(__xludf.DUMMYFUNCTION("""COMPUTED_VALUE"""),0.8956032065821777) -> 0.89560321 | AA15: =IFERROR(__xludf.DUMMYFUNCTION("""COMPUTED_VALUE"""),-0.2064205727568726) -> -0.20642057 | AB15: =IFERROR(__xludf.DUMMYFUNCTION("""COMPUTED_VALUE"""),-0.5270142365493308) -> -0.52701424 | AC15: =IFERROR(__xludf.DUMMYFUNCTION("""COMPUTED_VALUE"""),-0.4200144417760026) -> -0.42001444 | AD15: =IFERROR(__xludf.DUMMYFUNCTION("""COMPUTED_VALUE"""),1.5682323824479183) -> 1.5682324 | AE15: =IFERROR(__xludf.DUMMYFUNCTION("""COMPUTED_VALUE"""),-0.40525711089027455) -> -0.40525711
A16: =IF(VLOOKUP(H16,'Paste #BBall'!$B$2:$N1001,3,)="BRO","BKN",IF(VLOOKUP(H16,'Paste #BBall'!$B$2:$N1001,3,)="OKL","OKC",VLOOKUP(H16,'Paste #BBall'!$B$2:$N1001,3,))) -> DAL | B16: =VLOOKUP($A16,Schedule!$C$2:$G$31,2,0) -> 3 | C16: =VLOOKUP($A16,Schedule!$C$2:$G$31,3,0) -> 4 | D16: =VLOOKUP($A16,Schedule!$C$2:$G$31,4,0) -> 2 | E16: =SUM(B16:D16) -> 9 | F16: 11 | G16: =IFERROR(__xludf.DUMMYFUNCTION("""COMPUTED_VALUE"""),10.0) -> 10 | H16: =IFERROR(__xludf.DUMMYFUNCTION("""COMPUTED_VALUE"""),"Kyrie Irving") -> Kyrie Irving | I16: =IFERROR(__xludf.DUMMYFUNCTION("""COMPUTED_VALUE"""),62.0) -> 62 | J16: =IFERROR(__xludf.DUMMYFUNCTION("""COMPUTED_VALUE"""),"PG,SG") -> PG,SG | K16: =IFERROR(__xludf.DUMMYFUNCTION("""COMPUTED_VALUE"""),5.39863539570384) -> 5.3986354 | L16: =IFERROR(__xludf.DUMMYFUNCTION("""COMPUTED_VALUE"""),5.304467756856497) -> 5.3044678 | M16: =IFERROR(__xludf.DUMMYFUNCTION("""COMPUTED_VALUE"""),-0.0941676388473427) -> -0.094167639 | N16: =IFERROR(__xludf.DUMMYFUNCTION("""COMPUTED_VALUE"""),26.7) -> 26.7 | O16: =IFERROR(__xludf.DUMMYFUNCTION("""COMPUTED_VALUE"""),3.2) -> 3.2 | P16: =IFERROR(__xludf.DUMMYFUNCTION("""COMPUTED_VALUE"""),4.8) -> 4.8 | Q16: =IFERROR(__xludf.DUMMYFUNCTION("""COMPUTED_VALUE"""),5.5) -> 5.5 | R16: =IFERROR(__xludf.DUMMYFUNCTION("""COMPUTED_VALUE"""),1.2) -> 1.2 | S16: =IFERROR(__xludf.DUMMYFUNCTION("""COMPUTED_VALUE"""),0.7) -> 0.7 | T16: =IFERROR(__xludf.DUMMYFUNCTION("""COMPUTED_VALUE"""),48.756218905472636) -> 48.756219 | U16: =IFERROR(__xludf.DUMMYFUNCTION("""COMPUTED_VALUE"""),90.9090909090909) -> 90.909091 | V16: =IFERROR(__xludf.DUMMYFUNCTION("""COMPUTED_VALUE"""),2.2) -> 2.2 | W16: =IFERROR(__xludf.DUMMYFUNCTION("""COMPUTED_VALUE"""),1.5914507530778172) -> 1.5914508 | X16: =IFERROR(__xludf.DUMMYFUNCTION("""COMPUTED_VALUE"""),1.3486743066503788) -> 1.3486743 | Y16: =IFERROR(__xludf.DUMMYFUNCTION("""COMPUTED_VALUE"""),-0.5416484242010347) -> -0.54164842 | Z16: =IFERROR(__xludf.DUMMYFUNCTION("""COMPUTED_VALUE"""),0.8446007460706644) -> 0.84460075 | AA16: =IFERROR(__xludf.DUMMYFUNCTION("""COMPUTED_VALUE"""),0.44772912964166556) -> 0.44772913 | AB16: =IFERROR(__xludf.DUMMYFUNCTION("""COMPUTED_VALUE"""),-0.0017508778622903794) -> -0.0017508779 | AC16: =IFERROR(__xludf.DUMMYFUNCTION("""COMPUTED_VALUE"""),-0.16909488033568423) -> -0.16909488 | AD16: =IFERROR(__xludf.DUMMYFUNCTION("""COMPUTED_VALUE"""),1.3066068891921918) -> 1.3066069 | AE16: =IFERROR(__xludf.DUMMYFUNCTION("""COMPUTED_VALUE"""),-0.06374830957824563) -> -0.06374831
A17: =IF(VLOOKUP(H17,'Paste #BBall'!$B$2:$N1001,3,)="BRO","BKN",IF(VLOOKUP(H17,'Paste #BBall'!$B$2:$N1001,3,)="OKL","OKC",VLOOKUP(H17,'Paste #BBall'!$B$2:$N1001,3,))) -> LAL | B17: =VLOOKUP($A17,Schedule!$C$2:$G$31,2,0) -> 4 | C17: =VLOOKUP($A17,Schedule!$C$2:$G$31,3,0) -> 2 | D17: =VLOOKUP($A17,Schedule!$C$2:$G$31,4,0) -> 3 | E17: =SUM(B17:D17) -> 9 | F17: 12 | G17: =IFERROR(__xludf.DUMMYFUNCTION("""COMPUTED_VALUE"""),12.0) -> 12 | H17: =IFERROR(__xludf.DUMMYFUNCTION("""COMPUTED_VALUE"""),"Anthony Davis") -> Anthony Davis | I17: =IFERROR(__xludf.DUMMYFUNCTION("""COMPUTED_VALUE"""),60.0) -> 60 | J17: =IFERROR(__xludf.DUMMYFUNCTION("""COMPUTED_VALUE"""),"PF,C") -> PF,C | K17: =IFERROR(__xludf.DUMMYFUNCTION("""COMPUTED_VALUE"""),4.746284103456114) -> 4.7462841 | L17: =IFERROR(__xludf.DUMMYFUNCTION("""COMPUTED_VALUE"""),5.121027053206726) -> 5.1210271 | M17: =IFERROR(__xludf.DUMMYFUNCTION("""COMPUTED_VALUE"""),0.37474294975061184) -> 0.37474295 | N17: =IFERROR(__xludf.DUMMYFUNCTION("""COMPUTED_VALUE"""),24.3) -> 24.3 | O17: =IFERROR(__xludf.DUMMYFUNCTION("""COMPUTED_VALUE"""),0.3) -> 0.3 | P17: =IFERROR(__xludf.DUMMYFUNCTION("""COMPUTED_VALUE"""),11.2) -> 11.2 | Q17: =IFERROR(__xludf.DUMMYFUNCTION("""COMPUTED_VALUE"""),2.8) -> 2.8 | R17: =IFERROR(__xludf.DUMMYFUNCTION("""COMPUTED_VALUE"""),1.1) -> 1.1 | S17: =IFERROR(__xludf.DUMMYFUNCTION("""COMPUTED_VALUE"""),2.1) -> 2.1 | T17: =IFERROR(__xludf.DUMMYFUNCTION("""COMPUTED_VALUE"""),54.70588235294118) -> 54.705882 | U17: =IFERROR(__xludf.DUMMYFUNCTION("""COMPUTED_VALUE"""),75.71428571428571) -> 75.714286 | V17: =IFERROR(__xludf.DUMMYFUNCTION("""COMPUTED_VALUE"""),2.1) -> 2.1 | W17: =IFERROR(__xludf.DUMMYFUNCTION("""COMPUTED_VALUE"""),1.1869874483774896) -> 1.1869874 | X17: =IFERROR(__xludf.DUMMYFUNCTION("""COMPUTED_VALUE"""),-1.1659991755309944) -> -1.1659992 | Y17: =IFERROR(__xludf.DUMMYFUNCTION("""COMPUTED_VALUE"""),2.134535246581227) -> 2.1345352 | Z17: =IFERROR(__xludf.DUMMYFUNCTION("""COMPUTED_VALUE"""),-0.5324656877402022) -> -0.53246569 | AA17: =IFERROR(__xludf.DUMMYFUNCTION("""COMPUTED_VALUE"""),0.22967922884215308) -> 0.22967923 | AB17: =IFERROR(__xludf.DUMMYFUNCTION("""COMPUTED_VALUE"""),1.8366708775423515) -> 1.8366709 | AC17: =IFERROR(__xludf.DUMMYFUNCTION("""COMPUTED_VALUE"""),0.8672792576344284) -> 0.86727926 | AD17: =IFERROR(__xludf.DUMMYFUNCTION("""COMPUTED_VALUE"""),-0.5689572631172066) -> -0.56895726 | AE17: =IFERROR(__xludf.DUMMYFUNCTION("""COMPUTED_VALUE"""),-0.032702054913515695) -> -0.032702055
A18: =IF(VLOOKUP(H18,'Paste #BBall'!$B$2:$N1001,3,)="BRO","BKN",IF(VLOOKUP(H18,'Paste #BBall'!$B$2:$N1001,3,)="OKL","OKC",VLOOKUP(H18,'Paste #BBall'!$B$2:$N1001,3,))) -> ATL | B18: =VLOOKUP($A18,Schedule!$C$2:$G$31,2,0) -> 4 | C18: =VLOOKUP($A18,Schedule!$C$2:$G$31,3,0) -> 3 | D18: =VLOOKUP($A18,Schedule!$C$2:$G$31,4,0) -> 3 | E18: =SUM(B18:D18) -> 10 | F18: 13 | G18: =IFERROR(__xludf.DUMMYFUNCTION("""COMPUTED_VALUE"""),15.0) -> 15 | H18: =IFERROR(__xludf.DUMMYFUNCTION("""COMPUTED_VALUE"""),"Trae Young") -> Trae Young | I18: =IFERROR(__xludf.DUMMYFUNCTION("""COMPUTED_VALUE"""),75.0) -> 75 | J18: =IFERROR(__xludf.DUMMYFUNCTION("""COMPUTED_VALUE"""),"PG") -> PG | K18: =IFERROR(__xludf.DUMMYFUNCTION("""COMPUTED_VALUE"""),4.266807449081796) -> 4.2668074 | L18: =IFERROR(__xludf.DUMMYFUNCTION("""COMPUTED_VALUE"""),4.937474580159613) -> 4.9374746 | M18: =IFERROR(__xludf.DUMMYFUNCTION("""COMPUTED_VALUE"""),0.670667131077817) -> 0.67066713 | N18: =IFERROR(__xludf.DUMMYFUNCTION("""COMPUTED_VALUE"""),27.1) -> 27.1 | O18: =IFERROR(__xludf.DUMMYFUNCTION("""COMPUTED_VALUE"""),2.2) -> 2.2 | P18: =IFERROR(__xludf.DUMMYFUNCTION("""COMPUTED_VALUE"""),3.4) -> 3.4 | Q18: =IFERROR(__xludf.DUMMYFUNCTION("""COMPUTED_VALUE"""),10.0) -> 10 | R18: =IFERROR(__xludf.DUMMYFUNCTION("""COMPUTED_VALUE"""),1.1) -> 1.1 | S18: =IFERROR(__xludf.DUMMYFUNCTION("""COMPUTED_VALUE"""),0.1) -> 0.1 | T18: =IFERROR(__xludf.DUMMYFUNCTION("""COMPUTED_VALUE"""),43.62745098039216) -> 43.627451 | U18: =IFERROR(__xludf.DUMMYFUNCTION("""COMPUTED_VALUE"""),88.8888888888889) -> 88.888889 | V18: =IFERROR(__xludf.DUMMYFUNCTION("""COMPUTED_VALUE"""),4.1) -> 4.1 | W18: =IFERROR(__xludf.DUMMYFUNCTION("""COMPUTED_VALUE"""),1.6588613038612057) -> 1.6588613 | X18: =IFERROR(__xludf.DUMMYFUNCTION("""COMPUTED_VALUE"""),0.48154551969128473) -> 0.48154552 | Y18: =IFERROR(__xludf.DUMMYFUNCTION("""COMPUTED_VALUE"""),-1.1270636021846543) -> -1.1270636 | Z18: =IFERROR(__xludf.DUMMYFUNCTION("""COMPUTED_VALUE"""),3.1397114690887746) -> 3.1397115 | AA18: =IFERROR(__xludf.DUMMYFUNCTION("""COMPUTED_VALUE"""),0.22967922884215308) -> 0.22967923 | AB18: =IFERROR(__xludf.DUMMYFUNCTION("""COMPUTED_VALUE"""),-0.7896459158928509) -> -0.78964592 | AC18: =IFERROR(__xludf.DUMMYFUNCTION("""COMPUTED_VALUE"""),-1.2166998568887837) -> -1.2166999 | AD18: =IFERROR(__xludf.DUMMYFUNCTION("""COMPUTED_VALUE"""),1.9980137249618144) -> 1.9980137 | AE18: =IFERROR(__xludf.DUMMYFUNCTION("""COMPUTED_VALUE"""),-0.6536271482081137) -> -0.65362715
A19: =IF(VLOOKUP(H19,'Paste #BBall'!$B$2:$N1001,3,)="BRO","BKN",IF(VLOOKUP(H19,'Paste #BBall'!$B$2:$N1001,3,)="OKL","OKC",VLOOKUP(H19,'Paste #BBall'!$B$2:$N1001,3,))) -> PHI | B19: =VLOOKUP($A19,Schedule!$C$2:$G$31,2,0) -> 4 | C19: =VLOOKUP($A19,Schedule!$C$2:$G$31,3,0) -> 3 | D19: =VLOOKUP($A19,Schedule!$C$2:$G$31,4,0) -> 4 | E19: =SUM(B19:D19) -> 11 | F19: 14 | G19: =IFERROR(__xludf.DUMMYFUNCTION("""COMPUTED_VALUE"""),14.0) -> 14 | H19: =IFERROR(__xludf.DUMMYFUNCTION("""COMPUTED_VALUE"""),"James Harden") -> James Harden | I19: =IFERROR(__xludf.DUMMYFUNCTION("""COMPUTED_VALUE"""),60.0) -> 60 | J19: =IFERROR(__xludf.DUMMYFUNCTION("""COMPUTED_VALUE"""),"PG,SG") -> PG,SG | K19: =IFERROR(__xludf.DUMMYFUNCTION("""COMPUTED_VALUE"""),4.432903750997129) -> 4.4329038 | L19: =IFERROR(__xludf.DUMMYFUNCTION("""COMPUTED_VALUE"""),4.82347949870555) -> 4.8234795 | M19: =IFERROR(__xludf.DUMMYFUNCTION("""COMPUTED_VALUE"""),0.39057574770842063) -> 0.39057575 | N19: =IFERROR(__xludf.DUMMYFUNCTION("""COMPUTED_VALUE"""),20.0) -> 20 | O19: =IFERROR(__xludf.DUMMYFUNCTION("""COMPUTED_VALUE"""),2.4) -> 2.4 | P19: =IFERROR(__xludf.DUMMYFUNCTION("""COMPUTED_VALUE"""),5.6) -> 5.6 | Q19: =IFERROR(__xludf.DUMMYFUNCTION("""COMPUTED_VALUE"""),10.1) -> 10.1 | R19: =IFERROR(__xludf.DUMMYFUNCTION("""COMPUTED_VALUE"""),1.1) -> 1.1 | S19: =IFERROR(__xludf.DUMMYFUNCTION("""COMPUTED_VALUE"""),0.5) -> 0.5 | T19: =IFERROR(__xludf.DUMMYFUNCTION("""COMPUTED_VALUE"""),42.7536231884058) -> 42.753623 | U19: =IFERROR(__xludf.DUMMYFUNCTION("""COMPUTED_VALUE"""),86.76470588235294) -> 86.764706 | V19: =IFERROR(__xludf.DUMMYFUNCTION("""COMPUTED_VALUE"""),3.8) -> 3.8 | W19: =IFERROR(__xludf.DUMMYFUNCTION("""COMPUTED_VALUE"""),0.46232402745606893) -> 0.46232403 | X19: =IFERROR(__xludf.DUMMYFUNCTION("""COMPUTED_VALUE"""),0.6549712770831033) -> 0.65497128 | Y19: =IFERROR(__xludf.DUMMYFUNCTION("""COMPUTED_VALUE"""),-0.207125465353252) -> -0.20712547 | Z19: =IFERROR(__xludf.DUMMYFUNCTION("""COMPUTED_VALUE"""),3.190713929600288) -> 3.1907139 | AA19: =IFERROR(__xludf.DUMMYFUNCTION("""COMPUTED_VALUE"""),0.22967922884215308) -> 0.22967923 | AB19: =IFERROR(__xludf.DUMMYFUNCTION("""COMPUTED_VALUE"""),-0.2643825572058105) -> -0.26438256 | AC19: =IFERROR(__xludf.DUMMYFUNCTION("""COMPUTED_VALUE"""),-0.9435130390666896) -> -0.94351304 | AD19: =IFERROR(__xludf.DUMMYFUNCTION("""COMPUTED_VALUE"""),1.3177874424969223) -> 1.3177874 | AE19: =IFERROR(__xludf.DUMMYFUNCTION("""COMPUTED_VALUE"""),-0.5604883842139241) -> -0.56048838
A20: =IF(VLOOKUP(H20,'Paste #BBall'!$B$2:$N1001,3,)="BRO","BKN",IF(VLOOKUP(H20,'Paste #BBall'!$B$2:$N1001,3,)="OKL","OKC",VLOOKUP(H20,'Paste #BBall'!$B$2:$N1001,3,))) -> SAC | B20: =VLOOKUP($A20,Schedule!$C$2:$G$31,2,0) -> 4 | C20: =VLOOKUP($A20,Schedule!$C$2:$G$31,3,0) -> 3 | D20: =VLOOKUP($A20,Schedule!$C$2:$G$31,4,0) -> 4 | E20: =SUM(B20:D20) -> 11 | F20: 15 | G20: =IFERROR(__xludf.DUMMYFUNCTION("""COMPUTED_VALUE"""),18.0) -> 18 | H20: =IFERROR(__xludf.DUMMYFUNCTION("""COMPUTED_VALUE"""),"Domantas Sabonis") -> Domantas Sabonis | I20: =IFERROR(__xludf.DUMMYFUNCTION("""COMPUTED_VALUE"""),72.0) -> 72 | J20: =IFERROR(__xludf.DUMMYFUNCTION("""COMPUTED_VALUE"""),"PF,C") -> PF,C | K20: =IFERROR(__xludf.DUMMYFUNCTION("""COMPUTED_VALUE"""),3.579700592395934) -> 3.5797006 | L20: =IFERROR(__xludf.DUMMYFUNCTION("""COMPUTED_VALUE"""),4.734502334063159) -> 4.7345023 | M20: =IFERROR(__xludf.DUMMYFUNCTION("""COMPUTED_VALUE"""),1.1548017416672254) -> 1.1548017 | N20: =IFERROR(__xludf.DUMMYFUNCTION("""COMPUTED_VALUE"""),19.5) -> 19.5 | O20: =IFERROR(__xludf.DUMMYFUNCTION("""COMPUTED_VALUE"""),0.5) -> 0.5 | P20: =IFERROR(__xludf.DUMMYFUNCTION("""COMPUTED_VALUE"""),12.4) -> 12.4 | Q20: =IFERROR(__xludf.DUMMYFUNCTION("""COMPUTED_VALUE"""),7.3) -> 7.3 | R20: =IFERROR(__xludf.DUMMYFUNCTION("""COMPUTED_VALUE"""),0.9) -> 0.9 | S20: =IFERROR(__xludf.DUMMYFUNCTION("""COMPUTED_VALUE"""),0.5) -> 0.5 | T20: =IFERROR(__xludf.DUMMYFUNCTION("""COMPUTED_VALUE"""),60.655737704918046) -> 60.655738 | U20: =IFERROR(__xludf.DUMMYFUNCTION("""COMPUTED_VALUE"""),74.54545454545453) -> 74.545455 | V20: =IFERROR(__xludf.DUMMYFUNCTION("""COMPUTED_VALUE"""),3.0) -> 3 | W20: =IFERROR(__xludf.DUMMYFUNCTION("""COMPUTED_VALUE"""),0.378060838976834) -> 0.37806084 | X20: =IFERROR(__xludf.DUMMYFUNCTION("""COMPUTED_VALUE"""),-0.9925734181391757) -> -0.99257342 | Y20: =IFERROR(__xludf.DUMMYFUNCTION("""COMPUTED_VALUE"""),2.6363196848529014) -> 2.6363197 | Z20: =IFERROR(__xludf.DUMMYFUNCTION("""COMPUTED_VALUE"""),1.7626450352779086) -> 1.762645 | AA20: =IFERROR(__xludf.DUMMYFUNCTION("""COMPUTED_VALUE"""),-0.2064205727568726) -> -0.20642057 | AB20: =IFERROR(__xludf.DUMMYFUNCTION("""COMPUTED_VALUE"""),-0.2643825572058105) -> -0.26438256 | AC20: =IFERROR(__xludf.DUMMYFUNCTION("""COMPUTED_VALUE"""),1.3474589061050153) -> 1.3474589 | AD20: =IFERROR(__xludf.DUMMYFUNCTION("""COMPUTED_VALUE"""),-0.6070606542907326) -> -0.60706065 | AE20: =IFERROR(__xludf.DUMMYFUNCTION("""COMPUTED_VALUE"""),-0.31211834689608486) -> -0.31211835
A21: =IF(VLOOKUP(H21,'Paste #BBall'!$B$2:$N1001,3,)="BRO","BKN",IF(VLOOKUP(H21,'Paste #BBall'!$B$2:$N1001,3,)="OKL","OKC",VLOOKUP(H21,'Paste #BBall'!$B$2:$N1001,3,))) -> CLE | B21: =VLOOKUP($A21,Schedule!$C$2:$G$31,2,0) -> 4 | C21: =VLOOKUP($A21,Schedule!$C$2:$G$31,3,0) -> 3 | D21: =VLOOKUP($A21,Schedule!$C$2:$G$31,4,0) -> 4 | E21: =SUM(B21:D21) -> 11 | F21: 16 | G21: =IFERROR(__xludf.DUMMYFUNCTION("""COMPUTED_VALUE"""),11.0) -> 11 | H21: =IFERROR(__xludf.DUMMYFUNCTION("""COMPUTED_VALUE"""),"Donovan Mitchell") -> Donovan Mitchell | I21: =IFERROR(__xludf.DUMMYFUNCTION("""COMPUTED_VALUE"""),69.0) -> 69 | J21: =IFERROR(__xludf.DUMMYFUNCTION("""COMPUTED_VALUE"""),"PG,SG") -> PG,SG | K21: =IFERROR(__xludf.DUMMYFUNCTION("""COMPUTED_VALUE"""),4.8289869003301185) -> 4.8289869 | L21: =IFERROR(__xludf.DUMMYFUNCTION("""COMPUTED_VALUE"""),4.706132753642026) -> 4.7061328 | M21: =IFERROR(__xludf.DUMMYFUNCTION("""COMPUTED_VALUE"""),-0.12285414668809214) -> -0.12285415 | N21: =IFERROR(__xludf.DUMMYFUNCTION("""COMPUTED_VALUE"""),27.7) -> 27.7 | O21: =IFERROR(__xludf.DUMMYFUNCTION("""COMPUTED_VALUE"""),3.6) -> 3.6 | P21: =IFERROR(__xludf.DUMMYFUNCTION("""COMPUTED_VALUE"""),4.4) -> 4.4 | Q21: =IFERROR(__xludf.DUMMYFUNCTION("""COMPUTED_VALUE"""),4.4) -> 4.4 | R21: =IFERROR(__xludf.DUMMYFUNCTION("""COMPUTED_VALUE"""),1.5) -> 1.5 | S21: =IFERROR(__xludf.DUMMYFUNCTION("""COMPUTED_VALUE"""),0.3) -> 0.3 | T21: =IFERROR(__xludf.DUMMYFUNCTION("""COMPUTED_VALUE"""),47.804878048780495) -> 47.804878 | U21: =IFERROR(__xludf.DUMMYFUNCTION("""COMPUTED_VALUE"""),86.53846153846153) -> 86.538462 | V21: =IFERROR(__xludf.DUMMYFUNCTION("""COMPUTED_VALUE"""),2.7) -> 2.7 | W21: =IFERROR(__xludf.DUMMYFUNCTION("""COMPUTED_VALUE"""),1.7599771300362872) -> 1.7599771 | X21: =IFERROR(__xludf.DUMMYFUNCTION("""COMPUTED_VALUE"""),1.6955258214340165) -> 1.6955258 | Y21: =IFERROR(__xludf.DUMMYFUNCTION("""COMPUTED_VALUE"""),-0.7089099036249258) -> -0.7089099 | Z21: =IFERROR(__xludf.DUMMYFUNCTION("""COMPUTED_VALUE"""),0.28357368044401526) -> 0.28357368 | AA21: =IFERROR(__xludf.DUMMYFUNCTION("""COMPUTED_VALUE"""),1.101878832040204) -> 1.1018788 | AB21: =IFERROR(__xludf.DUMMYFUNCTION("""COMPUTED_VALUE"""),-0.5270142365493308) -> -0.52701424 | AC21: =IFERROR(__xludf.DUMMYFUNCTION("""COMPUTED_VALUE"""),-0.3672634806689693) -> -0.36726348 | AD21: =IFERROR(__xludf.DUMMYFUNCTION("""COMPUTED_VALUE"""),0.9784345898076978) -> 0.97843459 | AE21: =IFERROR(__xludf.DUMMYFUNCTION("""COMPUTED_VALUE"""),-0.2189795829018952) -> -0.21897958
A22: =IF(VLOOKUP(H22,'Paste #BBall'!$B$2:$N1001,3,)="BRO","BKN",IF(VLOOKUP(H22,'Paste #BBall'!$B$2:$N1001,3,)="OKL","OKC",VLOOKUP(H22,'Paste #BBall'!$B$2:$N1001,3,))) -> PHO | B22: =VLOOKUP($A22,Schedule!$C$2:$G$31,2,0) -> 3 | C22: =VLOOKUP($A22,Schedule!$C$2:$G$31,3,0) -> 4 | D22: =VLOOKUP($A22,Schedule!$C$2:$G$31,4,0) -> 3 | E22: =SUM(B22:D22) -> 10 | F22: 17 | G22: =IFERROR(__xludf.DUMMYFUNCTION("""COMPUTED_VALUE"""),13.0) -> 13 | H22: =IFERROR(__xludf.DUMMYFUNCTION("""COMPUTED_VALUE"""),"Kevin Durant") -> Kevin Durant | I22: =IFERROR(__xludf.DUMMYFUNCTION("""COMPUTED_VALUE"""),60.0) -> 60 | J22: =IFERROR(__xludf.DUMMYFUNCTION("""COMPUTED_VALUE"""),"SF,PF") -> SF,PF | K22: =IFERROR(__xludf.DUMMYFUNCTION("""COMPUTED_VALUE"""),4.606663231954464) -> 4.6066632 | L22: =IFERROR(__xludf.DUMMYFUNCTION("""COMPUTED_VALUE"""),4.562671069507245) -> 4.5626711 | M22: =IFERROR(__xludf.DUMMYFUNCTION("""COMPUTED_VALUE"""),-0.0439921624472186) -> -0.043992162 | N22: =IFERROR(__xludf.DUMMYFUNCTION("""COMPUTED_VALUE"""),25.3) -> 25.3 | O22: =IFERROR(__xludf.DUMMYFUNCTION("""COMPUTED_VALUE"""),1.9) -> 1.9 | P22: =IFERROR(__xludf.DUMMYFUNCTION("""COMPUTED_VALUE"""),6.5) -> 6.5 | Q22: =IFERROR(__xludf.DUMMYFUNCTION("""COMPUTED_VALUE"""),5.0) -> 5 | R22: =IFERROR(__xludf.DUMMYFUNCTION("""COMPUTED_VALUE"""),0.7) -> 0.7 | S22: =IFERROR(__xludf.DUMMYFUNCTION("""COMPUTED_VALUE"""),1.0) -> 1 | T22: =IFERROR(__xludf.DUMMYFUNCTION("""COMPUTED_VALUE"""),52.38095238095239) -> 52.380952 | U22: =IFERROR(__xludf.DUMMYFUNCTION("""COMPUTED_VALUE"""),89.3939393939394) -> 89.393939 | V22: =IFERROR(__xludf.DUMMYFUNCTION("""COMPUTED_VALUE"""),3.1) -> 3.1 | W22: =IFERROR(__xludf.DUMMYFUNCTION("""COMPUTED_VALUE"""),1.3555138253359595) -> 1.3555138 | X22: =IFERROR(__xludf.DUMMYFUNCTION("""COMPUTED_VALUE"""),0.2214068836035562) -> 0.22140688 | Y22: =IFERROR(__xludf.DUMMYFUNCTION("""COMPUTED_VALUE"""),0.16921286335050373) -> 0.16921286 | Z22: =IFERROR(__xludf.DUMMYFUNCTION("""COMPUTED_VALUE"""),0.5895884435130965) -> 0.58958844 | AA22: =IFERROR(__xludf.DUMMYFUNCTION("""COMPUTED_VALUE"""),-0.6425203743558983) -> -0.64252037 | AB22: =IFERROR(__xludf.DUMMYFUNCTION("""COMPUTED_VALUE"""),0.39219664115299) -> 0.39219664 | AC22: =IFERROR(__xludf.DUMMYFUNCTION("""COMPUTED_VALUE"""),0.4669310431882173) -> 0.46693104 | AD22: =IFERROR(__xludf.DUMMYFUNCTION("""COMPUTED_VALUE"""),1.710985970923737) -> 1.710986 | AE22: =IFERROR(__xludf.DUMMYFUNCTION("""COMPUTED_VALUE"""),-0.3431646015608148) -> -0.3431646
A23: =IF(VLOOKUP(H23,'Paste #BBall'!$B$2:$N1001,3,)="BRO","BKN",IF(VLOOKUP(H23,'Paste #BBall'!$B$2:$N1001,3,)="OKL","OKC",VLOOKUP(H23,'Paste #BBall'!$B$2:$N1001,3,))) -> PHO | B23: =VLOOKUP($A23,Schedule!$C$2:$G$31,2,0) -> 3 | C23: =VLOOKUP($A23,Schedule!$C$2:$G$31,3,0) -> 4 | D23: =VLOOKUP($A23,Schedule!$C$2:$G$31,4,0) -> 3 | E23: =SUM(B23:D23) -> 10 | F23: 18 | G23: =IFERROR(__xludf.DUMMYFUNCTION("""COMPUTED_VALUE"""),16.0) -> 16 | H23: =IFERROR(__xludf.DUMMYFUNCTION("""COMPUTED_VALUE"""),"Devin Booker") -> Devin Booker | I23: =IFERROR(__xludf.DUMMYFUNCTION("""COMPUTED_VALUE"""),68.0) -> 68 | J23: =IFERROR(__xludf.DUMMYFUNCTION("""COMPUTED_VALUE"""),"SG,SF") -> SG,SF | K23: =IFERROR(__xludf.DUMMYFUNCTION("""COMPUTED_VALUE"""),4.021516656325469) -> 4.0215167 | L23: =IFERROR(__xludf.DUMMYFUNCTION("""COMPUTED_VALUE"""),4.17398150830221) -> 4.1739815 | M23: =IFERROR(__xludf.DUMMYFUNCTION("""COMPUTED_VALUE"""),0.15246485197674087) -> 0.15246485 | N23: =IFERROR(__xludf.DUMMYFUNCTION("""COMPUTED_VALUE"""),27.2) -> 27.2 | O23: =IFERROR(__xludf.DUMMYFUNCTION("""COMPUTED_VALUE"""),2.3) -> 2.3 | P23: =IFERROR(__xludf.DUMMYFUNCTION("""COMPUTED_VALUE"""),4.9) -> 4.9 | Q23: =IFERROR(__xludf.DUMMYFUNCTION("""COMPUTED_VALUE"""),6.3) -> 6.3 | R23: =IFERROR(__xludf.DUMMYFUNCTION("""COMPUTED_VALUE"""),1.1) -> 1.1 | S23: =IFERROR(__xludf.DUMMYFUNCTION("""COMPUTED_VALUE"""),0.4) -> 0.4 | T23: =IFERROR(__xludf.DUMMYFUNCTION("""COMPUTED_VALUE"""),48.756218905472636) -> 48.756219 | U23: =IFERROR(__xludf.DUMMYFUNCTION("""COMPUTED_VALUE"""),86.88524590163935) -> 86.885246 | V23: =IFERROR(__xludf.DUMMYFUNCTION("""COMPUTED_VALUE"""),2.6) -> 2.6 | W23: =IFERROR(__xludf.DUMMYFUNCTION("""COMPUTED_VALUE"""),1.6757139415570521) -> 1.6757139 | X23: =IFERROR(__xludf.DUMMYFUNCTION("""COMPUTED_VALUE"""),0.5682583983871938) -> 0.5682584 | Y23: =IFERROR(__xludf.DUMMYFUNCTION("""COMPUTED_VALUE"""),-0.4998330543450616) -> -0.49983305 | Z23: =IFERROR(__xludf.DUMMYFUNCTION("""COMPUTED_VALUE"""),1.2526204301627728) -> 1.2526204 | AA23: =IFERROR(__xludf.DUMMYFUNCTION("""COMPUTED_VALUE"""),0.22967922884215308) -> 0.22967923 | AB23: =IFERROR(__xludf.DUMMYFUNCTION("""COMPUTED_VALUE"""),-0.39569839687757064) -> -0.3956984 | AC23: =IFERROR(__xludf.DUMMYFUNCTION("""COMPUTED_VALUE"""),-0.16909488033568423) -> -0.16909488 | AD23: =IFERROR(__xludf.DUMMYFUNCTION("""COMPUTED_VALUE"""),1.200436114803457) -> 1.2004361 | AE23: =IFERROR(__xludf.DUMMYFUNCTION("""COMPUTED_VALUE"""),-0.18793332823716524) -> -0.18793333
A24: =IF(VLOOKUP(H24,'Paste #BBall'!$B$2:$N1001,3,)="BRO","BKN",IF(VLOOKUP(H24,'Paste #BBall'!$B$2:$N1001,3,)="OKL","OKC",VLOOKUP(H24,'Paste #BBall'!$B$2:$N1001,3,))) -> MIA | B24: =VLOOKUP($A24,Schedule!$C$2:$G$31,2,0) -> 4 | C24: =VLOOKUP($A24,Schedule!$C$2:$G$31,3,0) -> 3 | D24: =VLOOKUP($A24,Schedule!$C$2:$G$31,4,0) -> 4 | E24: =SUM(B24:D24) -> 11 | F24: 19 | G24: =IFERROR(__xludf.DUMMYFUNCTION("""COMPUTED_VALUE"""),20.0) -> 20 | H24: =IFERROR(__xludf.DUMMYFUNCTION("""COMPUTED_VALUE"""),"Jimmy Butler") -> Jimmy Butler | I24: =IFERROR(__xludf.DUMMYFUNCTION("""COMPUTED_VALUE"""),65.0) -> 65 | J24: =IFERROR(__xludf.DUMMYFUNCTION("""COMPUTED_VALUE"""),"SF,PF") -> SF,PF | K24: =IFERROR(__xludf.DUMMYFUNCTION("""COMPUTED_VALUE"""),3.3619381711080165) -> 3.3619382 | L24: =IFERROR(__xludf.DUMMYFUNCTION("""COMPUTED_VALUE"""),3.792516404390513) -> 3.7925164 | M24: =IFERROR(__xludf.DUMMYFUNCTION("""COMPUTED_VALUE"""),0.43057823328249656) -> 0.43057823 | N24: =IFERROR(__xludf.DUMMYFUNCTION("""COMPUTED_VALUE"""),21.3) -> 21.3 | O24: =IFERROR(__xludf.DUMMYFUNCTION("""COMPUTED_VALUE"""),0.5) -> 0.5 | P24: =IFERROR(__xludf.DUMMYFUNCTION("""COMPUTED_VALUE"""),5.7) -> 5.7 | Q24: =IFERROR(__xludf.DUMMYFUNCTION("""COMPUTED_VALUE"""),5.0) -> 5 | R24: =IFERROR(__xludf.DUMMYFUNCTION("""COMPUTED_VALUE"""),1.6) -> 1.6 | S24: =IFERROR(__xludf.DUMMYFUNCTION("""COMPUTED_VALUE"""),0.4) -> 0.4 | T24: =IFERROR(__xludf.DUMMYFUNCTION("""COMPUTED_VALUE"""),51.47058823529412) -> 51.470588 | U24: =IFERROR(__xludf.DUMMYFUNCTION("""COMPUTED_VALUE"""),86.25) -> 86.25 | V24: =IFERROR(__xludf.DUMMYFUNCTION("""COMPUTED_VALUE"""),1.8) -> 1.8 | W24: =IFERROR(__xludf.DUMMYFUNCTION("""COMPUTED_VALUE"""),0.68140831750208) -> 0.68140832 | X24: =IFERROR(__xludf.DUMMYFUNCTION("""COMPUTED_VALUE"""),-0.9925734181391757) -> -0.99257342 | Y24: =IFERROR(__xludf.DUMMYFUNCTION("""COMPUTED_VALUE"""),-0.16531009549727893) -> -0.1653101 | Z24: =IFERROR(__xludf.DUMMYFUNCTION("""COMPUTED_VALUE"""),0.5895884435130965) -> 0.58958844 | AA24: =IFERROR(__xludf.DUMMYFUNCTION("""COMPUTED_VALUE"""),1.319928732839717) -> 1.3199287 | AB24: =IFERROR(__xludf.DUMMYFUNCTION("""COMPUTED_VALUE"""),-0.39569839687757064) -> -0.3956984 | AC24: =IFERROR(__xludf.DUMMYFUNCTION("""COMPUTED_VALUE"""),0.2543227932482316) -> 0.25432279 | AD24: =IFERROR(__xludf.DUMMYFUNCTION("""COMPUTED_VALUE"""),1.4478399005815639) -> 1.4478399 | AE24: =IFERROR(__xludf.DUMMYFUNCTION("""COMPUTED_VALUE"""),0.06043670908067405) -> 0.060436709
A25: =IF(VLOOKUP(H25,'Paste #BBall'!$B$2:$N1001,3,)="BRO","BKN",IF(VLOOKUP(H25,'Paste #BBall'!$B$2:$N1001,3,)="OKL","OKC",VLOOKUP(H25,'Paste #BBall'!$B$2:$N1001,3,))) -> HOU | B25: =VLOOKUP($A25,Schedule!$C$2:$G$31,2,0) -> 4 | C25: =VLOOKUP($A25,Schedule!$C$2:$G$31,3,0) -> 3 | D25: =VLOOKUP($A25,Schedule!$C$2:$G$31,4,0) -> 3 | E25: =SUM(B25:D25) -> 10 | F25: 20 | G25: =IFERROR(__xludf.DUMMYFUNCTION("""COMPUTED_VALUE"""),24.0) -> 24 | H25: =IFERROR(__xludf.DUMMYFUNCTION("""COMPUTED_VALUE"""),"Fred VanVleet") -> Fred VanVleet | I25: =IFERROR(__xludf.DUMMYFUNCTION("""COMPUTED_VALUE"""),67.0) -> 67 | J25: =IFERROR(__xludf.DUMMYFUNCTION("""COMPUTED_VALUE"""),"PG") -> PG | K25: =IFERROR(__xludf.DUMMYFUNCTION("""COMPUTED_VALUE"""),2.762430198240379) -> 2.7624302 | L25: =IFERROR(__xludf.DUMMYFUNCTION("""COMPUTED_VALUE"""),3.6988045120987563) -> 3.6988045 | M25: =IFERROR(__xludf.DUMMYFUNCTION("""COMPUTED_VALUE"""),0.9363743138583773) -> 0.93637431 | N25: =IFERROR(__xludf.DUMMYFUNCTION("""COMPUTED_VALUE"""),18.4) -> 18.4 | O25: =IFERROR(__xludf.DUMMYFUNCTION("""COMPUTED_VALUE"""),3.1) -> 3.1 | P25: =IFERROR(__xludf.DUMMYFUNCTION("""COMPUTED_VALUE"""),3.9) -> 3.9 | Q25: =IFERROR(__xludf.DUMMYFUNCTION("""COMPUTED_VALUE"""),6.4) -> 6.4 | R25: =IFERROR(__xludf.DUMMYFUNCTION("""COMPUTED_VALUE"""),1.6) -> 1.6 | S25: =IFERROR(__xludf.DUMMYFUNCTION("""COMPUTED_VALUE"""),0.5) -> 0.5 | T25: =IFERROR(__xludf.DUMMYFUNCTION("""COMPUTED_VALUE"""),39.869281045751634) -> 39.869281 | U25: =IFERROR(__xludf.DUMMYFUNCTION("""COMPUTED_VALUE"""),88.57142857142858) -> 88.571429 | V25: =IFERROR(__xludf.DUMMYFUNCTION("""COMPUTED_VALUE"""),2.1) -> 2.1 | W25: =IFERROR(__xludf.DUMMYFUNCTION("""COMPUTED_VALUE"""),0.19268182432251685) -> 0.19268182 | X25: =IFERROR(__xludf.DUMMYFUNCTION("""COMPUTED_VALUE"""),1.2619614279544695) -> 1.2619614 | Y25: =IFERROR(__xludf.DUMMYFUNCTION("""COMPUTED_VALUE"""),-0.9179867529047901) -> -0.91798675 | Z25: =IFERROR(__xludf.DUMMYFUNCTION("""COMPUTED_VALUE"""),1.3036228906742866) -> 1.3036229 | AA25: =IFERROR(__xludf.DUMMYFUNCTION("""COMPUTED_VALUE"""),1.319928732839717) -> 1.3199287 | AB25: =IFERROR(__xludf.DUMMYFUNCTION("""COMPUTED_VALUE"""),-0.2643825572058105) -> -0.26438256 | AC25: =IFERROR(__xludf.DUMMYFUNCTION("""COMPUTED_VALUE"""),-1.4868722844713707) -> -1.4868723 | AD25: =IFERROR(__xludf.DUMMYFUNCTION("""COMPUTED_VALUE"""),0.8356810013318832) -> 0.835681 | AE25: =IFERROR(__xludf.DUMMYFUNCTION("""COMPUTED_VALUE"""),-0.032702054913515695) -> -0.032702055
A26: =IF(VLOOKUP(H26,'Paste #BBall'!$B$2:$N1001,3,)="BRO","BKN",IF(VLOOKUP(H26,'Paste #BBall'!$B$2:$N1001,3,)="OKL","OKC",VLOOKUP(H26,'Paste #BBall'!$B$2:$N1001,3,))) -> LAC | B26: =VLOOKUP($A26,Schedule!$C$2:$G$31,2,0) -> 4 | C26: =VLOOKUP($A26,Schedule!$C$2:$G$31,3,0) -> 4 | D26: =VLOOKUP($A26,Schedule!$C$2:$G$31,4,0) -> 3 | E26: =SUM(B26:D26) -> 11 | F26: 21 | G26: =IFERROR(__xludf.DUMMYFUNCTION("""COMPUTED_VALUE"""),19.0) -> 19 | H26: =IFERROR(__xludf.DUMMYFUNCTION("""COMPUTED_VALUE"""),"Paul George") -> Paul George | I26: =IFERROR(__xludf.DUMMYFUNCTION("""COMPUTED_VALUE"""),60.0) -> 60 | J26: =IFERROR(__xludf.DUMMYFUNCTION("""COMPUTED_VALUE"""),"SG,SF,PF") -> SG,SF,PF | K26: =IFERROR(__xludf.DUMMYFUNCTION("""COMPUTED_VALUE"""),3.569957191869557) -> 3.5699572 | L26: =IFERROR(__xludf.DUMMYFUNCTION("""COMPUTED_VALUE"""),3.683648395764549) -> 3.6836484 | M26: =IFERROR(__xludf.DUMMYFUNCTION("""COMPUTED_VALUE"""),0.11369120389499177) -> 0.1136912 | N26: =IFERROR(__xludf.DUMMYFUNCTION("""COMPUTED_VALUE"""),23.0) -> 23 | O26: =IFERROR(__xludf.DUMMYFUNCTION("""COMPUTED_VALUE"""),2.8) -> 2.8 | P26: =IFERROR(__xludf.DUMMYFUNCTION("""COMPUTED_VALUE"""),6.1) -> 6.1 | Q26: =IFERROR(__xludf.DUMMYFUNCTION("""COMPUTED_VALUE"""),5.0) -> 5 | R26: =IFERROR(__xludf.DUMMYFUNCTION("""COMPUTED_VALUE"""),1.5) -> 1.5 | S26: =IFERROR(__xludf.DUMMYFUNCTION("""COMPUTED_VALUE"""),0.4) -> 0.4 | T26: =IFERROR(__xludf.DUMMYFUNCTION("""COMPUTED_VALUE"""),44.19889502762431) -> 44.198895 | U26: =IFERROR(__xludf.DUMMYFUNCTION("""COMPUTED_VALUE"""),85.71428571428571) -> 85.714286 | V26: =IFERROR(__xludf.DUMMYFUNCTION("""COMPUTED_VALUE"""),3.3) -> 3.3 | W26: =IFERROR(__xludf.DUMMYFUNCTION("""COMPUTED_VALUE"""),0.9679031583314787) -> 0.96790316 | X26: =IFERROR(__xludf.DUMMYFUNCTION("""COMPUTED_VALUE"""),1.001822791866741) -> 1.0018228 | Y26: =IFERROR(__xludf.DUMMYFUNCTION("""COMPUTED_VALUE"""),0.0019513839266122224) -> 0.0019513839 | Z26: =IFERROR(__xludf.DUMMYFUNCTION("""COMPUTED_VALUE"""),0.5895884435130965) -> 0.58958844 | AA26: =IFERROR(__xludf.DUMMYFUNCTION("""COMPUTED_VALUE"""),1.101878832040204) -> 1.1018788 | AB26: =IFERROR(__xludf.DUMMYFUNCTION("""COMPUTED_VALUE"""),-0.39569839687757064) -> -0.3956984 | AC26: =IFERROR(__xludf.DUMMYFUNCTION("""COMPUTED_VALUE"""),-0.9762089312755282) -> -0.97620893 | AD26: =IFERROR(__xludf.DUMMYFUNCTION("""COMPUTED_VALUE"""),0.8214592938542618) -> 0.82145929 | AE26: =IFERROR(__xludf.DUMMYFUNCTION("""COMPUTED_VALUE"""),-0.40525711089027455) -> -0.40525711
