Workbook

Sheet Draft
B2: Pick | C2: Your Pick | D2: Round 1 | E2: Round 2 | F2: Round 3 | G2: Round 4 | H2: Round 5 | I2: Round 6 | J2: Round 7 | K2: Round 8 | L2: Round 9 | M2: Round 10 | N2: Round 11 | O2: Round 12 | P2: Round 13 | Q2: Round 14
B3: 1 | C3: =IF(B3=Projections!$G$3,TRUE) -> FALSE | D3: Victor Wembanyama
B4: 2 | C4: =IF(B4=Projections!$G$3,TRUE) -> FALSE
B5: 3 | C5: =IF(B5=Projections!$G$3,TRUE) -> FALSE
B6: 4 | C6: =IF(B6=Projections!$G$3,TRUE) -> FALSE
B7: 5 | C7: =IF(B7=Projections!$G$3,TRUE) -> FALSE
B8: 6 | C8: =IF(B8=Projections!$G$3,TRUE) -> TRUE
B9: 7 | C9: =IF(B9=Projections!$G$3,TRUE) -> FALSE
B10: 8 | C10: =IF(B10=Projections!$G$3,TRUE) -> FALSE
B11: 9 | C11: =IF(B11=Projections!$G$3,TRUE) -> FALSE
B12: 10 | C12: =IF(B12=Projections!$G$3,TRUE) -> FALSE
B13: 11 | C13: =IF(B13=Projections!$G$3,TRUE) -> FALSE
B14: 12 | C14: =IF(B14=Projections!$G$3,TRUE) -> FALSE
C16: Pick # | D16: =IF(C3=TRUE,"1",IF(C4=TRUE,"2", IF(C5=True, "3",IF(C6=True, "4",IF(C7=True, "5",IF(C8=True, "6",IF(C9=True, "7",IF(C10=True, "8",IF(C11=True, "9",IF(C12=True, "10",IF(C13=True, "11",IF(C14=True, "12"))))))))))))*1 -> 6 | E16: =IF(C3=TRUE,"24",IF(C4=TRUE,"23", IF(C5=True, "22",IF(C6=True, "21",IF(C7=True, "20",IF(C8=True, "19",IF(C9=True, "18",IF(C10=True, "17",IF(C11=True, "16",IF(C12=True, "15",IF(C13=True, "14",IF(C14=True, "13"))))))))))))*1 -> 19 | F16: =IF(C3=TRUE,"25",IF(C4=TRUE,"26", IF(C5=True, "27",IF(C6=True, "28",IF(C7=True, "29",IF(C8=True, "30",IF(C9=True, "31",IF(C10=True, "32",IF(C11=True, "33",IF(C12=True, "34",IF(C13=True, "35",IF(C14=True, "36"))))))))))))*1 -> 30 | G16: =IF(C3=TRUE,"48",IF(C4=TRUE,"47", IF(C5=True, "46",IF(C6=True, "45",IF(C7=True, "44",IF(C8=True, "43",IF(C9=True, "42",IF(C10=True, "41",IF(C11=True, "40",IF(C12=True, "39",IF(C13=True, "38",IF(C14=True, "37"))))))))))))*1 -> 43 | H16: =IF(C3=TRUE,"49",IF(C4=TRUE,"50", IF(C5=True, "51",IF(C6=True, "52",IF(C7=True, "53",IF(C8=True, "54",IF(C9=True, "55",IF(C10=True, "56",IF(C11=True, "57",IF(C12=True, "58",IF(C13=True, "59",IF(C14=True, "60"))))))))))))*1 -> 54 | I16: =IF(C3=TRUE,"72",IF(C4=TRUE,"71", IF(C5=True, "70",IF(C6=True, "69",IF(C7=True, "68",IF(C8=True, "67",IF(C9=True, "66",IF(C10=True, "65",IF(C11=True, "64",IF(C12=True, "63",IF(C13=True, "62",IF(C14=True, "61"))))))))))))*1 -> 67 | J16: =IF(C3=TRUE,"73",IF(C4=TRUE,"74", IF(C5=True, "75",IF(C6=True, "76",IF(C7=True, "77",IF(C8=True, "78",IF(C9=True, "79",IF(C10=True, "80",IF(C11=True, "81",IF(C12=True, "82",IF(C13=True, "83",IF(C14=True, "84"))))))))))))*1 -> 78 | K16: =IF(C3=TRUE,"96",IF(C4=TRUE,"95", IF(C5=True, "94",IF(C6=True, "93",IF(C7=True, "92",IF(C8=True, "91",IF(C9=True, "90",IF(C10=True, "89",IF(C11=True, "88",IF(C12=True, "87",IF(C13=True, "86",IF(C14=True, "85"))))))))))))*1 -> 91 | L16: =IF(C3=TRUE,"97",IF(C4=TRUE,"98", IF(C5=True, "99",IF(C6=True, "100",IF(C7=True, "101",IF(C8=True, "102",IF(C9=True, "103",IF(C10=True, "104",IF(C11=True, "105",IF(C12=True, "106",IF(C13=True, "107",IF(C14=True, "108"))))))))))))*1 -> 102 | M16: =IF(C3=TRUE,"120",IF(C4=TRUE,"119", IF(C5=True, "118",IF(C6=True, "117",IF(C7=True, "116",IF(C8=True, "115",IF(C9=True, "114",IF(C10=True, "113",IF(C11=True, "112",IF(C12=True, "111",IF(C13=True, "110",IF(C14=True, "109"))))))))))))*1 -> 115 | N16: =IF(C3=TRUE,"121",IF(C4=TRUE,"122", IF(C5=True, "123",IF(C6=True, "124",IF(C7=True, "125",IF(C8=True, "126",IF(C9=True, "127",IF(C10=True, "128",IF(C11=True, "129",IF(C12=True, "130",IF(C13=True, "131",IF(C14=True, "132"))))))))))))*1 -> 126 | O16: =IF(C3=TRUE,"144",IF(C4=TRUE,"143", IF(C5=True, "142",IF(C6=True, "141",IF(C7=True, "140",IF(C8=True, "139",IF(C9=True, "138",IF(C10=True, "137",IF(C11=True, "136",IF(C12=True, "135",IF(C13=True, "134",IF(C14=True, "133"))))))))))))*1 -> 139 | P16: =IF(C3=TRUE,"145",IF(C4=TRUE,"146", IF(C5=True, "147",IF(C6=True, "148",IF(C7=True, "149",IF(C8=True, "150",IF(C9=True, "151",IF(C10=True, "152",IF(C11=True, "153",IF(C12=True, "154",IF(C13=True, "155",IF(C14=True, "156")))))))))))) -> 150 | Q16: =IF(C3=TRUE,"168",IF(C4=TRUE,"167", IF(C5=True, "166",IF(C6=True, "165",IF(C7=True, "164",IF(C8=True, "163",IF(C9=True, "162",IF(C10=True, "161",IF(C11=True, "160",IF(C12=True, "159",IF(C13=True, "158",IF(C14=True, "157")))))))))))) -> 163
C17: 3RR | D17: =D16 -> 6 | E17: =E16 -> 19 | F17: =F16+IF($C$3,11, IF($C$4,9,IF($C$5,7,IF($C$6,5,IF($C$7,3,IF($C$8,1,IF($C$9,-1,IF($C$10,-3,IF($C$11,-5,IF($C$12,-7, IF($C$13,-9, IF($C$14,-11))))))))))))*1 -> 31 | G17: =G16-IF($C$3,11, IF($C$4,9,IF($C$5,7,IF($C$6,5,IF($C$7,3,IF($C$8,1,IF($C$9,-1,IF($C$10,-3,IF($C$11,-5,IF($C$12,-7, IF($C$13,-9, IF($C$14,-11))))))))))))*1 -> 42 | H17: =H16+IF($C$3,11, IF($C$4,9,IF($C$5,7,IF($C$6,5,IF($C$7,3,IF($C$8,1,IF($C$9,-1,IF($C$10,-3,IF($C$11,-5,IF($C$12,-7, IF($C$13,-9, IF($C$14,-11))))))))))))*1 -> 55 | I17: =I16-IF($C$3,11, IF($C$4,9,IF($C$5,7,IF($C$6,5,IF($C$7,3,IF($C$8,1,IF($C$9,-1,IF($C$10,-3,IF($C$11,-5,IF($C$12,-7, IF($C$13,-9, IF($C$14,-11))))))))))))*1 -> 66 | J17: =J16+IF($C$3,11, IF($C$4,9,IF($C$5,7,IF($C$6,5,IF($C$7,3,IF($C$8,1,IF($C$9,-1,IF($C$10,-3,IF($C$11,-5,IF($C$12,-7, IF($C$13,-9, IF($C$14,-11))))))))))))*1 -> 79 | K17: =K16-IF($C$3,11, IF($C$4,9,IF($C$5,7,IF($C$6,5,IF($C$7,3,IF($C$8,1,IF($C$9,-1,IF($C$10,-3,IF($C$11,-5,IF($C$12,-7, IF($C$13,-9, IF($C$14,-11))))))))))))*1 -> 90 | L17: =L16+IF($C$3,11, IF($C$4,9,IF($C$5,7,IF($C$6,5,IF($C$7,3,IF($C$8,1,IF($C$9,-1,IF($C$10,-3,IF($C$11,-5,IF($C$12,-7, IF($C$13,-9, IF($C$14,-11))))))))))))*1 -> 103 | M17: =M16-IF($C$3,11, IF($C$4,9,IF($C$5,7,IF($C$6,5,IF($C$7,3,IF($C$8,1,IF($C$9,-1,IF($C$10,-3,IF($C$11,-5,IF($C$12,-7, IF($C$13,-9, IF($C$14,-11))))))))))))*1 -> 114 | N17: =N16+IF($C$3,11, IF($C$4,9,IF($C$5,7,IF($C$6,5,IF($C$7,3,IF($C$8,1,IF($C$9,-1,IF($C$10,-3,IF($C$11,-5,IF($C$12,-7, IF($C$13,-9, IF($C$14,-11))))))))))))*1 -> 127 | O17: =O16-IF($C$3,11, IF($C$4,9,IF($C$5,7,IF($C$6,5,IF($C$7,3,IF($C$8,1,IF($C$9,-1,IF($C$10,-3,IF($C$11,-5,IF($C$12,-7, IF($C$13,-9, IF($C$14,-11))))))))))))*1 -> 138 | P17: =P16+IF($B$3,11, IF($B$4,9,IF($B$5,7,IF($B$6,5,IF($B$7,3,IF($B$8,1,IF($B$9,-1,IF($B$10,-3,IF($B$11,-5,IF($B$12,-7, IF($B$13,-9, IF($B$14,-11)))))))))))) -> 161 | Q17: =Q16-IF($B$3,11, IF($B$4,9,IF($B$5,7,IF($B$6,5,IF($B$7,3,IF($B$8,1,IF($B$9,-1,IF($B$10,-3,IF($B$11,-5,IF($B$12,-7, IF($B$13,-9, IF($B$14,-11)))))))))))) -> 152
D19: MAKE A COPY
D20: File -> Make a copy

Sheet Projections
I2: Pick # | J2: Team | K2: PTS | L2: 3P | M2: REB | N2: AST | O2: STL | P2: BLK | Q2: FG% | R2: FT% | S2: TO | T2: Cats Won | U2: Winrate | V2: Punt Sum | W2: ="Round "&Column(A1) -> Round 1 | Y2: ="Round "&Column(B1) -> Round 2 | AA2: ="Round "&Column(C1) -> Round 3 | AC2: ="Round "&Column(D1) -> Round 4 | AE2: ="Round "&Column(F1) -> Round 6 | AG2: ="Round "&Column(G1) -> Round 7 | AI2: ="Round "&Column(H1) -> Round 8 | AK2: ="Round "&Column(P1) -> Round 16 | AM2: ="Round "&Column(R1) -> Round 18 | AO2: ="Round "&Column(T1) -> Round 20 | AQ2: ="Round "&Column(V1) -> Round 22 | AS2: ="Round "&Column(X1) -> Round 24 | AU2: ="Round "&Column(Z1) -> Round 26 | AW2: ="Round "&Column(I1) -> Round 9 | AX2: ="Round "&Column(J1) -> Round 10 | AY2: ="Round "&Column(K1) -> Round 11 | AZ2: ="Round "&Column(L1) -> Round 12 | BA2: ="Round "&Column(M1) -> Round 13 | BB2: ="Round "&Column(N1) -> Round 14 | BC2: ="Round "&Column(O1) -> Round 15 | BD2: =Draft!AK3 | BE2: =Draft!AL3 | BF2: =Draft!AM3 | BG2: =Draft!AN3 | BH2: =Draft!AO3
F3: Your Pick # | G3: 6 | I3: =Draft!C3 -> FALSE | J3: 1 | K3: ='All Teams'!E18 -> 1.3900854 | L3: ='All Teams'!F18 -> 0.55639491 | M3: ='All Teams'!G18 -> 2.446126 | N3: ='All Teams'!H18 -> 0.5619911 | O3: ='All Teams'!I18 -> 0.9889591 | P3: ='All Teams'!J18 -> 6.0230448 | Q3: ='All Teams'!K18 -> -0.52457188 | R3: ='All Teams'!L18 -> 0.13810553 | S3: ='All Teams'!M18 -> -1.9190058 | T3: {=if(Team!D$1=$J3,"-", countif(indirect(address(row($J$2)+ VLOOKUP(Team!D$1,$J$3:$J$14,1),COLUMN($K$2))):indirect(address(row($J$2)+ VLOOKUP(Team!D$1,$J$3:$J$14,1),COLUMN($S$2)))>indirect(address(row($J3),COLUMN($K$2))):indirect(address(row($J3),COLUMN($S$2))),TRUE()))} -> 2 | U3: =SUM(AK$22:AK$33)/99 -> 0.77777778 | V3: =IF(I3, SUMIF(K3:R3,">-1.5"),) | W3: =Draft!D3 -> Victor Wembanyama | Y3: =Draft!E3 | AA3: =Draft!F3 | AC3: =Draft!G3 | AE3: =Draft!H3 | AG3: =Draft!I3 | AI3: =Draft!J3 | AK3: =Draft!R4 | AL3: =Draft!S4 | AM3: =Draft!T4 | AN3: =Draft!U4 | AO3: =Draft!V4 | AP3: =Draft!W4 | AQ3: =Draft!X4 | AR3: =Draft!Y4 | ... AV3: =Draft!AC4 | AW3: =Draft!K3 | AX3: =Draft!L3 | AY3: =Draft!M3 | AZ3: =Draft!N3 | BA3: =Draft!O3 | BB3: =Draft!P3 | BC3: =Draft!AJ4 | BD3: =Draft!AK4 | BE3: =Draft!AL4 | BF3: =Draft!AM4 | BG3: =Draft!AN4 | BH3: =Draft!AO4
I4: =Draft!C4 -> FALSE | J4: 2 | K4: ='All Teams'!E35 | L4: ='All Teams'!F35 | M4: ='All Teams'!G35 | N4: ='All Teams'!H35 | O4: ='All Teams'!I35 | P4: ='All Teams'!J35 | Q4: ='All Teams'!K35 -> 0 | R4: ='All Teams'!L35 -> 0 | S4: ='All Teams'!M35 | T4: {=if(Team!D$1=$J4,"-", countif(indirect(address(row($J$2)+ VLOOKUP(Team!D$1,$J$3:$J$14,1),COLUMN($K$2))):indirect(address(row($J$2)+ VLOOKUP(Team!D$1,$J$3:$J$14,1),COLUMN($S$2)))>indirect(address(row($J4),COLUMN($K$2))):indirect(address(row($J4),COLUMN($S$2))),TRUE()))} -> 0 | U4: =SUM(AL$22:AL$33)/99 -> 0.02020202 | V4: =IF(I4, SUMIF(K4:R4,">-1.5"),) | W4: =Draft!D4 | Y4: =Draft!E4 | AA4: =Draft!F4 | AC4: =Draft!G4 | AE4: =Draft!H4 | AG4: =Draft!I4 | AI4: =Draft!J4 | AK4: =Draft!R5 | AL4: =Draft!S5 | AM4: =Draft!T5 | AN4: =Draft!U5 | AO4: =Draft!V5 | AP4: =Draft!W5 | AQ4: =Draft!X5 | AR4: =Draft!Y5 | ... AT4: =Draft!AA5 | AV4: =Draft!AC5 | AW4: =Draft!K4 | AX4: =Draft!L4 | AY4: =Draft!M4 | AZ4: =Draft!N4 | BA4: =Draft!O4 | BB4: =Draft!P4 | BC4: =Draft!AJ5 | BD4: =Draft!AK5 | BE4: =Draft!AL5 | BF4: =Draft!AM5 | BG4: =Draft!AN5 | BH4: =Draft!AO5
F5: Next Pick Simulation | I5: =Draft!C5 -> FALSE | J5: 3 | K5: ='All Teams'!E52 | L5: ='All Teams'!F52 | M5: ='All Teams'!G52 | N5: ='All Teams'!H52 | O5: ='All Teams'!I52 | P5: ='All Teams'!J52 | Q5: ='All Teams'!K52 -> 0 | R5: ='All Teams'!L52 -> 0 | S5: ='All Teams'!M52 | T5: {=if(Team!D$1=$J5,"-", countif(indirect(address(row($J$2)+ VLOOKUP(Team!D$1,$J$3:$J$14,1),COLUMN($K$2))):indirect(address(row($J$2)+ VLOOKUP(Team!D$1,$J$3:$J$14,1),COLUMN($S$2)))>indirect(address(row($J5),COLUMN($K$2))):indirect(address(row($J5),COLUMN($S$2))),TRUE()))} -> 0 | U5: =SUM(AM$22:AM$33)/99 -> 0.02020202 | V5: =IF(I5, SUMIF(K5:R5,">-1.5"),) | W5: =Draft!D5 | Y5: =Draft!E5 | AA5: =Draft!F5 | AC5: =Draft!G5 | AE5: =Draft!H5 | AG5: =Draft!I5 | AI5: =Draft!J5 | AK5: =Draft!R6 | AL5: =Draft!S6 | AM5: =Draft!T6 | AN5: =Draft!U6 | AO5: =Draft!V6 | AP5: =Draft!W6 | AQ5: =Draft!X6 | AR5: =Draft!Y6 | ... AV5: =Draft!AC6 | AW5: =Draft!K5 | AX5: =Draft!L5 | AY5: =Draft!M5 | AZ5: =Draft!N5 | BA5: =Draft!O5 | BB5: =Draft!P5 | BC5: =Draft!AJ6 | BD5: =Draft!AK6 | BE5: =Draft!AL6 | BF5: =Draft!AM6 | BG5: =Draft!AN6 | BH5: =Draft!AO6
F6: Round # | G6: 1 | I6: =Draft!C6 -> FALSE | J6: 4 | K6: ='All Teams'!E69 | L6: ='All Teams'!F69 | M6: ='All Teams'!G69 | N6: ='All Teams'!H69 | O6: ='All Teams'!I69 | P6: ='All Teams'!J69 | Q6: ='All Teams'!K69 -> 0 | R6: ='All Teams'!L69 -> 0 | S6: ='All Teams'!M69 | T6: {=if(Team!D$1=$J6,"-", countif(indirect(address(row($J$2)+ VLOOKUP(Team!D$1,$J$3:$J$14,1),COLUMN($K$2))):indirect(address(row($J$2)+ VLOOKUP(Team!D$1,$J$3:$J$14,1),COLUMN($S$2)))>indirect(address(row($J6),COLUMN($K$2))):indirect(address(row($J6),COLUMN($S$2))),TRUE()))} -> 0 | U6: =SUM(AN$22:AN$33)/99 -> 0.02020202 | V6: =IF(I6, SUMIF(K6:R6,">-1.5"),) | W6: =Draft!D6 | Y6: =Draft!E6 | AA6: =Draft!F6 | AC6: =Draft!G6 | AE6: =Draft!H6 | AG6: =Draft!I6 | AI6: =Draft!J6 | AK6: =Draft!R7 | AL6: =Draft!S7 | AM6: =Draft!T7 | AN6: =Draft!U7 | AO6: =Draft!V7 | AP6: =Draft!W7 | AQ6: =Draft!X7 | AR6: =Draft!Y7 | ... AV6: =Draft!AC7 | AW6: =Draft!K6 | AX6: =Draft!L6 | AY6: =Draft!M6 | AZ6: =Draft!N6 | BA6: =Draft!O6 | BB6: =Draft!P6 | BC6: =Draft!AJ7 | BD6: =Draft!AK7 | BE6: =Draft!AL7 | BF6: =Draft!AM7 | BG6: =Draft!AN7 | BH6: =Draft!AO7
F7: Victor Wembanyama | I7: =Draft!C7 -> FALSE | J7: 5 | K7: ='All Teams'!E86 | L7: ='All Teams'!F86 | M7: ='All Teams'!G86 | N7: ='All Teams'!H86 | O7: ='All Teams'!I86 | P7: ='All Teams'!J86 | Q7: ='All Teams'!K86 -> 0 | R7: ='All Teams'!L86 -> 0 | S7: ='All Teams'!M86 | T7: {=if(Team!D$1=$J7,"-", countif(indirect(address(row($J$2)+ VLOOKUP(Team!D$1,$J$3:$J$14,1),COLUMN($K$2))):indirect(address(row($J$2)+ VLOOKUP(Team!D$1,$J$3:$J$14,1),COLUMN($S$2)))>indirect(address(row($J7),COLUMN($K$2))):indirect(address(row($J7),COLUMN($S$2))),TRUE()))} -> 0 | U7: =SUM(AO$22:AO$33)/99 -> 0.02020202 | V7: =IF(I7, SUMIF(K7:R7,">-1.5"),) | W7: =Draft!D7 | Y7: =Draft!E7 | AA7: =Draft!F7 | AC7: =Draft!G7 | AE7: =Draft!H7 | AG7: =Draft!I7 | AI7: =Draft!J7 | AK7: =Draft!R8 | AL7: =Draft!S8 | AM7: =Draft!T8 | AN7: =Draft!U8 | AO7: =Draft!V8 | AP7: =Draft!W8 | AQ7: =Draft!X8 | AR7: =Draft!Y8 | ... AV7: =Draft!AC8 | AW7: =Draft!K7 | AX7: =Draft!L7 | AY7: =Draft!M7 | AZ7: =Draft!N7 | BA7: =Draft!O7 | BB7: =Draft!P7 | BC7: =Draft!AJ8 | BD7: =Draft!AK8 | BE7: =Draft!AL8 | BF7: =Draft!AM8 | BG7: =Draft!AN8 | BH7: =Draft!AO8
I8: =Draft!C8 -> TRUE | J8: 6 | K8: ='All Teams'!E103 | L8: ='All Teams'!F103 | M8: ='All Teams'!G103 | N8: ='All Teams'!H103 | O8: ='All Teams'!I103 | P8: ='All Teams'!J103 | Q8: ='All Teams'!K103 -> 0 | R8: ='All Teams'!L103 -> 0 | S8: ='All Teams'!M103 | T8: {=if(Team!D$1=$J8,"-", countif(indirect(address(row($J$2)+ VLOOKUP(Team!D$1,$J$3:$J$14,1),COLUMN($K$2))):indirect(address(row($J$2)+ VLOOKUP(Team!D$1,$J$3:$J$14,1),COLUMN($S$2)))>indirect(address(row($J8),COLUMN($K$2))):indirect(address(row($J8),COLUMN($S$2))),TRUE()))} -> - | U8: =SUM(AP$22:AP$33)/99 -> 0.02020202 | V8: =IF(I8, SUMIF(K8:R8,">-2.5"),) -> 0 | W8: =Draft!D8 | Y8: =Draft!E8 | AA8: =Draft!F8 | AC8: =Draft!G8 | AE8: =Draft!H8 | AG8: =Draft!I8 | AI8: =Draft!J8 | AK8: =Draft!R9 | AL8: =Draft!S9 | AM8: =Draft!T9 | AN8: =Draft!U9 | AO8: =Draft!V9 | AP8: =Draft!W9 | AQ8: =Draft!X9 | AR8: =Draft!Y9 | ... AV8: =Draft!AC9 | AW8: =Draft!K8 | AX8: =Draft!L8 | AY8: =Draft!M8 | AZ8: =Draft!N8 | BA8: =Draft!O8 | BB8: =Draft!P8 | BC8: =Draft!AJ9 | BD8: =Draft!AK9 | BE8: =Draft!AL9 | BF8: =Draft!AM9 | BG8: =Draft!AN9 | BH8: =Draft!AO9
I9: =Draft!C9 -> FALSE | J9: 7 | K9: ='All Teams'!E120 | L9: ='All Teams'!F120 | M9: ='All Teams'!G120 | N9: ='All Teams'!H120 | O9: ='All Teams'!I120 | P9: ='All Teams'!J120 | Q9: ='All Teams'!K120 -> 0 | R9: ='All Teams'!L120 -> 0 | S9: ='All Teams'!M120 | T9: {=if(Team!D$1=$J9,"-", countif(indirect(address(row($J$2)+ VLOOKUP(Team!D$1,$J$3:$J$14,1),COLUMN($K$2))):indirect(address(row($J$2)+ VLOOKUP(Team!D$1,$J$3:$J$14,1),COLUMN($S$2)))>indirect(address(row($J9),COLUMN($K$2))):indirect(address(row($J9),COLUMN($S$2))),TRUE()))} -> 0 | U9: =SUM(AQ$22:AQ$33)/99 -> 0.02020202 | V9: =IF(I9, SUMIF(K9:R9,">-1.5"),) | W9: =Draft!D9 | Y9: =Draft!E9 | AA9: =Draft!F9 | AC9: =Draft!G9 | AE9: =Draft!H9 | AG9: =Draft!I9 | AI9: =Draft!J9 | AK9: =Draft!R10 | AL9: =Draft!S10 | AM9: =Draft!T10 | AN9: =Draft!U10 | AO9: =Draft!V10 | AP9: =Draft!W10 | AQ9: =Draft!X10 | AR9: =Draft!Y10 | ... AV9: =Draft!AC10 | AW9: =Draft!K9 | AX9: =Draft!L9 | AY9: =Draft!M9 | AZ9: =Draft!N9 | BA9: =Draft!O9 | BB9: =Draft!P9 | BC9: =Draft!AJ10 | BD9: =Draft!AK10 | BE9: =Draft!AL10 | BF9: =Draft!AM10 | BG9: =Draft!AN10 | BH9: =Draft!AO10
I10: =Draft!C10 -> FALSE | J10: 8 | K10: ='All Teams'!E137 | L10: ='All Teams'!F137 | M10: ='All Teams'!G137 | N10: ='All Teams'!H137 | O10: ='All Teams'!I137 | P10: ='All Teams'!J137 | Q10: ='All Teams'!K137 -> 0 | R10: ='All Teams'!L137 -> 0 | S10: ='All Teams'!M137 | T10: {=if(Team!D$1=$J10,"-", countif(indirect(address(row($J$2)+ VLOOKUP(Team!D$1,$J$3:$J$14,1),COLUMN($K$2))):indirect(address(row($J$2)+ VLOOKUP(Team!D$1,$J$3:$J$14,1),COLUMN($S$2)))>indirect(address(row($J10),COLUMN($K$2))):indirect(address(row($J10),COLUMN($S$2))),TRUE()))} -> 0 | U10: =SUM(AR$22:AR$33)/99 -> 0.02020202 | V10: =IF(I10, SUMIF(K10:R10,">-1.5"),) | W10: =Draft!D10 | Y10: =Draft!E10 | AA10: =Draft!F10 | AC10: =Draft!G10 | AE10: =Draft!H10 | AG10: =Draft!I10 | AI10: =Draft!J10 | AK10: =Draft!R11 | AL10: =Draft!S11 | AM10: =Draft!T11 | AN10: =Draft!U11 | AO10: =Draft!V11 | AP10: =Draft!W11 | AQ10: =Draft!X11 | AR10: =Draft!Y11 | ... AV10: =Draft!AC11 | AW10: =Draft!K10 | AX10: =Draft!L10 | AY10: =Draft!M10 | AZ10: =Draft!N10 | BA10: =Draft!O10 | BB10: =Draft!P10 | BC10: =Draft!AJ11 | BD10: =Draft!AK11 | BE10: =Draft!AL11 | BF10: =Draft!AM11 | BG10: =Draft!AN11 | BH10: =Draft!AO11
F11: Input Draft Picks | I11: =Draft!C11 -> FALSE | J11: 9 | K11: ='All Teams'!E154 | L11: ='All Teams'!F154 | M11: ='All Teams'!G154 | N11: ='All Teams'!H154 | O11: ='All Teams'!I154 | P11: ='All Teams'!J154 | Q11: ='All Teams'!K154 -> 0 | R11: ='All Teams'!L154 -> 0 | S11: ='All Teams'!M154 | T11: {=if(Team!D$1=$J11,"-", countif(indirect(address(row($J$2)+ VLOOKUP(Team!D$1,$J$3:$J$14,1),COLUMN($K$2))):indirect(address(row($J$2)+ VLOOKUP(Team!D$1,$J$3:$J$14,1),COLUMN($S$2)))>indirect(address(row($J11),COLUMN($K$2))):indirect(address(row($J11),COLUMN($S$2))),TRUE()))} -> 0 | U11: =SUM(AS$22:AS$33)/99 -> 0.02020202 | V11: =IF(I11, SUMIF(K11:R11,">-1.5"),) | W11: =Draft!D11 | Y11: =Draft!E11 | AA11: =Draft!F11 | AC11: =Draft!G11 | AE11: =Draft!H11 | AG11: =Draft!I11 | AI11: =Draft!J11 | AK11: =Draft!R12 | AL11: =Draft!S12 | AM11: =Draft!T12 | AN11: =Draft!U12 | AO11: =Draft!V12 | AP11: =Draft!W12 | AQ11: =Draft!X12 | AR11: =Draft!Y12 | ... AV11: =Draft!AC12 | AW11: =Draft!K11 | AX11: =Draft!L11 | AY11: =Draft!M11 | AZ11: =Draft!N11 | BA11: =Draft!O11 | BB11: =Draft!P11 | BC11: =Draft!AJ12 | BD11: =Draft!AK12 | BE11: =Draft!AL12 | BF11: =Draft!AM12 | BG11: =Draft!AN12 | BH11: =Draft!AO12
F12: 3RR | G12: TRUE | I12: =Draft!C12 -> FALSE | J12: 10 | K12: ='All Teams'!E171 | L12: ='All Teams'!F171 | M12: ='All Teams'!G171 | N12: ='All Teams'!H171 | O12: ='All Teams'!I171 | P12: ='All Teams'!J171 | Q12: ='All Teams'!K171 -> 0 | R12: ='All Teams'!L171 -> 0 | S12: ='All Teams'!M171 | T12: {=if(Team!D$1=$J12,"-", countif(indirect(address(row($J$2)+ VLOOKUP(Team!D$1,$J$3:$J$14,1),COLUMN($K$2))):indirect(address(row($J$2)+ VLOOKUP(Team!D$1,$J$3:$J$14,1),COLUMN($S$2)))>indirect(address(row($J12),COLUMN($K$2))):indirect(address(row($J12),COLUMN($S$2))),TRUE()))} -> 0 | U12: =SUM(AT$22:AT$33)/99 -> 0.02020202 | V12: =IF(I12, SUMIF(K12:R12,">-1.5"),) | W12: =Draft!D12 | Y12: =Draft!E12 | AA12: =Draft!F12 | AC12: =Draft!G12 | AE12: =Draft!H12 | AG12: =Draft!I12 | AI12: =Draft!J12 | AK12: =Draft!R13 | AL12: =Draft!S13 | AM12: =Draft!T13 | AN12: =Draft!U13 | AO12: =Draft!V13 | AP12: =Draft!W13 | AQ12: =Draft!X13 | AR12: =Draft!Y13 | ... AV12: =Draft!AC13 | AW12: =Draft!K12 | AX12: =Draft!L12 | AY12: =Draft!M12 | AZ12: =Draft!N12 | BA12: =Draft!O12 | BB12: =Draft!P12 | BC12: =Draft!AJ13 | BD12: =Draft!AK13 | BE12: =Draft!AL13 | BF12: =Draft!AM13 | BG12: =Draft!AN13 | BH12: =Draft!AO13
F13: Current Pick #1 | G13: 2 | I13: =Draft!C13 -> FALSE | J13: 11 | K13: ='All Teams'!E188 | L13: ='All Teams'!F188 | M13: ='All Teams'!G188 | N13: ='All Teams'!H188 | O13: ='All Teams'!I188 | P13: ='All Teams'!J188 | Q13: ='All Teams'!K188 -> 0 | R13: ='All Teams'!L188 -> 0 | S13: ='All Teams'!M188 | T13: {=if(Team!D$1=$J13,"-", countif(indirect(address(row($J$2)+ VLOOKUP(Team!D$1,$J$3:$J$14,1),COLUMN($K$2))):indirect(address(row($J$2)+ VLOOKUP(Team!D$1,$J$3:$J$14,1),COLUMN($S$2)))>indirect(address(row($J13),COLUMN($K$2))):indirect(address(row($J13),COLUMN($S$2))),TRUE()))} -> 0 | U13: =SUM(AU$22:AU$33)/99 -> 0.02020202 | V13: =IF(I13, SUMIF(K13:R13,">-1.5"),) | W13: =Draft!D13 | Y13: =Draft!E13 | AA13: =Draft!F13 | AC13: =Draft!G13 | AE13: =Draft!H13 | AG13: =Draft!I13 | AI13: =Draft!J13 | AK13: =Draft!R14 | AL13: =Draft!S14 | AM13: =Draft!T14 | AN13: =Draft!U14 | AO13: =Draft!V14 | AP13: =Draft!W14 | AQ13: =Draft!X14 | AR13: =Draft!Y14 | ... AV13: =Draft!AC14 | AW13: =Draft!K13 | AX13: =Draft!L13 | AY13: =Draft!M13 | AZ13: =Draft!N13 | BA13: =Draft!O13 | BB13: =Draft!P13 | BC13: =Draft!AJ14 | BD13: =Draft!AK14 | BE13: =Draft!AL14 | BF13: =Draft!AM14 | BG13: =Draft!AN14 | BH13: =Draft!AO14
F14: Your Next Pick # | G14: =IFERROR(__xludf.DUMMYFUNCTION("MIN(FILTER(IF(G12,Draft!D17:O17,Draft!D16:O16),IF(G12,Draft!D17:O17,Draft!D16:O16)>G13))"),6.0) -> 6 | I14: =Draft!C14 -> FALSE | J14: 12 | K14: ='All Teams'!E205 | L14: ='All Teams'!F205 | M14: ='All Teams'!G205 | N14: ='All Teams'!H205 | O14: ='All Teams'!I205 | P14: ='All Teams'!J205 | Q14: ='All Teams'!K205 -> 0 | R14: ='All Teams'!L205 -> 0 | S14: ='All Teams'!M205 | T14: {=if(Team!D$1=$J14,"-", countif(indirect(address(row($J$2)+ VLOOKUP(Team!D$1,$J$3:$J$14,1),COLUMN($K$2))):indirect(address(row($J$2)+ VLOOKUP(Team!D$1,$J$3:$J$14,1),COLUMN($S$2)))>indirect(address(row($J14),COLUMN($K$2))):indirect(address(row($J14),COLUMN($S$2))),TRUE()))} -> 0 | U14: =SUM(AV$22:AV$33)/99 -> 0.02020202 | V14: =IF(I14, SUMIF(K14:R14,">-1.5"),) | W14: =Draft!D14 | Y14: =Draft!E14 | AA14: =Draft!F14 | AC14: =Draft!G14 | AE14: =Draft!H14 | AG14: =Draft!I14 | AI14: =Draft!J14 | AK14: =Draft!R15 | AL14: =Draft!S15 | AM14: =Draft!T15 | AN14: =Draft!U15 | AO14: =Draft!V15 | AP14: =Draft!W15 | AQ14: =Draft!X15 | AR14: =Draft!Y15 | ... AV14: =Draft!AC15 | AW14: =Draft!K14 | AX14: =Draft!L14 | AY14: =Draft!M14 | AZ14: =Draft!N14 | BA14: =Draft!O14 | BB14: =Draft!P14 | BC14: =Draft!AJ15 | BD14: =Draft!AK15 | BE14: =Draft!AL15 | BF14: =Draft!AM15 | BG14: =Draft!AN15 | BH14: =Draft!AO15
F15: Player Name | G15: Victor Wembanyama | W15: =IF($G$12,Draft!D17,Draft!D16) -> 6 | Y15: =IF($G$12,Draft!E17,Draft!E16) -> 19 | AA15: =IF($G$12,Draft!F17,Draft!F16) -> 31 | AC15: =IF($G$12,Draft!G17,Draft!G16) -> 42 | AE15: =IF($G$12,Draft!H17,Draft!H16) -> 55 | AG15: =IF($G$12,Draft!I17,Draft!I16) -> 66 | AI15: =IF($G$12,Draft!J17,Draft!J16) -> 79 | AK15: =IF($G$12,Draft!R16,Draft!R16) | AM15: =IF($G$12,Draft!T16,Draft!T16) | AO15: =IF($G$12,Draft!V16,Draft!V16) | AQ15: =IF($G$12,Draft!X16,Draft!X16) | AS15: =IF($G$12,Draft!Z16,Draft!Z16) | AU15: =IF($G$12,Draft!AB16,Draft!AB16) | AW15: =IF($G$12,Draft!K17,Draft!K16) -> 90 | AX15: =IF($G$12,Draft!L17,Draft!L16) -> 103 | AY15: =IF($G$12,Draft!M17,Draft!M16) -> 114 | AZ15: =IF($G$12,Draft!N17,Draft!N16) -> 127 | BA15: =IF($G$12,Draft!O17,Draft!O16) -> 138 | BB15: =IF($G$12,Draft!P17,Draft!P16) -> 161 | BC15: =IF($G$12,Draft!Q17,Draft!Q16) -> 152
I16: -1 Cat | J16: -2 Cat | K16: PTS | L16: 3P | M16: REB | N16: AST | O16: STL | P16: BLK | Q16: FG% | R16: FT% | S16: TO | T16: PG | U16: SG | V16: SF | W16: PF | X16: C | Z16: Sort by | AB16: Remove Drafted | AE16: Top | AG16: Projections
I17: FALSE | J17: FALSE | K17: 1 | L17: 1 | M17: 1 | N17: 1 | O17: 1 | P17: 1 | Q17: 1 | R17: 1 | S17: 0 | T17: PG | U17: SG | V17: SF | W17: PF | X17: C | Z17: PuntV | AB17: TRUE | AE17: 200 | AG17: BBM
A19: W18 | B19: W19 | C19: W20 | D19: Total | F19: Team | G19: PuntRank | H19: LgRank | I19: ADP | J19: Player | K19: GP | L19: Pos | M19: LeagV | N19: PuntV | O19: Punt+ | P19: PTS | Q19: 3P | R19: REB | S19: AST | T19: STL | U19: BLK | V19: FG% | W19: FT% | X19: TO | Y19: z p/g | Z19: z 3/g | AA19: z r/g | AB19: z a/g | AC19: z s/g | AD19: z b/g | AE19: z fg% | AF19: z ft% | AG19: z to/g
A20: =VLOOKUP($F20,UpdateHashtag!$V$3:$Y$32,COLUMN(B$15),0) -> 4 | B20: =VLOOKUP($F20,UpdateHashtag!$V$3:$Y$32,COLUMN(C$13),0) -> 4 | C20: =VLOOKUP($F20,UpdateHashtag!$V$3:$Y$32,COLUMN(D$13),0) -> 4 | D20: =SUM(A20:C20) -> 12 | F20: =IF(VLOOKUP(J20,PasteHashtag!$C$2:$P1015,3,)="BRO","BKN",IF(VLOOKUP(J20,PasteHashtag!$C$2:$P1015,3,)="OKL","OKC",VLOOKUP(J20,PasteHashtag!$C$2:$P1015,3,))) -> PHI | G20: 1 | H20: =IFERROR(__xludf.DUMMYFUNCTION("Filter('NO USAR3'!B5:AA420,IF('NO USAR3'!AB5:AB420="""",FALSE,TRUE),NOT(COUNTIF('NO USAR3'!A5:A200,'NO USAR3'!D5:D420)),IF('NO USAR3'!B5:B420>AE17,FALSE,TRUE))"),2.0) -> 2 | I20: =IFERROR(__xludf.DUMMYFUNCTION("""COMPUTED_VALUE"""),9.6) -> 9.6 | J20: =IFERROR(__xludf.DUMMYFUNCTION("""COMPUTED_VALUE"""),"Joel Embiid") -> Joel Embiid | K20: =IFERROR(__xludf.DUMMYFUNCTION("""COMPUTED_VALUE"""),68.0) -> 68 | L20: =IFERROR(__xludf.DUMMYFUNCTION("""COMPUTED_VALUE"""),"C") -> C | M20: =IFERROR(__xludf.DUMMYFUNCTION("""COMPUTED_VALUE"""),8.957904690194928) -> 8.9579047 | N20: =IFERROR(__xludf.DUMMYFUNCTION("""COMPUTED_VALUE"""),9.410476436812917) -> 9.4104764 | O20: =IFERROR(__xludf.DUMMYFUNCTION("""COMPUTED_VALUE"""),0.4525717466179895) -> 0.45257175 | P20: =IFERROR(__xludf.DUMMYFUNCTION("""COMPUTED_VALUE"""),30.23877193) -> 30.238772 | Q20: =IFERROR(__xludf.DUMMYFUNCTION("""COMPUTED_VALUE"""),1.142982456) -> 1.1429825 | R20: =IFERROR(__xludf.DUMMYFUNCTION("""COMPUTED_VALUE"""),10.51052632) -> 10.510526 | S20: =IFERROR(__xludf.DUMMYFUNCTION("""COMPUTED_VALUE"""),5.037368421) -> 5.0373684 | T20: =IFERROR(__xludf.DUMMYFUNCTION("""COMPUTED_VALUE"""),1.143859649) -> 1.1438596 | U20: =IFERROR(__xludf.DUMMYFUNCTION("""COMPUTED_VALUE"""),1.551052632) -> 1.5510526 | V20: =IFERROR(__xludf.DUMMYFUNCTION("""COMPUTED_VALUE"""),0.5367911594) -> 0.53679116 | W20: =IFERROR(__xludf.DUMMYFUNCTION("""COMPUTED_VALUE"""),0.8699991153) -> 0.86999912 | X20: =IFERROR(__xludf.DUMMYFUNCTION("""COMPUTED_VALUE"""),3.573684211) -> 3.5736842 | Y20: =IFERROR(__xludf.DUMMYFUNCTION("""COMPUTED_VALUE"""),2.2982783682718377) -> 2.2982784 | Z20: =IFERROR(__xludf.DUMMYFUNCTION("""COMPUTED_VALUE"""),-0.6007954542058588) -> -0.60079545 | AA20: =IFERROR(__xludf.DUMMYFUNCTION("""COMPUTED_VALUE"""),1.7350479056104444) -> 1.7350479 | AB20: =IFERROR(__xludf.DUMMYFUNCTION("""COMPUTED_VALUE"""),0.5013847387233921) -> 0.50138474 | AC20: =IFERROR(__xludf.DUMMYFUNCTION("""COMPUTED_VALUE"""),0.5553323226280126) -> 0.55533232 | AD20: =IFERROR(__xludf.DUMMYFUNCTION("""COMPUTED_VALUE"""),1.4311739809683646) -> 1.431174 | AE20: =IFERROR(__xludf.DUMMYFUNCTION("""COMPUTED_VALUE"""),0.8770105201052155) -> 0.87701052 | AF20: =IFERROR(__xludf.DUMMYFUNCTION("""COMPUTED_VALUE"""),2.61304405471151) -> 2.6130441 | AG20: =IFERROR(__xludf.DUMMYFUNCTION("""COMPUTED_VALUE"""),0.0) -> 0 | AK20: 1 | AL20: 2 | AM20: 3 | AN20: 4 | AO20: 5 | AP20: 6 | AQ20: 7 | AR20: 8 | AS20: 9 | AT20: 10 | AU20: 11 | AV20: 12
A21: =VLOOKUP($F21,UpdateHashtag!$V$3:$Y$32,COLUMN(B$15),0) -> 3 | B21: =VLOOKUP($F21,UpdateHashtag!$V$3:$Y$32,COLUMN(C$13),0) -> 4 | C21: =VLOOKUP($F21,UpdateHashtag!$V$3:$Y$32,COLUMN(D$13),0) -> 4 | D21: =SUM(A21:C21) -> 11 | F21: =IF(VLOOKUP(J21,PasteHashtag!$C$2:$P1015,3,)="BRO","BKN",IF(VLOOKUP(J21,PasteHashtag!$C$2:$P1015,3,)="OKL","OKC",VLOOKUP(J21,PasteHashtag!$C$2:$P1015,3,))) -> DEN | G21: 2 | H21: =IFERROR(__xludf.DUMMYFUNCTION("""COMPUTED_VALUE"""),3.0) -> 3 | I21: =IFERROR(__xludf.DUMMYFUNCTION("""COMPUTED_VALUE"""),2.4) -> 2.4 | J21: =IFERROR(__xludf.DUMMYFUNCTION("""COMPUTED_VALUE"""),"Nikola Jokic") -> Nikola Jokic | K21: =IFERROR(__xludf.DUMMYFUNCTION("""COMPUTED_VALUE"""),67.0) -> 67 | L21: =IFERROR(__xludf.DUMMYFUNCTION("""COMPUTED_VALUE"""),"PF,C") -> PF,C | M21: =IFERROR(__xludf.DUMMYFUNCTION("""COMPUTED_VALUE"""),8.517820594732509) -> 8.5178206 | N21: =IFERROR(__xludf.DUMMYFUNCTION("""COMPUTED_VALUE"""),8.881589989729328) -> 8.88159 | O21: =IFERROR(__xludf.DUMMYFUNCTION("""COMPUTED_VALUE"""),0.3637693949968188) -> 0.36376939 | P21: =IFERROR(__xludf.DUMMYFUNCTION("""COMPUTED_VALUE"""),25.55948052) -> 25.559481 | Q21: =IFERROR(__xludf.DUMMYFUNCTION("""COMPUTED_VALUE"""),0.9916883117) -> 0.99168831 | R21: =IFERROR(__xludf.DUMMYFUNCTION("""COMPUTED_VALUE"""),11.79064935) -> 11.790649 | S21: =IFERROR(__xludf.DUMMYFUNCTION("""COMPUTED_VALUE"""),8.360649351) -> 8.3606494 | T21: =IFERROR(__xludf.DUMMYFUNCTION("""COMPUTED_VALUE"""),1.492597403) -> 1.4925974 | U21: =IFERROR(__xludf.DUMMYFUNCTION("""COMPUTED_VALUE"""),0.788961039) -> 0.78896104 | V21: =IFERROR(__xludf.DUMMYFUNCTION("""COMPUTED_VALUE"""),0.5897010341) -> 0.58970103 | W21: =IFERROR(__xludf.DUMMYFUNCTION("""COMPUTED_VALUE"""),0.8110073214) -> 0.81100732 | X21: =IFERROR(__xludf.DUMMYFUNCTION("""COMPUTED_VALUE"""),3.215584416) -> 3.2155844 | Y21: =IFERROR(__xludf.DUMMYFUNCTION("""COMPUTED_VALUE"""),1.4548097063016192) -> 1.4548097 | Z21: =IFERROR(__xludf.DUMMYFUNCTION("""COMPUTED_VALUE"""),-0.7508684337265839) -> -0.75086843 | AA21: =IFERROR(__xludf.DUMMYFUNCTION("""COMPUTED_VALUE"""),2.2367370772400488) -> 2.2367371 | AB21: =IFERROR(__xludf.DUMMYFUNCTION("""COMPUTED_VALUE"""),2.0106142545298287) -> 2.0106143 | AC21: =IFERROR(__xludf.DUMMYFUNCTION("""COMPUTED_VALUE"""),1.7090661000464076) -> 1.7090661 | AD21: =IFERROR(__xludf.DUMMYFUNCTION("""COMPUTED_VALUE"""),0.07187096952644342) -> 0.07187097 | AE21: =IFERROR(__xludf.DUMMYFUNCTION("""COMPUTED_VALUE"""),1.8597186873550178) -> 1.8597187 | AF21: =IFERROR(__xludf.DUMMYFUNCTION("""COMPUTED_VALUE"""),0.2896416284565464) -> 0.28964163 | AG21: =IFERROR(__xludf.DUMMYFUNCTION("""COMPUTED_VALUE"""),0.0) -> 0 | AJ21: % Games/Week | AK21: Categories won | AW21: Round | AX21: Player Name | AZ21: PTS | BA21: 3P | BB21: REB | BC21: AST | BD21: STL | BE21: BLK | BF21: FG% | BG21: FT% | BH21: TO | BI21: POS | BJ21: Count | BK21: POS
A22: =VLOOKUP($F22,UpdateHashtag!$V$3:$Y$32,COLUMN(B$15),0) -> 4 | B22: =VLOOKUP($F22,UpdateHashtag!$V$3:$Y$32,COLUMN(C$13),0) -> 4 | C22: =VLOOKUP($F22,UpdateHashtag!$V$3:$Y$32,COLUMN(D$13),0) -> 2 | D22: =SUM(A22:C22) -> 10 | F22: =IF(VLOOKUP(J22,PasteHashtag!$C$2:$P1015,3,)="BRO","BKN",IF(VLOOKUP(J22,PasteHashtag!$C$2:$P1015,3,)="OKL","OKC",VLOOKUP(J22,PasteHashtag!$C$2:$P1015,3,))) -> DAL | G22: 3 | H22: =IFERROR(__xludf.DUMMYFUNCTION("""COMPUTED_VALUE"""),4.0) -> 4 | I22: =IFERROR(__xludf.DUMMYFUNCTION("""COMPUTED_VALUE"""),3.8) -> 3.8 | J22: =IFERROR(__xludf.DUMMYFUNCTION("""COMPUTED_VALUE"""),"Luka Doncic") -> Luka Doncic | K22: =IFERROR(__xludf.DUMMYFUNCTION("""COMPUTED_VALUE"""),68.0) -> 68 | L22: =IFERROR(__xludf.DUMMYFUNCTION("""COMPUTED_VALUE"""),"PG,SG") -> PG,SG | M22: =IFERROR(__xludf.DUMMYFUNCTION("""COMPUTED_VALUE"""),8.299053452451961) -> 8.2990535 | N22: =IFERROR(__xludf.DUMMYFUNCTION("""COMPUTED_VALUE"""),8.833457384158983) -> 8.8334574 | O22: =IFERROR(__xludf.DUMMYFUNCTION("""COMPUTED_VALUE"""),0.5344039317070219) -> 0.53440393 | P22: =IFERROR(__xludf.DUMMYFUNCTION("""COMPUTED_VALUE"""),31.87132353) -> 31.871324 | Q22: =IFERROR(__xludf.DUMMYFUNCTION("""COMPUTED_VALUE"""),3.974117647) -> 3.9741176 | R22: =IFERROR(__xludf.DUMMYFUNCTION("""COMPUTED_VALUE"""),9.108970588) -> 9.1089706 | S22: =IFERROR(__xludf.DUMMYFUNCTION("""COMPUTED_VALUE"""),9.498235294) -> 9.4982353 | T22: =IFERROR(__xludf.DUMMYFUNCTION("""COMPUTED_VALUE"""),1.394852941) -> 1.3948529 | U22: =IFERROR(__xludf.DUMMYFUNCTION("""COMPUTED_VALUE"""),0.5467647059) -> 0.54676471 | V22: =IFERROR(__xludf.DUMMYFUNCTION("""COMPUTED_VALUE"""),0.4797165326) -> 0.47971653 | W22: =IFERROR(__xludf.DUMMYFUNCTION("""COMPUTED_VALUE"""),0.7859938088) -> 0.78599381 | X22: =IFERROR(__xludf.DUMMYFUNCTION("""COMPUTED_VALUE"""),3.903676471) -> 3.9036765 | Y22: =IFERROR(__xludf.DUMMYFUNCTION("""COMPUTED_VALUE"""),2.5925549997093618) -> 2.592555 | Z22: =IFERROR(__xludf.DUMMYFUNCTION("""COMPUTED_VALUE"""),2.2074883396259914) -> 2.2074883 | AA22: =IFERROR(__xludf.DUMMYFUNCTION("""COMPUTED_VALUE"""),1.185768408482888) -> 1.1857684 | AB22: =IFERROR(__xludf.DUMMYFUNCTION("""COMPUTED_VALUE"""),2.5272357253310047) -> 2.5272357 | AC22: =IFERROR(__xludf.DUMMYFUNCTION("""COMPUTED_VALUE"""),1.3856967886612432) -> 1.3856968 | AD22: =IFERROR(__xludf.DUMMYFUNCTION("""COMPUTED_VALUE"""),-0.36012199295598174) -> -0.36012199 | AE22: =IFERROR(__xludf.DUMMYFUNCTION("""COMPUTED_VALUE"""),-0.46671174701275525) -> -0.46671175 | AF22: =IFERROR(__xludf.DUMMYFUNCTION("""COMPUTED_VALUE"""),-0.23845313768276888) -> -0.23845314 | AG22: =IFERROR(__xludf.DUMMYFUNCTION("""COMPUTED_VALUE"""),0.0) -> 0 | AJ22: 100 | AK22: {=if(AK$20=$J3,"-", countif(indirect(address(row($J$2)+ VLOOKUP(AK$20,$J$3:$J$14,1),COLUMN($K$4))):indirect(address(row($J$2)+ VLOOKUP(AK$20,$J$3:$J$14,1),COLUMN($S$2)))>indirect(address(row($J3),COLUMN($K$2))):indirect(address(row($J3),COLUMN($S$2))),TRUE()))} -> - | AL22: {=if(AL$20=$J3,"-", countif(indirect(address(row($J$2)+ VLOOKUP(AL$20,$J$3:$J$14,1),COLUMN($K$4))):indirect(address(row($J$2)+ VLOOKUP(AL$20,$J$3:$J$14,1),COLUMN($S$2)))>indirect(address(row($J3),COLUMN($K$2))):indirect(address(row($J3),COLUMN($S$2))),TRUE()))} -> 2 | AM22: {=if(AM$20=$J3,"-", countif(indirect(address(row($J$2)+ VLOOKUP(AM$20,$J$3:$J$14,1),COLUMN($K$4))):indirect(address(row($J$2)+ VLOOKUP(AM$20,$J$3:$J$14,1),COLUMN($S$2)))>indirect(address(row($J3),COLUMN($K$2))):indirect(address(row($J3),COLUMN($S$2))),TRUE()))} -> 2 | AN22: {=if(AN$20=$J3,"-", countif(indirect(address(row($J$2)+ VLOOKUP(AN$20,$J$3:$J$14,1),COLUMN($K$4))):indirect(address(row($J$2)+ VLOOKUP(AN$20,$J$3:$J$14,1),COLUMN($S$2)))>indirect(address(row($J3),COLUMN($K$2))):indirect(address(row($J3),COLUMN($S$2))),TRUE()))} -> 2 | AO22: {=if(AO$20=$J3,"-", countif(indirect(address(row($J$2)+ VLOOKUP(AO$20,$J$3:$J$14,1),COLUMN($K$4))):indirect(address(row($J$2)+ VLOOKUP(AO$20,$J$3:$J$14,1),COLUMN($S$2)))>indirect(address(row($J3),COLUMN($K$2))):indirect(address(row($J3),COLUMN($S$2))),TRUE()))} -> 2 | AP22: {=if(AP$20=$J3,"-", countif(indirect(address(row($J$2)+ VLOOKUP(AP$20,$J$3:$J$14,1),COLUMN($K$4))):indirect(address(row($J$2)+ VLOOKUP(AP$20,$J$3:$J$14,1),COLUMN($S$2)))>indirect(address(row($J3),COLUMN($K$2))):indirect(address(row($J3),COLUMN($S$2))),TRUE()))} -> 2 | AQ22: {=if(AQ$20=$J3,"-", countif(indirect(address(row($J$2)+ VLOOKUP(AQ$20,$J$3:$J$14,1),COLUMN($K$4))):indirect(address(row($J$2)+ VLOOKUP(AQ$20,$J$3:$J$14,1),COLUMN($S$2)))>indirect(address(row($J3),COLUMN($K$2))):indirect(address(row($J3),COLUMN($S$2))),TRUE()))} -> 2 | AR22: {=if(AR$20=$J3,"-", countif(indirect(address(row($J$2)+ VLOOKUP(AR$20,$J$3:$J$14,1),COLUMN($K$4))):indirect(address(row($J$2)+ VLOOKUP(AR$20,$J$3:$J$14,1),COLUMN($S$2)))>indirect(address(row($J3),COLUMN($K$2))):indirect(address(row($J3),COLUMN($S$2))),TRUE()))} -> 2 | ... AV22: {=if(AV$20=$J3,"-", countif(indirect(address(row($J$2)+ VLOOKUP(AV$20,$J$3:$J$14,1),COLUMN($K$4))):indirect(address(row($J$2)+ VLOOKUP(AV$20,$J$3:$J$14,1),COLUMN($S$2)))>indirect(address(row($J3),COLUMN($K$2))):indirect(address(row($J3),COLUMN($S$2))),TRUE()))} -> 2 | AW22: 1 | AX22: {=INDIRECT("Draft!D"&TEXT(VLOOKUP(TRUE,I3:J14,2,0)+2,"0"))} | AZ22: =IF($AX22="","", VLOOKUP($AX22,'Final Update'!$P$21:$AD1015,Column(H1),False)) | BA22: =IF($AX22="","", VLOOKUP($AX22,'Final Update'!$P$21:$AD1015,Column(I1),False)) | BB22: =IF($AX22="","", VLOOKUP($AX22,'Final Update'!$P$21:$AD1015,Column(J1),False)) | BC22: =IF($AX22="","", VLOOKUP($AX22,'Final Update'!$P$21:$AD1015,Column(K1),False)) | BD22: =IF($AX22="","", VLOOKUP($AX22,'Final Update'!$P$21:$AD1015,Column(L1),False)) | BE22: =IF($AX22="","", VLOOKUP($AX22,'Final Update'!$P$21:$AD1015,Column(M1),False)) | BF22: =IF($AX22="","", VLOOKUP($AX22,'Final Update'!$P$21:$AD1015,Column(N1),False)) | BG22: =IF($AX22="","", VLOOKUP($AX22,'Final Update'!$P$21:$AD1015,Column(O1),False)) | BH22: =IF($AX22="","", VLOOKUP($AX22,'Final Update'!$P$21:$AD1015,Column(P1),False)) | BI22: =IF($AX22="","", VLOOKUP($AX22,'Final Update'!$P$21:$AD1015,Column(C1),False)) | BJ22: {=COUNTIF(FIND(BK22,$BI$22:$BI$33),">0")} -> 0 | BK22: PG
A23: =VLOOKUP($F23,UpdateHashtag!$V$3:$Y$32,COLUMN(B$15),0) -> 3 | B23: =VLOOKUP($F23,UpdateHashtag!$V$3:$Y$32,COLUMN(C$13),0) -> 4 | C23: =VLOOKUP($F23,UpdateHashtag!$V$3:$Y$32,COLUMN(D$13),0) -> 3 | D23: =SUM(A23:C23) -> 10 | F23: =IF(VLOOKUP(J23,PasteHashtag!$C$2:$P1015,3,)="BRO","BKN",IF(VLOOKUP(J23,PasteHashtag!$C$2:$P1015,3,)="OKL","OKC",VLOOKUP(J23,PasteHashtag!$C$2:$P1015,3,))) -> LAL | G23: 4 | H23: =IFERROR(__xludf.DUMMYFUNCTION("""COMPUTED_VALUE"""),5.0) -> 5 | I23: =IFERROR(__xludf.DUMMYFUNCTION("""COMPUTED_VALUE"""),7.4) -> 7.4 | J23: =IFERROR(__xludf.DUMMYFUNCTION("""COMPUTED_VALUE"""),"Anthony Davis") -> Anthony Davis | K23: =IFERROR(__xludf.DUMMYFUNCTION("""COMPUTED_VALUE"""),74.0) -> 74 | L23: =IFERROR(__xludf.DUMMYFUNCTION("""COMPUTED_VALUE"""),"SF,PF") -> SF,PF | M23: =IFERROR(__xludf.DUMMYFUNCTION("""COMPUTED_VALUE"""),7.557301441135948) -> 7.5573014 | N23: =IFERROR(__xludf.DUMMYFUNCTION("""COMPUTED_VALUE"""),7.711756738160858) -> 7.7117567 | O23: =IFERROR(__xludf.DUMMYFUNCTION("""COMPUTED_VALUE"""),0.15445529702491) -> 0.1544553 | P23: =IFERROR(__xludf.DUMMYFUNCTION("""COMPUTED_VALUE"""),25.12242424) -> 25.122424 | Q23: =IFERROR(__xludf.DUMMYFUNCTION("""COMPUTED_VALUE"""),0.5036363636) -> 0.50363636 | R23: =IFERROR(__xludf.DUMMYFUNCTION("""COMPUTED_VALUE"""),13.46393939) -> 13.463939 | S23: =IFERROR(__xludf.DUMMYFUNCTION("""COMPUTED_VALUE"""),3.366060606) -> 3.3660606 | T23: =IFERROR(__xludf.DUMMYFUNCTION("""COMPUTED_VALUE"""),1.307878788) -> 1.3078788 | U23: =IFERROR(__xludf.DUMMYFUNCTION("""COMPUTED_VALUE"""),2.065454545) -> 2.0654545 | V23: =IFERROR(__xludf.DUMMYFUNCTION("""COMPUTED_VALUE"""),0.556141401) -> 0.5561414 | W23: =IFERROR(__xludf.DUMMYFUNCTION("""COMPUTED_VALUE"""),0.8080080528) -> 0.80800805 | X23: =IFERROR(__xludf.DUMMYFUNCTION("""COMPUTED_VALUE"""),2.371515152) -> 2.3715152 | Y23: =IFERROR(__xludf.DUMMYFUNCTION("""COMPUTED_VALUE"""),1.37602784738395) -> 1.3760278 | Z23: =IFERROR(__xludf.DUMMYFUNCTION("""COMPUTED_VALUE"""),-1.2349810895807822) -> -1.2349811 | AA23: =IFERROR(__xludf.DUMMYFUNCTION("""COMPUTED_VALUE"""),2.8925111508177013) -> 2.8925112 | AB23: =IFERROR(__xludf.DUMMYFUNCTION("""COMPUTED_VALUE"""),-0.2576203341327158) -> -0.25762033 | AC23: =IFERROR(__xludf.DUMMYFUNCTION("""COMPUTED_VALUE"""),1.0979590346397636) -> 1.097959 | AD23: =IFERROR(__xludf.DUMMYFUNCTION("""COMPUTED_VALUE"""),2.3486858336839282) -> 2.3486858 | AE23: =IFERROR(__xludf.DUMMYFUNCTION("""COMPUTED_VALUE"""),1.1791629477595917) -> 1.1791629 | AF23: =IFERROR(__xludf.DUMMYFUNCTION("""COMPUTED_VALUE"""),0.31001134758942167) -> 0.31001135 | AG23: =IFERROR(__xludf.DUMMYFUNCTION("""COMPUTED_VALUE"""),0.0) -> 0 | AJ23: 100 | AK23: {=if(AK$20=$J4,"-", countif(indirect(address(row($J$2)+ VLOOKUP(AK$20,$J$3:$J$14,1),COLUMN($K$4))):indirect(address(row($J$2)+ VLOOKUP(AK$20,$J$3:$J$14,1),COLUMN($S$2)))>indirect(address(row($J4),COLUMN($K$2))):indirect(address(row($J4),COLUMN($S$2))),TRUE()))} -> 7 | AL23: {=if(AL$20=$J4,"-", countif(indirect(address(row($J$2)+ VLOOKUP(AL$20,$J$3:$J$14,1),COLUMN($K$4))):indirect(address(row($J$2)+ VLOOKUP(AL$20,$J$3:$J$14,1),COLUMN($S$2)))>indirect(address(row($J4),COLUMN($K$2))):indirect(address(row($J4),COLUMN($S$2))),TRUE()))} -> - | AM23: {=if(AM$20=$J4,"-", countif(indirect(address(row($J$2)+ VLOOKUP(AM$20,$J$3:$J$14,1),COLUMN($K$4))):indirect(address(row($J$2)+ VLOOKUP(AM$20,$J$3:$J$14,1),COLUMN($S$2)))>indirect(address(row($J4),COLUMN($K$2))):indirect(address(row($J4),COLUMN($S$2))),TRUE()))} -> 0 | AN23: {=if(AN$20=$J4,"-", countif(indirect(address(row($J$2)+ VLOOKUP(AN$20,$J$3:$J$14,1),COLUMN($K$4))):indirect(address(row($J$2)+ VLOOKUP(AN$20,$J$3:$J$14,1),COLUMN($S$2)))>indirect(address(row($J4),COLUMN($K$2))):indirect(address(row($J4),COLUMN($S$2))),TRUE()))} -> 0 | AO23: {=if(AO$20=$J4,"-", countif(indirect(address(row($J$2)+ VLOOKUP(AO$20,$J$3:$J$14,1),COLUMN($K$4))):indirect(address(row($J$2)+ VLOOKUP(AO$20,$J$3:$J$14,1),COLUMN($S$2)))>indirect(address(row($J4),COLUMN($K$2))):indirect(address(row($J4),COLUMN($S$2))),TRUE()))} -> 0 | AP23: {=if(AP$20=$J4,"-", countif(indirect(address(row($J$2)+ VLOOKUP(AP$20,$J$3:$J$14,1),COLUMN($K$4))):indirect(address(row($J$2)+ VLOOKUP(AP$20,$J$3:$J$14,1),COLUMN($S$2)))>indirect(address(row($J4),COLUMN($K$2))):indirect(address(row($J4),COLUMN($S$2))),TRUE()))} -> 0 | AQ23: {=if(AQ$20=$J4,"-", countif(indirect(address(row($J$2)+ VLOOKUP(AQ$20,$J$3:$J$14,1),COLUMN($K$4))):indirect(address(row($J$2)+ VLOOKUP(AQ$20,$J$3:$J$14,1),COLUMN($S$2)))>indirect(address(row($J4),COLUMN($K$2))):indirect(address(row($J4),COLUMN($S$2))),TRUE()))} -> 0 | AR23: {=if(AR$20=$J4,"-", countif(indirect(address(row($J$2)+ VLOOKUP(AR$20,$J$3:$J$14,1),COLUMN($K$4))):indirect(address(row($J$2)+ VLOOKUP(AR$20,$J$3:$J$14,1),COLUMN($S$2)))>indirect(address(row($J4),COLUMN($K$2))):indirect(address(row($J4),COLUMN($S$2))),TRUE()))} -> 0 | ... AV23: {=if(AV$20=$J4,"-", countif(indirect(address(row($J$2)+ VLOOKUP(AV$20,$J$3:$J$14,1),COLUMN($K$4))):indirect(address(row($J$2)+ VLOOKUP(AV$20,$J$3:$J$14,1),COLUMN($S$2)))>indirect(address(row($J4),COLUMN($K$2))):indirect(address(row($J4),COLUMN($S$2))),TRUE()))} -> 0 | AW23: 2 | AX23: {=INDIRECT("Draft!E"&TEXT(15-VLOOKUP(TRUE,I3:J14,2,0),"0"))} | AZ23: =IF($AX23="","", VLOOKUP($AX23,'Final Update'!$P$21:$AD1015,Column(H2),False)) | BA23: =IF($AX23="","", VLOOKUP($AX23,'Final Update'!$P$21:$AD1015,Column(I2),False)) | BB23: =IF($AX23="","", VLOOKUP($AX23,'Final Update'!$P$21:$AD1015,Column(J2),False)) | BC23: =IF($AX23="","", VLOOKUP($AX23,'Final Update'!$P$21:$AD1015,Column(K2),False)) | BD23: =IF($AX23="","", VLOOKUP($AX23,'Final Update'!$P$21:$AD1015,Column(L2),False)) | BE23: =IF($AX23="","", VLOOKUP($AX23,'Final Update'!$P$21:$AD1015,Column(M2),False)) | BF23: =IF($AX23="","", VLOOKUP($AX23,'Final Update'!$P$21:$AD1015,Column(N2),False)) | BG23: =IF($AX23="","", VLOOKUP($AX23,'Final Update'!$P$21:$AD1015,Column(O2),False)) | BH23: =IF($AX23="","", VLOOKUP($AX23,'Final Update'!$P$21:$AD1015,Column(P2),False)) | BI23: =IF($AX23="","", VLOOKUP($AX23,'Final Update'!$P$21:$AD1015,Column(C2),False)) | BJ23: {=COUNTIF(FIND(BK23,$BI$22:$BI$33),">0")} -> 0 | BK23: SG
A24: =VLOOKUP($F24,UpdateHashtag!$V$3:$Y$32,COLUMN(B$15),0) -> 4 | B24: =VLOOKUP($F24,UpdateHashtag!$V$3:$Y$32,COLUMN(C$13),0) -> 4 | C24: =VLOOKUP($F24,UpdateHashtag!$V$3:$Y$32,COLUMN(D$13),0) -> 3 | D24: =SUM(A24:C24) -> 11 | F24: =IF(VLOOKUP(J24,PasteHashtag!$C$2:$P1015,3,)="BRO","BKN",IF(VLOOKUP(J24,PasteHashtag!$C$2:$P1015,3,)="OKL","OKC",VLOOKUP(J24,PasteHashtag!$C$2:$P1015,3,))) -> OKC | G24: 5 | H24: =IFERROR(__xludf.DUMMYFUNCTION("""COMPUTED_VALUE"""),6.0) -> 6 | I24: =IFERROR(__xludf.DUMMYFUNCTION("""COMPUTED_VALUE"""),4.5) -> 4.5 | J24: =IFERROR(__xludf.DUMMYFUNCTION("""COMPUTED_VALUE"""),"Shai Gilgeous-Alexander") -> Shai Gilgeous-Alexander | K24: =IFERROR(__xludf.DUMMYFUNCTION("""COMPUTED_VALUE"""),64.0) -> 64 | L24: =IFERROR(__xludf.DUMMYFUNCTION("""COMPUTED_VALUE"""),"SG,SF") -> SG,SF | M24: =IFERROR(__xludf.DUMMYFUNCTION("""COMPUTED_VALUE"""),6.736591490731338) -> 6.7365915 | N24: =IFERROR(__xludf.DUMMYFUNCTION("""COMPUTED_VALUE"""),6.959358711350021) -> 6.9593587 | O24: =IFERROR(__xludf.DUMMYFUNCTION("""COMPUTED_VALUE"""),0.2227672206186826) -> 0.22276722 | P24: =IFERROR(__xludf.DUMMYFUNCTION("""COMPUTED_VALUE"""),29.18123288) -> 29.181233 | Q24: =IFERROR(__xludf.DUMMYFUNCTION("""COMPUTED_VALUE"""),1.557945205) -> 1.5579452 | R24: =IFERROR(__xludf.DUMMYFUNCTION("""COMPUTED_VALUE"""),5.437123288) -> 5.4371233 | S24: =IFERROR(__xludf.DUMMYFUNCTION("""COMPUTED_VALUE"""),6.939589041) -> 6.939589 | T24: =IFERROR(__xludf.DUMMYFUNCTION("""COMPUTED_VALUE"""),1.502328767) -> 1.5023288 | U24: =IFERROR(__xludf.DUMMYFUNCTION("""COMPUTED_VALUE"""),0.7869863014) -> 0.7869863 | V24: =IFERROR(__xludf.DUMMYFUNCTION("""COMPUTED_VALUE"""),0.5123976584) -> 0.51239766 | W24: =IFERROR(__xludf.DUMMYFUNCTION("""COMPUTED_VALUE"""),0.8549952613) -> 0.85499526 | X24: =IFERROR(__xludf.DUMMYFUNCTION("""COMPUTED_VALUE"""),2.646986301) -> 2.6469863 | Y24: =IFERROR(__xludf.DUMMYFUNCTION("""COMPUTED_VALUE"""),2.107650991319318) -> 2.107651 | Z24: =IFERROR(__xludf.DUMMYFUNCTION("""COMPUTED_VALUE"""),-0.18918206083448794) -> -0.18918206 | AA24: =IFERROR(__xludf.DUMMYFUNCTION("""COMPUTED_VALUE"""),-0.2532542378696264) -> -0.25325424 | AB24: =IFERROR(__xludf.DUMMYFUNCTION("""COMPUTED_VALUE"""),1.365256185570836) -> 1.3652562 | AC24: =IFERROR(__xludf.DUMMYFUNCTION("""COMPUTED_VALUE"""),1.7412605017662555) -> 1.7412605 | AD24: =IFERROR(__xludf.DUMMYFUNCTION("""COMPUTED_VALUE"""),0.06834873310349474) -> 0.068348733 | AE24: =IFERROR(__xludf.DUMMYFUNCTION("""COMPUTED_VALUE"""),0.35176815797639455) -> 0.35176816 | AF24: =IFERROR(__xludf.DUMMYFUNCTION("""COMPUTED_VALUE"""),1.7675104403178359) -> 1.7675104 | AG24: =IFERROR(__xludf.DUMMYFUNCTION("""COMPUTED_VALUE"""),0.0) -> 0 | AJ24: 100 | AK24: {=if(AK$20=$J5,"-", countif(indirect(address(row($J$2)+ VLOOKUP(AK$20,$J$3:$J$14,1),COLUMN($K$4))):indirect(address(row($J$2)+ VLOOKUP(AK$20,$J$3:$J$14,1),COLUMN($S$2)))>indirect(address(row($J5),COLUMN($K$2))):indirect(address(row($J5),COLUMN($S$2))),TRUE()))} -> 7 | AL24: {=if(AL$20=$J5,"-", countif(indirect(address(row($J$2)+ VLOOKUP(AL$20,$J$3:$J$14,1),COLUMN($K$4))):indirect(address(row($J$2)+ VLOOKUP(AL$20,$J$3:$J$14,1),COLUMN($S$2)))>indirect(address(row($J5),COLUMN($K$2))):indirect(address(row($J5),COLUMN($S$2))),TRUE()))} -> 0 | AM24: {=if(AM$20=$J5,"-", countif(indirect(address(row($J$2)+ VLOOKUP(AM$20,$J$3:$J$14,1),COLUMN($K$4))):indirect(address(row($J$2)+ VLOOKUP(AM$20,$J$3:$J$14,1),COLUMN($S$2)))>indirect(address(row($J5),COLUMN($K$2))):indirect(address(row($J5),COLUMN($S$2))),TRUE()))} -> - | AN24: {=if(AN$20=$J5,"-", countif(indirect(address(row($J$2)+ VLOOKUP(AN$20,$J$3:$J$14,1),COLUMN($K$4))):indirect(address(row($J$2)+ VLOOKUP(AN$20,$J$3:$J$14,1),COLUMN($S$2)))>indirect(address(row($J5),COLUMN($K$2))):indirect(address(row($J5),COLUMN($S$2))),TRUE()))} -> 0 | AO24: {=if(AO$20=$J5,"-", countif(indirect(address(row($J$2)+ VLOOKUP(AO$20,$J$3:$J$14,1),COLUMN($K$4))):indirect(address(row($J$2)+ VLOOKUP(AO$20,$J$3:$J$14,1),COLUMN($S$2)))>indirect(address(row($J5),COLUMN($K$2))):indirect(address(row($J5),COLUMN($S$2))),TRUE()))} -> 0 | AP24: {=if(AP$20=$J5,"-", countif(indirect(address(row($J$2)+ VLOOKUP(AP$20,$J$3:$J$14,1),COLUMN($K$4))):indirect(address(row($J$2)+ VLOOKUP(AP$20,$J$3:$J$14,1),COLUMN($S$2)))>indirect(address(row($J5),COLUMN($K$2))):indirect(address(row($J5),COLUMN($S$2))),TRUE()))} -> 0 | AQ24: {=if(AQ$20=$J5,"-", countif(indirect(address(row($J$2)+ VLOOKUP(AQ$20,$J$3:$J$14,1),COLUMN($K$4))):indirect(address(row($J$2)+ VLOOKUP(AQ$20,$J$3:$J$14,1),COLUMN($S$2)))>indirect(address(row($J5),COLUMN($K$2))):indirect(address(row($J5),COLUMN($S$2))),TRUE()))} -> 0 | AR24: {=if(AR$20=$J5,"-", countif(indirect(address(row($J$2)+ VLOOKUP(AR$20,$J$3:$J$14,1),COLUMN($K$4))):indirect(address(row($J$2)+ VLOOKUP(AR$20,$J$3:$J$14,1),COLUMN($S$2)))>indirect(address(row($J5),COLUMN($K$2))):indirect(address(row($J5),COLUMN($S$2))),TRUE()))} -> 0 | ... AV24: {=if(AV$20=$J5,"-", countif(indirect(address(row($J$2)+ VLOOKUP(AV$20,$J$3:$J$14,1),COLUMN($K$4))):indirect(address(row($J$2)+ VLOOKUP(AV$20,$J$3:$J$14,1),COLUMN($S$2)))>indirect(address(row($J5),COLUMN($K$2))):indirect(address(row($J5),COLUMN($S$2))),TRUE()))} -> 0 | AW24: 3 | AX24: {=INDIRECT("Draft!F"&TEXT(VLOOKUP(TRUE,I3:J14,2,0)+2,"0"))} | AZ24: =IF($AX24="","", VLOOKUP($AX24,'Final Update'!$P$21:$AD1015,Column(H3),False)) | BA24: =IF($AX24="","", VLOOKUP($AX24,'Final Update'!$P$21:$AD1015,Column(I3),False)) | BB24: =IF($AX24="","", VLOOKUP($AX24,'Final Update'!$P$21:$AD1015,Column(J3),False)) | BC24: =IF($AX24="","", VLOOKUP($AX24,'Final Update'!$P$21:$AD1015,Column(K3),False)) | BD24: =IF($AX24="","", VLOOKUP($AX24,'Final Update'!$P$21:$AD1015,Column(L3),False)) | BE24: =IF($AX24="","", VLOOKUP($AX24,'Final Update'!$P$21:$AD1015,Column(M3),False)) | BF24: =IF($AX24="","", VLOOKUP($AX24,'Final Update'!$P$21:$AD1015,Column(N3),False)) | BG24: =IF($AX24="","", VLOOKUP($AX24,'Final Update'!$P$21:$AD1015,Column(O3),False)) | BH24: =IF($AX24="","", VLOOKUP($AX24,'Final Update'!$P$21:$AD1015,Column(P3),False)) | BI24: =IF($AX24="","", VLOOKUP($AX24,'Final Update'!$P$21:$AD1015,Column(C3),False)) | BJ24: {=COUNTIF(FIND(BK24,$BI$22:$BI$33),">0")} -> 0 | BK24: SF
A25: =VLOOKUP($F25,UpdateHashtag!$V$3:$Y$32,COLUMN(B$15),0) -> 4 | B25: =VLOOKUP($F25,UpdateHashtag!$V$3:$Y$32,COLUMN(C$13),0) -> 3 | C25: =VLOOKUP($F25,UpdateHashtag!$V$3:$Y$32,COLUMN(D$13),0) -> 4 | D25: =SUM(A25:C25) -> 11 | F25: =IF(VLOOKUP(J25,PasteHashtag!$C$2:$P1015,3,)="BRO","BKN",IF(VLOOKUP(J25,PasteHashtag!$C$2:$P1015,3,)="OKL","OKC",VLOOKUP(J25,PasteHashtag!$C$2:$P1015,3,))) -> CHA | G25: 6 | H25: =IFERROR(__xludf.DUMMYFUNCTION("""COMPUTED_VALUE"""),7.0) -> 7 | I25: =IFERROR(__xludf.DUMMYFUNCTION("""COMPUTED_VALUE"""),22.3) -> 22.3 | J25: =IFERROR(__xludf.DUMMYFUNCTION("""COMPUTED_VALUE"""),"LaMelo Ball") -> LaMelo Ball | K25: =IFERROR(__xludf.DUMMYFUNCTION("""COMPUTED_VALUE"""),77.0) -> 77 | L25: =IFERROR(__xludf.DUMMYFUNCTION("""COMPUTED_VALUE"""),"PG,SG") -> PG,SG | M25: =IFERROR(__xludf.DUMMYFUNCTION("""COMPUTED_VALUE"""),6.171957496592203) -> 6.1719575 | N25: =IFERROR(__xludf.DUMMYFUNCTION("""COMPUTED_VALUE"""),6.588658143108068) -> 6.5886581 | O25: =IFERROR(__xludf.DUMMYFUNCTION("""COMPUTED_VALUE"""),0.41670064651586536) -> 0.41670065 | P25: =IFERROR(__xludf.DUMMYFUNCTION("""COMPUTED_VALUE"""),26.09983871) -> 26.099839 | Q25: =IFERROR(__xludf.DUMMYFUNCTION("""COMPUTED_VALUE"""),3.96) -> 3.96 | R25: =IFERROR(__xludf.DUMMYFUNCTION("""COMPUTED_VALUE"""),5.909677419) -> 5.9096774 | S25: =IFERROR(__xludf.DUMMYFUNCTION("""COMPUTED_VALUE"""),8.492419355) -> 8.4924194 | T25: =IFERROR(__xludf.DUMMYFUNCTION("""COMPUTED_VALUE"""),1.680483871) -> 1.6804839 | U25: =IFERROR(__xludf.DUMMYFUNCTION("""COMPUTED_VALUE"""),0.2917741935) -> 0.29177419 | V25: =IFERROR(__xludf.DUMMYFUNCTION("""COMPUTED_VALUE"""),0.4356151932) -> 0.43561519 | W25: =IFERROR(__xludf.DUMMYFUNCTION("""COMPUTED_VALUE"""),0.846013795) -> 0.84601379 | X25: =IFERROR(__xludf.DUMMYFUNCTION("""COMPUTED_VALUE"""),3.429032258) -> 3.4290323 | Y25: =IFERROR(__xludf.DUMMYFUNCTION("""COMPUTED_VALUE"""),1.5522123169896227) -> 1.5522123 | Z25: =IFERROR(__xludf.DUMMYFUNCTION("""COMPUTED_VALUE"""),2.1934846426626065) -> 2.1934846 | AA25: =IFERROR(__xludf.DUMMYFUNCTION("""COMPUTED_VALUE"""),-0.0680569677825962) -> -0.068056968 | AB25: =IFERROR(__xludf.DUMMYFUNCTION("""COMPUTED_VALUE"""),2.070456074563602) -> 2.0704561 | AC25: =IFERROR(__xludf.DUMMYFUNCTION("""COMPUTED_VALUE"""),2.3306534159165455) -> 2.3306534 | AD25: =IFERROR(__xludf.DUMMYFUNCTION("""COMPUTED_VALUE"""),-0.8149352655050185) -> -0.81493527 | AE25: =IFERROR(__xludf.DUMMYFUNCTION("""COMPUTED_VALUE"""),-1.5010523381290475) -> -1.5010523 | AF25: =IFERROR(__xludf.DUMMYFUNCTION("""COMPUTED_VALUE"""),0.8258962643923514) -> 0.82589626 | AG25: =IFERROR(__xludf.DUMMYFUNCTION("""COMPUTED_VALUE"""),0.0) -> 0 | AJ25: 100 | AK25: {=if(AK$20=$J6,"-", countif(indirect(address(row($J$2)+ VLOOKUP(AK$20,$J$3:$J$14,1),COLUMN($K$4))):indirect(address(row($J$2)+ VLOOKUP(AK$20,$J$3:$J$14,1),COLUMN($S$2)))>indirect(address(row($J6),COLUMN($K$2))):indirect(address(row($J6),COLUMN($S$2))),TRUE()))} -> 7 | AL25: {=if(AL$20=$J6,"-", countif(indirect(address(row($J$2)+ VLOOKUP(AL$20,$J$3:$J$14,1),COLUMN($K$4))):indirect(address(row($J$2)+ VLOOKUP(AL$20,$J$3:$J$14,1),COLUMN($S$2)))>indirect(address(row($J6),COLUMN($K$2))):indirect(address(row($J6),COLUMN($S$2))),TRUE()))} -> 0 | AM25: {=if(AM$20=$J6,"-", countif(indirect(address(row($J$2)+ VLOOKUP(AM$20,$J$3:$J$14,1),COLUMN($K$4))):indirect(address(row($J$2)+ VLOOKUP(AM$20,$J$3:$J$14,1),COLUMN($S$2)))>indirect(address(row($J6),COLUMN($K$2))):indirect(address(row($J6),COLUMN($S$2))),TRUE()))} -> 0 | AN25: {=if(AN$20=$J6,"-", countif(indirect(address(row($J$2)+ VLOOKUP(AN$20,$J$3:$J$14,1),COLUMN($K$4))):indirect(address(row($J$2)+ VLOOKUP(AN$20,$J$3:$J$14,1),COLUMN($S$2)))>indirect(address(row($J6),COLUMN($K$2))):indirect(address(row($J6),COLUMN($S$2))),TRUE()))} -> - | AO25: {=if(AO$20=$J6,"-", countif(indirect(address(row($J$2)+ VLOOKUP(AO$20,$J$3:$J$14,1),COLUMN($K$4))):indirect(address(row($J$2)+ VLOOKUP(AO$20,$J$3:$J$14,1),COLUMN($S$2)))>indirect(address(row($J6),COLUMN($K$2))):indirect(address(row($J6),COLUMN($S$2))),TRUE()))} -> 0 | AP25: {=if(AP$20=$J6,"-", countif(indirect(address(row($J$2)+ VLOOKUP(AP$20,$J$3:$J$14,1),COLUMN($K$4))):indirect(address(row($J$2)+ VLOOKUP(AP$20,$J$3:$J$14,1),COLUMN($S$2)))>indirect(address(row($J6),COLUMN($K$2))):indirect(address(row($J6),COLUMN($S$2))),TRUE()))} -> 0 | AQ25: {=if(AQ$20=$J6,"-", countif(indirect(address(row($J$2)+ VLOOKUP(AQ$20,$J$3:$J$14,1),COLUMN($K$4))):indirect(address(row($J$2)+ VLOOKUP(AQ$20,$J$3:$J$14,1),COLUMN($S$2)))>indirect(address(row($J6),COLUMN($K$2))):indirect(address(row($J6),COLUMN($S$2))),TRUE()))} -> 0 | AR25: {=if(AR$20=$J6,"-", countif(indirect(address(row($J$2)+ VLOOKUP(AR$20,$J$3:$J$14,1),COLUMN($K$4))):indirect(address(row($J$2)+ VLOOKUP(AR$20,$J$3:$J$14,1),COLUMN($S$2)))>indirect(address(row($J6),COLUMN($K$2))):indirect(address(row($J6),COLUMN($S$2))),TRUE()))} -> 0 | ... AV25: {=if(AV$20=$J6,"-", countif(indirect(address(row($J$2)+ VLOOKUP(AV$20,$J$3:$J$14,1),COLUMN($K$4))):indirect(address(row($J$2)+ VLOOKUP(AV$20,$J$3:$J$14,1),COLUMN($S$2)))>indirect(address(row($J6),COLUMN($K$2))):indirect(address(row($J6),COLUMN($S$2))),TRUE()))} -> 0 | AW25: 4 | AX25: {=INDIRECT("Draft!G"&TEXT(15-VLOOKUP(TRUE,I3:J14,2,0),"0"))} | AZ25: =IF($AX25="","", VLOOKUP($AX25,'Final Update'!$P$21:$AD1015,Column(H4),False)) | BA25: =IF($AX25="","", VLOOKUP($AX25,'Final Update'!$P$21:$AD1015,Column(I4),False)) | BB25: =IF($AX25="","", VLOOKUP($AX25,'Final Update'!$P$21:$AD1015,Column(J4),False)) | BC25: =IF($AX25="","", VLOOKUP($AX25,'Final Update'!$P$21:$AD1015,Column(K4),False)) | BD25: =IF($AX25="","", VLOOKUP($AX25,'Final Update'!$P$21:$AD1015,Column(L4),False)) | BE25: =IF($AX25="","", VLOOKUP($AX25,'Final Update'!$P$21:$AD1015,Column(M4),False)) | BF25: =IF($AX25="","", VLOOKUP($AX25,'Final Update'!$P$21:$AD1015,Column(N4),False)) | BG25: =IF($AX25="","", VLOOKUP($AX25,'Final Update'!$P$21:$AD1015,Column(O4),False)) | BH25: =IF($AX25="","", VLOOKUP($AX25,'Final Update'!$P$21:$AD1015,Column(P4),False)) | BI25: =IF($AX25="","", VLOOKUP($AX25,'Final Update'!$P$21:$AD1015,Column(C4),False)) | BJ25: {=COUNTIF(FIND(BK25,$BI$22:$BI$33),">0")} -> 0 | BK25: PF
