Workbook

Sheet Projections
BD2: =Draft!AK3 | BE2: =Draft!AL3 | BF2: =Draft!AM3 | BG2: =Draft!AN3 | BH2: =Draft!AO3
J3: Current Player Auctioned | L3: Draft Average | BD3: =Draft!AK4 | BE3: =Draft!AL4 | BF3: =Draft!AM4 | BG3: =Draft!AN4 | BH3: =Draft!AO4
F4: Total $ Left | G4: =200*13 -> 2600 | J4: $ Value | BD4: =Draft!AK5 | BE4: =Draft!AL5 | BF4: =Draft!AM5 | BG4: =Draft!AN5 | BH4: =Draft!AO5
F5: Total LeagV/$ Left | J5: LeagV/$ | BD5: =Draft!AK6 | BE5: =Draft!AL6 | BF5: =Draft!AM6 | BG5: =Draft!AN6 | BH5: =Draft!AO6
F6: Total PuntV/$ Left | J6: PuntV/$ | BD6: =Draft!AK7 | BE6: =Draft!AL7 | BF6: =Draft!AM7 | BG6: =Draft!AN7 | BH6: =Draft!AO7
BD7: =Draft!AK8 | BE7: =Draft!AL8 | BF7: =Draft!AM8 | BG7: =Draft!AN8 | BH7: =Draft!AO8
BD8: =Draft!AK15 | BE8: =Draft!AL15 | BF8: =Draft!AM15 | BG8: =Draft!AN15 | BH8: =Draft!AO15
J9: Avg Zscore Available | K9: =SUM(Y14:Y1009)/ COUNT($K$14:$K1009) -> -0.016206118 | L9: =SUM(Z14:Z1009)/ COUNT($K$14:$K1009) -> -0.012146398 | M9: =SUM(AA14:AA1009)/ COUNT($K$14:$K1009) -> -0.030786282 | N9: =SUM(AB14:AB1009)/ COUNT($K$14:$K1009) -> 0.033647248 | O9: =SUM(AC14:AC1009)/ COUNT($K$14:$K1009) -> -0.064760135 | P9: =SUM(AD14:AD1009)/ COUNT($K$14:$K1009) -> -0.0051344442 | Q9: =SUM(AE14:AE1009)/ COUNT($K$14:$K1009) -> 0.15190162 | R9: =SUM(AF14:AF1009)/ COUNT($K$14:$K1009) -> 0.15278051 | S9: =SUM(AG14:AG1009)/ COUNT($K$14:$K1009) -> 0
I10: -1 Cat | J10: -2 Cat | K10: PTS | L10: 3P | M10: REB | N10: AST | O10: STL | P10: BLK | Q10: FG% | R10: FT% | S10: TO | T10: PG | U10: SG | V10: SF | W10: PF | X10: C | Z10: Sort by | AB10: Remove Drafted | AE10: Top | AG10: Projections
I11: TRUE | J11: FALSE | K11: 1 | L11: 1 | M11: 1 | N11: 1 | O11: 1 | P11: 1 | Q11: 1 | R11: 1 | S11: 0 | T11: PG | U11: SG | V11: SF | W11: PF | X11: C | Z11: PuntV | AB11: FALSE | AE11: 156 | AG11: BBM
A13: W18 | B13: W19 | C13: W20 | D13: Total | F13: Team | G13: PuntRank | H13: LgRank | I13: Auction $ | J13: Player | K13: GP | L13: Pos | M13: LeagV | N13: PuntV | O13: Punt+ | P13: PTS | Q13: 3P | R13: REB | S13: AST | T13: STL | U13: BLK | V13: FG% | W13: FT% | X13: TO | Y13: z p/g | Z13: z 3/g | AA13: z r/g | AB13: z a/g | AC13: z s/g | AD13: z b/g | AE13: z fg% | AF13: z ft% | AG13: z to/g
A14: =VLOOKUP($F14,UpdateHashtag!$V$3:$Y$32,COLUMN(B$9),0) -> #N/A | B14: =VLOOKUP($F14,UpdateHashtag!$V$3:$Y$32,COLUMN(#REF!),0) -> #REF! | C14: =VLOOKUP($F14,UpdateHashtag!$V$3:$Y$32,COLUMN(#REF!),0) -> #REF! | D14: =SUM(A14:C14) -> #N/A | F14: =VLOOKUP(J14,UpdateBBM!$C$2:E1009,3,0) -> SAS | G14: 1 | H14: =IFERROR(__xludf.DUMMYFUNCTION("Filter('NO USAR3'!B5:AA420,IF('NO USAR3'!AB5:AB420="""",FALSE,TRUE),NOT(COUNTIF('NO USAR3'!A5:A200,'NO USAR3'!D5:D420)),IF('NO USAR3'!B5:B420>AE11,FALSE,TRUE))"),1.0) -> 1 | J14: =IFERROR(__xludf.DUMMYFUNCTION("""COMPUTED_VALUE"""),"Victor Wembanyama") -> Victor Wembanyama | K14: =IFERROR(__xludf.DUMMYFUNCTION("""COMPUTED_VALUE"""),73.0) -> 73 | L14: =IFERROR(__xludf.DUMMYFUNCTION("""COMPUTED_VALUE"""),"C") -> C | M14: =IFERROR(__xludf.DUMMYFUNCTION("""COMPUTED_VALUE"""),11.3425419387325) -> 11.342542 | N14: =IFERROR(__xludf.DUMMYFUNCTION("""COMPUTED_VALUE"""),11.589733589107464) -> 11.589734 | O14: =IFERROR(__xludf.DUMMYFUNCTION("""COMPUTED_VALUE"""),0.2471916503749636) -> 0.24719165 | P14: =IFERROR(__xludf.DUMMYFUNCTION("""COMPUTED_VALUE"""),25.83918) -> 25.83918 | Q14: =IFERROR(__xludf.DUMMYFUNCTION("""COMPUTED_VALUE"""),3.049863) -> 3.049863 | R14: =IFERROR(__xludf.DUMMYFUNCTION("""COMPUTED_VALUE"""),11.92123) -> 11.92123 | S14: =IFERROR(__xludf.DUMMYFUNCTION("""COMPUTED_VALUE"""),3.829315) -> 3.829315 | T14: =IFERROR(__xludf.DUMMYFUNCTION("""COMPUTED_VALUE"""),1.158356) -> 1.158356 | U14: =IFERROR(__xludf.DUMMYFUNCTION("""COMPUTED_VALUE"""),3.901507) -> 3.901507 | V14: =IFERROR(__xludf.DUMMYFUNCTION("""COMPUTED_VALUE"""),0.491121) -> 0.491121 | W14: =IFERROR(__xludf.DUMMYFUNCTION("""COMPUTED_VALUE"""),0.816988) -> 0.816988 | X14: =IFERROR(__xludf.DUMMYFUNCTION("""COMPUTED_VALUE"""),2.745479) -> 2.745479 | Y14: =IFERROR(__xludf.DUMMYFUNCTION("""COMPUTED_VALUE"""),1.520135093083864) -> 1.5201351 | Z14: =IFERROR(__xludf.DUMMYFUNCTION("""COMPUTED_VALUE"""),1.2365655716765753) -> 1.2365656 | AA14: =IFERROR(__xludf.DUMMYFUNCTION("""COMPUTED_VALUE"""),2.348916477230807) -> 2.3489165 | AB14: =IFERROR(__xludf.DUMMYFUNCTION("""COMPUTED_VALUE"""),-0.003704573661539899) -> -0.0037045737 | AC14: =IFERROR(__xludf.DUMMYFUNCTION("""COMPUTED_VALUE"""),0.34484979672257154) -> 0.3448498 | AD14: =IFERROR(__xludf.DUMMYFUNCTION("""COMPUTED_VALUE"""),5.76537101565873) -> 5.765371 | AE14: =IFERROR(__xludf.DUMMYFUNCTION("""COMPUTED_VALUE"""),-0.059921646652902165) -> -0.059921647 | AF14: =IFERROR(__xludf.DUMMYFUNCTION("""COMPUTED_VALUE"""),0.3776002083964553) -> 0.37760021 | AG14: =IFERROR(__xludf.DUMMYFUNCTION("""COMPUTED_VALUE"""),0.0) -> 0 | AK14: 1 | AL14: 2 | AM14: 3 | AN14: 4 | AO14: 5 | AP14: 6 | AQ14: 7 | AR14: 8 | AS14: 9 | AT14: 10 | AU14: 11 | AV14: 12
A15: =VLOOKUP($F15,UpdateHashtag!$V$3:$Y$32,COLUMN(B$9),0) -> 3 | B15: =VLOOKUP($F15,UpdateHashtag!$V$3:$Y$32,COLUMN(#REF!),0) -> #REF! | C15: =VLOOKUP($F15,UpdateHashtag!$V$3:$Y$32,COLUMN(#REF!),0) -> #REF! | D15: =SUM(A15:C15) -> #REF! | F15: =VLOOKUP(J15,UpdateBBM!$C$2:E1009,3,0) -> DEN | G15: 2 | H15: =IFERROR(__xludf.DUMMYFUNCTION("""COMPUTED_VALUE"""),2.0) -> 2 | J15: =IFERROR(__xludf.DUMMYFUNCTION("""COMPUTED_VALUE"""),"Nikola Jokic") -> Nikola Jokic | K15: =IFERROR(__xludf.DUMMYFUNCTION("""COMPUTED_VALUE"""),73.0) -> 73 | L15: =IFERROR(__xludf.DUMMYFUNCTION("""COMPUTED_VALUE"""),"C") -> C | M15: =IFERROR(__xludf.DUMMYFUNCTION("""COMPUTED_VALUE"""),9.4823258240044) -> 9.4823258 | N15: =IFERROR(__xludf.DUMMYFUNCTION("""COMPUTED_VALUE"""),9.821236890688052) -> 9.8212369 | O15: =IFERROR(__xludf.DUMMYFUNCTION("""COMPUTED_VALUE"""),0.3389110666836519) -> 0.33891107 | P15: =IFERROR(__xludf.DUMMYFUNCTION("""COMPUTED_VALUE"""),27.67616) -> 27.67616 | Q15: =IFERROR(__xludf.DUMMYFUNCTION("""COMPUTED_VALUE"""),1.596849) -> 1.596849 | R15: =IFERROR(__xludf.DUMMYFUNCTION("""COMPUTED_VALUE"""),12.16205) -> 12.16205 | S15: =IFERROR(__xludf.DUMMYFUNCTION("""COMPUTED_VALUE"""),8.994658) -> 8.994658 | T15: =IFERROR(__xludf.DUMMYFUNCTION("""COMPUTED_VALUE"""),1.430822) -> 1.430822 | U15: =IFERROR(__xludf.DUMMYFUNCTION("""COMPUTED_VALUE"""),0.715479) -> 0.715479 | V15: =IFERROR(__xludf.DUMMYFUNCTION("""COMPUTED_VALUE"""),0.585091) -> 0.585091 | W15: =IFERROR(__xludf.DUMMYFUNCTION("""COMPUTED_VALUE"""),0.810004) -> 0.810004 | X15: =IFERROR(__xludf.DUMMYFUNCTION("""COMPUTED_VALUE"""),3.115342) -> 3.115342 | Y15: =IFERROR(__xludf.DUMMYFUNCTION("""COMPUTED_VALUE"""),1.842419662370102) -> 1.8424197 | Z15: =IFERROR(__xludf.DUMMYFUNCTION("""COMPUTED_VALUE"""),-0.1668039380108046) -> -0.16680394 | AA15: =IFERROR(__xludf.DUMMYFUNCTION("""COMPUTED_VALUE"""),2.446533732690303) -> 2.4465337 | AB15: =IFERROR(__xludf.DUMMYFUNCTION("""COMPUTED_VALUE"""),2.51964036424524) -> 2.5196404 | AC15: =IFERROR(__xludf.DUMMYFUNCTION("""COMPUTED_VALUE"""),1.1751163763235453) -> 1.1751164 | AD15: =IFERROR(__xludf.DUMMYFUNCTION("""COMPUTED_VALUE"""),-0.02680311688072257) -> -0.026803117 | AE15: =IFERROR(__xludf.DUMMYFUNCTION("""COMPUTED_VALUE"""),1.5802315736235906) -> 1.5802316 | AF15: =IFERROR(__xludf.DUMMYFUNCTION("""COMPUTED_VALUE"""),0.28409829831599426) -> 0.2840983 | AG15: =IFERROR(__xludf.DUMMYFUNCTION("""COMPUTED_VALUE"""),0.0) -> 0 | AJ15: % Games/Week | AK15: Categories won | AW15: Round | AX15: Player Name | AZ15: PTS | BA15: 3P | BB15: REB | BC15: AST | BD15: STL | BE15: BLK | BF15: FG% | BG15: FT% | BH15: TO | BI15: POS | BJ15: Count | BK15: POS
A16: =VLOOKUP($F16,UpdateHashtag!$V$3:$Y$32,COLUMN(B$9),0) -> 3 | B16: =VLOOKUP($F16,UpdateHashtag!$V$3:$Y$32,COLUMN(#REF!),0) -> #REF! | C16: =VLOOKUP($F16,UpdateHashtag!$V$3:$Y$32,COLUMN(#REF!),0) -> #REF! | D16: =SUM(A16:C16) -> #REF! | F16: =VLOOKUP(J16,UpdateBBM!$C$2:E1009,3,0) -> LAL | G16: 3 | H16: =IFERROR(__xludf.DUMMYFUNCTION("""COMPUTED_VALUE"""),3.0) -> 3 | J16: =IFERROR(__xludf.DUMMYFUNCTION("""COMPUTED_VALUE"""),"Luka Doncic") -> Luka Doncic | K16: =IFERROR(__xludf.DUMMYFUNCTION("""COMPUTED_VALUE"""),68.0) -> 68 | L16: =IFERROR(__xludf.DUMMYFUNCTION("""COMPUTED_VALUE"""),"G") -> G | M16: =IFERROR(__xludf.DUMMYFUNCTION("""COMPUTED_VALUE"""),7.082632867736175) -> 7.0826329 | N16: =IFERROR(__xludf.DUMMYFUNCTION("""COMPUTED_VALUE"""),7.5056636902266645) -> 7.5056637 | O16: =IFERROR(__xludf.DUMMYFUNCTION("""COMPUTED_VALUE"""),0.42303082249048973) -> 0.42303082 | P16: =IFERROR(__xludf.DUMMYFUNCTION("""COMPUTED_VALUE"""),29.94368) -> 29.94368 | Q16: =IFERROR(__xludf.DUMMYFUNCTION("""COMPUTED_VALUE"""),3.678088) -> 3.678088 | R16: =IFERROR(__xludf.DUMMYFUNCTION("""COMPUTED_VALUE"""),7.791029) -> 7.791029 | S16: =IFERROR(__xludf.DUMMYFUNCTION("""COMPUTED_VALUE"""),7.497059) -> 7.497059 | T16: =IFERROR(__xludf.DUMMYFUNCTION("""COMPUTED_VALUE"""),1.47) -> 1.47 | U16: =IFERROR(__xludf.DUMMYFUNCTION("""COMPUTED_VALUE"""),0.44) -> 0.44 | V16: =IFERROR(__xludf.DUMMYFUNCTION("""COMPUTED_VALUE"""),0.468707) -> 0.468707 | W16: =IFERROR(__xludf.DUMMYFUNCTION("""COMPUTED_VALUE"""),0.791004) -> 0.791004 | X16: =IFERROR(__xludf.DUMMYFUNCTION("""COMPUTED_VALUE"""),3.454559) -> 3.454559 | Y16: =IFERROR(__xludf.DUMMYFUNCTION("""COMPUTED_VALUE"""),2.2402392938020883) -> 2.2402393 | Z16: =IFERROR(__xludf.DUMMYFUNCTION("""COMPUTED_VALUE"""),1.8433262843905296) -> 1.8433263 | AA16: =IFERROR(__xludf.DUMMYFUNCTION("""COMPUTED_VALUE"""),0.6747246073027928) -> 0.67472461 | AB16: =IFERROR(__xludf.DUMMYFUNCTION("""COMPUTED_VALUE"""),1.788041541928067) -> 1.7880415 | AC16: =IFERROR(__xludf.DUMMYFUNCTION("""COMPUTED_VALUE"""),1.2945007547619811) -> 1.2945008 | AD16: =IFERROR(__xludf.DUMMYFUNCTION("""COMPUTED_VALUE"""),-0.5276217970234695) -> -0.5276218 | AE16: =IFERROR(__xludf.DUMMYFUNCTION("""COMPUTED_VALUE"""),-0.3727730401818931) -> -0.37277304 | AF16: =IFERROR(__xludf.DUMMYFUNCTION("""COMPUTED_VALUE"""),0.03760424822309971) -> 0.037604248 | AG16: =IFERROR(__xludf.DUMMYFUNCTION("""COMPUTED_VALUE"""),0.0) -> 0 | AJ16: 100 | AK16: {=if(AK$14=$J3,"-", countif(indirect(address(row($J$2)+ VLOOKUP(AK$14,$J$3:$J$8,1),COLUMN($K$4))):indirect(address(row($J$2)+ VLOOKUP(AK$14,$J$3:$J$8,1),COLUMN($S$2)))>indirect(address(row($J3),COLUMN($K$2))):indirect(address(row($J3),COLUMN($S$2))),TRUE()))} -> 0 | AL16: {=if(AL$14=$J3,"-", countif(indirect(address(row($J$2)+ VLOOKUP(AL$14,$J$3:$J$8,1),COLUMN($K$4))):indirect(address(row($J$2)+ VLOOKUP(AL$14,$J$3:$J$8,1),COLUMN($S$2)))>indirect(address(row($J3),COLUMN($K$2))):indirect(address(row($J3),COLUMN($S$2))),TRUE()))} -> 0 | AM16: {=if(AM$14=$J3,"-", countif(indirect(address(row($J$2)+ VLOOKUP(AM$14,$J$3:$J$8,1),COLUMN($K$4))):indirect(address(row($J$2)+ VLOOKUP(AM$14,$J$3:$J$8,1),COLUMN($S$2)))>indirect(address(row($J3),COLUMN($K$2))):indirect(address(row($J3),COLUMN($S$2))),TRUE()))} -> 0 | AN16: {=if(AN$14=$J3,"-", countif(indirect(address(row($J$2)+ VLOOKUP(AN$14,$J$3:$J$8,1),COLUMN($K$4))):indirect(address(row($J$2)+ VLOOKUP(AN$14,$J$3:$J$8,1),COLUMN($S$2)))>indirect(address(row($J3),COLUMN($K$2))):indirect(address(row($J3),COLUMN($S$2))),TRUE()))} -> 0 | AO16: {=if(AO$14=$J3,"-", countif(indirect(address(row($J$2)+ VLOOKUP(AO$14,$J$3:$J$8,1),COLUMN($K$4))):indirect(address(row($J$2)+ VLOOKUP(AO$14,$J$3:$J$8,1),COLUMN($S$2)))>indirect(address(row($J3),COLUMN($K$2))):indirect(address(row($J3),COLUMN($S$2))),TRUE()))} -> 0 | AP16: {=if(AP$14=$J3,"-", countif(indirect(address(row($J$2)+ VLOOKUP(AP$14,$J$3:$J$8,1),COLUMN($K$4))):indirect(address(row($J$2)+ VLOOKUP(AP$14,$J$3:$J$8,1),COLUMN($S$2)))>indirect(address(row($J3),COLUMN($K$2))):indirect(address(row($J3),COLUMN($S$2))),TRUE()))} -> 0 | AQ16: {=if(AQ$14=$J3,"-", countif(indirect(address(row($J$2)+ VLOOKUP(AQ$14,$J$3:$J$8,1),COLUMN($K$4))):indirect(address(row($J$2)+ VLOOKUP(AQ$14,$J$3:$J$8,1),COLUMN($S$2)))>indirect(address(row($J3),COLUMN($K$2))):indirect(address(row($J3),COLUMN($S$2))),TRUE()))} -> 0 | AR16: {=if(AR$14=$J3,"-", countif(indirect(address(row($J$2)+ VLOOKUP(AR$14,$J$3:$J$8,1),COLUMN($K$4))):indirect(address(row($J$2)+ VLOOKUP(AR$14,$J$3:$J$8,1),COLUMN($S$2)))>indirect(address(row($J3),COLUMN($K$2))):indirect(address(row($J3),COLUMN($S$2))),TRUE()))} -> 0 | ... AV16: {=if(AV$14=$J3,"-", countif(indirect(address(row($J$2)+ VLOOKUP(AV$14,$J$3:$J$8,1),COLUMN($K$4))):indirect(address(row($J$2)+ VLOOKUP(AV$14,$J$3:$J$8,1),COLUMN($S$2)))>indirect(address(row($J3),COLUMN($K$2))):indirect(address(row($J3),COLUMN($S$2))),TRUE()))} -> 0 | AW16: 1 | AX16: {=INDIRECT("Draft!D"&TEXT(VLOOKUP(TRUE,I3:J8,2,0)+2,"0"))} -> #N/A | AZ16: =IF($AX16="","", VLOOKUP($AX16,'Final Update'!$Q$21:$AE1009,Column(G1),False)) -> #N/A | BA16: =IF($AX16="","", VLOOKUP($AX16,'Final Update'!$Q$21:$AE1009,Column(H1),False)) -> #N/A | BB16: =IF($AX16="","", VLOOKUP($AX16,'Final Update'!$Q$21:$AE1009,Column(I1),False)) -> #N/A | BC16: =IF($AX16="","", VLOOKUP($AX16,'Final Update'!$Q$21:$AE1009,Column(J1),False)) -> #N/A | BD16: =IF($AX16="","", VLOOKUP($AX16,'Final Update'!$Q$21:$AE1009,Column(K1),False)) -> #N/A | BE16: =IF($AX16="","", VLOOKUP($AX16,'Final Update'!$Q$21:$AE1009,Column(L1),False)) -> #N/A | BF16: =IF($AX16="","", VLOOKUP($AX16,'Final Update'!$Q$21:$AE1009,Column(M1),False)) -> #N/A | BG16: =IF($AX16="","", VLOOKUP($AX16,'Final Update'!$Q$21:$AE1009,Column(N1),False)) -> #N/A | BH16: =IF($AX16="","", VLOOKUP($AX16,'Final Update'!$Q$21:$AE1009,Column(O1),False)) -> #N/A | BI16: =IF($AX16="","", VLOOKUP($AX16,'Final Update'!$Q$21:$AE1009,Column(C1),False)) -> #N/A | BJ16: {=COUNTIF(FIND(BK16,$BI$16:$BI$27),">0")} -> 0 | BK16: PG
A17: =VLOOKUP($F17,UpdateHashtag!$V$3:$Y$32,COLUMN(B$9),0) -> 4 | B17: =VLOOKUP($F17,UpdateHashtag!$V$3:$Y$32,COLUMN(#REF!),0) -> #REF! | C17: =VLOOKUP($F17,UpdateHashtag!$V$3:$Y$32,COLUMN(#REF!),0) -> #REF! | D17: =SUM(A17:C17) -> #REF! | F17: =VLOOKUP(J17,UpdateBBM!$C$2:E1009,3,0) -> OKC | G17: 4 | H17: =IFERROR(__xludf.DUMMYFUNCTION("""COMPUTED_VALUE"""),4.0) -> 4 | J17: =IFERROR(__xludf.DUMMYFUNCTION("""COMPUTED_VALUE"""),"Shai Gilgeous-Alexander") -> Shai Gilgeous-Alexander | K17: =IFERROR(__xludf.DUMMYFUNCTION("""COMPUTED_VALUE"""),73.0) -> 73 | L17: =IFERROR(__xludf.DUMMYFUNCTION("""COMPUTED_VALUE"""),"G") -> G | M17: =IFERROR(__xludf.DUMMYFUNCTION("""COMPUTED_VALUE"""),6.761339091582645) -> 6.7613391 | N17: =IFERROR(__xludf.DUMMYFUNCTION("""COMPUTED_VALUE"""),6.7798438491212725) -> 6.7798438 | O17: =IFERROR(__xludf.DUMMYFUNCTION("""COMPUTED_VALUE"""),0.01850475753862746) -> 0.018504758 | P17: =IFERROR(__xludf.DUMMYFUNCTION("""COMPUTED_VALUE"""),30.51822) -> 30.51822 | Q17: =IFERROR(__xludf.DUMMYFUNCTION("""COMPUTED_VALUE"""),1.935479) -> 1.935479 | R17: =IFERROR(__xludf.DUMMYFUNCTION("""COMPUTED_VALUE"""),4.558082) -> 4.558082 | S17: =IFERROR(__xludf.DUMMYFUNCTION("""COMPUTED_VALUE"""),6.030685) -> 6.030685 | T17: =IFERROR(__xludf.DUMMYFUNCTION("""COMPUTED_VALUE"""),1.462877) -> 1.462877 | U17: =IFERROR(__xludf.DUMMYFUNCTION("""COMPUTED_VALUE"""),0.91589) -> 0.91589 | V17: =IFERROR(__xludf.DUMMYFUNCTION("""COMPUTED_VALUE"""),0.505971) -> 0.505971 | W17: =IFERROR(__xludf.DUMMYFUNCTION("""COMPUTED_VALUE"""),0.889004) -> 0.889004 | X17: =IFERROR(__xludf.DUMMYFUNCTION("""COMPUTED_VALUE"""),1.823288) -> 1.823288 | Y17: =IFERROR(__xludf.DUMMYFUNCTION("""COMPUTED_VALUE"""),2.341038092067565) -> 2.3410381 | Z17: =IFERROR(__xludf.DUMMYFUNCTION("""COMPUTED_VALUE"""),0.16025623970629752) -> 0.16025624 | AA17: =IFERROR(__xludf.DUMMYFUNCTION("""COMPUTED_VALUE"""),-0.6357621179941515) -> -0.63576212 | AB17: =IFERROR(__xludf.DUMMYFUNCTION("""COMPUTED_VALUE"""),1.0716965847823137) -> 1.0716966 | AC17: =IFERROR(__xludf.DUMMYFUNCTION("""COMPUTED_VALUE"""),1.2727953351995487) -> 1.2727953 | AD17: =IFERROR(__xludf.DUMMYFUNCTION("""COMPUTED_VALUE"""),0.33754252291791204) -> 0.33754252 | AE17: =IFERROR(__xludf.DUMMYFUNCTION("""COMPUTED_VALUE"""),0.1639756592911051) -> 0.16397566 | AF17: =IFERROR(__xludf.DUMMYFUNCTION("""COMPUTED_VALUE"""),1.4325394151565307) -> 1.4325394 | AG17: =IFERROR(__xludf.DUMMYFUNCTION("""COMPUTED_VALUE"""),0.0) -> 0 | AJ17: 100 | AK17: {=if(AK$14=$J4,"-", countif(indirect(address(row($J$2)+ VLOOKUP(AK$14,$J$3:$J$8,1),COLUMN($K$4))):indirect(address(row($J$2)+ VLOOKUP(AK$14,$J$3:$J$8,1),COLUMN($S$2)))>indirect(address(row($J4),COLUMN($K$2))):indirect(address(row($J4),COLUMN($S$2))),TRUE()))} -> 0 | AL17: {=if(AL$14=$J4,"-", countif(indirect(address(row($J$2)+ VLOOKUP(AL$14,$J$3:$J$8,1),COLUMN($K$4))):indirect(address(row($J$2)+ VLOOKUP(AL$14,$J$3:$J$8,1),COLUMN($S$2)))>indirect(address(row($J4),COLUMN($K$2))):indirect(address(row($J4),COLUMN($S$2))),TRUE()))} -> 0 | AM17: {=if(AM$14=$J4,"-", countif(indirect(address(row($J$2)+ VLOOKUP(AM$14,$J$3:$J$8,1),COLUMN($K$4))):indirect(address(row($J$2)+ VLOOKUP(AM$14,$J$3:$J$8,1),COLUMN($S$2)))>indirect(address(row($J4),COLUMN($K$2))):indirect(address(row($J4),COLUMN($S$2))),TRUE()))} -> 0 | AN17: {=if(AN$14=$J4,"-", countif(indirect(address(row($J$2)+ VLOOKUP(AN$14,$J$3:$J$8,1),COLUMN($K$4))):indirect(address(row($J$2)+ VLOOKUP(AN$14,$J$3:$J$8,1),COLUMN($S$2)))>indirect(address(row($J4),COLUMN($K$2))):indirect(address(row($J4),COLUMN($S$2))),TRUE()))} -> 0 | AO17: {=if(AO$14=$J4,"-", countif(indirect(address(row($J$2)+ VLOOKUP(AO$14,$J$3:$J$8,1),COLUMN($K$4))):indirect(address(row($J$2)+ VLOOKUP(AO$14,$J$3:$J$8,1),COLUMN($S$2)))>indirect(address(row($J4),COLUMN($K$2))):indirect(address(row($J4),COLUMN($S$2))),TRUE()))} -> 0 | AP17: {=if(AP$14=$J4,"-", countif(indirect(address(row($J$2)+ VLOOKUP(AP$14,$J$3:$J$8,1),COLUMN($K$4))):indirect(address(row($J$2)+ VLOOKUP(AP$14,$J$3:$J$8,1),COLUMN($S$2)))>indirect(address(row($J4),COLUMN($K$2))):indirect(address(row($J4),COLUMN($S$2))),TRUE()))} -> 0 | AQ17: {=if(AQ$14=$J4,"-", countif(indirect(address(row($J$2)+ VLOOKUP(AQ$14,$J$3:$J$8,1),COLUMN($K$4))):indirect(address(row($J$2)+ VLOOKUP(AQ$14,$J$3:$J$8,1),COLUMN($S$2)))>indirect(address(row($J4),COLUMN($K$2))):indirect(address(row($J4),COLUMN($S$2))),TRUE()))} -> 0 | AR17: {=if(AR$14=$J4,"-", countif(indirect(address(row($J$2)+ VLOOKUP(AR$14,$J$3:$J$8,1),COLUMN($K$4))):indirect(address(row($J$2)+ VLOOKUP(AR$14,$J$3:$J$8,1),COLUMN($S$2)))>indirect(address(row($J4),COLUMN($K$2))):indirect(address(row($J4),COLUMN($S$2))),TRUE()))} -> 0 | ... AV17: {=if(AV$14=$J4,"-", countif(indirect(address(row($J$2)+ VLOOKUP(AV$14,$J$3:$J$8,1),COLUMN($K$4))):indirect(address(row($J$2)+ VLOOKUP(AV$14,$J$3:$J$8,1),COLUMN($S$2)))>indirect(address(row($J4),COLUMN($K$2))):indirect(address(row($J4),COLUMN($S$2))),TRUE()))} -> 0 | AW17: 2 | AX17: {=INDIRECT("Draft!E"&TEXT(15-VLOOKUP(TRUE,I3:J8,2,0),"0"))} -> #N/A | AZ17: =IF($AX17="","", VLOOKUP($AX17,'Final Update'!$Q$21:$AE1009,Column(G2),False)) -> #N/A | BA17: =IF($AX17="","", VLOOKUP($AX17,'Final Update'!$Q$21:$AE1009,Column(H2),False)) -> #N/A | BB17: =IF($AX17="","", VLOOKUP($AX17,'Final Update'!$Q$21:$AE1009,Column(I2),False)) -> #N/A | BC17: =IF($AX17="","", VLOOKUP($AX17,'Final Update'!$Q$21:$AE1009,Column(J2),False)) -> #N/A | BD17: =IF($AX17="","", VLOOKUP($AX17,'Final Update'!$Q$21:$AE1009,Column(K2),False)) -> #N/A | BE17: =IF($AX17="","", VLOOKUP($AX17,'Final Update'!$Q$21:$AE1009,Column(L3),False)) -> #N/A | BF17: =IF($AX17="","", VLOOKUP($AX17,'Final Update'!$Q$21:$AE1009,Column(M2),False)) -> #N/A | BG17: =IF($AX17="","", VLOOKUP($AX17,'Final Update'!$Q$21:$AE1009,Column(N2),False)) -> #N/A | BH17: =IF($AX17="","", VLOOKUP($AX17,'Final Update'!$Q$21:$AE1009,Column(O2),False)) -> #N/A | BI17: =IF($AX17="","", VLOOKUP($AX17,'Final Update'!$Q$21:$AE1009,Column(C2),False)) -> #N/A | BJ17: {=COUNTIF(FIND(BK17,$BI$16:$BI$27),">0")} -> 0 | BK17: SG
A18: =VLOOKUP($F18,UpdateHashtag!$V$3:$Y$32,COLUMN(B$9),0) -> 4 | B18: =VLOOKUP($F18,UpdateHashtag!$V$3:$Y$32,COLUMN(#REF!),0) -> #REF! | C18: =VLOOKUP($F18,UpdateHashtag!$V$3:$Y$32,COLUMN(#REF!),0) -> #REF! | D18: =SUM(A18:C18) -> #REF! | F18: =VLOOKUP(J18,UpdateBBM!$C$2:E1009,3,0) -> MIL | G18: 5 | H18: =IFERROR(__xludf.DUMMYFUNCTION("""COMPUTED_VALUE"""),5.0) -> 5 | J18: =IFERROR(__xludf.DUMMYFUNCTION("""COMPUTED_VALUE"""),"Giannis Antetokounmpo") -> Giannis Antetokounmpo | K18: =IFERROR(__xludf.DUMMYFUNCTION("""COMPUTED_VALUE"""),61.0) -> 61 | L18: =IFERROR(__xludf.DUMMYFUNCTION("""COMPUTED_VALUE"""),"F,C") -> F,C | M18: =IFERROR(__xludf.DUMMYFUNCTION("""COMPUTED_VALUE"""),6.561425853867311) -> 6.5614259 | N18: =IFERROR(__xludf.DUMMYFUNCTION("""COMPUTED_VALUE"""),6.83742310901598) -> 6.8374231 | O18: =IFERROR(__xludf.DUMMYFUNCTION("""COMPUTED_VALUE"""),0.2759972551486687) -> 0.27599726 | P18: =IFERROR(__xludf.DUMMYFUNCTION("""COMPUTED_VALUE"""),31.87295) -> 31.87295 | Q18: =IFERROR(__xludf.DUMMYFUNCTION("""COMPUTED_VALUE"""),0.322951) -> 0.322951 | R18: =IFERROR(__xludf.DUMMYFUNCTION("""COMPUTED_VALUE"""),11.01738) -> 11.01738 | S18: =IFERROR(__xludf.DUMMYFUNCTION("""COMPUTED_VALUE"""),8.227213) -> 8.227213 | T18: =IFERROR(__xludf.DUMMYFUNCTION("""COMPUTED_VALUE"""),0.929508) -> 0.929508 | U18: =IFERROR(__xludf.DUMMYFUNCTION("""COMPUTED_VALUE"""),0.93) -> 0.93 | V18: =IFERROR(__xludf.DUMMYFUNCTION("""COMPUTED_VALUE"""),0.582004) -> 0.582004 | W18: =IFERROR(__xludf.DUMMYFUNCTION("""COMPUTED_VALUE"""),0.638995) -> 0.638995 | X18: =IFERROR(__xludf.DUMMYFUNCTION("""COMPUTED_VALUE"""),2.861639) -> 2.861639 | Y18: =IFERROR(__xludf.DUMMYFUNCTION("""COMPUTED_VALUE"""),2.5787154617445047) -> 2.5787155 | Z18: =IFERROR(__xludf.DUMMYFUNCTION("""COMPUTED_VALUE"""),-1.397177225296222) -> -1.3971772 | AA18: =IFERROR(__xludf.DUMMYFUNCTION("""COMPUTED_VALUE"""),1.9825376202128466) -> 1.9825376 | AB18: =IFERROR(__xludf.DUMMYFUNCTION("""COMPUTED_VALUE"""),2.144732356031291) -> 2.1447324 | AC18: =IFERROR(__xludf.DUMMYFUNCTION("""COMPUTED_VALUE"""),-0.3525027030701494) -> -0.3525027 | AD18: =IFERROR(__xludf.DUMMYFUNCTION("""COMPUTED_VALUE"""),0.363194393212251) -> 0.36319439 | AE18: =IFERROR(__xludf.DUMMYFUNCTION("""COMPUTED_VALUE"""),1.5179232061814574) -> 1.5179232 | AF18: =IFERROR(__xludf.DUMMYFUNCTION("""COMPUTED_VALUE"""),-1.519645010763219) -> -1.519645 | AG18: =IFERROR(__xludf.DUMMYFUNCTION("""COMPUTED_VALUE"""),0.0) -> 0 | AJ18: 100 | AK18: {=if(AK$14=$J5,"-", countif(indirect(address(row($J$2)+ VLOOKUP(AK$14,$J$3:$J$8,1),COLUMN($K$4))):indirect(address(row($J$2)+ VLOOKUP(AK$14,$J$3:$J$8,1),COLUMN($S$2)))>indirect(address(row($J5),COLUMN($K$2))):indirect(address(row($J5),COLUMN($S$2))),TRUE()))} -> 0 | AL18: {=if(AL$14=$J5,"-", countif(indirect(address(row($J$2)+ VLOOKUP(AL$14,$J$3:$J$8,1),COLUMN($K$4))):indirect(address(row($J$2)+ VLOOKUP(AL$14,$J$3:$J$8,1),COLUMN($S$2)))>indirect(address(row($J5),COLUMN($K$2))):indirect(address(row($J5),COLUMN($S$2))),TRUE()))} -> 0 | AM18: {=if(AM$14=$J5,"-", countif(indirect(address(row($J$2)+ VLOOKUP(AM$14,$J$3:$J$8,1),COLUMN($K$4))):indirect(address(row($J$2)+ VLOOKUP(AM$14,$J$3:$J$8,1),COLUMN($S$2)))>indirect(address(row($J5),COLUMN($K$2))):indirect(address(row($J5),COLUMN($S$2))),TRUE()))} -> 0 | AN18: {=if(AN$14=$J5,"-", countif(indirect(address(row($J$2)+ VLOOKUP(AN$14,$J$3:$J$8,1),COLUMN($K$4))):indirect(address(row($J$2)+ VLOOKUP(AN$14,$J$3:$J$8,1),COLUMN($S$2)))>indirect(address(row($J5),COLUMN($K$2))):indirect(address(row($J5),COLUMN($S$2))),TRUE()))} -> 0 | AO18: {=if(AO$14=$J5,"-", countif(indirect(address(row($J$2)+ VLOOKUP(AO$14,$J$3:$J$8,1),COLUMN($K$4))):indirect(address(row($J$2)+ VLOOKUP(AO$14,$J$3:$J$8,1),COLUMN($S$2)))>indirect(address(row($J5),COLUMN($K$2))):indirect(address(row($J5),COLUMN($S$2))),TRUE()))} -> 0 | AP18: {=if(AP$14=$J5,"-", countif(indirect(address(row($J$2)+ VLOOKUP(AP$14,$J$3:$J$8,1),COLUMN($K$4))):indirect(address(row($J$2)+ VLOOKUP(AP$14,$J$3:$J$8,1),COLUMN($S$2)))>indirect(address(row($J5),COLUMN($K$2))):indirect(address(row($J5),COLUMN($S$2))),TRUE()))} -> 0 | AQ18: {=if(AQ$14=$J5,"-", countif(indirect(address(row($J$2)+ VLOOKUP(AQ$14,$J$3:$J$8,1),COLUMN($K$4))):indirect(address(row($J$2)+ VLOOKUP(AQ$14,$J$3:$J$8,1),COLUMN($S$2)))>indirect(address(row($J5),COLUMN($K$2))):indirect(address(row($J5),COLUMN($S$2))),TRUE()))} -> 0 | AR18: {=if(AR$14=$J5,"-", countif(indirect(address(row($J$2)+ VLOOKUP(AR$14,$J$3:$J$8,1),COLUMN($K$4))):indirect(address(row($J$2)+ VLOOKUP(AR$14,$J$3:$J$8,1),COLUMN($S$2)))>indirect(address(row($J5),COLUMN($K$2))):indirect(address(row($J5),COLUMN($S$2))),TRUE()))} -> 0 | ... AV18: {=if(AV$14=$J5,"-", countif(indirect(address(row($J$2)+ VLOOKUP(AV$14,$J$3:$J$8,1),COLUMN($K$4))):indirect(address(row($J$2)+ VLOOKUP(AV$14,$J$3:$J$8,1),COLUMN($S$2)))>indirect(address(row($J5),COLUMN($K$2))):indirect(address(row($J5),COLUMN($S$2))),TRUE()))} -> 0 | AW18: 3 | AX18: {=INDIRECT("Draft!F"&TEXT(VLOOKUP(TRUE,I3:J8,2,0)+2,"0"))} -> #N/A | AZ18: =IF($AX18="","", VLOOKUP($AX18,'Final Update'!$Q$21:$AE1009,Column(#REF!),False)) -> #N/A | BA18: =IF($AX18="","", VLOOKUP($AX18,'Final Update'!$Q$21:$AE1009,Column(H3),False)) -> #N/A | BB18: =IF($AX18="","", VLOOKUP($AX18,'Final Update'!$Q$21:$AE1009,Column(I3),False)) -> #N/A | BC18: =IF($AX18="","", VLOOKUP($AX18,'Final Update'!$Q$21:$AE1009,Column(J3),False)) -> #N/A | BD18: =IF($AX18="","", VLOOKUP($AX18,'Final Update'!$Q$21:$AE1009,Column(K3),False)) -> #N/A | BE18: =IF($AX18="","", VLOOKUP($AX18,'Final Update'!$Q$21:$AE1009,Column(#REF!),False)) -> #N/A | BF18: =IF($AX18="","", VLOOKUP($AX18,'Final Update'!$Q$21:$AE1009,Column(M3),False)) -> #N/A | BG18: =IF($AX18="","", VLOOKUP($AX18,'Final Update'!$Q$21:$AE1009,Column(#REF!),False)) -> #N/A | BH18: =IF($AX18="","", VLOOKUP($AX18,'Final Update'!$Q$21:$AE1009,Column(#REF!),False)) -> #N/A | BI18: =IF($AX18="","", VLOOKUP($AX18,'Final Update'!$Q$21:$AE1009,Column(C3),False)) -> #N/A | BJ18: {=COUNTIF(FIND(BK18,$BI$16:$BI$27),">0")} -> 0 | BK18: SF
A19: =VLOOKUP($F19,UpdateHashtag!$V$3:$Y$32,COLUMN(B$9),0) -> 4 | B19: =VLOOKUP($F19,UpdateHashtag!$V$3:$Y$32,COLUMN(#REF!),0) -> #REF! | C19: =VLOOKUP($F19,UpdateHashtag!$V$3:$Y$32,COLUMN(#REF!),0) -> #REF! | D19: =SUM(A19:C19) -> #REF! | F19: =VLOOKUP(J19,UpdateBBM!$C$2:E1009,3,0) -> ATL | G19: 6 | H19: =IFERROR(__xludf.DUMMYFUNCTION("""COMPUTED_VALUE"""),6.0) -> 6 | J19: =IFERROR(__xludf.DUMMYFUNCTION("""COMPUTED_VALUE"""),"Trae Young") -> Trae Young | K19: =IFERROR(__xludf.DUMMYFUNCTION("""COMPUTED_VALUE"""),77.0) -> 77 | L19: =IFERROR(__xludf.DUMMYFUNCTION("""COMPUTED_VALUE"""),"G") -> G | M19: =IFERROR(__xludf.DUMMYFUNCTION("""COMPUTED_VALUE"""),5.693887490632928) -> 5.6938875 | N19: =IFERROR(__xludf.DUMMYFUNCTION("""COMPUTED_VALUE"""),6.324092755769335) -> 6.3240928 | O19: =IFERROR(__xludf.DUMMYFUNCTION("""COMPUTED_VALUE"""),0.6302052651364072) -> 0.63020527 | P19: =IFERROR(__xludf.DUMMYFUNCTION("""COMPUTED_VALUE"""),25.69468) -> 25.69468 | Q19: =IFERROR(__xludf.DUMMYFUNCTION("""COMPUTED_VALUE"""),3.18987) -> 3.18987 | R19: =IFERROR(__xludf.DUMMYFUNCTION("""COMPUTED_VALUE"""),2.885974) -> 2.885974 | S19: =IFERROR(__xludf.DUMMYFUNCTION("""COMPUTED_VALUE"""),11.73519) -> 11.73519 | T19: =IFERROR(__xludf.DUMMYFUNCTION("""COMPUTED_VALUE"""),1.171558) -> 1.171558 | U19: =IFERROR(__xludf.DUMMYFUNCTION("""COMPUTED_VALUE"""),0.077922) -> 0.077922 | V19: =IFERROR(__xludf.DUMMYFUNCTION("""COMPUTED_VALUE"""),0.419483) -> 0.419483 | W19: =IFERROR(__xludf.DUMMYFUNCTION("""COMPUTED_VALUE"""),0.883994) -> 0.883994 | X19: =IFERROR(__xludf.DUMMYFUNCTION("""COMPUTED_VALUE"""),4.29) -> 4.29 | Y19: =IFERROR(__xludf.DUMMYFUNCTION("""COMPUTED_VALUE"""),1.494783635658165) -> 1.4947836 | Z19: =IFERROR(__xludf.DUMMYFUNCTION("""COMPUTED_VALUE"""),1.371789014081673) -> 1.371789 | AA19: =IFERROR(__xludf.DUMMYFUNCTION("""COMPUTED_VALUE"""),-1.3135571258500867) -> -1.3135571 | AB19: =IFERROR(__xludf.DUMMYFUNCTION("""COMPUTED_VALUE"""),3.8584299759654193) -> 3.85843 | AC19: =IFERROR(__xludf.DUMMYFUNCTION("""COMPUTED_VALUE"""),0.38507932768750724) -> 0.38507933 | AD19: =IFERROR(__xludf.DUMMYFUNCTION("""COMPUTED_VALUE"""),-1.1858767858564676) -> -1.1858768 | AE19: =IFERROR(__xludf.DUMMYFUNCTION("""COMPUTED_VALUE"""),-0.9539049358971645) -> -0.95390494 | AF19: =IFERROR(__xludf.DUMMYFUNCTION("""COMPUTED_VALUE"""),1.3537925241302025) -> 1.3537925 | AG19: =IFERROR(__xludf.DUMMYFUNCTION("""COMPUTED_VALUE"""),0.0) -> 0 | AJ19: 100 | AK19: {=if(AK$14=$J6,"-", countif(indirect(address(row($J$2)+ VLOOKUP(AK$14,$J$3:$J$8,1),COLUMN($K$4))):indirect(address(row($J$2)+ VLOOKUP(AK$14,$J$3:$J$8,1),COLUMN($S$2)))>indirect(address(row($J6),COLUMN($K$2))):indirect(address(row($J6),COLUMN($S$2))),TRUE()))} -> 0 | AL19: {=if(AL$14=$J6,"-", countif(indirect(address(row($J$2)+ VLOOKUP(AL$14,$J$3:$J$8,1),COLUMN($K$4))):indirect(address(row($J$2)+ VLOOKUP(AL$14,$J$3:$J$8,1),COLUMN($S$2)))>indirect(address(row($J6),COLUMN($K$2))):indirect(address(row($J6),COLUMN($S$2))),TRUE()))} -> 0 | AM19: {=if(AM$14=$J6,"-", countif(indirect(address(row($J$2)+ VLOOKUP(AM$14,$J$3:$J$8,1),COLUMN($K$4))):indirect(address(row($J$2)+ VLOOKUP(AM$14,$J$3:$J$8,1),COLUMN($S$2)))>indirect(address(row($J6),COLUMN($K$2))):indirect(address(row($J6),COLUMN($S$2))),TRUE()))} -> 0 | AN19: {=if(AN$14=$J6,"-", countif(indirect(address(row($J$2)+ VLOOKUP(AN$14,$J$3:$J$8,1),COLUMN($K$4))):indirect(address(row($J$2)+ VLOOKUP(AN$14,$J$3:$J$8,1),COLUMN($S$2)))>indirect(address(row($J6),COLUMN($K$2))):indirect(address(row($J6),COLUMN($S$2))),TRUE()))} -> 0 | AO19: {=if(AO$14=$J6,"-", countif(indirect(address(row($J$2)+ VLOOKUP(AO$14,$J$3:$J$8,1),COLUMN($K$4))):indirect(address(row($J$2)+ VLOOKUP(AO$14,$J$3:$J$8,1),COLUMN($S$2)))>indirect(address(row($J6),COLUMN($K$2))):indirect(address(row($J6),COLUMN($S$2))),TRUE()))} -> 0 | AP19: {=if(AP$14=$J6,"-", countif(indirect(address(row($J$2)+ VLOOKUP(AP$14,$J$3:$J$8,1),COLUMN($K$4))):indirect(address(row($J$2)+ VLOOKUP(AP$14,$J$3:$J$8,1),COLUMN($S$2)))>indirect(address(row($J6),COLUMN($K$2))):indirect(address(row($J6),COLUMN($S$2))),TRUE()))} -> 0 | AQ19: {=if(AQ$14=$J6,"-", countif(indirect(address(row($J$2)+ VLOOKUP(AQ$14,$J$3:$J$8,1),COLUMN($K$4))):indirect(address(row($J$2)+ VLOOKUP(AQ$14,$J$3:$J$8,1),COLUMN($S$2)))>indirect(address(row($J6),COLUMN($K$2))):indirect(address(row($J6),COLUMN($S$2))),TRUE()))} -> 0 | AR19: {=if(AR$14=$J6,"-", countif(indirect(address(row($J$2)+ VLOOKUP(AR$14,$J$3:$J$8,1),COLUMN($K$4))):indirect(address(row($J$2)+ VLOOKUP(AR$14,$J$3:$J$8,1),COLUMN($S$2)))>indirect(address(row($J6),COLUMN($K$2))):indirect(address(row($J6),COLUMN($S$2))),TRUE()))} -> 0 | ... AV19: {=if(AV$14=$J6,"-", countif(indirect(address(row($J$2)+ VLOOKUP(AV$14,$J$3:$J$8,1),COLUMN($K$4))):indirect(address(row($J$2)+ VLOOKUP(AV$14,$J$3:$J$8,1),COLUMN($S$2)))>indirect(address(row($J6),COLUMN($K$2))):indirect(address(row($J6),COLUMN($S$2))),TRUE()))} -> 0 | AW19: 4 | AX19: {=INDIRECT("Draft!G"&TEXT(15-VLOOKUP(TRUE,I3:J8,2,0),"0"))} -> #N/A | AZ19: =IF($AX19="","", VLOOKUP($AX19,'Final Update'!$Q$21:$AE1009,Column(#REF!),False)) -> #N/A | BA19: =IF($AX19="","", VLOOKUP($AX19,'Final Update'!$Q$21:$AE1009,Column(#REF!),False)) -> #N/A | BB19: =IF($AX19="","", VLOOKUP($AX19,'Final Update'!$Q$21:$AE1009,Column(I4),False)) -> #N/A | BC19: =IF($AX19="","", VLOOKUP($AX19,'Final Update'!$Q$21:$AE1009,Column(J4),False)) -> #N/A | BD19: =IF($AX19="","", VLOOKUP($AX19,'Final Update'!$Q$21:$AE1009,Column(K4),False)) -> #N/A | BE19: =IF($AX19="","", VLOOKUP($AX19,'Final Update'!$Q$21:$AE1009,Column(L4),False)) -> #N/A | BF19: =IF($AX19="","", VLOOKUP($AX19,'Final Update'!$Q$21:$AE1009,Column(M4),False)) -> #N/A | BG19: =IF($AX19="","", VLOOKUP($AX19,'Final Update'!$Q$21:$AE1009,Column(#REF!),False)) -> #N/A | BH19: =IF($AX19="","", VLOOKUP($AX19,'Final Update'!$Q$21:$AE1009,Column(O3),False)) -> #N/A | BI19: =IF($AX19="","", VLOOKUP($AX19,'Final Update'!$Q$21:$AE1009,Column(C4),False)) -> #N/A | BJ19: {=COUNTIF(FIND(BK19,$BI$16:$BI$27),">0")} -> 0 | BK19: PF
A20: =VLOOKUP($F20,UpdateHashtag!$V$3:$Y$32,COLUMN(B$9),0) -> #N/A | B20: =VLOOKUP($F20,UpdateHashtag!$V$3:$Y$32,COLUMN(#REF!),0) -> #REF! | C20: =VLOOKUP($F20,UpdateHashtag!$V$3:$Y$32,COLUMN(#REF!),0) -> #REF! | D20: =SUM(A20:C20) -> #N/A | F20: =VLOOKUP(J20,UpdateBBM!$C$2:E1009,3,0) -> GSW | G20: 7 | H20: =IFERROR(__xludf.DUMMYFUNCTION("""COMPUTED_VALUE"""),7.0) -> 7 | J20: =IFERROR(__xludf.DUMMYFUNCTION("""COMPUTED_VALUE"""),"Stephen Curry") -> Stephen Curry | K20: =IFERROR(__xludf.DUMMYFUNCTION("""COMPUTED_VALUE"""),68.0) -> 68 | L20: =IFERROR(__xludf.DUMMYFUNCTION("""COMPUTED_VALUE"""),"G") -> G | M20: =IFERROR(__xludf.DUMMYFUNCTION("""COMPUTED_VALUE"""),5.645798593164934) -> 5.6457986 | N20: =IFERROR(__xludf.DUMMYFUNCTION("""COMPUTED_VALUE"""),5.903191980581784) -> 5.903192 | O20: =IFERROR(__xludf.DUMMYFUNCTION("""COMPUTED_VALUE"""),0.25739338741685014) -> 0.25739339 | P20: =IFERROR(__xludf.DUMMYFUNCTION("""COMPUTED_VALUE"""),25.34912) -> 25.34912 | Q20: =IFERROR(__xludf.DUMMYFUNCTION("""COMPUTED_VALUE"""),4.625882) -> 4.625882 | R20: =IFERROR(__xludf.DUMMYFUNCTION("""COMPUTED_VALUE"""),4.492059) -> 4.492059 | S20: =IFERROR(__xludf.DUMMYFUNCTION("""COMPUTED_VALUE"""),5.887794) -> 5.887794 | T20: =IFERROR(__xludf.DUMMYFUNCTION("""COMPUTED_VALUE"""),1.020882) -> 1.020882 | U20: =IFERROR(__xludf.DUMMYFUNCTION("""COMPUTED_VALUE"""),0.407647) -> 0.407647 | V20: =IFERROR(__xludf.DUMMYFUNCTION("""COMPUTED_VALUE"""),0.453424) -> 0.453424 | W20: =IFERROR(__xludf.DUMMYFUNCTION("""COMPUTED_VALUE"""),0.920009) -> 0.920009 | X20: =IFERROR(__xludf.DUMMYFUNCTION("""COMPUTED_VALUE"""),2.786618) -> 2.786618 | Y20: =IFERROR(__xludf.DUMMYFUNCTION("""COMPUTED_VALUE"""),1.4341576866752945) -> 1.4341577 | Z20: =IFERROR(__xludf.DUMMYFUNCTION("""COMPUTED_VALUE"""),2.758737423625692) -> 2.7587374 | AA20: =IFERROR(__xludf.DUMMYFUNCTION("""COMPUTED_VALUE"""),-0.662524779140245) -> -0.66252478 | AB20: =IFERROR(__xludf.DUMMYFUNCTION("""COMPUTED_VALUE"""),1.0018922597796107) -> 1.0018923 | AC20: =IFERROR(__xludf.DUMMYFUNCTION("""COMPUTED_VALUE"""),-0.07406510555537915) -> -0.074065106 | AD20: =IFERROR(__xludf.DUMMYFUNCTION("""COMPUTED_VALUE"""),-0.5864392994779517) -> -0.5864393 | AE20: =IFERROR(__xludf.DUMMYFUNCTION("""COMPUTED_VALUE"""),-0.5687843301986628) -> -0.56878433 | AF20: =IFERROR(__xludf.DUMMYFUNCTION("""COMPUTED_VALUE"""),1.9376933457331804) -> 1.9376933 | AG20: =IFERROR(__xludf.DUMMYFUNCTION("""COMPUTED_VALUE"""),0.0) -> 0 | AJ20: 100 | AK20: {=if(AK$14=$F4,"-", countif(indirect(address(row($J$2)+ VLOOKUP(AK$14,$J$3:$J$8,1),COLUMN($K$4))):indirect(address(row($J$2)+ VLOOKUP(AK$14,$J$3:$J$8,1),COLUMN($S$2)))>indirect(address(row($F4),COLUMN($K$2))):indirect(address(row($F4),COLUMN($S$2))),TRUE()))} -> 0 | AL20: {=if(AL$14=$F4,"-", countif(indirect(address(row($J$2)+ VLOOKUP(AL$14,$J$3:$J$8,1),COLUMN($K$4))):indirect(address(row($J$2)+ VLOOKUP(AL$14,$J$3:$J$8,1),COLUMN($S$2)))>indirect(address(row($F4),COLUMN($K$2))):indirect(address(row($F4),COLUMN($S$2))),TRUE()))} -> 0 | AM20: {=if(AM$14=$F4,"-", countif(indirect(address(row($J$2)+ VLOOKUP(AM$14,$J$3:$J$8,1),COLUMN($K$4))):indirect(address(row($J$2)+ VLOOKUP(AM$14,$J$3:$J$8,1),COLUMN($S$2)))>indirect(address(row($F4),COLUMN($K$2))):indirect(address(row($F4),COLUMN($S$2))),TRUE()))} -> 0 | AN20: {=if(AN$14=$F4,"-", countif(indirect(address(row($J$2)+ VLOOKUP(AN$14,$J$3:$J$8,1),COLUMN($K$4))):indirect(address(row($J$2)+ VLOOKUP(AN$14,$J$3:$J$8,1),COLUMN($S$2)))>indirect(address(row($F4),COLUMN($K$2))):indirect(address(row($F4),COLUMN($S$2))),TRUE()))} -> 0 | AO20: {=if(AO$14=$F4,"-", countif(indirect(address(row($J$2)+ VLOOKUP(AO$14,$J$3:$J$8,1),COLUMN($K$4))):indirect(address(row($J$2)+ VLOOKUP(AO$14,$J$3:$J$8,1),COLUMN($S$2)))>indirect(address(row($F4),COLUMN($K$2))):indirect(address(row($F4),COLUMN($S$2))),TRUE()))} -> 0 | AP20: {=if(AP$14=$F4,"-", countif(indirect(address(row($J$2)+ VLOOKUP(AP$14,$J$3:$J$8,1),COLUMN($K$4))):indirect(address(row($J$2)+ VLOOKUP(AP$14,$J$3:$J$8,1),COLUMN($S$2)))>indirect(address(row($F4),COLUMN($K$2))):indirect(address(row($F4),COLUMN($S$2))),TRUE()))} -> 0 | AQ20: {=if(AQ$14=$F4,"-", countif(indirect(address(row($J$2)+ VLOOKUP(AQ$14,$J$3:$J$8,1),COLUMN($K$4))):indirect(address(row($J$2)+ VLOOKUP(AQ$14,$J$3:$J$8,1),COLUMN($S$2)))>indirect(address(row($F4),COLUMN($K$2))):indirect(address(row($F4),COLUMN($S$2))),TRUE()))} -> 0 | AR20: {=if(AR$14=$F4,"-", countif(indirect(address(row($J$2)+ VLOOKUP(AR$14,$J$3:$J$8,1),COLUMN($K$4))):indirect(address(row($J$2)+ VLOOKUP(AR$14,$J$3:$J$8,1),COLUMN($S$2)))>indirect(address(row($F4),COLUMN($K$2))):indirect(address(row($F4),COLUMN($S$2))),TRUE()))} -> 0 | ... AV20: {=if(AV$14=$F4,"-", countif(indirect(address(row($J$2)+ VLOOKUP(AV$14,$J$3:$J$8,1),COLUMN($K$4))):indirect(address(row($J$2)+ VLOOKUP(AV$14,$J$3:$J$8,1),COLUMN($S$2)))>indirect(address(row($F4),COLUMN($K$2))):indirect(address(row($F4),COLUMN($S$2))),TRUE()))} -> 0 | AW20: 5 | AX20: {=INDIRECT("Draft!H"&TEXT(VLOOKUP(TRUE,I3:J8,2,0)+2,"0"))} -> #N/A | AZ20: =IF($AX20="","", VLOOKUP($AX20,'Final Update'!$Q$21:$AE1009,Column(F6),False)) -> #N/A | BA20: =IF($AX20="","", VLOOKUP($AX20,'Final Update'!$Q$21:$AE1009,Column(#REF!),False)) -> #N/A | BB20: =IF($AX20="","", VLOOKUP($AX20,'Final Update'!$Q$21:$AE1009,Column(I5),False)) -> #N/A | BC20: =IF($AX20="","", VLOOKUP($AX20,'Final Update'!$Q$21:$AE1009,Column(J5),False)) -> #N/A | BD20: =IF($AX20="","", VLOOKUP($AX20,'Final Update'!$Q$21:$AE1009,Column(K5),False)) -> #N/A | BE20: =IF($AX20="","", VLOOKUP($AX20,'Final Update'!$Q$21:$AE1009,Column(L5),False)) -> #N/A | BF20: =IF($AX20="","", VLOOKUP($AX20,'Final Update'!$Q$21:$AE1009,Column(M5),False)) -> #N/A | BG20: =IF($AX20="","", VLOOKUP($AX20,'Final Update'!$Q$21:$AE1009,Column(#REF!),False)) -> #N/A | BH20: =IF($AX20="","", VLOOKUP($AX20,'Final Update'!$Q$21:$AE1009,Column(G5),False)) -> #N/A | BI20: =IF($AX20="","", VLOOKUP($AX20,'Final Update'!$Q$21:$AE1009,Column(C5),False)) -> #N/A | BJ20: {=COUNTIF(FIND(BK20,$BI$16:$BI$27),">0")} -> 0 | BK20: C
A21: =VLOOKUP($F21,UpdateHashtag!$V$3:$Y$32,COLUMN(B$9),0) -> 4 | B21: =VLOOKUP($F21,UpdateHashtag!$V$3:$Y$32,COLUMN(#REF!),0) -> #REF! | C21: =VLOOKUP($F21,UpdateHashtag!$V$3:$Y$32,COLUMN(#REF!),0) -> #REF! | D21: =SUM(A21:C21) -> #REF! | F21: =VLOOKUP(J21,UpdateBBM!$C$2:E1009,3,0) -> LAC | G21: 8 | H21: =IFERROR(__xludf.DUMMYFUNCTION("""COMPUTED_VALUE"""),8.0) -> 8 | J21: =IFERROR(__xludf.DUMMYFUNCTION("""COMPUTED_VALUE"""),"James Harden") -> James Harden | K21: =IFERROR(__xludf.DUMMYFUNCTION("""COMPUTED_VALUE"""),73.0) -> 73 | L21: =IFERROR(__xludf.DUMMYFUNCTION("""COMPUTED_VALUE"""),"G") -> G | M21: =IFERROR(__xludf.DUMMYFUNCTION("""COMPUTED_VALUE"""),5.187333301395962) -> 5.1873333 | N21: =IFERROR(__xludf.DUMMYFUNCTION("""COMPUTED_VALUE"""),5.630668653098455) -> 5.6306687 | O21: =IFERROR(__xludf.DUMMYFUNCTION("""COMPUTED_VALUE"""),0.44333535170249316) -> 0.44333535 | P21: =IFERROR(__xludf.DUMMYFUNCTION("""COMPUTED_VALUE"""),23.15562) -> 23.15562 | Q21: =IFERROR(__xludf.DUMMYFUNCTION("""COMPUTED_VALUE"""),3.018356) -> 3.018356 | R21: =IFERROR(__xludf.DUMMYFUNCTION("""COMPUTED_VALUE"""),5.304658) -> 5.304658 | S21: =IFERROR(__xludf.DUMMYFUNCTION("""COMPUTED_VALUE"""),8.091781) -> 8.091781 | T21: =IFERROR(__xludf.DUMMYFUNCTION("""COMPUTED_VALUE"""),1.202329) -> 1.202329 | U21: =IFERROR(__xludf.DUMMYFUNCTION("""COMPUTED_VALUE"""),0.712192) -> 0.712192 | V21: =IFERROR(__xludf.DUMMYFUNCTION("""COMPUTED_VALUE"""),0.443798) -> 0.443798 | W21: =IFERROR(__xludf.DUMMYFUNCTION("""COMPUTED_VALUE"""),0.872994) -> 0.872994 | X21: =IFERROR(__xludf.DUMMYFUNCTION("""COMPUTED_VALUE"""),3.536438) -> 3.536438 | Y21: =IFERROR(__xludf.DUMMYFUNCTION("""COMPUTED_VALUE"""),1.0493243173792963) -> 1.0493243 | Z21: =IFERROR(__xludf.DUMMYFUNCTION("""COMPUTED_VALUE"""),1.206135057489017) -> 1.2061351 | AA21: =IFERROR(__xludf.DUMMYFUNCTION("""COMPUTED_VALUE"""),-0.3331348440471021) -> -0.33313484 | AB21: =IFERROR(__xludf.DUMMYFUNCTION("""COMPUTED_VALUE"""),2.07857186066233) -> 2.0785719 | AC21: =IFERROR(__xludf.DUMMYFUNCTION("""COMPUTED_VALUE"""),0.47884564319440154) -> 0.47884564 | AD21: =IFERROR(__xludf.DUMMYFUNCTION("""COMPUTED_VALUE"""),-0.032778857324201646) -> -0.032778857 | AE21: =IFERROR(__xludf.DUMMYFUNCTION("""COMPUTED_VALUE"""),-0.6850393076828555) -> -0.68503931 | AF21: =IFERROR(__xludf.DUMMYFUNCTION("""COMPUTED_VALUE"""),1.1837054757447134) -> 1.1837055 | AG21: =IFERROR(__xludf.DUMMYFUNCTION("""COMPUTED_VALUE"""),0.0) -> 0 | AJ21: 100 | AK21: {=if(AK$14=#REF!,"-", countif(indirect(address(row($J$2)+ VLOOKUP(AK$14,$J$3:$J$8,1),COLUMN($K$4))):indirect(address(row($J$2)+ VLOOKUP(AK$14,$J$3:$J$8,1),COLUMN($S$2)))>indirect(address(row(#REF!),COLUMN($K$2))):indirect(address(row(#REF!),COLUMN($S$2))),TRUE()))} -> #REF! | AL21: {=if(AL$14=#REF!,"-", countif(indirect(address(row($J$2)+ VLOOKUP(AL$14,$J$3:$J$8,1),COLUMN($K$4))):indirect(address(row($J$2)+ VLOOKUP(AL$14,$J$3:$J$8,1),COLUMN($S$2)))>indirect(address(row(#REF!),COLUMN($K$2))):indirect(address(row(#REF!),COLUMN($S$2))),TRUE()))} -> #REF! | AM21: {=if(AM$14=#REF!,"-", countif(indirect(address(row($J$2)+ VLOOKUP(AM$14,$J$3:$J$8,1),COLUMN($K$4))):indirect(address(row($J$2)+ VLOOKUP(AM$14,$J$3:$J$8,1),COLUMN($S$2)))>indirect(address(row(#REF!),COLUMN($K$2))):indirect(address(row(#REF!),COLUMN($S$2))),TRUE()))} -> #REF! | AN21: {=if(AN$14=#REF!,"-", countif(indirect(address(row($J$2)+ VLOOKUP(AN$14,$J$3:$J$8,1),COLUMN($K$4))):indirect(address(row($J$2)+ VLOOKUP(AN$14,$J$3:$J$8,1),COLUMN($S$2)))>indirect(address(row(#REF!),COLUMN($K$2))):indirect(address(row(#REF!),COLUMN($S$2))),TRUE()))} -> #REF! | AO21: {=if(AO$14=#REF!,"-", countif(indirect(address(row($J$2)+ VLOOKUP(AO$14,$J$3:$J$8,1),COLUMN($K$4))):indirect(address(row($J$2)+ VLOOKUP(AO$14,$J$3:$J$8,1),COLUMN($S$2)))>indirect(address(row(#REF!),COLUMN($K$2))):indirect(address(row(#REF!),COLUMN($S$2))),TRUE()))} -> #REF! | AP21: {=if(AP$14=#REF!,"-", countif(indirect(address(row($J$2)+ VLOOKUP(AP$14,$J$3:$J$8,1),COLUMN($K$4))):indirect(address(row($J$2)+ VLOOKUP(AP$14,$J$3:$J$8,1),COLUMN($S$2)))>indirect(address(row(#REF!),COLUMN($K$2))):indirect(address(row(#REF!),COLUMN($S$2))),TRUE()))} -> #REF! | AQ21: {=if(AQ$14=#REF!,"-", countif(indirect(address(row($J$2)+ VLOOKUP(AQ$14,$J$3:$J$8,1),COLUMN($K$4))):indirect(address(row($J$2)+ VLOOKUP(AQ$14,$J$3:$J$8,1),COLUMN($S$2)))>indirect(address(row(#REF!),COLUMN($K$2))):indirect(address(row(#REF!),COLUMN($S$2))),TRUE()))} -> #REF! | AR21: {=if(AR$14=#REF!,"-", countif(indirect(address(row($J$2)+ VLOOKUP(AR$14,$J$3:$J$8,1),COLUMN($K$4))):indirect(address(row($J$2)+ VLOOKUP(AR$14,$J$3:$J$8,1),COLUMN($S$2)))>indirect(address(row(#REF!),COLUMN($K$2))):indirect(address(row(#REF!),COLUMN($S$2))),TRUE()))} -> #REF! | ... AV21: {=if(AV$14=#REF!,"-", countif(indirect(address(row($J$2)+ VLOOKUP(AV$14,$J$3:$J$8,1),COLUMN($K$4))):indirect(address(row($J$2)+ VLOOKUP(AV$14,$J$3:$J$8,1),COLUMN($S$2)))>indirect(address(row(#REF!),COLUMN($K$2))):indirect(address(row(#REF!),COLUMN($S$2))),TRUE()))} -> #REF! | AW21: 6 | AX21: {=INDIRECT("Draft!I"&TEXT(15-VLOOKUP(TRUE,I3:J8,2,0),"0"))} -> #N/A | AZ21: =IF($AX21="","", VLOOKUP($AX21,'Final Update'!$Q$21:$AE1009,Column(#REF!),False)) -> #N/A | BA21: =IF($AX21="","", VLOOKUP($AX21,'Final Update'!$Q$21:$AE1009,Column(#REF!),False)) -> #N/A | BB21: =IF($AX21="","", VLOOKUP($AX21,'Final Update'!$Q$21:$AE1009,Column(I6),False)) -> #N/A | BC21: =IF($AX21="","", VLOOKUP($AX21,'Final Update'!$Q$21:$AE1009,Column(J6),False)) -> #N/A | BD21: =IF($AX21="","", VLOOKUP($AX21,'Final Update'!$Q$21:$AE1009,Column(K6),False)) -> #N/A | BE21: =IF($AX21="","", VLOOKUP($AX21,'Final Update'!$Q$21:$AE1009,Column(L6),False)) -> #N/A | BF21: =IF($AX21="","", VLOOKUP($AX21,'Final Update'!$Q$21:$AE1009,Column(M6),False)) -> #N/A | BG21: =IF($AX21="","", VLOOKUP($AX21,'Final Update'!$Q$21:$AE1009,Column(#REF!),False)) -> #N/A | BH21: =IF($AX21="","", VLOOKUP($AX21,'Final Update'!$Q$21:$AE1009,Column(G6),False)) -> #N/A | BI21: =IF($AX21="","", VLOOKUP($AX21,'Final Update'!$Q$21:$AE1009,Column(C6),False)) -> #N/A
A22: =VLOOKUP($F22,UpdateHashtag!$V$3:$Y$32,COLUMN(B$9),0) -> 4 | B22: =VLOOKUP($F22,UpdateHashtag!$V$3:$Y$32,COLUMN(#REF!),0) -> #REF! | C22: =VLOOKUP($F22,UpdateHashtag!$V$3:$Y$32,COLUMN(#REF!),0) -> #REF! | D22: =SUM(A22:C22) -> #REF! | F22: =VLOOKUP(J22,UpdateBBM!$C$2:E1009,3,0) -> DAL | G22: 9 | H22: =IFERROR(__xludf.DUMMYFUNCTION("""COMPUTED_VALUE"""),9.0) -> 9 | J22: =IFERROR(__xludf.DUMMYFUNCTION("""COMPUTED_VALUE"""),"Anthony Davis") -> Anthony Davis | K22: =IFERROR(__xludf.DUMMYFUNCTION("""COMPUTED_VALUE"""),62.0) -> 62 | L22: =IFERROR(__xludf.DUMMYFUNCTION("""COMPUTED_VALUE"""),"F,C") -> F,C | M22: =IFERROR(__xludf.DUMMYFUNCTION("""COMPUTED_VALUE"""),5.142238350012554) -> 5.1422384 | N22: =IFERROR(__xludf.DUMMYFUNCTION("""COMPUTED_VALUE"""),5.400510338132858) -> 5.4005103 | O22: =IFERROR(__xludf.DUMMYFUNCTION("""COMPUTED_VALUE"""),0.2582719881203044) -> 0.25827199 | P22: =IFERROR(__xludf.DUMMYFUNCTION("""COMPUTED_VALUE"""),22.60968) -> 22.60968 | Q22: =IFERROR(__xludf.DUMMYFUNCTION("""COMPUTED_VALUE"""),0.879677) -> 0.879677 | R22: =IFERROR(__xludf.DUMMYFUNCTION("""COMPUTED_VALUE"""),10.01581) -> 10.01581 | S22: =IFERROR(__xludf.DUMMYFUNCTION("""COMPUTED_VALUE"""),4.149355) -> 4.149355 | T22: =IFERROR(__xludf.DUMMYFUNCTION("""COMPUTED_VALUE"""),1.227258) -> 1.227258 | U22: =IFERROR(__xludf.DUMMYFUNCTION("""COMPUTED_VALUE"""),2.074677) -> 2.074677 | V22: =IFERROR(__xludf.DUMMYFUNCTION("""COMPUTED_VALUE"""),0.494364) -> 0.494364 | W22: =IFERROR(__xludf.DUMMYFUNCTION("""COMPUTED_VALUE"""),0.766012) -> 0.766012 | X22: =IFERROR(__xludf.DUMMYFUNCTION("""COMPUTED_VALUE"""),2.790161) -> 2.790161 | Y22: =IFERROR(__xludf.DUMMYFUNCTION("""COMPUTED_VALUE"""),0.9535431778153772) -> 0.95354318 | Z22: =IFERROR(__xludf.DUMMYFUNCTION("""COMPUTED_VALUE"""),-0.8594726376940267) -> -0.85947264 | AA22: =IFERROR(__xludf.DUMMYFUNCTION("""COMPUTED_VALUE"""),1.576547608791175) -> 1.5765476 | AB22: =IFERROR(__xludf.DUMMYFUNCTION("""COMPUTED_VALUE"""),0.15263960598493978) -> 0.15263961 | AC22: =IFERROR(__xludf.DUMMYFUNCTION("""COMPUTED_VALUE"""),0.5548100408178579) -> 0.55481004 | AD22: =IFERROR(__xludf.DUMMYFUNCTION("""COMPUTED_VALUE"""),2.4442082793152173) -> 2.4442083 | AE22: =IFERROR(__xludf.DUMMYFUNCTION("""COMPUTED_VALUE"""),-0.012156836884575905) -> -0.012156837 | AF22: =IFERROR(__xludf.DUMMYFUNCTION("""COMPUTED_VALUE"""),-0.2690815377071333) -> -0.26908154 | AG22: =IFERROR(__xludf.DUMMYFUNCTION("""COMPUTED_VALUE"""),0.0) -> 0 | AJ22: 100 | AK22: {=if(AK$14=#REF!,"-", countif(indirect(address(row($J$2)+ VLOOKUP(AK$14,$J$3:$J$8,1),COLUMN($K$4))):indirect(address(row($J$2)+ VLOOKUP(AK$14,$J$3:$J$8,1),COLUMN($S$2)))>indirect(address(row(#REF!),COLUMN($K$2))):indirect(address(row(#REF!),COLUMN($S$2))),TRUE()))} -> #REF! | AL22: {=if(AL$14=#REF!,"-", countif(indirect(address(row($J$2)+ VLOOKUP(AL$14,$J$3:$J$8,1),COLUMN($K$4))):indirect(address(row($J$2)+ VLOOKUP(AL$14,$J$3:$J$8,1),COLUMN($S$2)))>indirect(address(row(#REF!),COLUMN($K$2))):indirect(address(row(#REF!),COLUMN($S$2))),TRUE()))} -> #REF! | AM22: {=if(AM$14=#REF!,"-", countif(indirect(address(row($J$2)+ VLOOKUP(AM$14,$J$3:$J$8,1),COLUMN($K$4))):indirect(address(row($J$2)+ VLOOKUP(AM$14,$J$3:$J$8,1),COLUMN($S$2)))>indirect(address(row(#REF!),COLUMN($K$2))):indirect(address(row(#REF!),COLUMN($S$2))),TRUE()))} -> #REF! | AN22: {=if(AN$14=#REF!,"-", countif(indirect(address(row($J$2)+ VLOOKUP(AN$14,$J$3:$J$8,1),COLUMN($K$4))):indirect(address(row($J$2)+ VLOOKUP(AN$14,$J$3:$J$8,1),COLUMN($S$2)))>indirect(address(row(#REF!),COLUMN($K$2))):indirect(address(row(#REF!),COLUMN($S$2))),TRUE()))} -> #REF! | AO22: {=if(AO$14=#REF!,"-", countif(indirect(address(row($J$2)+ VLOOKUP(AO$14,$J$3:$J$8,1),COLUMN($K$4))):indirect(address(row($J$2)+ VLOOKUP(AO$14,$J$3:$J$8,1),COLUMN($S$2)))>indirect(address(row(#REF!),COLUMN($K$2))):indirect(address(row(#REF!),COLUMN($S$2))),TRUE()))} -> #REF! | AP22: {=if(AP$14=#REF!,"-", countif(indirect(address(row($J$2)+ VLOOKUP(AP$14,$J$3:$J$8,1),COLUMN($K$4))):indirect(address(row($J$2)+ VLOOKUP(AP$14,$J$3:$J$8,1),COLUMN($S$2)))>indirect(address(row(#REF!),COLUMN($K$2))):indirect(address(row(#REF!),COLUMN($S$2))),TRUE()))} -> #REF! | AQ22: {=if(AQ$14=#REF!,"-", countif(indirect(address(row($J$2)+ VLOOKUP(AQ$14,$J$3:$J$8,1),COLUMN($K$4))):indirect(address(row($J$2)+ VLOOKUP(AQ$14,$J$3:$J$8,1),COLUMN($S$2)))>indirect(address(row(#REF!),COLUMN($K$2))):indirect(address(row(#REF!),COLUMN($S$2))),TRUE()))} -> #REF! | AR22: {=if(AR$14=#REF!,"-", countif(indirect(address(row($J$2)+ VLOOKUP(AR$14,$J$3:$J$8,1),COLUMN($K$4))):indirect(address(row($J$2)+ VLOOKUP(AR$14,$J$3:$J$8,1),COLUMN($S$2)))>indirect(address(row(#REF!),COLUMN($K$2))):indirect(address(row(#REF!),COLUMN($S$2))),TRUE()))} -> #REF! | ... AV22: {=if(AV$14=#REF!,"-", countif(indirect(address(row($J$2)+ VLOOKUP(AV$14,$J$3:$J$8,1),COLUMN($K$4))):indirect(address(row($J$2)+ VLOOKUP(AV$14,$J$3:$J$8,1),COLUMN($S$2)))>indirect(address(row(#REF!),COLUMN($K$2))):indirect(address(row(#REF!),COLUMN($S$2))),TRUE()))} -> #REF! | AW22: 7 | AX22: {=INDIRECT("Draft!J"&TEXT(VLOOKUP(TRUE,I3:J8,2,0)+2,"0"))} -> #N/A | AZ22: =IF($AX22="","", VLOOKUP($AX22,'Final Update'!$Q$21:$AE1009,Column(G7),False)) -> #N/A | BA22: =IF($AX22="","", VLOOKUP($AX22,'Final Update'!$Q$21:$AE1009,Column(H7),False)) -> #N/A | BB22: =IF($AX22="","", VLOOKUP($AX22,'Final Update'!$Q$21:$AE1009,Column(I7),False)) -> #N/A | BC22: =IF($AX22="","", VLOOKUP($AX22,'Final Update'!$Q$21:$AE1009,Column(F4),False)) -> #N/A | BD22: =IF($AX22="","", VLOOKUP($AX22,'Final Update'!$Q$21:$AE1009,Column(K7),False)) -> #N/A | BE22: =IF($AX22="","", VLOOKUP($AX22,'Final Update'!$Q$21:$AE1009,Column(L7),False)) -> #N/A | BF22: =IF($AX22="","", VLOOKUP($AX22,'Final Update'!$Q$21:$AE1009,Column(M7),False)) -> #N/A | BG22: =IF($AX22="","", VLOOKUP($AX22,'Final Update'!$Q$21:$AE1009,Column(N7),False)) -> #N/A | BH22: =IF($AX22="","", VLOOKUP($AX22,'Final Update'!$Q$21:$AE1009,Column(O7),False)) -> #N/A | BI22: =IF($AX22="","", VLOOKUP($AX22,'Final Update'!$Q$21:$AE1009,Column(C7),False)) -> #N/A
A23: =VLOOKUP($F23,UpdateHashtag!$V$3:$Y$32,COLUMN(B$9),0) -> 4 | B23: =VLOOKUP($F23,UpdateHashtag!$V$3:$Y$32,COLUMN(#REF!),0) -> #REF! | C23: =VLOOKUP($F23,UpdateHashtag!$V$3:$Y$32,COLUMN(#REF!),0) -> #REF! | D23: =SUM(A23:C23) -> #REF! | F23: =VLOOKUP(J23,UpdateBBM!$C$2:E1009,3,0) -> CHA | G23: 10 | H23: =IFERROR(__xludf.DUMMYFUNCTION("""COMPUTED_VALUE"""),10.0) -> 10 | J23: =IFERROR(__xludf.DUMMYFUNCTION("""COMPUTED_VALUE"""),"LaMelo Ball") -> LaMelo Ball | K23: =IFERROR(__xludf.DUMMYFUNCTION("""COMPUTED_VALUE"""),59.0) -> 59 | L23: =IFERROR(__xludf.DUMMYFUNCTION("""COMPUTED_VALUE"""),"G") -> G | M23: =IFERROR(__xludf.DUMMYFUNCTION("""COMPUTED_VALUE"""),4.884388546694007) -> 4.8843885 | N23: =IFERROR(__xludf.DUMMYFUNCTION("""COMPUTED_VALUE"""),5.331128941088887) -> 5.3311289 | O23: =IFERROR(__xludf.DUMMYFUNCTION("""COMPUTED_VALUE"""),0.44674039439488045) -> 0.44674039 | P23: =IFERROR(__xludf.DUMMYFUNCTION("""COMPUTED_VALUE"""),23.88695) -> 23.88695 | Q23: =IFERROR(__xludf.DUMMYFUNCTION("""COMPUTED_VALUE"""),3.725254) -> 3.725254 | R23: =IFERROR(__xludf.DUMMYFUNCTION("""COMPUTED_VALUE"""),4.95) -> 4.95 | S23: =IFERROR(__xludf.DUMMYFUNCTION("""COMPUTED_VALUE"""),8.13678) -> 8.13678 | T23: =IFERROR(__xludf.DUMMYFUNCTION("""COMPUTED_VALUE"""),1.252542) -> 1.252542 | U23: =IFERROR(__xludf.DUMMYFUNCTION("""COMPUTED_VALUE"""),0.272712) -> 0.272712 | V23: =IFERROR(__xludf.DUMMYFUNCTION("""COMPUTED_VALUE"""),0.416645) -> 0.416645 | W23: =IFERROR(__xludf.DUMMYFUNCTION("""COMPUTED_VALUE"""),0.850015) -> 0.850015 | X23: =IFERROR(__xludf.DUMMYFUNCTION("""COMPUTED_VALUE"""),3.550169) -> 3.550169 | Y23: =IFERROR(__xludf.DUMMYFUNCTION("""COMPUTED_VALUE"""),1.1776307627712463) -> 1.1776308 | Z23: =IFERROR(__xludf.DUMMYFUNCTION("""COMPUTED_VALUE"""),1.8888807844118063) -> 1.8888808 | AA23: =IFERROR(__xludf.DUMMYFUNCTION("""COMPUTED_VALUE"""),-0.47689674333600574) -> -0.47689674 | AB23: =IFERROR(__xludf.DUMMYFUNCTION("""COMPUTED_VALUE"""),2.100554524516573) -> 2.1005545 | AC23: =IFERROR(__xludf.DUMMYFUNCTION("""COMPUTED_VALUE"""),0.6318562051048922) -> 0.63185621 | AD23: =IFERROR(__xludf.DUMMYFUNCTION("""COMPUTED_VALUE"""),-0.8317500803543943) -> -0.83175008 | AE23: =IFERROR(__xludf.DUMMYFUNCTION("""COMPUTED_VALUE"""),-0.9829715408115209) -> -0.98297154 | AF23: =IFERROR(__xludf.DUMMYFUNCTION("""COMPUTED_VALUE"""),0.8408534879747702) -> 0.84085349 | AG23: =IFERROR(__xludf.DUMMYFUNCTION("""COMPUTED_VALUE"""),0.0) -> 0 | AJ23: 100 | AK23: {=if(AK$14=#REF!,"-", countif(indirect(address(row($J$2)+ VLOOKUP(AK$14,$J$3:$J$8,1),COLUMN($K$4))):indirect(address(row($J$2)+ VLOOKUP(AK$14,$J$3:$J$8,1),COLUMN($S$2)))>indirect(address(row(#REF!),COLUMN($K$2))):indirect(address(row(#REF!),COLUMN($S$2))),TRUE()))} -> #REF! | AL23: {=if(AL$14=#REF!,"-", countif(indirect(address(row($J$2)+ VLOOKUP(AL$14,$J$3:$J$8,1),COLUMN($K$4))):indirect(address(row($J$2)+ VLOOKUP(AL$14,$J$3:$J$8,1),COLUMN($S$2)))>indirect(address(row(#REF!),COLUMN($K$2))):indirect(address(row(#REF!),COLUMN($S$2))),TRUE()))} -> #REF! | AM23: {=if(AM$14=#REF!,"-", countif(indirect(address(row($J$2)+ VLOOKUP(AM$14,$J$3:$J$8,1),COLUMN($K$4))):indirect(address(row($J$2)+ VLOOKUP(AM$14,$J$3:$J$8,1),COLUMN($S$2)))>indirect(address(row(#REF!),COLUMN($K$2))):indirect(address(row(#REF!),COLUMN($S$2))),TRUE()))} -> #REF! | AN23: {=if(AN$14=#REF!,"-", countif(indirect(address(row($J$2)+ VLOOKUP(AN$14,$J$3:$J$8,1),COLUMN($K$4))):indirect(address(row($J$2)+ VLOOKUP(AN$14,$J$3:$J$8,1),COLUMN($S$2)))>indirect(address(row(#REF!),COLUMN($K$2))):indirect(address(row(#REF!),COLUMN($S$2))),TRUE()))} -> #REF! | AO23: {=if(AO$14=#REF!,"-", countif(indirect(address(row($J$2)+ VLOOKUP(AO$14,$J$3:$J$8,1),COLUMN($K$4))):indirect(address(row($J$2)+ VLOOKUP(AO$14,$J$3:$J$8,1),COLUMN($S$2)))>indirect(address(row(#REF!),COLUMN($K$2))):indirect(address(row(#REF!),COLUMN($S$2))),TRUE()))} -> #REF! | AP23: {=if(AP$14=#REF!,"-", countif(indirect(address(row($J$2)+ VLOOKUP(AP$14,$J$3:$J$8,1),COLUMN($K$4))):indirect(address(row($J$2)+ VLOOKUP(AP$14,$J$3:$J$8,1),COLUMN($S$2)))>indirect(address(row(#REF!),COLUMN($K$2))):indirect(address(row(#REF!),COLUMN($S$2))),TRUE()))} -> #REF! | AQ23: {=if(AQ$14=#REF!,"-", countif(indirect(address(row($J$2)+ VLOOKUP(AQ$14,$J$3:$J$8,1),COLUMN($K$4))):indirect(address(row($J$2)+ VLOOKUP(AQ$14,$J$3:$J$8,1),COLUMN($S$2)))>indirect(address(row(#REF!),COLUMN($K$2))):indirect(address(row(#REF!),COLUMN($S$2))),TRUE()))} -> #REF! | AR23: {=if(AR$14=#REF!,"-", countif(indirect(address(row($J$2)+ VLOOKUP(AR$14,$J$3:$J$8,1),COLUMN($K$4))):indirect(address(row($J$2)+ VLOOKUP(AR$14,$J$3:$J$8,1),COLUMN($S$2)))>indirect(address(row(#REF!),COLUMN($K$2))):indirect(address(row(#REF!),COLUMN($S$2))),TRUE()))} -> #REF! | ... AV23: {=if(AV$14=#REF!,"-", countif(indirect(address(row($J$2)+ VLOOKUP(AV$14,$J$3:$J$8,1),COLUMN($K$4))):indirect(address(row($J$2)+ VLOOKUP(AV$14,$J$3:$J$8,1),COLUMN($S$2)))>indirect(address(row(#REF!),COLUMN($K$2))):indirect(address(row(#REF!),COLUMN($S$2))),TRUE()))} -> #REF! | AW23: 8 | AX23: {=INDIRECT("Draft!K"&TEXT(15-VLOOKUP(TRUE,I3:J8,2,0),"0"))} -> #N/A | AZ23: =IF($AX23="","", VLOOKUP($AX23,'Final Update'!$Q$21:$AE1009,Column(#REF!),False)) -> #N/A | BA23: =IF($AX23="","", VLOOKUP($AX23,'Final Update'!$Q$21:$AE1009,Column(#REF!),False)) -> #N/A | BB23: =IF($AX23="","", VLOOKUP($AX23,'Final Update'!$Q$21:$AE1009,Column(#REF!),False)) -> #N/A | BC23: =IF($AX23="","", VLOOKUP($AX23,'Final Update'!$Q$21:$AE1009,Column(#REF!),False)) -> #N/A | BD23: =IF($AX23="","", VLOOKUP($AX23,'Final Update'!$Q$21:$AE1009,Column(#REF!),False)) -> #N/A | BE23: =IF($AX23="","", VLOOKUP($AX23,'Final Update'!$Q$21:$AE1009,Column(#REF!),False)) -> #N/A | BF23: =IF($AX23="","", VLOOKUP($AX23,'Final Update'!$Q$21:$AE1009,Column(#REF!),False)) -> #N/A | BG23: =IF($AX23="","", VLOOKUP($AX23,'Final Update'!$Q$21:$AE1009,Column(#REF!),False)) -> #N/A | ... BI23: =IF($AX23="","", VLOOKUP($AX23,'Final Update'!$Q$21:$AE1009,Column(#REF!),False)) -> #N/A
