Workbook

Sheet Draft
B2: Pick | C2: Your Pick | D2: Round 1 | E2: Round 2 | F2: Round 3 | G2: Round 4 | H2: Round 5 | I2: Round 6 | J2: Round 7 | K2: Round 8 | L2: Round 9 | M2: Round 10 | N2: Round 11 | O2: Round 12 | P2: Round 13 | Q2: Round 14
B3: 1 | C3: =IF(B3=Projections!$G$3,TRUE) -> FALSE | D3: Victor Wembanyama | E3: James Harden | F3: Cooper Flagg | G3: Brandon Miller | H3: O.G. Anunoby | I3: Alexandre Sarr | J3: Paul George | K3: Cam Johnson | L3: Jaden McDaniels | M3: Jrue Holiday | N3: Zaccharie Risacher | O3: Nikola Jovic | P3: Alex Caruso
B4: 2 | C4: =IF(B4=Projections!$G$3,TRUE) -> FALSE | D4: Nikola Jokic | E4: Stephen Curry | F4: Jalen Brunson | G4: Julius Randle | H4: Kristaps Porzingis | I4: Jalen Duren | J4: Michael Porter Jr. | K4: PJ Washington | L4: Naz Reid | M4: Klay Thompson | N4: Kyrie Irving | O4: Duncan Robinson | P4: Keon Ellis
B5: 3 | C5: =IF(B5=Projections!$G$3,TRUE) -> FALSE | D5: Shai Gilgeous-Alexander | E5: Alperen Sengun | F5: Pascal Siakam | G5: Nikola Vucevic | H5: Lauri Markkanen | I5: Deandre Ayton | J5: Isaiah Hartenstein | K5: R.J. Barrett | L5: Andrew Wiggins | M5: Jabari Smith Jr. | N5: Collin Sexton | O5: Stephon Castle | P5: Dylan Harper
B6: 4 | C6: =IF(B6=Projections!$G$3,TRUE) -> TRUE | D6: Luka Doncic | E6: Kevin Durant | F6: Bam Adebayo | G6: Kawhi Leonard | H6: Joel Embiid | I6: Matas Buzelis | J6: Jordan Poole | K6: Donovan Clingan | L6: Bobby Portis | M6: Andrew Nembhard | N6: Cason Wallace | O6: Mitchell Robinson | P6: Sam Hauser
B7: 5 | C7: =IF(B7=Projections!$G$3,TRUE) -> FALSE | D7: Giannis Antetokounmpo | E7: Evan Mobley | F7: LeBron James | G7: Dyson Daniels | H7: Rudy Gobert | I7: Miles Bridges | J7: Immanuel Quickley | K7: John Collins | L7: Anfernee Simons | M7: Jonathan Kuminga | N7: Tobias Harris | O7: Chris Boucher | P7: Malik Monk
B8: 6 | C8: =IF(B8=Projections!$G$3,TRUE) -> FALSE | D8: Cade Cunningham | E8: Donovan Mitchell | F8: Scottie Barnes | G8: Austin Reaves | H8: Walker Kessler | I8: Ausar Thompson | J8: Shaedon Sharpe | K8: Draymond Green | L8: Kevin Porter Jr. | M8: Donte DiVincenzo | N8: Jaden Ivey | O8: Santi Aldama | P8: VJ Edgecombe
B9: 7 | C9: =IF(B9=Projections!$G$3,TRUE) -> FALSE | D9: Anthony Edwards | E9: Tyrese Maxey | F9: Jaren Jackson Jr. | G9: Myles Turner | H9: Coby White | I9: Jakob Poeltl | J9: Tari Eason | K9: Cam Thomas | L9: Brandin Podziemski | M9: Bennedict Mathurin | N9: Aaron Nesmith | O9: Cam Whitmore | P9: Taylor Hendricks
B10: 8 | C10: =IF(B10=Projections!$G$3,TRUE) -> FALSE | D10: Karl-Anthony Towns | E10: Jalen Johnson | F10: Franz Wagner | G10: Zion Williamson | H10: Ivica Zubac | I10: Mark Williams | J10: Onyeka Okongwu | K10: C.J. McCollum | L10: Keyonte George | M10: D'Angelo Russell | N10: Isaiah Jackson | O10: Neemias Queta | P10: Gradey Dick
B11: 9 | C11: =IF(B11=Projections!$G$3,TRUE) -> FALSE | D11: Devin Booker | E11: Josh Giddey | F11: Jamal Murray | G11: Ja Morant | H11: Jimmy Butler | I11: Payton Pritchard | J11: Toumani Camara | K11: Jalen Green | L11: Nicolas Claxton | M11: Reed Sheppard | N11: Davion Mitchell | O11: Keegan Murray | P11: Ace Bailey
B12: 10 | C12: =IF(B12=Projections!$G$3,TRUE) -> FALSE | D12: Domantas Sabonis | E12: Jalen Williams | F12: Paolo Banchero | G12: Jaylen Brown | H12: Desmond Bane | I12: Jarrett Allen | J12: Brandon Ingram | K12: Mikal Bridges | L12: Aaron Gordon | M12: Norman Powell | N12: Kel'el Ware | O12: De'Andre Hunter | P12: Dennis Schroder
B13: 11 | C13: =IF(B13=Projections!$G$3,TRUE) -> FALSE | D13: Trae Young | E13: Derrick White | F13: Chet Holmgren | G13: Trey Murphy | H13: Zach LaVine | I13: Tyler Herro | J13: Josh Hart | K13: James Harden | L13: Chris Paul | M13: Jalen Suggs | N13: Brook Lopez | O13: Dereck Lively II | P13: Jerami Grant
B14: 12 | C14: =IF(B14=Projections!$G$3,TRUE) -> FALSE | D14: Anthony Davis | E14: LaMelo Ball | F14: Amen Thompson | G14: De'Aaron Fox | H14: Deni Avdija | I14: DeMar DeRozan | J14: Darius Garland | K14: Bradley Beal | L14: Zach Edey | M14: Devin Vassell | N14: Herb Jones | O14: Miles McBride | P14: Bilal Coulibaly
C16: Pick # | D16: =IF(C3=TRUE,"1",IF(C4=TRUE,"2", IF(C5=True, "3",IF(C6=True, "4",IF(C7=True, "5",IF(C8=True, "6",IF(C9=True, "7",IF(C10=True, "8",IF(C11=True, "9",IF(C12=True, "10",IF(C13=True, "11",IF(C14=True, "12"))))))))))))*1 -> 4 | E16: =IF(C3=TRUE,"24",IF(C4=TRUE,"23", IF(C5=True, "22",IF(C6=True, "21",IF(C7=True, "20",IF(C8=True, "19",IF(C9=True, "18",IF(C10=True, "17",IF(C11=True, "16",IF(C12=True, "15",IF(C13=True, "14",IF(C14=True, "13"))))))))))))*1 -> 21 | F16: =IF(C3=TRUE,"25",IF(C4=TRUE,"26", IF(C5=True, "27",IF(C6=True, "28",IF(C7=True, "29",IF(C8=True, "30",IF(C9=True, "31",IF(C10=True, "32",IF(C11=True, "33",IF(C12=True, "34",IF(C13=True, "35",IF(C14=True, "36"))))))))))))*1 -> 28 | G16: =IF(C3=TRUE,"48",IF(C4=TRUE,"47", IF(C5=True, "46",IF(C6=True, "45",IF(C7=True, "44",IF(C8=True, "43",IF(C9=True, "42",IF(C10=True, "41",IF(C11=True, "40",IF(C12=True, "39",IF(C13=True, "38",IF(C14=True, "37"))))))))))))*1 -> 45 | H16: =IF(C3=TRUE,"49",IF(C4=TRUE,"50", IF(C5=True, "51",IF(C6=True, "52",IF(C7=True, "53",IF(C8=True, "54",IF(C9=True, "55",IF(C10=True, "56",IF(C11=True, "57",IF(C12=True, "58",IF(C13=True, "59",IF(C14=True, "60"))))))))))))*1 -> 52 | I16: =IF(C3=TRUE,"72",IF(C4=TRUE,"71", IF(C5=True, "70",IF(C6=True, "69",IF(C7=True, "68",IF(C8=True, "67",IF(C9=True, "66",IF(C10=True, "65",IF(C11=True, "64",IF(C12=True, "63",IF(C13=True, "62",IF(C14=True, "61"))))))))))))*1 -> 69 | J16: =IF(C3=TRUE,"73",IF(C4=TRUE,"74", IF(C5=True, "75",IF(C6=True, "76",IF(C7=True, "77",IF(C8=True, "78",IF(C9=True, "79",IF(C10=True, "80",IF(C11=True, "81",IF(C12=True, "82",IF(C13=True, "83",IF(C14=True, "84"))))))))))))*1 -> 76 | K16: =IF(C3=TRUE,"96",IF(C4=TRUE,"95", IF(C5=True, "94",IF(C6=True, "93",IF(C7=True, "92",IF(C8=True, "91",IF(C9=True, "90",IF(C10=True, "89",IF(C11=True, "88",IF(C12=True, "87",IF(C13=True, "86",IF(C14=True, "85"))))))))))))*1 -> 93 | L16: =IF(C3=TRUE,"97",IF(C4=TRUE,"98", IF(C5=True, "99",IF(C6=True, "100",IF(C7=True, "101",IF(C8=True, "102",IF(C9=True, "103",IF(C10=True, "104",IF(C11=True, "105",IF(C12=True, "106",IF(C13=True, "107",IF(C14=True, "108"))))))))))))*1 -> 100 | M16: =IF(C3=TRUE,"120",IF(C4=TRUE,"119", IF(C5=True, "118",IF(C6=True, "117",IF(C7=True, "116",IF(C8=True, "115",IF(C9=True, "114",IF(C10=True, "113",IF(C11=True, "112",IF(C12=True, "111",IF(C13=True, "110",IF(C14=True, "109"))))))))))))*1 -> 117 | N16: =IF(C3=TRUE,"121",IF(C4=TRUE,"122", IF(C5=True, "123",IF(C6=True, "124",IF(C7=True, "125",IF(C8=True, "126",IF(C9=True, "127",IF(C10=True, "128",IF(C11=True, "129",IF(C12=True, "130",IF(C13=True, "131",IF(C14=True, "132"))))))))))))*1 -> 124 | O16: =IF(C3=TRUE,"144",IF(C4=TRUE,"143", IF(C5=True, "142",IF(C6=True, "141",IF(C7=True, "140",IF(C8=True, "139",IF(C9=True, "138",IF(C10=True, "137",IF(C11=True, "136",IF(C12=True, "135",IF(C13=True, "134",IF(C14=True, "133"))))))))))))*1 -> 141 | P16: =IF(C3=TRUE,"145",IF(C4=TRUE,"146", IF(C5=True, "147",IF(C6=True, "148",IF(C7=True, "149",IF(C8=True, "150",IF(C9=True, "151",IF(C10=True, "152",IF(C11=True, "153",IF(C12=True, "154",IF(C13=True, "155",IF(C14=True, "156")))))))))))) -> 148 | Q16: =IF(C3=TRUE,"168",IF(C4=TRUE,"167", IF(C5=True, "166",IF(C6=True, "165",IF(C7=True, "164",IF(C8=True, "163",IF(C9=True, "162",IF(C10=True, "161",IF(C11=True, "160",IF(C12=True, "159",IF(C13=True, "158",IF(C14=True, "157")))))))))))) -> 165
C17: 3RR | D17: =D16 -> 4 | E17: =E16 -> 21 | F17: =F16+IF($C$3,11, IF($C$4,9,IF($C$5,7,IF($C$6,5,IF($C$7,3,IF($C$8,1,IF($C$9,-1,IF($C$10,-3,IF($C$11,-5,IF($C$12,-7, IF($C$13,-9, IF($C$14,-11))))))))))))*1 -> 33 | G17: =G16-IF($C$3,11, IF($C$4,9,IF($C$5,7,IF($C$6,5,IF($C$7,3,IF($C$8,1,IF($C$9,-1,IF($C$10,-3,IF($C$11,-5,IF($C$12,-7, IF($C$13,-9, IF($C$14,-11))))))))))))*1 -> 40 | H17: =H16+IF($C$3,11, IF($C$4,9,IF($C$5,7,IF($C$6,5,IF($C$7,3,IF($C$8,1,IF($C$9,-1,IF($C$10,-3,IF($C$11,-5,IF($C$12,-7, IF($C$13,-9, IF($C$14,-11))))))))))))*1 -> 57 | I17: =I16-IF($C$3,11, IF($C$4,9,IF($C$5,7,IF($C$6,5,IF($C$7,3,IF($C$8,1,IF($C$9,-1,IF($C$10,-3,IF($C$11,-5,IF($C$12,-7, IF($C$13,-9, IF($C$14,-11))))))))))))*1 -> 64 | J17: =J16+IF($C$3,11, IF($C$4,9,IF($C$5,7,IF($C$6,5,IF($C$7,3,IF($C$8,1,IF($C$9,-1,IF($C$10,-3,IF($C$11,-5,IF($C$12,-7, IF($C$13,-9, IF($C$14,-11))))))))))))*1 -> 81 | K17: =K16-IF($C$3,11, IF($C$4,9,IF($C$5,7,IF($C$6,5,IF($C$7,3,IF($C$8,1,IF($C$9,-1,IF($C$10,-3,IF($C$11,-5,IF($C$12,-7, IF($C$13,-9, IF($C$14,-11))))))))))))*1 -> 88 | L17: =L16+IF($C$3,11, IF($C$4,9,IF($C$5,7,IF($C$6,5,IF($C$7,3,IF($C$8,1,IF($C$9,-1,IF($C$10,-3,IF($C$11,-5,IF($C$12,-7, IF($C$13,-9, IF($C$14,-11))))))))))))*1 -> 105 | M17: =M16-IF($C$3,11, IF($C$4,9,IF($C$5,7,IF($C$6,5,IF($C$7,3,IF($C$8,1,IF($C$9,-1,IF($C$10,-3,IF($C$11,-5,IF($C$12,-7, IF($C$13,-9, IF($C$14,-11))))))))))))*1 -> 112 | N17: =N16+IF($C$3,11, IF($C$4,9,IF($C$5,7,IF($C$6,5,IF($C$7,3,IF($C$8,1,IF($C$9,-1,IF($C$10,-3,IF($C$11,-5,IF($C$12,-7, IF($C$13,-9, IF($C$14,-11))))))))))))*1 -> 129 | O17: =O16-IF($C$3,11, IF($C$4,9,IF($C$5,7,IF($C$6,5,IF($C$7,3,IF($C$8,1,IF($C$9,-1,IF($C$10,-3,IF($C$11,-5,IF($C$12,-7, IF($C$13,-9, IF($C$14,-11))))))))))))*1 -> 136 | P17: =P16+IF($B$3,11, IF($B$4,9,IF($B$5,7,IF($B$6,5,IF($B$7,3,IF($B$8,1,IF($B$9,-1,IF($B$10,-3,IF($B$11,-5,IF($B$12,-7, IF($B$13,-9, IF($B$14,-11)))))))))))) -> 159 | Q17: =Q16-IF($B$3,11, IF($B$4,9,IF($B$5,7,IF($B$6,5,IF($B$7,3,IF($B$8,1,IF($B$9,-1,IF($B$10,-3,IF($B$11,-5,IF($B$12,-7, IF($B$13,-9, IF($B$14,-11)))))))))))) -> 154
D19: MAKE A COPY
D20: File -> Make a copy

Sheet Projections
I2: Pick # | J2: Team | K2: PTS | L2: 3P | M2: REB | N2: AST | O2: STL | P2: BLK | Q2: FG% | R2: FT% | S2: TO | T2: Cats Won | U2: Winrate | V2: Punt Sum | W2: Total LeagV | X2: ="Round "&Column(A1) -> Round 1 | Z2: ="Round "&Column(B1) -> Round 2 | AB2: ="Round "&Column(C1) -> Round 3 | AD2: ="Round "&Column(D1) -> Round 4 | AF2: ="Round "&Column(E1) -> Round 5 | AH2: ="Round "&Column(F1) -> Round 6 | AJ2: ="Round "&Column(G1) -> Round 7 | AL2: ="Round "&Column(P1) -> Round 16 | AN2: ="Round "&Column(R1) -> Round 18 | AP2: ="Round "&Column(T1) -> Round 20 | AR2: ="Round "&Column(V1) -> Round 22 | AT2: ="Round "&Column(Y1) -> Round 25 | AV2: ="Round "&Column(AA1) -> Round 27 | AX2: ="Round "&Column(H1) -> Round 8 | AY2: ="Round "&Column(I1) -> Round 9 | AZ2: ="Round "&Column(J1) -> Round 10 | BA2: ="Round "&Column(K1) -> Round 11 | BB2: ="Round "&Column(L1) -> Round 12 | BC2: ="Round "&Column(M1) -> Round 13 | BD2: ="Round "&Column(N1) -> Round 14 | BE2: =Draft!AK3 | BF2: =Draft!AL3 | BG2: =Draft!AM3 | BH2: =Draft!AN3 | BI2: =Draft!AO3
F3: Your Pick # | G3: 4 | I3: =Draft!C3 -> FALSE | J3: 1 | K3: ='All Teams'!E18 -> -34.708945 | L3: ='All Teams'!F18 -> -19.147552 | M3: ='All Teams'!G18 -> -26.18659 | N3: ='All Teams'!H18 -> -19.725229 | O3: ='All Teams'!I18 -> -35.642096 | P3: ='All Teams'!J18 -> -14.620014 | Q3: ='All Teams'!K18 -> -5.2478343 | R3: ='All Teams'!L18 -> 2.9962745 | S3: ='All Teams'!M18 -> 19.080076 | T3: {=if(Team!D$1=$J3,"-", countif(indirect(address(row($J$2)+ VLOOKUP(Team!D$1,$J$3:$J$14,1),COLUMN($K$2))):indirect(address(row($J$2)+ VLOOKUP(Team!D$1,$J$3:$J$14,1),COLUMN($S$2)))>indirect(address(row($J3),COLUMN($K$2))):indirect(address(row($J3),COLUMN($S$2))),TRUE()))} -> 7 | U3: =SUM(AL$22:AL$33)/99 -> 0.50505051 | V3: =SUMIF(K3:R3,">-2.5") -> 2.9962745 | W3: ='All Teams'!N18 -> 20.181353 | X3: =Draft!D3 -> Victor Wembanyama | Z3: =Draft!E3 -> James Harden | AB3: =Draft!F3 -> Cooper Flagg | AD3: =Draft!G3 -> Brandon Miller | AF3: =Draft!H3 -> O.G. Anunoby | AH3: =Draft!I3 -> Alexandre Sarr | AJ3: =Draft!J3 -> Paul George | AL3: =Draft!R4 | AM3: =Draft!S4 | AN3: =Draft!T4 | AO3: =Draft!U4 | AP3: =Draft!V4 | AQ3: =Draft!W4 | AR3: =Draft!X4 | AS3: =Draft!Y4 | ... AW3: =Draft!AC4 | AX3: =Draft!K3 -> Cam Johnson | AY3: =Draft!L3 -> Jaden McDaniels | AZ3: =Draft!M3 -> Jrue Holiday | BA3: =Draft!N3 -> Zaccharie Risacher | BB3: =Draft!O3 -> Nikola Jovic | BC3: =Draft!P3 -> Alex Caruso | BD3: =Draft!AJ4 | BE3: =Draft!AK4 | BF3: =Draft!AL4 | BG3: =Draft!AM4 | BH3: =Draft!AN4 | BI3: =Draft!AO4
I4: =Draft!C4 -> FALSE | J4: 2 | K4: ='All Teams'!E35 -> -37.864303 | L4: ='All Teams'!F35 -> -20.888239 | M4: ='All Teams'!G35 -> -28.567189 | N4: ='All Teams'!H35 -> -21.518432 | O4: ='All Teams'!I35 -> -38.882286 | P4: ='All Teams'!J35 -> -15.949106 | Q4: ='All Teams'!K35 -> -0.72657459 | R4: ='All Teams'!L35 -> 4.6952454 | S4: ='All Teams'!M35 -> 20.814628 | T4: {=if(Team!D$1=$J4,"-", countif(indirect(address(row($J$2)+ VLOOKUP(Team!D$1,$J$3:$J$14,1),COLUMN($K$2))):indirect(address(row($J$2)+ VLOOKUP(Team!D$1,$J$3:$J$14,1),COLUMN($S$2)))>indirect(address(row($J4),COLUMN($K$2))):indirect(address(row($J4),COLUMN($S$2))),TRUE()))} -> 6 | U4: =SUM(AM$22:AM$33)/99 -> 0.22222222 | V4: =SUMIF(K4:R4,">-2.5") -> 3.9686708 | W4: ='All Teams'!N35 -> 28.059191 | X4: =Draft!D4 -> Nikola Jokic | Z4: =Draft!E4 -> Stephen Curry | AB4: =Draft!F4 -> Jalen Brunson | AD4: =Draft!G4 -> Julius Randle | AF4: =Draft!H4 -> Kristaps Porzingis | AH4: =Draft!I4 -> Jalen Duren | AJ4: =Draft!J4 -> Michael Porter Jr. | AL4: =Draft!R5 | AM4: =Draft!S5 | AN4: =Draft!T5 | AO4: =Draft!U5 | AP4: =Draft!V5 | AQ4: =Draft!W5 | AR4: =Draft!X5 | AS4: =Draft!Y5 | ... AU4: =Draft!AA5 | AW4: =Draft!AC5 | AX4: =Draft!K4 -> PJ Washington | AY4: =Draft!L4 -> Naz Reid | AZ4: =Draft!M4 -> Klay Thompson | BA4: =Draft!N4 -> Kyrie Irving | BB4: =Draft!O4 -> Duncan Robinson | BC4: =Draft!P4 -> Keon Ellis | BD4: =Draft!AJ5 | BE4: =Draft!AK5 | BF4: =Draft!AL5 | BG4: =Draft!AM5 | BH4: =Draft!AN5 | BI4: =Draft!AO5
F5: Next Pick Simulation | I5: =Draft!C5 -> FALSE | J5: 3 | K5: ='All Teams'!E52 -> -37.864303 | L5: ='All Teams'!F52 -> -20.888239 | M5: ='All Teams'!G52 -> -28.567189 | N5: ='All Teams'!H52 -> -21.518432 | O5: ='All Teams'!I52 -> -38.882286 | P5: ='All Teams'!J52 -> -15.949106 | Q5: ='All Teams'!K52 -> 2.1706373 | R5: ='All Teams'!L52 -> 2.9487046 | S5: ='All Teams'!M52 -> 20.814628 | T5: {=if(Team!D$1=$J5,"-", countif(indirect(address(row($J$2)+ VLOOKUP(Team!D$1,$J$3:$J$14,1),COLUMN($K$2))):indirect(address(row($J$2)+ VLOOKUP(Team!D$1,$J$3:$J$14,1),COLUMN($S$2)))>indirect(address(row($J5),COLUMN($K$2))):indirect(address(row($J5),COLUMN($S$2))),TRUE()))} -> 7 | U5: =SUM(AN$22:AN$33)/99 -> 0.23232323 | V5: =SUMIF(K5:R5,">-2.5") -> 5.1193419 | W5: ='All Teams'!N52 -> 11.268646 | X5: =Draft!D5 -> Shai Gilgeous-Alexander | Z5: =Draft!E5 -> Alperen Sengun | AB5: =Draft!F5 -> Pascal Siakam | AD5: =Draft!G5 -> Nikola Vucevic | AF5: =Draft!H5 -> Lauri Markkanen | AH5: =Draft!I5 -> Deandre Ayton | AJ5: =Draft!J5 -> Isaiah Hartenstein | AL5: =Draft!R6 | AM5: =Draft!S6 | AN5: =Draft!T6 | AO5: =Draft!U6 | AP5: =Draft!V6 | AQ5: =Draft!W6 | AR5: =Draft!X6 | AS5: =Draft!Y6 | ... AW5: =Draft!AC6 | AX5: =Draft!K5 -> R.J. Barrett | AY5: =Draft!L5 -> Andrew Wiggins | AZ5: =Draft!M5 -> Jabari Smith Jr. | BA5: =Draft!N5 -> Collin Sexton | BB5: =Draft!O5 -> Stephon Castle | BC5: =Draft!P5 -> Dylan Harper | BD5: =Draft!AJ6 | BE5: =Draft!AK6 | BF5: =Draft!AL6 | BG5: =Draft!AM6 | BH5: =Draft!AN6 | BI5: =Draft!AO6
F6: Round # | G6: 1 | I6: =Draft!C6 -> TRUE | J6: 4 | K6: ='All Teams'!E69 -> 0.50530601 | L6: ='All Teams'!F69 -> 1.4432671 | M6: ='All Teams'!G69 -> -0.5994361 | N6: ='All Teams'!H69 -> 1.1477191 | O6: ='All Teams'!I69 -> -1.2315582 | P6: ='All Teams'!J69 -> -4.8151532 | Q6: ='All Teams'!K69 -> -4.2549158 | R6: ='All Teams'!L69 -> 2.9594596 | S6: ='All Teams'!M69 -> -3.1538368 | T6: {=if(Team!D$1=$J6,"-", countif(indirect(address(row($J$2)+ VLOOKUP(Team!D$1,$J$3:$J$14,1),COLUMN($K$2))):indirect(address(row($J$2)+ VLOOKUP(Team!D$1,$J$3:$J$14,1),COLUMN($S$2)))>indirect(address(row($J6),COLUMN($K$2))):indirect(address(row($J6),COLUMN($S$2))),TRUE()))} -> - | U6: =SUM(AO$22:AO$33)/99 -> 0.74747475 | V6: =SUMIF(K6:R6,">-2.5") -> 4.2247575 | W6: ='All Teams'!N69 -> 8.7608866 | X6: =Draft!D6 -> Luka Doncic | Z6: =Draft!E6 -> Kevin Durant | AB6: =Draft!F6 -> Bam Adebayo | AD6: =Draft!G6 -> Kawhi Leonard | AF6: =Draft!H6 -> Joel Embiid | AH6: =Draft!I6 -> Matas Buzelis | AJ6: =Draft!J6 -> Jordan Poole | AL6: =Draft!R7 | AM6: =Draft!S7 | AN6: =Draft!T7 | AO6: =Draft!U7 | AP6: =Draft!V7 | AQ6: =Draft!W7 | AR6: =Draft!X7 | AS6: =Draft!Y7 | ... AW6: =Draft!AC7 | AX6: =Draft!K6 -> Donovan Clingan | AY6: =Draft!L6 -> Bobby Portis | AZ6: =Draft!M6 -> Andrew Nembhard | BA6: =Draft!N6 -> Cason Wallace | BB6: =Draft!O6 -> Mitchell Robinson | BC6: =Draft!P6 -> Sam Hauser | BD6: =Draft!AJ7 | BE6: =Draft!AK7 | BF6: =Draft!AL7 | BG6: =Draft!AM7 | BH6: =Draft!AN7 | BI6: =Draft!AO7
F7: T.J. McConnell | I7: =Draft!C7 -> FALSE | J7: 5 | K7: ='All Teams'!E86 -> -37.864303 | L7: ='All Teams'!F86 -> -20.888239 | M7: ='All Teams'!G86 -> -28.567189 | N7: ='All Teams'!H86 -> -21.518432 | O7: ='All Teams'!I86 -> -38.882286 | P7: ='All Teams'!J86 -> -15.949106 | Q7: ='All Teams'!K86 -> 4.8228994 | R7: ='All Teams'!L86 -> -8.293296 | S7: ='All Teams'!M86 -> 20.814628 | T7: {=if(Team!D$1=$J7,"-", countif(indirect(address(row($J$2)+ VLOOKUP(Team!D$1,$J$3:$J$14,1),COLUMN($K$2))):indirect(address(row($J$2)+ VLOOKUP(Team!D$1,$J$3:$J$14,1),COLUMN($S$2)))>indirect(address(row($J7),COLUMN($K$2))):indirect(address(row($J7),COLUMN($S$2))),TRUE()))} -> 7 | U7: =SUM(AP$22:AP$33)/99 -> 0.17171717 | V7: =SUMIF(K7:R7,">-2.5") -> 4.8228994 | W7: ='All Teams'!N86 -> 16.234371 | X7: =Draft!D7 -> Giannis Antetokounmpo | Z7: =Draft!E7 -> Evan Mobley | AB7: =Draft!F7 -> LeBron James | AD7: =Draft!G7 -> Dyson Daniels | AF7: =Draft!H7 -> Rudy Gobert | AH7: =Draft!I7 -> Miles Bridges | AJ7: =Draft!J7 -> Immanuel Quickley | AL7: =Draft!R8 | AM7: =Draft!S8 | AN7: =Draft!T8 | AO7: =Draft!U8 | AP7: =Draft!V8 | AQ7: =Draft!W8 | AR7: =Draft!X8 | AS7: =Draft!Y8 | ... AW7: =Draft!AC8 | AX7: =Draft!K7 -> John Collins | AY7: =Draft!L7 -> Anfernee Simons | AZ7: =Draft!M7 -> Jonathan Kuminga | BA7: =Draft!N7 -> Tobias Harris | BB7: =Draft!O7 -> Chris Boucher | BC7: =Draft!P7 -> Malik Monk | BD7: =Draft!AJ8 | BE7: =Draft!AK8 | BF7: =Draft!AL8 | BG7: =Draft!AM8 | BH7: =Draft!AN8 | BI7: =Draft!AO8
I8: =Draft!C8 -> FALSE | J8: 6 | K8: ='All Teams'!E103 -> -37.864303 | L8: ='All Teams'!F103 -> -20.888239 | M8: ='All Teams'!G103 -> -28.567189 | N8: ='All Teams'!H103 -> -21.518432 | O8: ='All Teams'!I103 -> -38.882286 | P8: ='All Teams'!J103 -> -15.949106 | Q8: ='All Teams'!K103 -> -4.3715673 | R8: ='All Teams'!L103 -> -1.1279605 | S8: ='All Teams'!M103 -> 20.814628 | T8: {=if(Team!D$1=$J8,"-", countif(indirect(address(row($J$2)+ VLOOKUP(Team!D$1,$J$3:$J$14,1),COLUMN($K$2))):indirect(address(row($J$2)+ VLOOKUP(Team!D$1,$J$3:$J$14,1),COLUMN($S$2)))>indirect(address(row($J8),COLUMN($K$2))):indirect(address(row($J8),COLUMN($S$2))),TRUE()))} -> 8 | U8: =SUM(AQ$22:AQ$33)/99 -> 0.12121212 | V8: =SUMIF(K8:R8,">-2.5") -> -1.1279605 | W8: ='All Teams'!N103 -> -4.0213622 | X8: =Draft!D8 -> Cade Cunningham | Z8: =Draft!E8 -> Donovan Mitchell | AB8: =Draft!F8 -> Scottie Barnes | AD8: =Draft!G8 -> Austin Reaves | AF8: =Draft!H8 -> Walker Kessler | AH8: =Draft!I8 -> Ausar Thompson | AJ8: =Draft!J8 -> Shaedon Sharpe | AL8: =Draft!R9 | AM8: =Draft!S9 | AN8: =Draft!T9 | AO8: =Draft!U9 | AP8: =Draft!V9 | AQ8: =Draft!W9 | AR8: =Draft!X9 | AS8: =Draft!Y9 | ... AW8: =Draft!AC9 | AX8: =Draft!K8 -> Draymond Green | AY8: =Draft!L8 -> Kevin Porter Jr. | AZ8: =Draft!M8 -> Donte DiVincenzo | BA8: =Draft!N8 -> Jaden Ivey | BB8: =Draft!O8 -> Santi Aldama | BC8: =Draft!P8 -> VJ Edgecombe | BD8: =Draft!AJ9 | BE8: =Draft!AK9 | BF8: =Draft!AL9 | BG8: =Draft!AM9 | BH8: =Draft!AN9 | BI8: =Draft!AO9
I9: =Draft!C9 -> FALSE | J9: 7 | K9: ='All Teams'!E120 -> -5.9528607 | L9: ='All Teams'!F120 -> 0.79635917 | M9: ='All Teams'!G120 -> -2.4038492 | N9: ='All Teams'!H120 -> -3.1350873 | O9: ='All Teams'!I120 -> 6.2369271 | P9: ='All Teams'!J120 -> -1.3810744 | Q9: ='All Teams'!K120 -> -5.2753818 | R9: ='All Teams'!L120 -> 0.18693412 | S9: ='All Teams'!M120 -> -0.35163867 | T9: {=if(Team!D$1=$J9,"-", countif(indirect(address(row($J$2)+ VLOOKUP(Team!D$1,$J$3:$J$14,1),COLUMN($K$2))):indirect(address(row($J$2)+ VLOOKUP(Team!D$1,$J$3:$J$14,1),COLUMN($S$2)))>indirect(address(row($J9),COLUMN($K$2))):indirect(address(row($J9),COLUMN($S$2))),TRUE()))} -> 6 | U9: =SUM(AR$22:AR$33)/99 -> 0.67676768 | V9: =SUMIF(K9:R9,">-2.5") -> 3.4352968 | W9: ='All Teams'!N120 -> 3.3428336 | X9: =Draft!D9 -> Anthony Edwards | Z9: =Draft!E9 -> Tyrese Maxey | AB9: =Draft!F9 -> Jaren Jackson Jr. | AD9: =Draft!G9 -> Myles Turner | AF9: =Draft!H9 -> Coby White | AH9: =Draft!I9 -> Jakob Poeltl | AJ9: =Draft!J9 -> Tari Eason | AL9: =Draft!R10 | AM9: =Draft!S10 | AN9: =Draft!T10 | AO9: =Draft!U10 | AP9: =Draft!V10 | AQ9: =Draft!W10 | AR9: =Draft!X10 | AS9: =Draft!Y10 | ... AW9: =Draft!AC10 | AX9: =Draft!K9 -> Cam Thomas | AY9: =Draft!L9 -> Brandin Podziemski | AZ9: =Draft!M9 -> Bennedict Mathurin | BA9: =Draft!N9 -> Aaron Nesmith | BB9: =Draft!O9 -> Cam Whitmore | BC9: =Draft!P9 -> Taylor Hendricks | BD9: =Draft!AJ10 | BE9: =Draft!AK10 | BF9: =Draft!AL10 | BG9: =Draft!AM10 | BH9: =Draft!AN10 | BI9: =Draft!AO10
I10: =Draft!C10 -> FALSE | J10: 8 | K10: ='All Teams'!E137 -> -8.4999978 | L10: ='All Teams'!F137 -> -8.260352 | M10: ='All Teams'!G137 -> 1.0971044 | N10: ='All Teams'!H137 -> -8.7277946 | O10: ='All Teams'!I137 -> -8.4510939 | P10: ='All Teams'!J137 -> 1.071839 | Q10: ='All Teams'!K137 -> 1.7067832 | R10: ='All Teams'!L137 -> -0.73045859 | S10: ='All Teams'!M137 -> 1.9545952 | T10: {=if(Team!D$1=$J10,"-", countif(indirect(address(row($J$2)+ VLOOKUP(Team!D$1,$J$3:$J$14,1),COLUMN($K$2))):indirect(address(row($J$2)+ VLOOKUP(Team!D$1,$J$3:$J$14,1),COLUMN($S$2)))>indirect(address(row($J10),COLUMN($K$2))):indirect(address(row($J10),COLUMN($S$2))),TRUE()))} -> 5 | U10: =SUM(AS$22:AS$33)/99 -> 0.73737374 | V10: =SUMIF(K10:R10,">-2.5") -> 3.145268 | W10: ='All Teams'!N137 -> -14.61334 | X10: =Draft!D10 -> Karl-Anthony Towns | Z10: =Draft!E10 -> Jalen Johnson | AB10: =Draft!F10 -> Franz Wagner | AD10: =Draft!G10 -> Zion Williamson | AF10: =Draft!H10 -> Ivica Zubac | AH10: =Draft!I10 -> Mark Williams | AJ10: =Draft!J10 -> Onyeka Okongwu | AL10: =Draft!R11 | AM10: =Draft!S11 | AN10: =Draft!T11 | AO10: =Draft!U11 | AP10: =Draft!V11 | AQ10: =Draft!W11 | AR10: =Draft!X11 | AS10: =Draft!Y11 | ... AW10: =Draft!AC11 | AX10: =Draft!K10 -> C.J. McCollum | AY10: =Draft!L10 -> Keyonte George | AZ10: =Draft!M10 -> D'Angelo Russell | BA10: =Draft!N10 -> Isaiah Jackson | BB10: =Draft!O10 -> Neemias Queta | BC10: =Draft!P10 -> Gradey Dick | BD10: =Draft!AJ11 | BE10: =Draft!AK11 | BF10: =Draft!AL11 | BG10: =Draft!AM11 | BH10: =Draft!AN11 | BI10: =Draft!AO11
F11: Input Draft Picks | I11: =Draft!C11 -> FALSE | J11: 9 | K11: ='All Teams'!E154 -> -37.864303 | L11: ='All Teams'!F154 -> -20.888239 | M11: ='All Teams'!G154 -> -28.567189 | N11: ='All Teams'!H154 -> -21.518432 | O11: ='All Teams'!I154 -> -38.882286 | P11: ='All Teams'!J154 -> -15.949106 | Q11: ='All Teams'!K154 -> 1.8485008 | R11: ='All Teams'!L154 -> -1.6771829 | S11: ='All Teams'!M154 -> 20.814628 | T11: {=if(Team!D$1=$J11,"-", countif(indirect(address(row($J$2)+ VLOOKUP(Team!D$1,$J$3:$J$14,1),COLUMN($K$2))):indirect(address(row($J$2)+ VLOOKUP(Team!D$1,$J$3:$J$14,1),COLUMN($S$2)))>indirect(address(row($J11),COLUMN($K$2))):indirect(address(row($J11),COLUMN($S$2))),TRUE()))} -> 7 | U11: =SUM(AT$22:AT$33)/99 -> 0.17171717 | V11: =SUMIF(K11:R11,">-2.5") -> 0.17131787 | W11: ='All Teams'!N154 -> -6.0699979 | X11: =Draft!D11 -> Devin Booker | Z11: =Draft!E11 -> Josh Giddey | AB11: =Draft!F11 -> Jamal Murray | AD11: =Draft!G11 -> Ja Morant | AF11: =Draft!H11 -> Jimmy Butler | AH11: =Draft!I11 -> Payton Pritchard | AJ11: =Draft!J11 -> Toumani Camara | AL11: =Draft!R12 | AM11: =Draft!S12 | AN11: =Draft!T12 | AO11: =Draft!U12 | AP11: =Draft!V12 | AQ11: =Draft!W12 | AR11: =Draft!X12 | AS11: =Draft!Y12 | ... AW11: =Draft!AC12 | AX11: =Draft!K11 -> Jalen Green | AY11: =Draft!L11 -> Nicolas Claxton | AZ11: =Draft!M11 -> Reed Sheppard | BA11: =Draft!N11 -> Davion Mitchell | BB11: =Draft!O11 -> Keegan Murray | BC11: =Draft!P11 -> Ace Bailey | BD11: =Draft!AJ12 | BE11: =Draft!AK12 | BF11: =Draft!AL12 | BG11: =Draft!AM12 | BH11: =Draft!AN12 | BI11: =Draft!AO12
F12: 3RR | G12: TRUE | I12: =Draft!C12 -> FALSE | J12: 10 | K12: ='All Teams'!E171 -> -31.553586 | L12: ='All Teams'!F171 -> -17.406866 | M12: ='All Teams'!G171 -> -23.805991 | N12: ='All Teams'!H171 -> -17.932027 | O12: ='All Teams'!I171 -> -32.401905 | P12: ='All Teams'!J171 -> -13.290922 | Q12: ='All Teams'!K171 -> 1.3061477 | R12: ='All Teams'!L171 -> -5.2055638 | S12: ='All Teams'!M171 -> 17.345524 | T12: {=if(Team!D$1=$J12,"-", countif(indirect(address(row($J$2)+ VLOOKUP(Team!D$1,$J$3:$J$14,1),COLUMN($K$2))):indirect(address(row($J$2)+ VLOOKUP(Team!D$1,$J$3:$J$14,1),COLUMN($S$2)))>indirect(address(row($J12),COLUMN($K$2))):indirect(address(row($J12),COLUMN($S$2))),TRUE()))} -> 7 | U12: =SUM(AU$22:AU$33)/99 -> 0.5959596 | V12: =SUMIF(K12:R12,">-2.5") -> 1.3061477 | W12: ='All Teams'!N171 -> -3.8365097 | X12: =Draft!D12 -> Domantas Sabonis | Z12: =Draft!E12 -> Jalen Williams | AB12: =Draft!F12 -> Paolo Banchero | AD12: =Draft!G12 -> Jaylen Brown | AF12: =Draft!H12 -> Desmond Bane | AH12: =Draft!I12 -> Jarrett Allen | AJ12: =Draft!J12 -> Brandon Ingram | AL12: =Draft!R13 | AM12: =Draft!S13 | AN12: =Draft!T13 | AO12: =Draft!U13 | AP12: =Draft!V13 | AQ12: =Draft!W13 | AR12: =Draft!X13 | AS12: =Draft!Y13 | ... AW12: =Draft!AC13 | AX12: =Draft!K12 -> Mikal Bridges | AY12: =Draft!L12 -> Aaron Gordon | AZ12: =Draft!M12 -> Norman Powell | BA12: =Draft!N12 -> Kel'el Ware | BB12: =Draft!O12 -> De'Andre Hunter | BC12: =Draft!P12 -> Dennis Schroder | BD12: =Draft!AJ13 | BE12: =Draft!AK13 | BF12: =Draft!AL13 | BG12: =Draft!AM13 | BH12: =Draft!AN13 | BI12: =Draft!AO13
F13: Current Pick #1 | G13: 145 | I13: =Draft!C13 -> FALSE | J13: 11 | K13: ='All Teams'!E188 -> -37.864303 | L13: ='All Teams'!F188 -> -20.888239 | M13: ='All Teams'!G188 -> -28.567189 | N13: ='All Teams'!H188 -> -21.518432 | O13: ='All Teams'!I188 -> -38.882286 | P13: ='All Teams'!J188 -> -15.949106 | Q13: ='All Teams'!K188 -> -4.7756018 | R13: ='All Teams'!L188 -> 6.407941 | S13: ='All Teams'!M188 -> 20.814628 | T13: {=if(Team!D$1=$J13,"-", countif(indirect(address(row($J$2)+ VLOOKUP(Team!D$1,$J$3:$J$14,1),COLUMN($K$2))):indirect(address(row($J$2)+ VLOOKUP(Team!D$1,$J$3:$J$14,1),COLUMN($S$2)))>indirect(address(row($J13),COLUMN($K$2))):indirect(address(row($J13),COLUMN($S$2))),TRUE()))} -> 7 | U13: =SUM(AV$22:AV$33)/99 -> 0.19191919 | V13: =SUMIF(K13:R13,">-2.5") -> 6.407941 | W13: ='All Teams'!N188 -> 8.3093883 | X13: =Draft!D13 -> Trae Young | Z13: =Draft!E13 -> Derrick White | AB13: =Draft!F13 -> Chet Holmgren | AD13: =Draft!G13 -> Trey Murphy | AF13: =Draft!H13 -> Zach LaVine | AH13: =Draft!I13 -> Tyler Herro | AJ13: =Draft!J13 -> Josh Hart | AL13: =Draft!R14 | AM13: =Draft!S14 | AN13: =Draft!T14 | AO13: =Draft!U14 | AP13: =Draft!V14 | AQ13: =Draft!W14 | AR13: =Draft!X14 | AS13: =Draft!Y14 | ... AW13: =Draft!AC14 | AX13: =Draft!K13 -> James Harden | AY13: =Draft!L13 -> Chris Paul | AZ13: =Draft!M13 -> Jalen Suggs | BA13: =Draft!N13 -> Brook Lopez | BB13: =Draft!O13 -> Dereck Lively II | BC13: =Draft!P13 -> Jerami Grant | BD13: =Draft!AJ14 | BE13: =Draft!AK14 | BF13: =Draft!AL14 | BG13: =Draft!AM14 | BH13: =Draft!AN14 | BI13: =Draft!AO14
F14: Your Next Pick # | G14: =IFERROR(__xludf.DUMMYFUNCTION("MIN(FILTER(IF(G12,Draft!D17:O17,Draft!D16:O16),IF(G12,Draft!D17:O17,Draft!D16:O16)>G13))"),"#N/A") -> #N/A | I14: =Draft!C14 -> FALSE | J14: 12 | K14: ='All Teams'!E205 -> -34.708945 | L14: ='All Teams'!F205 -> -19.147552 | M14: ='All Teams'!G205 -> -26.18659 | N14: ='All Teams'!H205 -> -19.725229 | O14: ='All Teams'!I205 -> -35.642096 | P14: ='All Teams'!J205 -> -14.620014 | Q14: ='All Teams'!K205 -> -2.5876042 | R14: ='All Teams'!L205 -> -1.0314651 | S14: ='All Teams'!M205 -> 19.080076 | T14: {=if(Team!D$1=$J14,"-", countif(indirect(address(row($J$2)+ VLOOKUP(Team!D$1,$J$3:$J$14,1),COLUMN($K$2))):indirect(address(row($J$2)+ VLOOKUP(Team!D$1,$J$3:$J$14,1),COLUMN($S$2)))>indirect(address(row($J14),COLUMN($K$2))):indirect(address(row($J14),COLUMN($S$2))),TRUE()))} -> 7 | U14: =SUM(AW$22:AW$33)/99 -> 0.49494949 | V14: =SUMIF(K14:R14,">-2.5") -> -1.0314651 | W14: ='All Teams'!N205 -> 5.3315954 | X14: =Draft!D14 -> Anthony Davis | Z14: =Draft!E14 -> LaMelo Ball | AB14: =Draft!F14 -> Amen Thompson | AD14: =Draft!G14 -> De'Aaron Fox | AF14: =Draft!H14 -> Deni Avdija | AH14: =Draft!I14 -> DeMar DeRozan | AJ14: =Draft!J14 -> Darius Garland | AL14: =Draft!R15 | AM14: =Draft!S15 | AN14: =Draft!T15 | AO14: =Draft!U15 | AP14: =Draft!V15 | AQ14: =Draft!W15 | AR14: =Draft!X15 | AS14: =Draft!Y15 | ... AW14: =Draft!AC15 | AX14: =Draft!K14 -> Bradley Beal | AY14: =Draft!L14 -> Zach Edey | AZ14: =Draft!M14 -> Devin Vassell | BA14: =Draft!N14 -> Herb Jones | BB14: =Draft!O14 -> Miles McBride | BC14: =Draft!P14 -> Bilal Coulibaly | BD14: =Draft!AJ15 | BE14: =Draft!AK15 | BF14: =Draft!AL15 | BG14: =Draft!AM15 | BH14: =Draft!AN15 | BI14: =Draft!AO15
F15: Player Name | G15: Ace Bailey | J15: Avg Zscore Available | K15: =SUM(Y20:Y1015)/ COUNT($K$20:$K1015) -> -0.061992885 | L15: =SUM(Z20:Z1015)/ COUNT($K$20:$K1015) -> -0.01751266 | M15: =SUM(AA20:AA1015)/ COUNT($K$20:$K1015) -> -0.016707343 | N15: =SUM(AB20:AB1015)/ COUNT($K$20:$K1015) -> 0.0067793346 | O15: =SUM(AC20:AC1015)/ COUNT($K$20:$K1015) -> 0.091902909 | P15: =SUM(AD20:AD1015)/ COUNT($K$20:$K1015) -> -0.010579725 | Q15: =SUM(AE20:AE1015)/ COUNT($K$20:$K1015) -> -0.1525195 | R15: =SUM(AF20:AF1015)/ COUNT($K$20:$K1015) -> 0.029303554 | S15: =SUM(AG20:AG1015)/ COUNT($K$20:$K1015) -> -0.04611196 | X15: =IF($G$12,Draft!D17,Draft!D16) -> 4 | Z15: =IF($G$12,Draft!E17,Draft!E16) -> 21 | AB15: =IF($G$12,Draft!F17,Draft!F16) -> 33 | AD15: =IF($G$12,Draft!G17,Draft!G16) -> 40 | AF15: =IF($G$12,Draft!H17,Draft!H16) -> 57 | AH15: =IF($G$12,Draft!I17,Draft!I16) -> 64 | AJ15: =IF($G$12,Draft!J17,Draft!J16) -> 81 | AL15: =IF($G$12,Draft!R16,Draft!R16) | AN15: =IF($G$12,Draft!T16,Draft!T16) | AP15: =IF($G$12,Draft!V16,Draft!V16) | AR15: =IF($G$12,Draft!X16,Draft!X16) | AT15: =IF($G$12,Draft!Z16,Draft!Z16) | AV15: =IF($G$12,Draft!AB16,Draft!AB16) | AX15: =IF($G$12,Draft!K17,Draft!K16) -> 88 | AY15: =IF($G$12,Draft!L17,Draft!L16) -> 105 | AZ15: =IF($G$12,Draft!M17,Draft!M16) -> 112 | BA15: =IF($G$12,Draft!N17,Draft!N16) -> 129 | BB15: =IF($G$12,Draft!O17,Draft!O16) -> 136 | BC15: =IF($G$12,Draft!P17,Draft!P16) -> 159 | BD15: =IF($G$12,Draft!Q17,Draft!Q16) -> 154
I16: -1 Cat | J16: -2 Cat | K16: PTS | L16: 3P | M16: REB | N16: AST | O16: STL | P16: BLK | Q16: FG% | R16: FT% | S16: TO | T16: PG | U16: SG | V16: SF | W16: PF | X16: C | AA16: Sort by | AC16: Remove Drafted | AF16: Top | AH16: Projections
I17: TRUE | J17: FALSE | K17: 1 | L17: 1 | M17: 1 | N17: 1 | O17: 1 | P17: 1 | Q17: 1 | R17: 1 | S17: 0.25 | T17: PG | U17: SG | V17: SF | W17: PF | X17: C | AA17: PuntV | AC17: FALSE | AF17: 156 | AH17: HASHTAG
A19: W18 | B19: W19 | C19: W20 | D19: Total | F19: Team | G19: PuntRank | H19: LgRank | I19: ADP | J19: Player | K19: GP | L19: Pos | M19: LeagV | N19: PuntV | O19: Punt+ | P19: PTS | Q19: 3P | R19: REB | S19: AST | T19: STL | U19: BLK | V19: FG% | W19: FT% | X19: TO | Y19: z p/g | Z19: z 3/g | AA19: z r/g | AB19: z a/g | AC19: z s/g | AD19: z b/g | AE19: z fg% | AF19: z ft% | AG19: z to/g
A20: =VLOOKUP($F20,UpdateHashtag!$V$3:$Y$32,COLUMN(B$15),0) -> #N/A | B20: =VLOOKUP($F20,UpdateHashtag!$V$3:$Y$32,COLUMN(C$13),0) -> #N/A | C20: =VLOOKUP($F20,UpdateHashtag!$V$3:$Y$32,COLUMN(D$13),0) -> #N/A | D20: =SUM(A20:C20) -> #N/A | F20: =VLOOKUP(J20,UpdateBBM!$C$2:E1015,3,0) -> SAS | G20: 1 | H20: =IFERROR(__xludf.DUMMYFUNCTION("Filter('NO USAR3'!B5:AA420,IF('NO USAR3'!AB5:AB420="""",FALSE,TRUE),NOT(COUNTIF('NO USAR3'!A5:A200,'NO USAR3'!D5:D420)),IF('NO USAR3'!B5:B420>AF17,FALSE,TRUE))"),1.0) -> 1 | I20: =IFERROR(__xludf.DUMMYFUNCTION("""COMPUTED_VALUE"""),2.0) -> 2 | J20: =IFERROR(__xludf.DUMMYFUNCTION("""COMPUTED_VALUE"""),"Victor Wembanyama") -> Victor Wembanyama | K20: =IFERROR(__xludf.DUMMYFUNCTION("""COMPUTED_VALUE"""),71.0) -> 71 | L20: =IFERROR(__xludf.DUMMYFUNCTION("""COMPUTED_VALUE"""),"C") -> C | M20: =IFERROR(__xludf.DUMMYFUNCTION("""COMPUTED_VALUE"""),10.595392267107387) -> 10.595392 | N20: =IFERROR(__xludf.DUMMYFUNCTION("""COMPUTED_VALUE"""),10.595392267107387) -> 10.595392 | O20: =IFERROR(__xludf.DUMMYFUNCTION("""COMPUTED_VALUE"""),0.0) -> 0 | P20: =IFERROR(__xludf.DUMMYFUNCTION("""COMPUTED_VALUE"""),24.1) -> 24.1 | Q20: =IFERROR(__xludf.DUMMYFUNCTION("""COMPUTED_VALUE"""),2.0) -> 2 | R20: =IFERROR(__xludf.DUMMYFUNCTION("""COMPUTED_VALUE"""),11.6) -> 11.6 | S20: =IFERROR(__xludf.DUMMYFUNCTION("""COMPUTED_VALUE"""),4.4) -> 4.4 | T20: =IFERROR(__xludf.DUMMYFUNCTION("""COMPUTED_VALUE"""),1.4) -> 1.4 | U20: =IFERROR(__xludf.DUMMYFUNCTION("""COMPUTED_VALUE"""),3.9) -> 3.9 | V20: =IFERROR(__xludf.DUMMYFUNCTION("""COMPUTED_VALUE"""),0.473) -> 0.473 | W20: =IFERROR(__xludf.DUMMYFUNCTION("""COMPUTED_VALUE"""),0.802) -> 0.802 | X20: =IFERROR(__xludf.DUMMYFUNCTION("""COMPUTED_VALUE"""),3.4) -> 3.4 | Y20: =IFERROR(__xludf.DUMMYFUNCTION("""COMPUTED_VALUE"""),1.1982586520799683) -> 1.1982587 | Z20: =IFERROR(__xludf.DUMMYFUNCTION("""COMPUTED_VALUE"""),0.2497993995559884) -> 0.2497994 | AA20: =IFERROR(__xludf.DUMMYFUNCTION("""COMPUTED_VALUE"""),2.169659944607731) -> 2.1696599 | AB20: =IFERROR(__xludf.DUMMYFUNCTION("""COMPUTED_VALUE"""),0.2115152388471211) -> 0.21151524 | AC20: =IFERROR(__xludf.DUMMYFUNCTION("""COMPUTED_VALUE"""),1.4068669802785894) -> 1.406867 | AD20: =IFERROR(__xludf.DUMMYFUNCTION("""COMPUTED_VALUE"""),5.628262228999039) -> 5.6282622 | AE20: =IFERROR(__xludf.DUMMYFUNCTION("""COMPUTED_VALUE"""),-0.5205826258886787) -> -0.52058263 | AF20: =IFERROR(__xludf.DUMMYFUNCTION("""COMPUTED_VALUE"""),0.14053098793907753) -> 0.14053099 | AG20: =IFERROR(__xludf.DUMMYFUNCTION("""COMPUTED_VALUE"""),-0.40950116520012636) -> -0.40950117 | AL20: 1 | AM20: 2 | AN20: 3 | AO20: 4 | AP20: 5 | AQ20: 6 | AR20: 7 | AS20: 8 | AT20: 9 | AU20: 10 | AV20: 11 | AW20: 12
A21: =VLOOKUP($F21,UpdateHashtag!$V$3:$Y$32,COLUMN(B$15),0) -> 3 | B21: =VLOOKUP($F21,UpdateHashtag!$V$3:$Y$32,COLUMN(C$13),0) -> 4 | C21: =VLOOKUP($F21,UpdateHashtag!$V$3:$Y$32,COLUMN(D$13),0) -> 3 | D21: =SUM(A21:C21) -> 10 | F21: =VLOOKUP(J21,UpdateBBM!$C$2:E1015,3,0) -> LAL | G21: 2 | H21: =IFERROR(__xludf.DUMMYFUNCTION("""COMPUTED_VALUE"""),2.0) -> 2 | I21: =IFERROR(__xludf.DUMMYFUNCTION("""COMPUTED_VALUE"""),3.8) -> 3.8 | J21: =IFERROR(__xludf.DUMMYFUNCTION("""COMPUTED_VALUE"""),"Luka Doncic") -> Luka Doncic | K21: =IFERROR(__xludf.DUMMYFUNCTION("""COMPUTED_VALUE"""),66.0) -> 66 | L21: =IFERROR(__xludf.DUMMYFUNCTION("""COMPUTED_VALUE"""),"PG,SG") -> PG,SG | M21: =IFERROR(__xludf.DUMMYFUNCTION("""COMPUTED_VALUE"""),10.094731628301643) -> 10.094732 | N21: =IFERROR(__xludf.DUMMYFUNCTION("""COMPUTED_VALUE"""),10.094731628301643) -> 10.094732 | O21: =IFERROR(__xludf.DUMMYFUNCTION("""COMPUTED_VALUE"""),0.0) -> 0 | P21: =IFERROR(__xludf.DUMMYFUNCTION("""COMPUTED_VALUE"""),34.4) -> 34.4 | Q21: =IFERROR(__xludf.DUMMYFUNCTION("""COMPUTED_VALUE"""),4.1) -> 4.1 | R21: =IFERROR(__xludf.DUMMYFUNCTION("""COMPUTED_VALUE"""),9.3) -> 9.3 | S21: =IFERROR(__xludf.DUMMYFUNCTION("""COMPUTED_VALUE"""),9.9) -> 9.9 | T21: =IFERROR(__xludf.DUMMYFUNCTION("""COMPUTED_VALUE"""),1.4) -> 1.4 | U21: =IFERROR(__xludf.DUMMYFUNCTION("""COMPUTED_VALUE"""),0.5) -> 0.5 | V21: =IFERROR(__xludf.DUMMYFUNCTION("""COMPUTED_VALUE"""),0.491) -> 0.491 | W21: =IFERROR(__xludf.DUMMYFUNCTION("""COMPUTED_VALUE"""),0.792) -> 0.792 | X21: =IFERROR(__xludf.DUMMYFUNCTION("""COMPUTED_VALUE"""),3.8) -> 3.8 | Y21: =IFERROR(__xludf.DUMMYFUNCTION("""COMPUTED_VALUE"""),3.05893325429639) -> 3.0589333 | Z21: =IFERROR(__xludf.DUMMYFUNCTION("""COMPUTED_VALUE"""),2.3398096792183596) -> 2.3398097 | AA21: =IFERROR(__xludf.DUMMYFUNCTION("""COMPUTED_VALUE"""),1.2674534087333724) -> 1.2674534 | AB21: =IFERROR(__xludf.DUMMYFUNCTION("""COMPUTED_VALUE"""),2.7174126120644333) -> 2.7174126 | AC21: =IFERROR(__xludf.DUMMYFUNCTION("""COMPUTED_VALUE"""),1.4068669802785894) -> 1.406867 | AD21: =IFERROR(__xludf.DUMMYFUNCTION("""COMPUTED_VALUE"""),-0.4371236407912776) -> -0.43712364 | AE21: =IFERROR(__xludf.DUMMYFUNCTION("""COMPUTED_VALUE"""),-0.15852282562441422) -> -0.15852283 | AF21: =IFERROR(__xludf.DUMMYFUNCTION("""COMPUTED_VALUE"""),-0.1000978398738095) -> -0.10009784 | AG21: =IFERROR(__xludf.DUMMYFUNCTION("""COMPUTED_VALUE"""),-0.508694019104073) -> -0.50869402 | AK21: % Games/Week | AL21: Categories won | AX21: Round | AY21: Player Name | BA21: PTS | BB21: 3P | BC21: REB | BD21: AST | BE21: STL | BF21: BLK | BG21: FG% | BH21: FT% | BI21: TO | BJ21: POS | BK21: Count | BL21: POS
A22: =VLOOKUP($F22,UpdateHashtag!$V$3:$Y$32,COLUMN(B$15),0) -> 3 | B22: =VLOOKUP($F22,UpdateHashtag!$V$3:$Y$32,COLUMN(C$13),0) -> 4 | C22: =VLOOKUP($F22,UpdateHashtag!$V$3:$Y$32,COLUMN(D$13),0) -> 4 | D22: =SUM(A22:C22) -> 11 | F22: =VLOOKUP(J22,UpdateBBM!$C$2:E1015,3,0) -> DEN | G22: 3 | H22: =IFERROR(__xludf.DUMMYFUNCTION("""COMPUTED_VALUE"""),3.0) -> 3 | I22: =IFERROR(__xludf.DUMMYFUNCTION("""COMPUTED_VALUE"""),2.4) -> 2.4 | J22: =IFERROR(__xludf.DUMMYFUNCTION("""COMPUTED_VALUE"""),"Nikola Jokic") -> Nikola Jokic | K22: =IFERROR(__xludf.DUMMYFUNCTION("""COMPUTED_VALUE"""),71.0) -> 71 | L22: =IFERROR(__xludf.DUMMYFUNCTION("""COMPUTED_VALUE"""),"C") -> C | M22: =IFERROR(__xludf.DUMMYFUNCTION("""COMPUTED_VALUE"""),10.047144673140297) -> 10.047145 | N22: =IFERROR(__xludf.DUMMYFUNCTION("""COMPUTED_VALUE"""),10.047144673140297) -> 10.047145 | O22: =IFERROR(__xludf.DUMMYFUNCTION("""COMPUTED_VALUE"""),0.0) -> 0 | P22: =IFERROR(__xludf.DUMMYFUNCTION("""COMPUTED_VALUE"""),26.7) -> 26.7 | Q22: =IFERROR(__xludf.DUMMYFUNCTION("""COMPUTED_VALUE"""),1.1) -> 1.1 | R22: =IFERROR(__xludf.DUMMYFUNCTION("""COMPUTED_VALUE"""),12.1) -> 12.1 | S22: =IFERROR(__xludf.DUMMYFUNCTION("""COMPUTED_VALUE"""),9.0) -> 9 | T22: =IFERROR(__xludf.DUMMYFUNCTION("""COMPUTED_VALUE"""),1.4) -> 1.4 | U22: =IFERROR(__xludf.DUMMYFUNCTION("""COMPUTED_VALUE"""),0.9) -> 0.9 | V22: =IFERROR(__xludf.DUMMYFUNCTION("""COMPUTED_VALUE"""),0.585) -> 0.585 | W22: =IFERROR(__xludf.DUMMYFUNCTION("""COMPUTED_VALUE"""),0.819) -> 0.819 | X22: =IFERROR(__xludf.DUMMYFUNCTION("""COMPUTED_VALUE"""),3.0) -> 3 | Y22: =IFERROR(__xludf.DUMMYFUNCTION("""COMPUTED_VALUE"""),1.66794350312489) -> 1.6679435 | Z22: =IFERROR(__xludf.DUMMYFUNCTION("""COMPUTED_VALUE"""),-0.645919291727885) -> -0.64591929 | AA22: =IFERROR(__xludf.DUMMYFUNCTION("""COMPUTED_VALUE"""),2.3657918002325915) -> 2.3657918 | AB22: =IFERROR(__xludf.DUMMYFUNCTION("""COMPUTED_VALUE"""),2.307356678265237) -> 2.3073567 | AC22: =IFERROR(__xludf.DUMMYFUNCTION("""COMPUTED_VALUE"""),1.4068669802785894) -> 1.406867 | AD22: =IFERROR(__xludf.DUMMYFUNCTION("""COMPUTED_VALUE"""),0.27645116741934783) -> 0.27645117 | AE22: =IFERROR(__xludf.DUMMYFUNCTION("""COMPUTED_VALUE"""),1.8383090470084225) -> 1.838309 | AF22: =IFERROR(__xludf.DUMMYFUNCTION("""COMPUTED_VALUE"""),0.4947338081073987) -> 0.49473381 | AG22: =IFERROR(__xludf.DUMMYFUNCTION("""COMPUTED_VALUE"""),-0.31030831129617975) -> -0.31030831 | AK22: 100 | AL22: {=if(AL$20=$J3,"-", countif(indirect(address(row($J$2)+ VLOOKUP(AL$20,$J$3:$J$14,1),COLUMN($K$4))):indirect(address(row($J$2)+ VLOOKUP(AL$20,$J$3:$J$14,1),COLUMN($S$2)))>indirect(address(row($J3),COLUMN($K$2))):indirect(address(row($J3),COLUMN($S$2))),TRUE()))} -> - | AM22: {=if(AM$20=$J3,"-", countif(indirect(address(row($J$2)+ VLOOKUP(AM$20,$J$3:$J$14,1),COLUMN($K$4))):indirect(address(row($J$2)+ VLOOKUP(AM$20,$J$3:$J$14,1),COLUMN($S$2)))>indirect(address(row($J3),COLUMN($K$2))):indirect(address(row($J3),COLUMN($S$2))),TRUE()))} -> 3 | AN22: {=if(AN$20=$J3,"-", countif(indirect(address(row($J$2)+ VLOOKUP(AN$20,$J$3:$J$14,1),COLUMN($K$4))):indirect(address(row($J$2)+ VLOOKUP(AN$20,$J$3:$J$14,1),COLUMN($S$2)))>indirect(address(row($J3),COLUMN($K$2))):indirect(address(row($J3),COLUMN($S$2))),TRUE()))} -> 2 | AO22: {=if(AO$20=$J3,"-", countif(indirect(address(row($J$2)+ VLOOKUP(AO$20,$J$3:$J$14,1),COLUMN($K$4))):indirect(address(row($J$2)+ VLOOKUP(AO$20,$J$3:$J$14,1),COLUMN($S$2)))>indirect(address(row($J3),COLUMN($K$2))):indirect(address(row($J3),COLUMN($S$2))),TRUE()))} -> 7 | AP22: {=if(AP$20=$J3,"-", countif(indirect(address(row($J$2)+ VLOOKUP(AP$20,$J$3:$J$14,1),COLUMN($K$4))):indirect(address(row($J$2)+ VLOOKUP(AP$20,$J$3:$J$14,1),COLUMN($S$2)))>indirect(address(row($J3),COLUMN($K$2))):indirect(address(row($J3),COLUMN($S$2))),TRUE()))} -> 2 | AQ22: {=if(AQ$20=$J3,"-", countif(indirect(address(row($J$2)+ VLOOKUP(AQ$20,$J$3:$J$14,1),COLUMN($K$4))):indirect(address(row($J$2)+ VLOOKUP(AQ$20,$J$3:$J$14,1),COLUMN($S$2)))>indirect(address(row($J3),COLUMN($K$2))):indirect(address(row($J3),COLUMN($S$2))),TRUE()))} -> 2 | AR22: {=if(AR$20=$J3,"-", countif(indirect(address(row($J$2)+ VLOOKUP(AR$20,$J$3:$J$14,1),COLUMN($K$4))):indirect(address(row($J$2)+ VLOOKUP(AR$20,$J$3:$J$14,1),COLUMN($S$2)))>indirect(address(row($J3),COLUMN($K$2))):indirect(address(row($J3),COLUMN($S$2))),TRUE()))} -> 6 | AS22: {=if(AS$20=$J3,"-", countif(indirect(address(row($J$2)+ VLOOKUP(AS$20,$J$3:$J$14,1),COLUMN($K$4))):indirect(address(row($J$2)+ VLOOKUP(AS$20,$J$3:$J$14,1),COLUMN($S$2)))>indirect(address(row($J3),COLUMN($K$2))):indirect(address(row($J3),COLUMN($S$2))),TRUE()))} -> 7 | ... AW22: {=if(AW$20=$J3,"-", countif(indirect(address(row($J$2)+ VLOOKUP(AW$20,$J$3:$J$14,1),COLUMN($K$4))):indirect(address(row($J$2)+ VLOOKUP(AW$20,$J$3:$J$14,1),COLUMN($S$2)))>indirect(address(row($J3),COLUMN($K$2))):indirect(address(row($J3),COLUMN($S$2))),TRUE()))} -> 1 | AX22: 1 | AY22: {=INDIRECT("Draft!D"&TEXT(VLOOKUP(TRUE,I3:J14,2,0)+2,"0"))} -> Luka Doncic | BA22: =IF($AY22="","", VLOOKUP($AY22,'Final Update'!$P$21:$AD1015,Column(G1),False)) -> 34.4 | BB22: =IF($AY22="","", VLOOKUP($AY22,'Final Update'!$P$21:$AD1015,Column(H1),False)) -> 4.1 | BC22: =IF($AY22="","", VLOOKUP($AY22,'Final Update'!$P$21:$AD1015,Column(I1),False)) -> 9.3 | BD22: =IF($AY22="","", VLOOKUP($AY22,'Final Update'!$P$21:$AD1015,Column(J1),False)) -> 9.9 | BE22: =IF($AY22="","", VLOOKUP($AY22,'Final Update'!$P$21:$AD1015,Column(K1),False)) -> 1.4 | BF22: =IF($AY22="","", VLOOKUP($AY22,'Final Update'!$P$21:$AD1015,Column(L1),False)) -> 0.5 | BG22: =IF($AY22="","", VLOOKUP($AY22,'Final Update'!$P$21:$AD1015,Column(M1),False)) -> 0.491 | BH22: =IF($AY22="","", VLOOKUP($AY22,'Final Update'!$P$21:$AD1015,Column(N1),False)) -> 0.792 | BI22: =IF($AY22="","", VLOOKUP($AY22,'Final Update'!$P$21:$AD1015,Column(O1),False)) -> 3.8 | BJ22: =IF($AY22="","", VLOOKUP($AY22,'Final Update'!$P$21:$AD1015,Column(C1),False)) -> PG,SG | BK22: {=COUNTIF(FIND(BL22,$BJ$22:$BJ$33),">0")} -> 6 | BL22: PG
A23: =VLOOKUP($F23,UpdateHashtag!$V$3:$Y$32,COLUMN(B$15),0) -> 4 | B23: =VLOOKUP($F23,UpdateHashtag!$V$3:$Y$32,COLUMN(C$13),0) -> 4 | C23: =VLOOKUP($F23,UpdateHashtag!$V$3:$Y$32,COLUMN(D$13),0) -> 3 | D23: =SUM(A23:C23) -> 11 | F23: =VLOOKUP(J23,UpdateBBM!$C$2:E1015,3,0) -> OKC | G23: 4 | H23: =IFERROR(__xludf.DUMMYFUNCTION("""COMPUTED_VALUE"""),4.0) -> 4 | I23: =IFERROR(__xludf.DUMMYFUNCTION("""COMPUTED_VALUE"""),4.5) -> 4.5 | J23: =IFERROR(__xludf.DUMMYFUNCTION("""COMPUTED_VALUE"""),"Shai Gilgeous-Alexander") -> Shai Gilgeous-Alexander | K23: =IFERROR(__xludf.DUMMYFUNCTION("""COMPUTED_VALUE"""),71.0) -> 71 | L23: =IFERROR(__xludf.DUMMYFUNCTION("""COMPUTED_VALUE"""),"PG") -> PG | M23: =IFERROR(__xludf.DUMMYFUNCTION("""COMPUTED_VALUE"""),9.640422694612987) -> 9.6404227 | N23: =IFERROR(__xludf.DUMMYFUNCTION("""COMPUTED_VALUE"""),9.640422694612987) -> 9.6404227 | O23: =IFERROR(__xludf.DUMMYFUNCTION("""COMPUTED_VALUE"""),0.0) -> 0 | P23: =IFERROR(__xludf.DUMMYFUNCTION("""COMPUTED_VALUE"""),29.9) -> 29.9 | Q23: =IFERROR(__xludf.DUMMYFUNCTION("""COMPUTED_VALUE"""),1.4) -> 1.4 | R23: =IFERROR(__xludf.DUMMYFUNCTION("""COMPUTED_VALUE"""),5.1) -> 5.1 | S23: =IFERROR(__xludf.DUMMYFUNCTION("""COMPUTED_VALUE"""),6.5) -> 6.5 | T23: =IFERROR(__xludf.DUMMYFUNCTION("""COMPUTED_VALUE"""),1.9) -> 1.9 | U23: =IFERROR(__xludf.DUMMYFUNCTION("""COMPUTED_VALUE"""),0.9) -> 0.9 | V23: =IFERROR(__xludf.DUMMYFUNCTION("""COMPUTED_VALUE"""),0.524) -> 0.524 | W23: =IFERROR(__xludf.DUMMYFUNCTION("""COMPUTED_VALUE"""),0.88) -> 0.88 | X23: =IFERROR(__xludf.DUMMYFUNCTION("""COMPUTED_VALUE"""),2.4) -> 2.4 | Y23: =IFERROR(__xludf.DUMMYFUNCTION("""COMPUTED_VALUE"""),2.2460171659494095) -> 2.2460172 | Z23: =IFERROR(__xludf.DUMMYFUNCTION("""COMPUTED_VALUE"""),-0.34734639463326067) -> -0.34734639 | AA23: =IFERROR(__xludf.DUMMYFUNCTION("""COMPUTED_VALUE"""),-0.38005417851545714) -> -0.38005418 | AB23: =IFERROR(__xludf.DUMMYFUNCTION("""COMPUTED_VALUE"""),1.1683124177119129) -> 1.1683124 | AC23: =IFERROR(__xludf.DUMMYFUNCTION("""COMPUTED_VALUE"""),3.066530371075986) -> 3.0665304 | AD23: =IFERROR(__xludf.DUMMYFUNCTION("""COMPUTED_VALUE"""),0.27645116741934783) -> 0.27645117 | AE23: =IFERROR(__xludf.DUMMYFUNCTION("""COMPUTED_VALUE"""),0.6197828012717082) -> 0.6197828 | AF23: =IFERROR(__xludf.DUMMYFUNCTION("""COMPUTED_VALUE"""),2.772194196258142) -> 2.7721942 | AG23: =IFERROR(__xludf.DUMMYFUNCTION("""COMPUTED_VALUE"""),-0.1615190304402598) -> -0.16151903 | AK23: 100 | AL23: {=if(AL$20=$J4,"-", countif(indirect(address(row($J$2)+ VLOOKUP(AL$20,$J$3:$J$14,1),COLUMN($K$4))):indirect(address(row($J$2)+ VLOOKUP(AL$20,$J$3:$J$14,1),COLUMN($S$2)))>indirect(address(row($J4),COLUMN($K$2))):indirect(address(row($J4),COLUMN($S$2))),TRUE()))} -> 6 | AM23: {=if(AM$20=$J4,"-", countif(indirect(address(row($J$2)+ VLOOKUP(AM$20,$J$3:$J$14,1),COLUMN($K$4))):indirect(address(row($J$2)+ VLOOKUP(AM$20,$J$3:$J$14,1),COLUMN($S$2)))>indirect(address(row($J4),COLUMN($K$2))):indirect(address(row($J4),COLUMN($S$2))),TRUE()))} -> - | AN23: {=if(AN$20=$J4,"-", countif(indirect(address(row($J$2)+ VLOOKUP(AN$20,$J$3:$J$14,1),COLUMN($K$4))):indirect(address(row($J$2)+ VLOOKUP(AN$20,$J$3:$J$14,1),COLUMN($S$2)))>indirect(address(row($J4),COLUMN($K$2))):indirect(address(row($J4),COLUMN($S$2))),TRUE()))} -> 1 | AO23: {=if(AO$20=$J4,"-", countif(indirect(address(row($J$2)+ VLOOKUP(AO$20,$J$3:$J$14,1),COLUMN($K$4))):indirect(address(row($J$2)+ VLOOKUP(AO$20,$J$3:$J$14,1),COLUMN($S$2)))>indirect(address(row($J4),COLUMN($K$2))):indirect(address(row($J4),COLUMN($S$2))),TRUE()))} -> 6 | AP23: {=if(AP$20=$J4,"-", countif(indirect(address(row($J$2)+ VLOOKUP(AP$20,$J$3:$J$14,1),COLUMN($K$4))):indirect(address(row($J$2)+ VLOOKUP(AP$20,$J$3:$J$14,1),COLUMN($S$2)))>indirect(address(row($J4),COLUMN($K$2))):indirect(address(row($J4),COLUMN($S$2))),TRUE()))} -> 1 | AQ23: {=if(AQ$20=$J4,"-", countif(indirect(address(row($J$2)+ VLOOKUP(AQ$20,$J$3:$J$14,1),COLUMN($K$4))):indirect(address(row($J$2)+ VLOOKUP(AQ$20,$J$3:$J$14,1),COLUMN($S$2)))>indirect(address(row($J4),COLUMN($K$2))):indirect(address(row($J4),COLUMN($S$2))),TRUE()))} -> 0 | AR23: {=if(AR$20=$J4,"-", countif(indirect(address(row($J$2)+ VLOOKUP(AR$20,$J$3:$J$14,1),COLUMN($K$4))):indirect(address(row($J$2)+ VLOOKUP(AR$20,$J$3:$J$14,1),COLUMN($S$2)))>indirect(address(row($J4),COLUMN($K$2))):indirect(address(row($J4),COLUMN($S$2))),TRUE()))} -> 6 | AS23: {=if(AS$20=$J4,"-", countif(indirect(address(row($J$2)+ VLOOKUP(AS$20,$J$3:$J$14,1),COLUMN($K$4))):indirect(address(row($J$2)+ VLOOKUP(AS$20,$J$3:$J$14,1),COLUMN($S$2)))>indirect(address(row($J4),COLUMN($K$2))):indirect(address(row($J4),COLUMN($S$2))),TRUE()))} -> 7 | ... AW23: {=if(AW$20=$J4,"-", countif(indirect(address(row($J$2)+ VLOOKUP(AW$20,$J$3:$J$14,1),COLUMN($K$4))):indirect(address(row($J$2)+ VLOOKUP(AW$20,$J$3:$J$14,1),COLUMN($S$2)))>indirect(address(row($J4),COLUMN($K$2))):indirect(address(row($J4),COLUMN($S$2))),TRUE()))} -> 6 | AX23: 2 | AY23: {=INDIRECT("Draft!E"&TEXT(15-VLOOKUP(TRUE,I3:J14,2,0),"0"))} -> Josh Giddey | BA23: =IF($AY23="","", VLOOKUP($AY23,'Final Update'!$P$21:$AD1015,Column(G2),False)) -> 16.1 | BB23: =IF($AY23="","", VLOOKUP($AY23,'Final Update'!$P$21:$AD1015,Column(H2),False)) -> 1.1 | BC23: =IF($AY23="","", VLOOKUP($AY23,'Final Update'!$P$21:$AD1015,Column(I2),False)) -> 7.4 | BD23: =IF($AY23="","", VLOOKUP($AY23,'Final Update'!$P$21:$AD1015,Column(J2),False)) -> 6.1 | BE23: =IF($AY23="","", VLOOKUP($AY23,'Final Update'!$P$21:$AD1015,Column(K2),False)) -> 0.8 | BF23: =IF($AY23="","", VLOOKUP($AY23,'Final Update'!$P$21:$AD1015,Column(L2),False)) -> 0.5 | BG23: =IF($AY23="","", VLOOKUP($AY23,'Final Update'!$P$21:$AD1015,Column(M2),False)) -> 0.479 | BH23: =IF($AY23="","", VLOOKUP($AY23,'Final Update'!$P$21:$AD1015,Column(N2),False)) -> 0.795 | BI23: =IF($AY23="","", VLOOKUP($AY23,'Final Update'!$P$21:$AD1015,Column(O2),False)) -> 2.7 | BJ23: =IF($AY23="","", VLOOKUP($AY23,'Final Update'!$P$21:$AD1015,Column(C2),False)) -> SG,SF | BK23: {=COUNTIF(FIND(BL23,$BJ$22:$BJ$33),">0")} -> 6 | BL23: SG
A24: =VLOOKUP($F24,UpdateHashtag!$V$3:$Y$32,COLUMN(B$15),0) -> 4 | B24: =VLOOKUP($F24,UpdateHashtag!$V$3:$Y$32,COLUMN(C$13),0) -> 4 | C24: =VLOOKUP($F24,UpdateHashtag!$V$3:$Y$32,COLUMN(D$13),0) -> 2 | D24: =SUM(A24:C24) -> 10 | F24: =VLOOKUP(J24,UpdateBBM!$C$2:E1015,3,0) -> DAL | G24: 5 | H24: =IFERROR(__xludf.DUMMYFUNCTION("""COMPUTED_VALUE"""),5.0) -> 5 | I24: =IFERROR(__xludf.DUMMYFUNCTION("""COMPUTED_VALUE"""),7.4) -> 7.4 | J24: =IFERROR(__xludf.DUMMYFUNCTION("""COMPUTED_VALUE"""),"Anthony Davis") -> Anthony Davis | K24: =IFERROR(__xludf.DUMMYFUNCTION("""COMPUTED_VALUE"""),58.0) -> 58 | L24: =IFERROR(__xludf.DUMMYFUNCTION("""COMPUTED_VALUE"""),"PF,C") -> PF,C | M24: =IFERROR(__xludf.DUMMYFUNCTION("""COMPUTED_VALUE"""),8.69583899859487) -> 8.695839 | N24: =IFERROR(__xludf.DUMMYFUNCTION("""COMPUTED_VALUE"""),8.69583899859487) -> 8.695839 | O24: =IFERROR(__xludf.DUMMYFUNCTION("""COMPUTED_VALUE"""),0.0) -> 0 | P24: =IFERROR(__xludf.DUMMYFUNCTION("""COMPUTED_VALUE"""),25.2) -> 25.2 | Q24: =IFERROR(__xludf.DUMMYFUNCTION("""COMPUTED_VALUE"""),0.4) -> 0.4 | R24: =IFERROR(__xludf.DUMMYFUNCTION("""COMPUTED_VALUE"""),12.7) -> 12.7 | S24: =IFERROR(__xludf.DUMMYFUNCTION("""COMPUTED_VALUE"""),3.6) -> 3.6 | T24: =IFERROR(__xludf.DUMMYFUNCTION("""COMPUTED_VALUE"""),1.2) -> 1.2 | U24: =IFERROR(__xludf.DUMMYFUNCTION("""COMPUTED_VALUE"""),2.3) -> 2.3 | V24: =IFERROR(__xludf.DUMMYFUNCTION("""COMPUTED_VALUE"""),0.559) -> 0.559 | W24: =IFERROR(__xludf.DUMMYFUNCTION("""COMPUTED_VALUE"""),0.802) -> 0.802 | X24: =IFERROR(__xludf.DUMMYFUNCTION("""COMPUTED_VALUE"""),2.1) -> 2.1 | Y24: =IFERROR(__xludf.DUMMYFUNCTION("""COMPUTED_VALUE"""),1.3969714736758965) -> 1.3969715 | Z24: =IFERROR(__xludf.DUMMYFUNCTION("""COMPUTED_VALUE"""),-1.3425893849486756) -> -1.3425894 | AA24: =IFERROR(__xludf.DUMMYFUNCTION("""COMPUTED_VALUE"""),2.6011500269824244) -> 2.60115 | AB24: =IFERROR(__xludf.DUMMYFUNCTION("""COMPUTED_VALUE"""),-0.1529789245299426) -> -0.15297892 | AC24: =IFERROR(__xludf.DUMMYFUNCTION("""COMPUTED_VALUE"""),0.7430016239596308) -> 0.74300162 | AD24: =IFERROR(__xludf.DUMMYFUNCTION("""COMPUTED_VALUE"""),2.7739629961565364) -> 2.773963 | AE24: =IFERROR(__xludf.DUMMYFUNCTION("""COMPUTED_VALUE"""),1.2376640116563253) -> 1.237664 | AF24: =IFERROR(__xludf.DUMMYFUNCTION("""COMPUTED_VALUE"""),0.18319218070629753) -> 0.18319218 | AG24: =IFERROR(__xludf.DUMMYFUNCTION("""COMPUTED_VALUE"""),-0.08712439001229988) -> -0.08712439 | AK24: 100 | AL24: {=if(AL$20=$J5,"-", countif(indirect(address(row($J$2)+ VLOOKUP(AL$20,$J$3:$J$14,1),COLUMN($K$4))):indirect(address(row($J$2)+ VLOOKUP(AL$20,$J$3:$J$14,1),COLUMN($S$2)))>indirect(address(row($J5),COLUMN($K$2))):indirect(address(row($J5),COLUMN($S$2))),TRUE()))} -> 7 | AM24: {=if(AM$20=$J5,"-", countif(indirect(address(row($J$2)+ VLOOKUP(AM$20,$J$3:$J$14,1),COLUMN($K$4))):indirect(address(row($J$2)+ VLOOKUP(AM$20,$J$3:$J$14,1),COLUMN($S$2)))>indirect(address(row($J5),COLUMN($K$2))):indirect(address(row($J5),COLUMN($S$2))),TRUE()))} -> 1 | AN24: {=if(AN$20=$J5,"-", countif(indirect(address(row($J$2)+ VLOOKUP(AN$20,$J$3:$J$14,1),COLUMN($K$4))):indirect(address(row($J$2)+ VLOOKUP(AN$20,$J$3:$J$14,1),COLUMN($S$2)))>indirect(address(row($J5),COLUMN($K$2))):indirect(address(row($J5),COLUMN($S$2))),TRUE()))} -> - | AO24: {=if(AO$20=$J5,"-", countif(indirect(address(row($J$2)+ VLOOKUP(AO$20,$J$3:$J$14,1),COLUMN($K$4))):indirect(address(row($J$2)+ VLOOKUP(AO$20,$J$3:$J$14,1),COLUMN($S$2)))>indirect(address(row($J5),COLUMN($K$2))):indirect(address(row($J5),COLUMN($S$2))),TRUE()))} -> 7 | AP24: {=if(AP$20=$J5,"-", countif(indirect(address(row($J$2)+ VLOOKUP(AP$20,$J$3:$J$14,1),COLUMN($K$4))):indirect(address(row($J$2)+ VLOOKUP(AP$20,$J$3:$J$14,1),COLUMN($S$2)))>indirect(address(row($J5),COLUMN($K$2))):indirect(address(row($J5),COLUMN($S$2))),TRUE()))} -> 1 | AQ24: {=if(AQ$20=$J5,"-", countif(indirect(address(row($J$2)+ VLOOKUP(AQ$20,$J$3:$J$14,1),COLUMN($K$4))):indirect(address(row($J$2)+ VLOOKUP(AQ$20,$J$3:$J$14,1),COLUMN($S$2)))>indirect(address(row($J5),COLUMN($K$2))):indirect(address(row($J5),COLUMN($S$2))),TRUE()))} -> 0 | AR24: {=if(AR$20=$J5,"-", countif(indirect(address(row($J$2)+ VLOOKUP(AR$20,$J$3:$J$14,1),COLUMN($K$4))):indirect(address(row($J$2)+ VLOOKUP(AR$20,$J$3:$J$14,1),COLUMN($S$2)))>indirect(address(row($J5),COLUMN($K$2))):indirect(address(row($J5),COLUMN($S$2))),TRUE()))} -> 6 | AS24: {=if(AS$20=$J5,"-", countif(indirect(address(row($J$2)+ VLOOKUP(AS$20,$J$3:$J$14,1),COLUMN($K$4))):indirect(address(row($J$2)+ VLOOKUP(AS$20,$J$3:$J$14,1),COLUMN($S$2)))>indirect(address(row($J5),COLUMN($K$2))):indirect(address(row($J5),COLUMN($S$2))),TRUE()))} -> 6 | ... AW24: {=if(AW$20=$J5,"-", countif(indirect(address(row($J$2)+ VLOOKUP(AW$20,$J$3:$J$14,1),COLUMN($K$4))):indirect(address(row($J$2)+ VLOOKUP(AW$20,$J$3:$J$14,1),COLUMN($S$2)))>indirect(address(row($J5),COLUMN($K$2))):indirect(address(row($J5),COLUMN($S$2))),TRUE()))} -> 6 | AX24: 3 | AY24: {=INDIRECT("Draft!F"&TEXT(VLOOKUP(TRUE,I3:J14,2,0)+2,"0"))} -> Bam Adebayo | BA24: =IF($AY24="","", VLOOKUP($AY24,'Final Update'!$P$21:$AD1015,Column(G3),False)) -> 20 | BB24: =IF($AY24="","", VLOOKUP($AY24,'Final Update'!$P$21:$AD1015,Column(H3),False)) -> 0.2 | BC24: =IF($AY24="","", VLOOKUP($AY24,'Final Update'!$P$21:$AD1015,Column(I3),False)) -> 10.4 | BD24: =IF($AY24="","", VLOOKUP($AY24,'Final Update'!$P$21:$AD1015,Column(J3),False)) -> 3.9 | BE24: =IF($AY24="","", VLOOKUP($AY24,'Final Update'!$P$21:$AD1015,Column(K3),False)) -> 1.2 | BF24: =IF($AY24="","", VLOOKUP($AY24,'Final Update'!$P$21:$AD1015,Column(L3),False)) -> 0.9 | BG24: =IF($AY24="","", VLOOKUP($AY24,'Final Update'!$P$21:$AD1015,Column(M3),False)) -> 0.531 | BH24: =IF($AY24="","", VLOOKUP($AY24,'Final Update'!$P$21:$AD1015,Column(N3),False)) -> 0.743 | BI24: =IF($AY24="","", VLOOKUP($AY24,'Final Update'!$P$21:$AD1015,Column(O3),False)) -> 2.4 | BJ24: =IF($AY24="","", VLOOKUP($AY24,'Final Update'!$P$21:$AD1015,Column(C3),False)) -> C | BK24: {=COUNTIF(FIND(BL24,$BJ$22:$BJ$33),">0")} -> 2 | BL24: SF
